Workbook
Name ABANG: [1]DAT2!#REF!
Name ABANG: [2]DAT2!#REF!
Name ABANG: [3]DAT2!#REF!
Name ABANG: [4]DAT2!#REF!
Name ABANG: [5]DAT2!#REF!
Name ABANG: [6]DAT2!#REF!
Name ABANG: [7]DAT2!#REF!
Name ACOS: [1]DAT2!#REF!
Name ACOS: [2]DAT2!#REF!
Name ACOS: [3]DAT2!#REF!
Name ACOS: [4]DAT2!#REF!
Name ACOS: [5]DAT2!#REF!
Name ACOS: [6]DAT2!#REF!
Name ACOS: [7]DAT2!#REF!
Name ALAJU: [1]DAT2!#REF!
Name ALAJU: [2]DAT2!#REF!
Name ALAJU: [3]DAT2!#REF!
Name ALAJU: [4]DAT2!#REF!
Name ALAJU: [5]DAT2!#REF!
Name ALAJU: [6]DAT2!#REF!
Name ALAJU: [7]DAT2!#REF!
Name ALAJUE: [1]DAT2!#REF!
Name ALAJUE: [2]DAT2!#REF!
Name ALAJUE: [3]DAT2!#REF!
Name ALAJUE: [4]DAT2!#REF!
Name ALAJUE: [5]DAT2!#REF!
Name ALAJUE: [6]DAT2!#REF!
Name ALAJUE: [7]DAT2!#REF!
Name ALVA: [1]DAT2!#REF!
Name ALVA: [2]DAT2!#REF!
Name ALVA: [3]DAT2!#REF!
Name ALVA: [4]DAT2!#REF!
Name ALVA: [5]DAT2!#REF!
Name ALVA: [6]DAT2!#REF!
Name ALVA: [7]DAT2!#REF!
Name ASERR: [1]DAT2!#REF!
Name ASERR: [2]DAT2!#REF!
Name ASERR: [3]DAT2!#REF!
Name ASERR: [4]DAT2!#REF!
Name ASERR: [5]DAT2!#REF!
Name ASERR: [6]DAT2!#REF!
Name ASERR: [7]DAT2!#REF!
Name ATE: [1]DAT2!#REF!
Name ATE: [2]DAT2!#REF!
Name ATE: [3]DAT2!#REF!
Name ATE: [4]DAT2!#REF!
Name ATE: [5]DAT2!#REF!
Name ATE: [6]DAT2!#REF!
Name ATE: [7]DAT2!#REF!
Name BAGAC: [1]DAT2!#REF!
Name BAGAC: [2]DAT2!#REF!
Name BAGAC: [3]DAT2!#REF!
Name BAGAC: [4]DAT2!#REF!
Name BAGAC: [5]DAT2!#REF!
Name BAGAC: [6]DAT2!#REF!
Name BAGAC: [7]DAT2!#REF!
Name BARV: [1]DAT2!#REF!
Name BARV: [2]DAT2!#REF!
Name BARV: [3]DAT2!#REF!
Name BARV: [4]DAT2!#REF!

Sheet D10 Curridabat
A1: PROGRAMA | B1: D10 Curridabat | C1: META | D1: AVANCE | E1: ENERO | F1: FEBRERO | G1: MARZO | H1: ABRIL | I1: MAYO | J1: JUNIO | K1: JULIO | L1: AGOSTO | M1: SEPTIEMBRE | N1: OCTUBRE | O1: NOVIEMBRE | P1: DICIEMBRE
C2: 2026 | D2: Porcentual
A3: PSCC | B3: Cuatro actividades de recuperación de espacios públicos, con las comunidades integradas al Programa de Seguridad Comunitaria, que se localicen, en los distritos que contemplan las área georreferenciadas del informe territorial de la Estrategia Sembremos Seguridad 2024, dos por año, una por semestre. | C3: 2 | D3: =SUM(E3:P3) -> 1 | H3: 1
A4: GREAT/MPAS/DARE | B4: Realizar 4 procesos formativos (Cursos de la oferta de los programas DARE - GREAT - MPAS) en Centros Educativos, 2 por año, dentro de los distritos que contemplan las áreas georreferenciadas del informe territorial de la Estrategia Sembremos Seguridad 2024. Un curso diferente por semestre, un nivel completo. En caso de no contar con instructor acreditado DARE, se puede cumplir la meta con las charlas de Habilidades para la vida DARE, con el aval del Coordinador Nacional. | C4: 2 | D4: =SUM(E4:P4) -> 0
A5: DARE | B5: Cubrir 2 procesos formativos en Centros Educativos (uno por año) ubicados dentro de los distritos que contemplan las áreas georreferenciadas del informe territorial de la Estrategia Sembremos Seguridad 2024, con los cursos del Programa DARE: , Curso primaria. Curso Secundaria; un nivel completo por centro educativo, por semestre. En caso de no contar con instructor acreditado, se puede cumplir la meta con las charlas de Habilidades para la vida DARE, con el aval del Coordinador Nacional. | C5: 1 | D5: =SUM(E5:P5) -> 1 | E5: 0 | F5: 0 | G5: 0 | H5: 1
A6: PSCC | B6: Cuatro actividades de recuperación de espacios públicos, con las comunidades integradas al Programa de Seguridad Comunitaria, que se localicen, en los distritos que contemplan las área georreferenciadas del informe territorial de la Estrategia Sembremos Seguridad 2024, dos por año, una por semestre. | C6: 2 | D6: =SUM(E6:P6) -> 0
A7: PSCC | B7: Cuatro comercios capacitados e integrados al Programa de Seguridad Comercial que se localicen, en los distritos que contemplan las áreas georreferenciadas del informe territorial de la Estrategia Sembremos Seguridad 2024, dos por año, una por semestre. | C7: 2 | D7: =SUM(E7:P7) -> 0
A8: PSCC | B8: Cuatro estrategias de divulgación (Por medio de brochures, post o imágenes en redes sociales) diseñadas por la Estrategia de divulgación de la Dirección de Programas Policiales Preventivos, en el tema de "Prevención del Consumo de alcohol en vía pública" dirigidas a las comunidades integradas al Programa de Seguridad Comunitaria y a los comercios integrados al Programa de Seguridad Comercial que se localicen, en los distritos que contemplan las área georreferenciadas del informe territorial de la Estrategia Sembremos Seguridad 2024, dos por año. | C8: 2 | D8: =SUM(E8:P8) -> 0
A9: PSCC | B9: Dos estrategias de divulgación (Por medio de brochures, post o imágenes en redes sociales) en el tema del procedimiento para realizar una "Denuncia ante daños" diseñadas por la Estrategia de divulgación de la Dirección de Programas Policiales Preventivos dirigidas a las comunidades integradas al Programa de Seguridad Comunitaria que se localicen, en los distritos que contemplan las área georreferenciadas del informe territorial de la Estrategia Sembremos Seguridad 2024, una por año. | C9: 1 | D9: =SUM(E9:P9) -> 1 | J9: 1
A10: PSCC | B10: Cuatro capacitaciones, en el tema de Denuncia, dirigidas a las comunidades integradas al Programa de Seguridad Comunitaria, que se localicen, en los distritos que contemplan las área georreferenciadas del informe territorial de la Estrategia Sembremos Seguridad 2024, dos por año, una por semestre. | C10: 2 | D10: =SUM(E10:P10) -> 1 | H10: 1
A11: PLAN DE POLITICA LOCAL E IMPLEMENTACIÓN DE LA POLITICA LOCAL DE SEGURIDAD | B11: Conformación Comité | C11: 3 | D11: =SUM(E11:P11) -> 2 | G11: 1 | H11: 1
B12: Conformación de Comercio | C12: 3 | D12: =SUM(E12:P12) -> 0
B13: Reuniones-Jefaturas | C13: 48 | D13: =SUM(E13:P13) -> 20 | E13: 4 | F13: 4 | G13: 3 | H13: 4 | I13: 4 | J13: 1
B14: Campañas de divulgación | C14: 18 | D14: =SUM(E14:P14) -> 6 | E14: 6
B15: Capacitaciones | C15: 5 | D15: =SUM(E15:P15) -> 5 | H15: 5
B16: Charlas | C16: 0 | D16: =SUM(E16:P16) -> 0
B17: Talleres | C17: 0 | D17: =SUM(E17:P17) -> 0
B18: Sensibilización | C18: 0 | D18: =SUM(E18:P18) -> 0
B19: Actividades deportivas | C19: 0 | D19: =SUM(E19:P19) -> 0
B20: Cine en mi Barrio | C20: 0 | D20: =SUM(E20:P20) -> 0
B21: Cívico-policial | C21: 5 | D21: =SUM(E21:P21) -> 0
B22: Actividades culturales | C22: 0 | D22: =SUM(E22:P22) -> 0
B23: Ferias | C23: 0 | D23: =SUM(E23:P23) -> 0
B24: Stand informativo | C24: 11 | D24: =SUM(E24:P24) -> 0
B25: Visitas | C25: 93 | D25: =SUM(E25:P25) -> 44 | E25: 13 | G25: 10 | H25: 13 | I25: 8
B26: Recuperación del espacio público | C26: 8 | D26: =SUM(E26:P26) -> 6 | E26: 5 | F26: 1
B27: Convocatoria de Mesas Locales | C27: 4 | D27: =SUM(E27:P27) -> 3 | F27: 2 | G27: 1
B28: Exposición Informe Territorial ESS | C28: 4 | D28: =SUM(E28:P28) -> 4 | H28: 4
B29: Primera Sesión de Trabajo | C29: 4 | D29: =SUM(E29:P29) -> 4 | I29: 4
B30: Segunda Sesión - Conformación Secretaria Técnica | C30: 4 | D30: =SUM(E30:P30) -> 0
B31: Tercera Sesión | C31: 4 | D31: =SUM(E31:P31) -> 0
B32: Elaboracióin del Texto de la Política Local | C32: 1 | D32: =SUM(E32:P32) -> 0
B33: Revisión Técnica DPPP | C33: 1 | D33: =SUM(E33:P33) -> 0
B34: Revisión Area Legal Gobierno Local | C34: 1 | D34: =SUM(E34:P34) -> 0
B35: Incorporación de Observaciones | C35: 1 | D35: =SUM(E35:P35) -> 0
B36: Aval del Director Regional | C36: 1 | D36: =SUM(E36:P36) -> 0
B37: Presentación al Consejo Municipal | C37: 1 | D37: =SUM(E37:P37) -> 0
B38: Presentación ante la Comunidad por parte del Director Regional y Alcalde | C38: 1 | D38: =SUM(E38:P38) -> 0
C39: =SUM(C3:C38) -> 235 | D39: =SUM(D3:D38) -> 98
D40: =D39/C39 -> 0.41702128

Sheet D11 Montes de Oca
A1: PROGRAMA | B1: D11 Montes de Oca | C1: META | D1: AVANCE | E1: ENERO | F1: FEBRERO | G1: MARZO | H1: ABRIL | I1: MAYO | J1: JUNIO | K1: JULIO | L1: AGOSTO | M1: SEPTIEMBRE | N1: OCTUBRE | O1: NOVIEMBRE | P1: DICIEMBRE
C2: 2026 | D2: Porcentual
A3: PSCC | B3: Cubrir 4 procesos formativos en Centros Educativos (dos por año) ubicados dentro de los distritos que contemplan las áreas georreferenciadas del informe territorial de la Estrategia Sembremos Seguridad 2024, con los cursos del Programa DARE: , Curso primaria. Curso Secundaria; un nivel completo por centro educativo, por semestre. En caso de no contar con instructor acreditado, se puede cumplir la meta con las charlas de Habilidades para la vida DARE, con el aval del Coordinador Nacional. | C3: 2 | D3: =SUM(E3:P3) -> 0
A4: GREAT/MPAS/DARE | B4: Cuatro actividades de recuperación de espacios públicos, con las comunidades integradas al Programa de Seguridad Comunitaria, que se localicen, en los distritos que contemplan las área georreferenciadas del informe territorial de la Estrategia Sembremos Seguridad 2024, dos por año, una por semestre. | C4: 2 | D4: =SUM(E4:P4) -> 1 | E4: 0 | F4: 0 | G4: 1 | H4: 0
A5: DARE | B5: Realizar 4 procesos formativos (Cursos de la oferta de los programas DARE - GREAT - MPAS) en Centros Educativos, 2 por año, dentro de los distritos que contemplan las áreas georreferenciadas del informe territorial de la Estrategia Sembremos Seguridad 2024. Un curso diferente por semestre, un nivel completo. En caso de no contar con instructor acreditado DARE, se puede cumplir la meta con las charlas de Habilidades para la vida DARE, con el aval del Coordinador Nacional. | C5: 1 | D5: =SUM(E5:P5) -> 1 | E5: 0 | F5: 0 | G5: 0 | H5: 1
A6: PLAN DE POLITICA LOCAL E IMPLEMENTACIÓN DE LA POLITICA LOCAL DE SEGURIDAD | B6: Conformación Comité | C6: 3 | D6: =SUM(E6:P6) -> 2 | I6: 2
B7: Conformación de Comercio | C7: 3 | D7: =SUM(E7:P7) -> 0
B8: Reuniones-Jefaturas | C8: 48 | D8: =SUM(E8:P8) -> 21 | F8: 6 | G8: 3 | H8: 5 | I8: 5 | J8: 2
B9: Campañas de divulgación | C9: 9 | D9: =SUM(E9:P9) -> 5 | F9: 3 | G9: 2
B10: Capacitaciones | C10: 12 | D10: =SUM(E10:P10) -> 13 | F10: 3 | G10: 3 | H10: 2 | I10: 3 | J10: 2
B11: Charlas | C11: 16 | D11: =SUM(E11:P11) -> 5 | H11: 3 | I11: 2
B12: Talleres | C12: 1 | D12: =SUM(E12:P12) -> 0
B13: Sensibilización | C13: 4 | D13: =SUM(E13:P13) -> 0
B14: Actividades deportivas | C14: 0 | D14: =SUM(E14:P14) -> 0
B15: Cine en mi Barrio | C15: 2 | D15: =SUM(E15:P15) -> 0
B16: Cívico-policial | C16: 0 | D16: =SUM(E16:P16) -> 0
B17: Actividades culturales | C17: 1 | D17: =SUM(E17:P17) -> 0
B18: Ferias | C18: 0 | D18: =SUM(E18:P18) -> 0
B19: Stand informativo | C19: 0 | D19: =SUM(E19:P19) -> 0
B20: Visitas | C20: 88 | D20: =SUM(E20:P20) -> 39 | E20: 22 | H20: 17
B21: Recuperación del espacio público | C21: 3 | D21: =SUM(E21:P21) -> 0
B22: Convocatoria de Mesas Locales | C22: 4 | D22: =SUM(E22:P22) -> 4 | G22: 2 | H22: 2
B23: Exposición Informe Territorial ESS | C23: 4 | D23: =SUM(E23:P23) -> 4 | H23: 4
B24: Primera Sesión de Trabajo | C24: 4 | D24: =SUM(E24:P24) -> 4 | I24: 4
B25: Segunda Sesión - Conformación Secretaria Técnica | C25: 4 | D25: =SUM(E25:P25) -> 0
B26: Tercera Sesión | C26: 4 | D26: =SUM(E26:P26) -> 0
B27: Elaboracióin del Texto de la Política Local | C27: 1 | D27: =SUM(E27:P27) -> 0
B28: Revisión Técnica DPPP | C28: 1 | D28: =SUM(E28:P28) -> 0
B29: Revisión Area Legal Gobierno Local | C29: 1 | D29: =SUM(E29:P29) -> 0
B30: Incorporación de Observaciones | C30: 1 | D30: =SUM(E30:P30) -> 0
B31: Aval del Director Regional | C31: 1 | D31: =SUM(E31:P31) -> 0
B32: Presentación al Consejo Municipal | C32: 1 | D32: =SUM(E32:P32) -> 0
B33: Presentación ante la Comunidad por parte del Director Regional y Alcalde | C33: 1 | D33: =SUM(E33:P33) -> 0
C34: =SUM(C3:C33) -> 222 | D34: =SUM(D3:D33) -> 99
D35: =D34/C34 -> 0.44594595

Sheet D12 Goicoechea
A1: PROGRAMA | B1: D12 Goicoechea | C1: META | D1: AVANCE | E1: ENERO | F1: FEBRERO | G1: MARZO | H1: ABRIL | I1: MAYO | J1: JUNIO | K1: JULIO | L1: AGOSTO | M1: SEPTIEMBRE | N1: OCTUBRE | O1: NOVIEMBRE | P1: DICIEMBRE
C2: 2026 | D2: Porcentual
A3: PSCC | B3: Cuatro actividades de recuperación de espacios públicos, con las comunidades integradas al Programa de Seguridad Comunitaria, que se localicen, en los distritos que contemplan las área georreferenciadas del informe territorial de la Estrategia Sembremos Seguridad 2024, dos por año, una por semestre. | C3: 2 | D3: =SUM(E3:P3) -> 1 | G3: 1
A4: GREAT/MPAS/DARE | B4: Realizar 4 procesos formativos (Cursos de la oferta de los programas DARE - GREAT - MPAS) en Centros Educativos, 2 por año, dentro de los distritos que contemplan las áreas georreferenciadas del informe territorial de la Estrategia Sembremos Seguridad 2024. Un curso diferente por semestre, un nivel completo. En caso de no contar con instructor acreditado DARE, se puede cumplir la meta con las charlas de Habilidades para la vida DARE, con el aval del Coordinador Nacional. | C4: 2 | D4: =SUM(E4:P4) -> 1 | E4: 0 | F4: 0 | G4: 0 | H4: 0 | J4: 1
A5: PSCC | B5: Dos estrategias de divulgación (Por medio de brochures, post o imágenes en redes sociales) en el tema del procedimiento para realizar una "Denuncia de ventas de drogas" diseñadas por la Estrategia de divulgación de la Dirección de Programas Policiales Preventivos dirigidas a las comunidades integradas al Programa de Seguridad Comunitaria que se localicen, en los distritos que contemplan las área georreferenciadas del informe territorial de la Estrategia Sembremos Seguridad 2024, una por año. | C5: 1 | D5: =SUM(E5:P5) -> 0
A6: PSCC | B6: Cuatro capacitaciones, en el tema de Denuncia, dirigidas a las comunidades integradas al Programa de Seguridad Comunitaria, que se localicen, en los distritos que contemplan las área georreferenciadas del informe territorial de la Estrategia Sembremos Seguridad 2024, dos por año, una por semestre. | C6: 2 | D6: =SUM(E6:P6) -> 0
A7: PLAN DE POLITICA LOCAL E IMPLEMENTACIÓN DE LA POLITICA LOCAL DE SEGURIDAD | B7: Conformación Comité | C7: 3 | D7: =SUM(E7:P7) -> 0
B8: Conformación de Comercio | C8: 3 | D8: =SUM(E8:P8) -> 0
B9: Reuniones-Jefaturas | C9: 80 | D9: =SUM(E9:P9) -> 35 | E9: 5 | F9: 3 | G9: 10 | H9: 6 | I9: 6 | J9: 5
B10: Campañas de divulgación | C10: 22 | D10: =SUM(E10:P10) -> 21 | H10: 21
B11: Capacitaciones | C11: 0 | D11: =SUM(E11:P11) -> 0
B12: Charlas | C12: 0 | D12: =SUM(E12:P12) -> 0
B13: Talleres | C13: 0 | D13: =SUM(E13:P13) -> 0
B14: Sensibilización | C14: 0 | D14: =SUM(E14:P14) -> 0
B15: Actividades deportivas | C15: 0 | D15: =SUM(E15:P15) -> 0
B16: Cine en mi Barrio | C16: 0 | D16: =SUM(E16:P16) -> 0
B17: Cívico-policial | C17: 0 | D17: =SUM(E17:P17) -> 0
B18: Actividades culturales | C18: 0 | D18: =SUM(E18:P18) -> 0
B19: Ferias | C19: 0 | D19: =SUM(E19:P19) -> 0
B20: Stand informativo | C20: 0 | D20: =SUM(E20:P20) -> 0
B21: Visitas | C21: 164 | D21: =SUM(E21:P21) -> 77 | E21: 12 | F21: 20 | G21: 9 | H21: 13 | I21: 20 | J21: 3
B22: Recuperación del espacio público | C22: 0 | D22: =SUM(E22:P22) -> 0
B23: Convocatoria de Mesas Locales | C23: 6 | D23: =SUM(E23:P23) -> 6 | G23: 5 | H23: 1
B24: Exposición Informe Territorial ESS | C24: 6 | D24: =SUM(E24:P24) -> 6 | H24: 6
B25: Primera Sesión de Trabajo | C25: 6 | D25: =SUM(E25:P25) -> 0
B26: Segunda Sesión - Conformación Secretaria Técnica | C26: 6 | D26: =SUM(E26:P26) -> 0
B27: Tercera Sesión | C27: 6 | D27: =SUM(E27:P27) -> 0
B28: Elaboracióin del Texto de la Política Local | C28: 1 | D28: =SUM(E28:P28) -> 0
B29: Revisión Técnica DPPP | C29: 1 | D29: =SUM(E29:P29) -> 0
B30: Revisión Area Legal Gobierno Local | C30: 1 | D30: =SUM(E30:P30) -> 0
B31: Incorporación de Observaciones | C31: 1 | D31: =SUM(E31:P31) -> 0
B32: Aval del Director Regional | C32: 1 | D32: =SUM(E32:P32) -> 0
B33: Presentación al Consejo Municipal | C33: 1 | D33: =SUM(E33:P33) -> 0
B34: Presentación ante la Comunidad por parte del Director Regional y Alcalde | C34: 1 | D34: =SUM(E34:P34) -> 0
C35: =SUM(C3:C34) -> 316 | D35: =SUM(D3:D34) -> 147
D36: =D35/C35 -> 0.46518987

Sheet D13 Moravia
A1: PROGRAMA | B1: D13 Moravia | C1: META | D1: AVANCE | E1: ENERO | F1: FEBRERO | G1: MARZO | H1: ABRIL | I1: MAYO | J1: JUNIO | K1: JULIO | L1: AGOSTO | M1: SEPTIEMBRE | N1: OCTUBRE | O1: NOVIEMBRE | P1: DICIEMBRE
C2: 2026 | D2: Porcentual
A3: GREAT/MPAS/DARE | B3: Realizar 4 procesos formativos (Cursos de la oferta de los programas DARE - GREAT - MPAS) en Centros Educativos, 2 por año, dentro de los distritos que contemplan las áreas georreferenciadas del informe territorial de la Estrategia Sembremos Seguridad 2024. Un curso diferente por semestre, un nivel completo. En caso de no contar con instructor acreditado DARE, se puede cumplir la meta con las charlas de Habilidades para la vida DARE, con el aval del Coordinador Nacional. | C3: 2 | D3: =SUM(E3:P3) -> 0 | E3: 0 | F3: 0 | G3: 0 | H3: 0
A4: PLAN DE POLITICA LOCAL E IMPLEMENTACIÓN DE LA POLITICA LOCAL DE SEGURIDAD | B4: Conformación Comité | C4: 3 | D4: =SUM(E4:O4) -> 0
B5: Conformación de Comercio | C5: 3 | D5: =SUM(E5:O5) -> 0
B6: Reuniones-Jefaturas | C6: 56 | D6: =SUM(E6:O6) -> 17 | E6: 5 | G6: 4 | H6: 5 | I6: 3
B7: Campañas de divulgación | C7: 171 | D7: =SUM(E7:O7) -> 0
B8: Capacitaciones | C8: 0 | D8: =SUM(E8:O8) -> 0
B9: Charlas | C9: 0 | D9: =SUM(E9:O9) -> 0
B10: Talleres | C10: 0 | D10: =SUM(E10:O10) -> 0
B11: Sensibilización | C11: 0 | D11: =SUM(E11:O11) -> 0
B12: Actividades deportivas | C12: 0 | D12: =SUM(E12:O12) -> 0
B13: Cine en mi Barrio | C13: 0 | D13: =SUM(E13:O13) -> 0
B14: Cívico-policial | C14: 0 | D14: =SUM(E14:O14) -> 0
B15: Actividades culturales | C15: 0 | D15: =SUM(E15:O15) -> 0
B16: Ferias | C16: 0 | D16: =SUM(E16:O16) -> 0
B17: Stand informativo | C17: 0 | D17: =SUM(E17:O17) -> 0
B18: Visitas | C18: 172 | D18: =SUM(E18:O18) -> 67 | E18: 13 | F18: 7 | G18: 10 | H18: 13 | I18: 9 | J18: 15
B19: Recuperación del espacio público | C19: 0 | D19: =SUM(E19:O19) -> 0
B20: Convocatoria de Mesas Locales | C20: 4 | D20: =SUM(E20:O20) -> 3 | G20: 3
B21: Exposición Informe Territorial ESS | C21: 4 | D21: =SUM(E21:O21) -> 4 | H21: 4
B22: Primera Sesión de Trabajo | C22: 4 | D22: =SUM(E22:O22) -> 4 | I22: 4
B23: Segunda Sesión - Conformación Secretaria Técnica | C23: 4 | D23: =SUM(E23:O23) -> 0
B24: Tercera Sesión | C24: 4 | D24: =SUM(E24:O24) -> 0
B25: Elaboracióin del Texto de la Política Local | C25: 1 | D25: =SUM(E25:O25) -> 0
B26: Revisión Técnica DPPP | C26: 1 | D26: =SUM(E26:O26) -> 0
B27: Revisión Area Legal Gobierno Local | C27: 1 | D27: =SUM(E27:O27) -> 0
B28: Incorporación de Observaciones | C28: 1 | D28: =SUM(E28:O28) -> 0
B29: Aval del Director Regional | C29: 1 | D29: =SUM(E29:O29) -> 0
B30: Presentación al Consejo Municipal | C30: 1 | D30: =SUM(E30:O30) -> 0
B31: Presentación ante la Comunidad por parte del Director Regional y Alcalde | C31: 1 | D31: =SUM(E31:O31) -> 0
C32: =SUM(C3:C31) -> 434 | D32: =SUM(D3:D31) -> 95
D33: =D32/C32 -> 0.21889401

Sheet D14 Tibás
A1: PROGRAMA | B1: D14 Tibás | C1: META | D1: AVANCE | E1: ENERO | F1: FEBRERO | G1: MARZO | H1: ABRIL | I1: MAYO | J1: JUNIO | K1: JULIO | L1: AGOSTO | M1: SEPTIEMBRE | N1: OCTUBRE | O1: NOVIEMBRE | P1: DICIEMBRE
C2: 2026 | D2: Porcentual
A3: PSCC | B3: Cubrir 4 procesos formativos en Centros Educativos (dos por año) ubicados dentro de los distritos que contemplan las áreas georreferenciadas del informe territorial de la Estrategia Sembremos Seguridad 2024, con los cursos del Programa DARE: , Curso primaria. Curso Secundaria; un nivel completo por centro educativo, por semestre. En caso de no contar con instructor acreditado, se puede cumplir la meta con las charlas de Habilidades para la vida DARE, con el aval del Coordinador Nacional. | C3: 2 | D3: =SUM(E3:P3) -> 1 | E3: 0 | F3: 0 | G3: 0 | H3: 1
A4: GREAT/MPAS/DARE | B4: Realizar 4 procesos formativos (Cursos de la oferta de los programas DARE - GREAT - MPAS) en Centros Educativos, 2 por año, dentro de los distritos que contemplan las áreas georreferenciadas del informe territorial de la Estrategia Sembremos Seguridad 2024. Un curso diferente por semestre, un nivel completo. En caso de no contar con instructor acreditado DARE, se puede cumplir la meta con las charlas de Habilidades para la vida DARE, con el aval del Coordinador Nacional. | C4: 2 | D4: =SUM(E4:P4) -> 1 | E4: 0 | F4: 0 | G4: 0 | H4: 0 | I4: 1
A5: PSCC | B5: Cuatro capacitaciones, en el tema de "Denuncia a búnkers", dirigidas a las comunidades integradas al Programa de Seguridad Comunitaria que se localicen, en los distritos que contemplan las área georreferenciadas del informe territorial de la Estrategia Sembremos Seguridad 2024, dos por año, una por semestre. | C5: 2 | D5: =SUM(E5:P5) -> 2 | H5: 2
A6: PSCC | B6: Dos estrategias de divulgación (Por medio de brochures, post o imágenes en redes sociales) en el tema del procedimiento para realizar una "Denuncia de búnkers" dirigidas a las comunidades integradas al Programa de Seguridad Comunitaria que se localicen, en los distritos que contemplan las área georreferenciadas del informe territorial de la Estrategia Sembremos Seguridad 2024, una por año. | C6: 1 | D6: =SUM(E6:P6) -> 1 | H6: 1
A7: PLAN DE POLITICA LOCAL E IMPLEMENTACIÓN DE LA POLITICA LOCAL DE SEGURIDAD | B7: Conformación Comité | C7: 3 | D7: =SUM(E7:P7) -> 1 | G7: 1
B8: Conformación de Comercio | C8: 3 | D8: =SUM(E8:P8) -> 0
B9: Reuniones-Jefaturas | C9: 52 | D9: =SUM(E9:P9) -> 14 | E9: 2 | F9: 7 | G9: 2 | H9: 2 | I9: 1
B10: Campañas de divulgación | C10: 33 | D10: =SUM(E10:P10) -> 11 | G10: 11
B11: Capacitaciones | C11: 0 | D11: =SUM(E11:P11) -> 0
B12: Charlas | C12: 3 | D12: =SUM(E12:P12) -> 0
B13: Talleres | C13: 0 | D13: =SUM(E13:P13) -> 0
B14: Sensibilización | C14: 0 | D14: =SUM(E14:P14) -> 0
B15: Actividades deportivas | C15: 4 | D15: =SUM(E15:P15) -> 0
B16: Cine en mi Barrio | C16: 2 | D16: =SUM(E16:P16) -> 0
B17: Cívico-policial | C17: 2 | D17: =SUM(E17:P17) -> 0
B18: Actividades culturales | C18: 0 | D18: =SUM(E18:P18) -> 0
B19: Ferias | C19: 0 | D19: =SUM(E19:P19) -> 0
B20: Stand informativo | C20: 0 | D20: =SUM(E20:P20) -> 0
B21: Visitas | C21: 105 | D21: =SUM(E21:P21) -> 32 | F21: 16 | I21: 16
B22: Recuperación del espacio público | C22: 3 | D22: =SUM(E22:P22) -> 0
B23: Convocatoria de Mesas Locales | C23: 5 | D23: =SUM(E23:P23) -> 3 | E23: 2 | F23: 1
B24: Exposición Informe Territorial ESS | C24: 5 | D24: =SUM(E24:P24) -> 5 | F24: 5
B25: Primera Sesión de Trabajo | C25: 5 | D25: =SUM(E25:P25) -> 5 | H25: 5
B26: Segunda Sesión - Conformación Secretaria Técnica | C26: 5 | D26: =SUM(E26:P26) -> 0
B27: Tercera Sesión | C27: 5 | D27: =SUM(E27:P27) -> 0
B28: Elaboracióin del Texto de la Política Local | C28: 1 | D28: =SUM(E28:P28) -> 0
B29: Revisión Técnica DPPP | C29: 1 | D29: =SUM(E29:P29) -> 0
B30: Revisión Area Legal Gobierno Local | C30: 1 | D30: =SUM(E30:P30) -> 0
B31: Incorporación de Observaciones | C31: 1 | D31: =SUM(E31:P31) -> 0
B32: Aval del Director Regional | C32: 1 | D32: =SUM(E32:P32) -> 0
B33: Presentación al Consejo Municipal | C33: 1 | D33: =SUM(E33:P33) -> 0
B34: Presentación ante la Comunidad por parte del Director Regional y Alcalde | C34: 1 | D34: =SUM(E34:P34) -> 0
C35: =SUM(C3:C34) -> 249 | D35: =SUM(D3:D34) -> 76
D36: =D35/C35 -> 0.30522088
C43: 3
C44: 3
C45: 52
C46: 33
...

Sheet D15 Coronado
A1: PROGRAMA | B1: D15 Vasquez de Coronado | C1: META | D1: AVANCE | E1: ENERO | F1: FEBRERO | G1: MARZO | H1: ABRIL | I1: MAYO | J1: JUNIO | K1: JULIO | L1: AGOSTO | M1: SEPTIEMBRE | N1: OCTUBRE | O1: NOVIEMBRE | P1: DICIEMBRE
C2: 2026 | D2: Porcentual
A3: PSCC | B3: Dos actividades de recuperación de espacios públicos, con las comunidades integradas al Programa de Seguridad Comunitaria, que se localicen, en los distritos que contemplan las área georreferenciadas del informe territorial de la Estrategia Sembremos Seguridad 2024, una por año. | C3: 1 | D3: =SUM(E3:P3) -> 1 | G3: 1
A4: GREAT/MPAS/DARE | B4: Realizar 4 procesos formativos (Cursos de la oferta de los programas DARE - GREAT - MPAS) en Centros Educativos, 2 por año, dentro de los distritos que contemplan las áreas georreferenciadas del informe territorial de la Estrategia Sembremos Seguridad 2024. Un curso diferente por semestre, un nivel completo. En caso de no contar con instructor acreditado DARE, se puede cumplir la meta con las charlas de Habilidades para la vida DARE, con el aval del Coordinador Nacional. | C4: 2 | D4: =SUM(E4:P4) -> 0 | E4: 0 | F4: 0 | G4: 0 | H4: 0
A5: DARE | B5: Cubrir 2 procesos formativos en Centros Educativos (uno por año) ubicados dentro de los distritos que contemplan las áreas georreferenciadas del informe territorial de la Estrategia Sembremos Seguridad 2024, con los cursos del Programa DARE: Curso primaria. Curso Secundaria; un nivel completo por centro educativo, por semestre. En caso de no contar con instructor acreditado, se puede cumplir la meta con las charlas de Habilidades para la vida DARE, con el aval del Coordinador Nacional. | C5: 1 | D5: =SUM(E5:P5) -> 0 | E5: 0 | F5: 0 | G5: 0 | H5: 0
A6: PLAN DE POLITICA LOCAL E IMPLEMENTACIÓN DE LA POLITICA LOCAL DE SEGURIDAD | B6: Conformación Comité | C6: 3 | D6: =SUM(E6:P6) -> 3 | F6: 1 | G6: 1 | H6: 1
B7: Conformación de Comercio | C7: 3 | D7: =SUM(E7:P7) -> 0
B8: Reuniones-Jefaturas | C8: 52 | D8: =SUM(E8:P8) -> 23 | E8: 4 | F8: 6 | G8: 3 | H8: 2 | I8: 5 | J8: 3
B9: Campañas de divulgación | C9: 33 | D9: =SUM(E9:P9) -> 29 | G9: 7 | H9: 22
B10: Capacitaciones | C10: 0 | D10: =SUM(E10:P10) -> 0
B11: Charlas | C11: 3 | D11: =SUM(E11:P11) -> 0
B12: Talleres | C12: 0 | D12: =SUM(E12:P12) -> 0
B13: Sensibilización | C13: 0 | D13: =SUM(E13:P13) -> 0
B14: Actividades deportivas | C14: 4 | D14: =SUM(E14:P14) -> 2 | G14: 2
B15: Cine en mi Barrio | C15: 2 | D15: =SUM(E15:P15) -> 1 | E15: 1
B16: Cívico-policial | C16: 2 | D16: =SUM(E16:P16) -> 0
B17: Actividades culturales | C17: 0 | D17: =SUM(E17:P17) -> 0
B18: Ferias | C18: 0 | D18: =SUM(E18:P18) -> 0
B19: Stand informativo | C19: 0 | D19: =SUM(E19:P19) -> 0
B20: Visitas | C20: 105 | D20: =SUM(E20:P20) -> 39 | E20: 13 | F20: 6 | G20: 7 | H20: 2 | I20: 10 | J20: 1
B21: Recuperación del espacio público | C21: 3 | D21: =SUM(E21:P21) -> 1 | G21: 1
B22: Convocatoria de Mesas Locales | C22: 5 | D22: =SUM(E22:P22) -> 2 | G22: 2
B23: Exposición Informe Territorial ESS | C23: 5 | D23: =SUM(E23:P23) -> 5 | H23: 5
B24: Primera Sesión de Trabajo | C24: 5 | D24: =SUM(E24:P24) -> 5 | I24: 5
B25: Segunda Sesión - Conformación Secretaria Técnica | C25: 5 | D25: =SUM(E25:P25) -> 0
B26: Tercera Sesión | C26: 5 | D26: =SUM(E26:P26) -> 0
B27: Elaboracióin del Texto de la Política Local | C27: 1 | D27: =SUM(E27:P27) -> 0
B28: Revisión Técnica DPPP | C28: 1 | D28: =SUM(E28:P28) -> 0
B29: Revisión Area Legal Gobierno Local | C29: 1 | D29: =SUM(E29:P29) -> 0
B30: Incorporación de Observaciones | C30: 1 | D30: =SUM(E30:P30) -> 0
B31: Aval del Director Regional | C31: 1 | D31: =SUM(E31:P31) -> 0
B32: Presentación al Consejo Municipal | C32: 1 | D32: =SUM(E32:P32) -> 0
B33: Presentación ante la Comunidad por parte del Director Regional y Alcalde | C33: 1 | D33: =SUM(E33:P33) -> 0
C34: =SUM(C3:C33) -> 246 | D34: =SUM(D3:D33) -> 111
D35: =D34/C34 -> 0.45121951

Sheet Total Region
A1: Delegación | C1: META | D1: AVANCE | E1: % AVANCE
A2: D10 | B2: CURRIDABAT | C2: ='D10 Curridabat'!C39 -> 235 | D2: ='D10 Curridabat'!D39 -> 98 | E2: ='D10 Curridabat'!D40 -> 0.41702128
A3: D11 | B3: MONTES DE OCA | C3: ='D11 Montes de Oca'!C34 -> 222 | D3: ='D11 Montes de Oca'!D34 -> 99 | E3: ='D11 Montes de Oca'!D35 -> 0.44594595
A4: D12 | B4: GOICOECHEA | C4: ='D12 Goicoechea'!C35 -> 316 | D4: ='D12 Goicoechea'!D35 -> 147 | E4: ='D12 Goicoechea'!D36 -> 0.46518987
A5: D13 | B5: MORAVIA | C5: ='D13 Moravia'!C32 -> 434 | D5: ='D13 Moravia'!D32 -> 95 | E5: ='D13 Moravia'!D33 -> 0.21889401
A6: D14 | B6: TIBÁS | C6: ='D14 Tibás'!C35 -> 249 | D6: ='D14 Tibás'!D35 -> 76 | E6: ='D14 Tibás'!D36 -> 0.30522088
A7: D15 | B7: VASQUEZ DE CORONADO | C7: ='D15 Coronado'!C34 -> 246 | D7: ='D15 Coronado'!D34 -> 111 | E7: ='D15 Coronado'!D35 -> 0.45121951
B8: TOTALES | C8: =SUM(C2:C7) -> 1702 | D8: =SUM(D2:D7) -> 626 | E8: =D8/C8 -> 0.36780259
