Workbook
Name ABANG: [1]DAT2!#REF!
Name ABANG: [2]DAT2!#REF!
Name ABANG: [3]DAT2!#REF!
Name ABANG: [4]DAT2!#REF!
Name ACOS: [1]DAT2!#REF!
Name ACOS: [2]DAT2!#REF!
Name ACOS: [3]DAT2!#REF!
Name ACOS: [4]DAT2!#REF!
Name ALAJU: [1]DAT2!#REF!
Name ALAJU: [2]DAT2!#REF!
Name ALAJU: [3]DAT2!#REF!
Name ALAJU: [4]DAT2!#REF!
Name ALAJUE: [1]DAT2!#REF!
Name ALAJUE: [2]DAT2!#REF!
Name ALAJUE: [3]DAT2!#REF!
Name ALAJUE: [4]DAT2!#REF!
Name ALVA: [1]DAT2!#REF!
Name ALVA: [2]DAT2!#REF!
Name ALVA: [3]DAT2!#REF!
Name ALVA: [4]DAT2!#REF!
Name ASERR: [1]DAT2!#REF!
Name ASERR: [2]DAT2!#REF!
Name ASERR: [3]DAT2!#REF!
Name ASERR: [4]DAT2!#REF!
Name ATE: [1]DAT2!#REF!
Name ATE: [2]DAT2!#REF!
Name ATE: [3]DAT2!#REF!
Name ATE: [4]DAT2!#REF!
Name BAGAC: [1]DAT2!#REF!
Name BAGAC: [2]DAT2!#REF!
Name BAGAC: [3]DAT2!#REF!
Name BAGAC: [4]DAT2!#REF!
Name BARV: [1]DAT2!#REF!
Name BARV: [2]DAT2!#REF!
Name BARV: [3]DAT2!#REF!
Name BARV: [4]DAT2!#REF!
Name BEL: [1]DAT2!#REF!
Name BEL: [2]DAT2!#REF!
Name BEL: [3]DAT2!#REF!
Name BEL: [4]DAT2!#REF!
Name BUEN: [1]DAT2!#REF!
Name BUEN: [2]DAT2!#REF!
Name BUEN: [3]DAT2!#REF!
Name BUEN: [4]DAT2!#REF!
Name CANTÓNN: [4]!Tabla103[#All]
Name CAÑ: [1]DAT2!#REF!
Name CAÑ: [2]DAT2!#REF!
Name CAÑ: [3]DAT2!#REF!
Name CAÑ: [4]DAT2!#REF!
Name CARR: [1]DAT2!#REF!
Name CARR: [2]DAT2!#REF!
Name CARR: [3]DAT2!#REF!
Name CARR: [4]DAT2!#REF!
Name CARTAG: [1]DAT2!#REF!
Name CARTAG: [2]DAT2!#REF!
Name CARTAG: [3]DAT2!#REF!
Name CARTAG: [4]DAT2!#REF!
Name CORR: [1]DAT2!#REF!
Name CORR: [2]DAT2!#REF!
Name CORR: [3]DAT2!#REF!

Sheet D94 Golfito
A1: PROGRAMA | B1: D94 GOLFITO | C1: META | D1: AVANCE | E1: ENERO | F1: FEBRERO | G1: MARZO | H1: ABRIL | I1: MAYO | J1: JUNIO | K1: JULIO | L1: AGOSTO | M1: SEPTIEMBRE | N1: OCTUBRE | O1: NOVIEMBRE | P1: DICIEMBRE
C2: 2026 | D2: Porcentual
A3: PSCC | B3: Cuatro actividades de recuperación de espacios públicos, con las comunidades integradas al Programa de Seguridad Comunitaria, que se localicen, en los distritos que contemplan las área georreferenciadas del informe territorial de la Estrategia Sembremos Seguridad 2024, dos por año, una por semestre. | C3: 2 | D3: =SUM(E3:P3) -> 1 | J3: 1
A4: GREAT/MPAS/DARE | B4: Realizar 4 procesos formativos (Cursos de la oferta de los programas DARE - GREAT - MPAS) en Centros Educativos, 2 por año, dentro de los distritos que contemplan las áreas georreferenciadas del informe territorial de la Estrategia Sembremos Seguridad 2024. Un curso diferente por semestre, un nivel completo. En caso de no contar con instructor acreditado DARE, se puede cumplir la meta con las charlas de Habilidades para la vida DARE, con el aval del Coordinador Nacional. | C4: 2 | D4: =SUM(E4:P4) -> 2 | E4: 0 | F4: 0 | G4: 0 | H4: 0 | I4: 1 | J4: 1
A5: DARE | B5: Cubrir 4 procesos formativos en Centros Educativos (dos por año) ubicados dentro de los distritos que contemplan las áreas georreferenciadas del informe territorial de la Estrategia Sembremos Seguridad 2024, con los cursos del Programa DARE: , Curso primaria. Curso Secundaria; un nivel completo por centro educativo, por semestre. En caso de no contar con instructor acreditado, se puede cumplir la meta con las charlas de Habilidades para la vida DARE, con el aval del Coordinador Nacional. | C5: 2 | D5: =SUM(E5:P5) -> 0 | E5: 0 | F5: 0 | G5: 0 | H5: 0
A6: PLAN DE POLITICA LOCAL E IMPLEMENTACIÓN DE LA POLITICA LOCAL DE SEGURIDAD | B6: Conformación Comité | C6: 3 | D6: =SUM(E6:O6) -> 0
B7: Conformación de Comercio | C7: 3 | D7: =SUM(E7:O7) -> 0
B8: Reuniones-Jefaturas | C8: 136 | D8: =SUM(E8:O8) -> 60 | E8: 8 | F8: 15 | G8: 7 | H8: 14 | I8: 14 | J8: 2
B9: Campañas de divulgación | C9: 31 | D9: =SUM(E9:O9) -> 96 | G9: 43 | H9: 23 | J9: 30
B10: Capacitaciones | C10: 0 | D10: =SUM(E10:O10) -> 0
B11: Charlas | C11: 27 | D11: =SUM(E11:O11) -> 4 | I11: 4
B12: Talleres | C12: 3 | D12: =SUM(E12:O12) -> 0
B13: Sensibilización | C13: 17 | D13: =SUM(E13:O13) -> 0
B14: Actividades deportivas | C14: 21 | D14: =SUM(E14:O14) -> 2 | E14: 1 | G14: 1
B15: Cine en mi Barrio | C15: 16 | D15: =SUM(E15:O15) -> 0
B16: Cívico-policial | C16: 18 | D16: =SUM(E16:O16) -> 0
B17: Actividades culturales | C17: 0 | D17: =SUM(E17:O17) -> 0
B18: Ferias | C18: 0 | D18: =SUM(E18:O18) -> 0
B19: Stand informativo | C19: 0 | D19: =SUM(E19:O19) -> 0
B20: Visitas | C20: 112 | D20: =SUM(E20:O20) -> 36 | E20: 10 | F20: 7 | G20: 2 | H20: 12 | I20: 4 | J20: 1
B21: Recuperación del espacio público | C21: 3 | D21: =SUM(E21:O21) -> 0
B22: Convocatoria de Mesas Locales | C22: 2 | D22: =SUM(E22:O22) -> 0
B23: Exposición Informe Territorial ESS | C23: 2 | D23: =SUM(E23:O23) -> 2 | H23: 2
B24: Primera Sesión de Trabajo | C24: 2 | D24: =SUM(E24:O24) -> 2 | I24: 2
B25: Segunda Sesión - Conformación Secretaria Técnica | C25: 2 | D25: =SUM(E25:O25) -> 0
B26: Tercera Sesión | C26: 2 | D26: =SUM(E26:O26) -> 0
B27: Elaboracióin del Texto de la Política Local | C27: 1 | D27: =SUM(E27:O27) -> 0
B28: Revisión Técnica DPPP | C28: 1 | D28: =SUM(E28:O28) -> 0
B29: Revisión Area Legal Gobierno Local | C29: 1 | D29: =SUM(E29:O29) -> 0
B30: Incorporación de Observaciones | C30: 1 | D30: =SUM(E30:O30) -> 0
B31: Aval del Director Regional | C31: 1 | D31: =SUM(E31:O31) -> 0
B32: Presentación al Consejo Municipal | C32: 1 | D32: =SUM(E32:O32) -> 0
B33: Presentación ante la Comunidad por parte del Director Regional y Alcalde | C33: 1 | D33: =SUM(E33:O33) -> 0
C34: =SUM(C3:C33) -> 413 | D34: =SUM(D3:D33) -> 205
D35: =D34/C34 -> 0.49636804

Sheet D95 Coto Brus
A1: PROGRAMA | B1: D95 COTO BRUS | C1: META | D1: AVANCE | E1: ENERO | F1: FEBRERO | G1: MARZO | H1: ABRIL | I1: MAYO | J1: JUNIO | K1: JULIO | L1: AGOSTO | M1: SEPTIEMBRE | N1: OCTUBRE | O1: NOVIEMBRE | P1: DICIEMBRE
C2: 2026 | D2: Porcentual
A3: PSCC | B3: Cuatro actividades de recuperación de espacios públicos, con las comunidades integradas al Programa de Seguridad Comunitaria, que se localicen, en los distritos que contemplan las área georreferenciadas del informe territorial de la Estrategia Sembremos Seguridad 2024, dos por año, una por semestre. | C3: 2 | D3: =SUM(E3:P3) -> 1 | F3: 1
A4: GREAT/MPAS/DARE | B4: Realizar 4 procesos formativos (Cursos de la oferta de los programas DARE - GREAT - MPAS) en Centros Educativos, dos por año, dentro de los distritos que contemplan las áreas georreferenciadas del informe territorial de la Estrategia Sembremos Seguridad 2024. En caso de no contar con instructor acreditado DARE, se puede cumplir la meta con las charlas de Habilidades para la vida DARE, con el aval del Coordinador Nacional. | C4: 2 | D4: =SUM(E4:P4) -> 0 | E4: 0 | F4: 0 | G4: 0 | H4: 0
A5: DARE | B5: Cubrir 2 procesos formativos en Centros Educativos (uno por año) ubicados dentro de los distritos que contemplan las áreas georreferenciadas del informe territorial de la Estrategia Sembremos Seguridad 2024, con los cursos del Programa DARE: , Curso primaria. Curso Secundaria; un nivel completo por centro educativo, por semestre. En caso de no contar con instructor acreditado, se puede cumplir la meta con las charlas de Habilidades para la vida DARE, con el aval del Coordinador Nacional. | C5: 1 | D5: =SUM(E5:P5) -> 0 | E5: 0 | F5: 0 | G5: 0 | H5: 0
A6: PSCC | B6: Cuatro comercios capacitados e integrados al Programa de Seguridad Comercial que se localicen, en los distritos que contemplan las área georreferenciadas del informe territorial de la Estrategia Sembremos Seguridad 2024, dos por año, una por semestre. | C6: 2 | D6: =SUM(E6:P6) -> 0
A7: PSCC | B7: Dos estrategias de divulgación (Por medio de brochures, post o imágenes en redes sociales) diseñadas por la Estrategia de divulgación de la Dirección de Programas Policiales Preventivos, en el tema de "Prevención del Consumo de alcohol en vía pública" dirigidas a las comunidades integradas al Programa de Seguridad Comunitaria y a los comercios integrados al Programa de Seguridad Comercial que se localicen, en los distritos que contemplan las área georreferenciadas del informe territorial de la Estrategia Sembremos Seguridad 2024, una por año. | C7: 1 | D7: =SUM(E7:P7) -> 0
A8: PSCC | B8: Dos estrategias de divulgación (Por medio de brochures, post o imágenes en redes sociales) en el tema del procedimiento para realizar una "Denuncia de ventas de drogas" diseñadas por la Estrategia de divulgación de la Dirección de Programas Policiales Preventivos dirigidas a las comunidades integradas al Programa de Seguridad Comunitaria que se localicen, en los distritos que contemplan las área georreferenciadas del informe territorial de la Estrategia Sembremos Seguridad 2024, una por año. | C8: 1 | D8: =SUM(E8:P8) -> 0
A9: PSCC | B9: Dos capacitaciones, en el tema de "Denuncia a búnkers", dirigidas a las comunidades integradas al Programa de Seguridad Comunitaria que se localicen, en los distritos que contemplan las área georreferenciadas del informe territorial de la Estrategia Sembremos Seguridad 2024, una por año. | C9: 1 | D9: =SUM(E9:P9) -> 0
A10: PSCC | B10: Dos estrategias de divulgación (Por medio de brochures, post o imágenes en redes sociales) en el tema del procedimiento para realizar una "Denuncia de búnkers" dirigidas a las comunidades integradas al Programa de Seguridad Comunitaria que se localicen, en los distritos que contemplan las área georreferenciadas del informe territorial de la Estrategia Sembremos Seguridad 2024, una por año. | C10: 1 | D10: =SUM(E10:P10) -> 0
A11: PSCC | B11: Dos capacitaciones, en el tema de Denuncia, dirigidas a las comunidades integradas al Programa de Seguridad Comunitaria, que se localicen, en los distritos que contemplan las área georreferenciadas del informe territorial de la Estrategia Sembremos Seguridad 2024, una por año. | C11: 1 | D11: =SUM(E11:P11) -> 0
A12: PLAN DE POLITICA LOCAL E IMPLEMENTACIÓN DE LA POLITICA LOCAL DE SEGURIDAD | B12: Conformación Comité | C12: 0 | D12: =SUM(E12:O12) -> 0
B13: Conformación de Comercio | C13: 1 | D13: =SUM(E13:O13) -> 0
B14: Reuniones-Jefaturas | C14: 176 | D14: =SUM(E14:O14) -> 74 | E14: 16 | F14: 14 | G14: 15 | H14: 13 | I14: 16
B15: Campañas de divulgación | C15: 31 | D15: =SUM(E15:O15) -> 23 | G15: 2 | H15: 21
B16: Capacitaciones | C16: 3 | D16: =SUM(E16:O16) -> 1 | I16: 1
B17: Charlas | C17: 45 | D17: =SUM(E17:O17) -> 16 | E17: 1 | G17: 4 | H17: 6 | I17: 5
B18: Talleres | C18: 0 | D18: =SUM(E18:O18) -> 0
B19: Sensibilización | C19: 40 | D19: =SUM(E19:O19) -> 34 | E19: 12 | F19: 11 | G19: 9 | H19: 2
B20: Actividades deportivas | C20: 3 | D20: =SUM(E20:O20) -> 2 | H20: 1 | I20: 1
B21: Cine en mi Barrio | C21: 5 | D21: =SUM(E21:O21) -> 1 | I21: 1
B22: Cívico-policial | C22: 0 | D22: =SUM(E22:O22) -> 0
B23: Actividades culturales | C23: 3 | D23: =SUM(E23:O23) -> 0
B24: Ferias | C24: 0 | D24: =SUM(E24:O24) -> 0
B25: Stand informativo | C25: 0 | D25: =SUM(E25:O25) -> 0
B26: Visitas | C26: 205 | D26: =SUM(E26:O26) -> 70 | E26: 16 | F26: 13 | G26: 15 | H26: 14 | I26: 12
B27: Recuperación del espacio público | C27: 5 | D27: =SUM(E27:O27) -> 2 | F27: 1 | G27: 1
B28: Convocatoria de Mesas Locales | C28: 6 | D28: =SUM(E28:O28) -> 5 | H28: 5
B29: Exposición Informe Territorial ESS | C29: 6 | D29: =SUM(E29:O29) -> 5 | H29: 5
B30: Primera Sesión de Trabajo | C30: 6 | D30: =SUM(E30:O30) -> 5 | I30: 5
B31: Segunda Sesión - Conformación Secretaria Técnica | C31: 6 | D31: =SUM(E31:O31) -> 0
B32: Tercera Sesión | C32: 6 | D32: =SUM(E32:O32) -> 0
B33: Elaboracióin del Texto de la Política Local | C33: 1 | D33: =SUM(E33:O33) -> 0
B34: Revisión Técnica DPPP | C34: 1 | D34: =SUM(E34:O34) -> 0
B35: Revisión Area Legal Gobierno Local | C35: 1 | D35: =SUM(E35:O35) -> 0
B36: Incorporación de Observaciones | C36: 1 | D36: =SUM(E36:O36) -> 0
B37: Aval del Director Regional | C37: 1 | D37: =SUM(E37:O37) -> 0
B38: Presentación al Consejo Municipal | C38: 1 | D38: =SUM(E38:O38) -> 0
B39: Presentación ante la Comunidad por parte del Director Regional y Alcalde | C39: 1 | D39: =SUM(E39:O39) -> 0
C40: =SUM(C3:C39) -> 566 | D40: =SUM(D3:D39) -> 239
...

Sheet D96 Corredores
A1: PROGRAMA | B1: D96 CORREDORES | C1: META | D1: AVANCE | E1: ENERO | F1: FEBRERO | G1: MARZO | H1: ABRIL | I1: MAYO | J1: JUNIO | K1: JULIO | L1: AGOSTO | M1: SEPTIEMBRE | N1: OCTUBRE | O1: NOVIEMBRE | P1: DICIEMBRE
C2: 2026 | D2: Porcentual
A3: PSCC | B3: Cuatro actividades de recuperación de espacios públicos, con las comunidades integradas al Programa de Seguridad Comunitaria, que se localicen, en los distritos que contemplan las área georreferenciadas del informe territorial de la Estrategia Sembremos Seguridad 2024, dos por año, una por semestre. | C3: 2 | D3: =SUM(E3:P3) -> 1 | E3: 1
A4: GREAT/MPAS/DARE | B4: Realizar 4 procesos formativos (Cursos de la oferta de los programas DARE - GREAT - MPAS) en Centros Educativos, 2 por año, dentro de los distritos que contemplan las áreas georreferenciadas del informe territorial de la Estrategia Sembremos Seguridad 2024. Un curso diferente por semestre, un nivel completo. En caso de no contar con instructor acreditado DARE, se puede cumplir la meta con las charlas de Habilidades para la vida DARE, con el aval del Coordinador Nacional. | C4: 2 | D4: =SUM(E4:P4) -> 0 | E4: 0 | F4: 0 | G4: 0 | H4: 0
A5: DARE | B5: Cubrir 4 procesos formativos en Centros Educativos (dos por año) ubicados dentro de los distritos que contemplan las áreas georreferenciadas del informe territorial de la Estrategia Sembremos Seguridad 2024, con los cursos del Programa DARE: , Curso primaria. Curso Secundaria; un nivel completo por centro educativo, por semestre. En caso de no contar con instructor acreditado, se puede cumplir la meta con las charlas de Habilidades para la vida DARE, con el aval del Coordinador Nacional. | C5: 2 | D5: =SUM(E5:P5) -> 0 | E5: 0 | F5: 0 | G5: 0 | H5: 0
A6: PSCC | B6: Dos estrategias de divulgación (Por medio de brochures, post o imágenes en redes sociales) en el tema del procedimiento para realizar una "Denuncia de ventas de drogas" dirigidas a las comunidades integradas al Programa de Seguridad Comunitaria, que se localicen, dentro del área georreferenciada del informe territorial de la Estrategia Sembremos Seguridad 2024, una por año. | C6: 1 | D6: =SUM(E6:P6) -> 0
A7: PSCC | B7: Cuatro capacitaciones, en el tema de "Denuncia a búnkers", dirigidas a las comunidades integradas al Programa de Seguridad Comunitaria, que se localicen, dentro del área georreferenciada del informe territorial de la Estrategia Sembremos Seguridad 2024, dos por año, una por semestre.. | C7: 2 | D7: =SUM(E7:P7) -> 1 | E7: 1
A8: PSCC | B8: Dos estrategias de divulgación (Por medio de brochures, post o imágenes en redes sociales) en el tema del procedimiento para realizar una "Denuncia de búnkers" dirigidas a las comunidades integradas al Programa de Seguridad Comunitaria, que se localicen, dentro del área georreferenciada del informe territorial de la Estrategia Sembremos Seguridad 2024, una por año. | C8: 1 | D8: =SUM(E8:P8) -> 0
A9: PLAN DE POLITICA LOCAL E IMPLEMENTACIÓN DE LA POLITICA LOCAL DE SEGURIDAD | B9: Conformación Comité | C9: 3 | D9: =SUM(E9:O9) -> 0
B10: Conformación de Comercio | C10: 0 | D10: =SUM(E10:O10) -> 0
B11: Reuniones-Jefaturas | C11: 108 | D11: =SUM(E11:O11) -> 47 | E11: 3 | F11: 11 | G11: 8 | H11: 16 | I11: 9
B12: Campañas de divulgación | C12: 7 | D12: =SUM(E12:O12) -> 3 | H12: 3
B13: Capacitaciones | C13: 0 | D13: =SUM(E13:O13) -> 0
B14: Charlas | C14: 89 | D14: =SUM(E14:O14) -> 38 | E14: 2 | F14: 13 | G14: 2 | H14: 12 | I14: 9
B15: Talleres | C15: 0 | D15: =SUM(E15:O15) -> 0
B16: Sensibilización | C16: 0 | D16: =SUM(E16:O16) -> 0
B17: Actividades deportivas | C17: 3 | D17: =SUM(E17:O17) -> 0
B18: Cine en mi Barrio | C18: 0 | D18: =SUM(E18:O18) -> 0
B19: Cívico-policial | C19: 13 | D19: =SUM(E19:O19) -> 2 | E19: 1 | I19: 1
B20: Actividades culturales | C20: 0 | D20: =SUM(E20:O20) -> 0
B21: Ferias | C21: 0 | D21: =SUM(E21:O21) -> 0
B22: Stand informativo | C22: 0 | D22: =SUM(E22:O22) -> 0
B23: Visitas | C23: 104 | D23: =SUM(E23:O23) -> 54 | E23: 27 | H23: 27
B24: Recuperación del espacio público | C24: 3 | D24: =SUM(E24:O24) -> 1 | J24: 1
B25: Convocatoria de Mesas Locales | C25: 5 | D25: =SUM(E25:O25) -> 4 | H25: 4
B26: Exposición Informe Territorial ESS | C26: 5 | D26: =SUM(E26:O26) -> 4 | H26: 4
B27: Primera Sesión de Trabajo | C27: 5 | D27: =SUM(E27:O27) -> 4 | I27: 4
B28: Segunda Sesión - Conformación Secretaria Técnica | C28: 5 | D28: =SUM(E28:O28) -> 0
B29: Tercera Sesión | C29: 5 | D29: =SUM(E29:O29) -> 0
B30: Elaboracióin del Texto de la Política Local | C30: 1 | D30: =SUM(E30:O30) -> 0
B31: Revisión Técnica DPPP | C31: 1 | D31: =SUM(E31:O31) -> 0
B32: Revisión Area Legal Gobierno Local | C32: 1 | D32: =SUM(E32:O32) -> 0
B33: Incorporación de Observaciones | C33: 1 | D33: =SUM(E33:O33) -> 0
B34: Aval del Director Regional | C34: 1 | D34: =SUM(E34:O34) -> 0
B35: Presentación al Consejo Municipal | C35: 1 | D35: =SUM(E35:O35) -> 0
B36: Presentación ante la Comunidad por parte del Director Regional y Alcalde | C36: 1 | D36: =SUM(E36:O36) -> 0
C37: =SUM(C3:C36) -> 372 | D37: =SUM(D3:D36) -> 159
D38: =D37/C37 -> 0.42741935

Sheet D97 Puerto Jiménez
A1: PROGRAMA | B1: D97 PUERTO JIMÉNEZ | C1: META | D1: AVANCE | E1: ENERO | F1: FEBRERO | G1: MARZO | H1: ABRIL | I1: MAYO | J1: JUNIO | K1: JULIO | L1: AGOSTO | M1: SEPTIEMBRE | N1: OCTUBRE | O1: NOVIEMBRE | P1: DICIEMBRE
C2: 2026 | D2: Porcentual
A3: PSCC | B3: Cuatro actividades de recuperación de espacios públicos, con las comunidades integradas al Programa de Seguridad Comunitaria, que se localicen, en los distritos que contemplan las área georreferenciadas del informe territorial de la Estrategia Sembremos Seguridad 2024, dos por año, una por semestre. | C3: 2 | D3: =SUM(E3:P3) -> 0
A4: GREAT/MPAS/DARE | B4: Realizar 2 procesos formativos (Cursos de la oferta de los programas DARE - GREAT - MPAS) en Centros Educativos, Uno por año, dentro de los distritos que contemplan las áreas georreferenciadas del informe territorial de la Estrategia Sembremos Seguridad 2024. En caso de no contar con instructor acreditado DARE, se puede cumplir la meta con las charlas de Habilidades para la vida DARE, con el aval del Coordinador Nacional. | C4: 1 | D4: =SUM(E4:P4) -> 0 | E4: 0 | F4: 0 | G4: 0 | H4: 0
A5: DARE | B5: Cubrir 2 procesos formativos en Centros Educativos (uno por año) ubicados dentro de los distritos que contemplan las áreas georreferenciadas del informe territorial de la Estrategia Sembremos Seguridad 2024, con los cursos del Programa DARE: , Curso primaria. Curso Secundaria; un nivel completo por centro educativo, por semestre. En caso de no contar con instructor acreditado, se puede cumplir la meta con las charlas de Habilidades para la vida DARE, con el aval del Coordinador Nacional. | C5: 1 | D5: =SUM(E5:P5) -> 0 | E5: 0 | F5: 0 | G5: 0 | H5: 0
A6: PSCC | B6: Cuatro comercios capacitados e integrados al Programa de Seguridad Comercial que se localicen, en los distritos que contemplan las área georreferenciadas del informe territorial de la Estrategia Sembremos Seguridad 2024, dos por año, una por semestre. | C6: 2 | D6: =SUM(E6:P6) -> 0
A7: PSCC | B7: Cuatro estrategias de divulgación (Por medio de brochures, post o imágenes en redes sociales) diseñadas por la Estrategia de divulgación de la Dirección de Programas Policiales Preventivos, en el tema de "Prevención del Consumo de alcohol en vía pública" dirigidas a las comunidades integradas al Programa de Seguridad Comunitaria y a los comercios integrados al Programa de Seguridad Comercial que se localicen, en los distritos que contemplan las área georreferenciadas del informe territorial de la Estrategia Sembremos Seguridad 2024, dos por año. | C7: 2 | D7: =SUM(E7:P7) -> 0
A8: PSCC | B8: Dos estrategias de divulgación (Por medio de brochures, post o imágenes en redes sociales) en el tema del procedimiento para realizar una "Denuncia de ventas de drogas" diseñadas por la Estrategia de divulgación de la Dirección de Programas Policiales Preventivos dirigidas a las comunidades integradas al Programa de Seguridad Comunitaria que se localicen, en los distritos que contemplan las área georreferenciadas del informe territorial de la Estrategia Sembremos Seguridad 2024, una por año. | C8: 1 | D8: =SUM(E8:P8) -> 0
A9: PSCC | B9: Cuatro capacitaciones, en el tema de "Denuncia a búnkers", dirigidas a las comunidades integradas al Programa de Seguridad Comunitaria que se localicen, en los distritos que contemplan las área georreferenciadas del informe territorial de la Estrategia Sembremos Seguridad 2024, dos por año, una por semestre. | C9: 2 | D9: =SUM(E9:P9) -> 0
A10: PSCC | B10: Dos estrategias de divulgación (Por medio de brochures, post o imágenes en redes sociales) en el tema del procedimiento para realizar una "Denuncia de búnkers" dirigidas a las comunidades integradas al Programa de Seguridad Comunitaria que se localicen, en los distritos que contemplan las área georreferenciadas del informe territorial de la Estrategia Sembremos Seguridad 2024, una por año. | C10: 1 | D10: =SUM(E10:P10) -> 0
A11: PLAN DE POLITICA LOCAL E IMPLEMENTACIÓN DE LA POLITICA LOCAL DE SEGURIDAD | B11: Conformación Comité | C11: 2 | D11: =SUM(E11:O11) -> 0
B12: Conformación de Comercio | C12: 3 | D12: =SUM(E12:O12) -> 0
B13: Reuniones-Jefaturas | C13: 56 | D13: =SUM(E13:O13) -> 21 | F13: 2 | G13: 6 | H13: 4 | I13: 9
B14: Campañas de divulgación | C14: 56 | D14: =SUM(E14:O14) -> 22 | G14: 14 | H14: 8
B15: Capacitaciones | C15: 0 | D15: =SUM(E15:O15) -> 0
B16: Charlas | C16: 13 | D16: =SUM(E16:O16) -> 10 | H16: 1 | I16: 8 | J16: 1
B17: Talleres | C17: 0 | D17: =SUM(E17:O17) -> 0
B18: Sensibilización | C18: 10 | D18: =SUM(E18:O18) -> 3 | G18: 3
B19: Actividades deportivas | C19: 0 | D19: =SUM(E19:O19) -> 0
B20: Cine en mi Barrio | C20: 0 | D20: =SUM(E20:O20) -> 0
B21: Cívico-policial | C21: 1 | D21: =SUM(E21:O21) -> 0
B22: Actividades culturales | C22: 0 | D22: =SUM(E22:O22) -> 0
B23: Ferias | C23: 0 | D23: =SUM(E23:O23) -> 0
B24: Stand informativo | C24: 0 | D24: =SUM(E24:O24) -> 0
B25: Visitas | C25: 137 | D25: =SUM(E25:O25) -> 43 | G25: 30 | I25: 13
B26: Recuperación del espacio público | C26: 4 | D26: =SUM(E26:O26) -> 0
B27: Convocatoria de Mesas Locales | C27: 4 | D27: =SUM(E27:O27) -> 2 | H27: 2
B28: Exposición Informe Territorial ESS | C28: 2 | D28: =SUM(E28:O28) -> 2 | H28: 2
B29: Primera Sesión de Trabajo | C29: 2 | D29: =SUM(E29:O29) -> 2 | I29: 2
B30: Segunda Sesión - Conformación Secretaria Técnica | C30: 2 | D30: =SUM(E30:O30) -> 1 | J30: 1
B31: Tercera Sesión | C31: 2 | D31: =SUM(E31:O31) -> 0
B32: Elaboracióin del Texto de la Política Local | C32: 1 | D32: =SUM(E32:O32) -> 0
B33: Revisión Técnica DPPP | C33: 1 | D33: =SUM(E33:O33) -> 0
B34: Revisión Area Legal Gobierno Local | C34: 1 | D34: =SUM(E34:O34) -> 0
B35: Incorporación de Observaciones | C35: 1 | D35: =SUM(E35:O35) -> 0
B36: Aval del Director Regional | C36: 1 | D36: =SUM(E36:O36) -> 0
B37: Presentación al Consejo Municipal | C37: 1 | D37: =SUM(E37:O37) -> 0
B38: Presentación ante la Comunidad por parte del Director Regional y Alcalde | C38: 1 | D38: =SUM(E38:O38) -> 0
C39: =SUM(C3:C38) -> 313 | D39: =SUM(D3:D38) -> 106
D40: =D39/C39 -> 0.33865815

Sheet Total Región
A1: Delegación | C1: META | D1: AVANCE | E1: % AVANCE
A2: D94 | B2: GOLFITO | C2: ='D94 Golfito'!C34 -> 413 | D2: ='D94 Golfito'!D34 -> 205 | E2: =D2/C2 -> 0.49636804
A3: D95 | B3: COTO BRUS | C3: ='D95 Coto Brus'!C40 -> 566 | D3: ='D95 Coto Brus'!D40 -> 239 | E3: =D3/C3 -> 0.42226148
A4: D96 | B4: CORREDORES | C4: ='D96 Corredores'!C37 -> 372 | D4: ='D96 Corredores'!D37 -> 159 | E4: =D4/C4 -> 0.42741935
A5: D97 | B5: PUERTO JIMÉNEZ | C5: ='D97 Puerto Jiménez'!C39 -> 313 | D5: ='D97 Puerto Jiménez'!D39 -> 106 | E5: =D5/C5 -> 0.33865815
B6: TOTALES | C6: =SUM(C2:C5) -> 1664 | D6: =SUM(D2:D5) -> 709 | E6: =D6/C6 -> 0.42608173
