Workbook
Name ABANG: [1]DAT2!#REF!
Name ABANG: [2]DAT2!#REF!
Name ABANG: [3]DAT2!#REF!
Name ABANG: [4]DAT2!#REF!
Name ABANG: [5]DAT2!#REF!
Name ACOS: [1]DAT2!#REF!
Name ACOS: [2]DAT2!#REF!
Name ACOS: [3]DAT2!#REF!
Name ACOS: [4]DAT2!#REF!
Name ACOS: [5]DAT2!#REF!
Name ALAJU: [1]DAT2!#REF!
Name ALAJU: [2]DAT2!#REF!
Name ALAJU: [3]DAT2!#REF!
Name ALAJU: [4]DAT2!#REF!
Name ALAJU: [5]DAT2!#REF!
Name ALAJUE: [1]DAT2!#REF!
Name ALAJUE: [2]DAT2!#REF!
Name ALAJUE: [3]DAT2!#REF!
Name ALAJUE: [4]DAT2!#REF!
Name ALAJUE: [5]DAT2!#REF!
Name ALVA: [1]DAT2!#REF!
Name ALVA: [2]DAT2!#REF!
Name ALVA: [3]DAT2!#REF!
Name ALVA: [4]DAT2!#REF!
Name ALVA: [5]DAT2!#REF!
Name ASERR: [1]DAT2!#REF!
Name ASERR: [2]DAT2!#REF!
Name ASERR: [3]DAT2!#REF!
Name ASERR: [4]DAT2!#REF!
Name ASERR: [5]DAT2!#REF!
Name ATE: [1]DAT2!#REF!
Name ATE: [2]DAT2!#REF!
Name ATE: [3]DAT2!#REF!
Name ATE: [4]DAT2!#REF!
Name ATE: [5]DAT2!#REF!
Name BAGAC: [1]DAT2!#REF!
Name BAGAC: [2]DAT2!#REF!
Name BAGAC: [3]DAT2!#REF!
Name BAGAC: [4]DAT2!#REF!
Name BAGAC: [5]DAT2!#REF!
Name BARV: [1]DAT2!#REF!
Name BARV: [2]DAT2!#REF!
Name BARV: [3]DAT2!#REF!
Name BARV: [4]DAT2!#REF!
Name BARV: [5]DAT2!#REF!
Name BEL: [1]DAT2!#REF!
Name BEL: [2]DAT2!#REF!
Name BEL: [3]DAT2!#REF!
Name BEL: [4]DAT2!#REF!
Name BEL: [5]DAT2!#REF!
Name BUEN: [1]DAT2!#REF!
Name BUEN: [2]DAT2!#REF!
Name BUEN: [3]DAT2!#REF!
Name BUEN: [4]DAT2!#REF!
Name BUEN: [5]DAT2!#REF!
Name CANTÓNN: [5]!Tabla103[#All]
Name CAÑ: [1]DAT2!#REF!
Name CAÑ: [2]DAT2!#REF!
Name CAÑ: [3]DAT2!#REF!
Name CAÑ: [4]DAT2!#REF!

Sheet D58 Sarapiquí
A1: PROGRAMA | B1: D58 SARAPIQUÍ | C1: META | D1: AVANCE | E1: ENERO | F1: FEBRERO | G1: MARZO | H1: ABRIL | I1: MAYO | J1: JUNIO | K1: JULIO | L1: AGOSTO | M1: SEPTIEMBRE | N1: OCTUBRE | O1: NOVIEMBRE | P1: DICIEMBRE
C2: 2026 | D2: Porcentual
A3: PSCC | B3: Cuatro actividades de recuperación de espacios públicos, con las comunidades integradas al Programa de Seguridad Comunitaria, que se localicen, en los distritos que contemplan las área georreferenciadas del informe territorial de la Estrategia Sembremos Seguridad 2024, dos por año, una por semestre. | C3: 2 | D3: =SUM(E3:P3) -> 0
A4: GREAT/MPAS/DARE | B4: Realizar 4 procesos formativos (Cursos de la oferta de los programas DARE - GREAT - MPAS) en Centros Educativos, dos por año, dentro de los distritos que contemplan las áreas georreferenciadas del informe territorial de la Estrategia Sembremos Seguridad 2024. En caso de no contar con instructor acreditado DARE, se puede cumplir la meta con las charlas de Habilidades para la vida DARE, con el aval del Coordinador Nacional. | C4: 2 | D4: =SUM(E4:P4) -> 2 | E4: 0 | F4: 0 | G4: 0 | H4: 0 | I4: 2
A5: DARE | B5: Cubrir 2 procesos formativos en Centros Educativos (uno por año) ubicados dentro de los distritos que contemplan las áreas georreferenciadas del informe territorial de la Estrategia Sembremos Seguridad 2024, con los cursos del Programa DARE: Curso primaria. Curso Secundaria; un nivel completo por centro educativo, por semestre. En caso de no contar con instructor acreditado, se puede cumplir la meta con las charlas de Habilidades para la vida DARE, con el aval del Coordinador Nacional. | C5: 1 | D5: =SUM(E5:P5) -> 0 | E5: 0 | F5: 0 | G5: 0 | H5: 0
A6: PSCC | B6: Cuatro comercios capacitados e integrados al Programa de Seguridad Comercial que se localicen, en los distritos que contemplan las área georreferenciadas del informe territorial de la Estrategia Sembremos Seguridad 2024, dos por año, una por semestre. | C6: 2 | D6: =SUM(E6:P6) -> 0
A7: PSCC | B7: Dos estrategias de divulgación (Por medio de brochures, post o imágenes en redes sociales) en el tema del procedimiento para realizar una "Denuncia de ventas de drogas" diseñadas por la Estrategia de divulgación de la Dirección de Programas Policiales Preventivos dirigidas a las comunidades integradas al Programa de Seguridad Comunitaria que se localicen, en los distritos que contemplan las área georreferenciadas del informe territorial de la Estrategia Sembremos Seguridad 2024, una por año. | C7: 1 | D7: =SUM(E7:P7) -> 0
A8: PSCC | B8: Cuatro estrategias de divulgación (Por medio de brochures, post o imágenes en redes sociales) diseñadas por la Estrategia de divulgación de la Dirección de Programas Policiales Preventivos, en el tema de "Prevención del Consumo de alcohol en vía pública" dirigidas a las comunidades integradas al Programa de Seguridad Comunitaria y a los comercios integrados al Programa de Seguridad Comercial que se localicen, en los distritos que contemplan las área georreferenciadas del informe territorial de la Estrategia Sembremos Seguridad 2024, dos por año. | C8: 2 | D8: =SUM(E8:P8) -> 0
A9: PLAN DE POLITICA LOCAL E IMPLEMENTACIÓN DE LA POLITICA LOCAL DE SEGURIDAD | B9: Conformación Comité | C9: 3 | D9: =SUM(E9:O9) -> 1 | G9: 1
B10: Conformación de Comercio | C10: 3 | D10: =SUM(E10:O10) -> 1 | H10: 1
B11: Reuniones-Jefaturas | C11: 108 | D11: =SUM(E11:O11) -> 52 | E11: 15 | F11: 10 | G11: 3 | H11: 16 | I11: 8
B12: Campañas de divulgación | C12: 49 | D12: =SUM(E12:O12) -> 11 | H12: 11
B13: Capacitaciones | C13: 16 | D13: =SUM(E13:O13) -> 9 | F13: 9
B14: Charlas | C14: 16 | D14: =SUM(E14:O14) -> 0
B15: Talleres | C15: 0 | D15: =SUM(E15:O15) -> 0
B16: Sensibilización | C16: 0 | D16: =SUM(E16:O16) -> 0
B17: Actividades deportivas | C17: 0 | D17: =SUM(E17:O17) -> 0
B18: Cine en mi Barrio | C18: 0 | D18: =SUM(E18:O18) -> 0
B19: Cívico-policial | C19: 0 | D19: =SUM(E19:O19) -> 0
B20: Actividades culturales | C20: 0 | D20: =SUM(E20:O20) -> 0
B21: Ferias | C21: 0 | D21: =SUM(E21:O21) -> 0
B22: Stand informativo | C22: 0 | D22: =SUM(E22:O22) -> 0
B23: Visitas | C23: 175 | D23: =SUM(E23:O23) -> 81 | E23: 15 | F23: 18 | G23: 11 | H23: 26 | I23: 11
B24: Recuperación del espacio público | C24: 0 | D24: =SUM(E24:O24) -> 0
B25: Convocatoria de Mesas Locales | C25: 5 | D25: =SUM(E25:O25) -> 2 | G25: 2
B26: Exposición Informe Territorial ESS | C26: 5 | D26: =SUM(E26:O26) -> 3 | H26: 3
B27: Primera Sesión de Trabajo | C27: 5 | D27: =SUM(E27:O27) -> 2 | I27: 2
B28: Segunda Sesión - Conformación Secretaria Técnica | C28: 5 | D28: =SUM(E28:O28) -> 0
B29: Tercera Sesión | C29: 5 | D29: =SUM(E29:O29) -> 0
B30: Elaboracióin del Texto de la Política Local | C30: 1 | D30: =SUM(E30:O30) -> 0
B31: Revisión Técnica DPPP | C31: 1 | D31: =SUM(E31:O31) -> 0
B32: Revisión Area Legal Gobierno Local | C32: 1 | D32: =SUM(E32:O32) -> 0
B33: Incorporación de Observaciones | C33: 1 | D33: =SUM(E33:O33) -> 0
B34: Aval del Director Regional | C34: 1 | D34: =SUM(E34:O34) -> 0
B35: Presentación al Consejo Municipal | C35: 1 | D35: =SUM(E35:O35) -> 0
B36: Presentación ante la Comunidad por parte del Director Regional y Alcalde | C36: 1 | D36: =SUM(E36:O36) -> 0
C37: =SUM(C3:C36) -> 412 | D37: =SUM(D3:D36) -> 164
D38: =D37/C37 -> 0.39805825

Sheet D89 Pococí Sur
A1: PROGRAMA | B1: D89 POCOCÍ SUR | C1: META | D1: AVANCE | E1: ENERO | F1: FEBRERO | G1: MARZO | H1: ABRIL | I1: MAYO | J1: JUNIO | K1: JULIO | L1: AGOSTO | M1: SEPTIEMBRE | N1: OCTUBRE | O1: NOVIEMBRE | P1: DICIEMBRE
C2: 2026 | D2: Porcentual
A3: GREAT/MPAS/DARE | B3: Realizar 4 procesos formativos (Cursos de la oferta de los programas DARE - GREAT - MPAS) en Centros Educativos, dos por año, dentro de los distritos que contemplan las áreas georreferenciadas del informe territorial de la Estrategia Sembremos Seguridad 2024. En caso de no contar con instructor acreditado DARE, se puede cumplir la meta con las charlas de Habilidades para la vida DARE, con el aval del Coordinador Nacional. | C3: 2 | D3: =SUM(E3:P3) -> 2 | E3: 0 | F3: 0 | G3: 0 | H3: 2
A4: PSCC | B4: Dos estrategias de divulgación (Por medio de brochures, post o imágenes en redes sociales) en el tema del procedimiento para realizar una "Denuncia de ventas de drogas" dirigidas a las comunidades integradas al Programa de Seguridad Comunitaria que se localicen, en los distritos que contemplan las área georreferenciadas del informe territorial de la Estrategia Sembremos Seguridad 2024, una por año. | C4: 1 | D4: =SUM(E4:P4) -> 1 | F4: 1
A5: PSCC | B5: Cuatro capacitaciones, en el tema de "Denuncia a búnkers", dirigidas a las comunidades integradas al Programa de Seguridad Comunitaria que se localicen, en los distritos que contemplan las área georreferenciadas del informe territorial de la Estrategia Sembremos Seguridad 2024, dos por año, una por semestre. | C5: 2 | D5: =SUM(E5:P5) -> 0
A6: PSCC | B6: Dos estrategias de divulgación (Por medio de brochures, post o imágenes en redes sociales) en el tema del procedimiento para realizar una "Denuncia de búnkers" dirigidas a las comunidades integradas al Programa de Seguridad Comunitaria que se localicen, en los distritos que contemplan las área georreferenciadas del informe territorial de la Estrategia Sembremos Seguridad 2024, una por año. | C6: 1 | D6: =SUM(E6:P6) -> 0
A7: PSCC | B7: Cuatro Charlas de Cultura Preventiva (Una por año) con enfasis en temas de estafa dirigidas a las comunidades integradas al Programa de Seguridad Comunitaria, que se localicen, en los distritos que contemplan las área georreferenciadas del informe territorial de la Estrategia Sembremos Seguridad 2024, dos por año, una por semestre. | C7: 2 | D7: =SUM(E7:P7) -> 1 | I7: 1
A8: PSCC | B8: Dos estrategias de divulgación (Por medio de brochures, post o imágenes en redes sociales) en el tema del procedimiento para realizar una "Denuncia ante Estafas" dirigidas a las comunidades integradas al Programa de Seguridad Comunitaria, que se localicen, en los distritos que contemplan las área georreferenciadas del informe territorial de la Estrategia Sembremos Seguridad 2024, una por año. | C8: 1 | D8: =SUM(E8:P8) -> 1 | G8: 1
A9: PSCC | B9: Dos capacitaciones, en el tema de "Cultura Preventiva autocuidado en zonas peligrosas", dirigidas a las comunidades integradas al Programa de Seguridad Comunitaria, que se localicen, en los distritos que contemplan las área georreferenciadas del informe territorial de la Estrategia Sembremos Seguridad 2024, Una por año. | C9: 1 | D9: =SUM(E9:P9) -> 2 | H9: 1 | I9: 1
A10: GREAT/MPAS/DARE | B10: Cuatro cursos del componente, Familias GREAT, dirigido a las comunidades integradas al Programa de Seguridad Comunitaria dentro de los distritos que contemplan las áreas georreferenciadas del informe territorial de la Estrategia Sembremos Seguridad 2024, según los lineamientos del programa. | C10: 2 | D10: =SUM(E10:P10) -> 0
A11: PLAN DE POLITICA LOCAL E IMPLEMENTACIÓN DE LA POLITICA LOCAL DE SEGURIDAD | B11: Conformación Comité | C11: 1 | D11: =SUM(E11:O11) -> 1 | E11: 1
B12: Conformación de Comercio | C12: 2 | D12: =SUM(E12:O12) -> 2 | E12: 2
B13: Reuniones-Jefaturas | C13: 80 | D13: =SUM(E13:O13) -> 40 | F13: 10 | G13: 8 | H13: 19 | I13: 3
B14: Campañas de divulgación | C14: 76 | D14: =SUM(E14:O14) -> 19 | F14: 1 | G14: 18
B15: Capacitaciones | C15: 3 | D15: =SUM(E15:O15) -> 1 | H15: 1
B16: Charlas | C16: 2 | D16: =SUM(E16:O16) -> 0
B17: Talleres | C17: 0 | D17: =SUM(E17:O17) -> 0
B18: Sensibilización | C18: 0 | D18: =SUM(E18:O18) -> 0
B19: Actividades deportivas | C19: 0 | D19: =SUM(E19:O19) -> 0
B20: Cine en mi Barrio | C20: 0 | D20: =SUM(E20:O20) -> 0
B21: Cívico-policial | C21: 0 | D21: =SUM(E21:O21) -> 0
B22: Actividades culturales | C22: 0 | D22: =SUM(E22:O22) -> 0
B23: Ferias | C23: 0 | D23: =SUM(E23:O23) -> 0
B24: Stand informativo | C24: 0 | D24: =SUM(E24:O24) -> 0
B25: Visitas | C25: 100 | D25: =SUM(E25:O25) -> 52 | E25: 25 | H25: 27
B26: Recuperación del espacio público | C26: 0 | D26: =SUM(E26:O26) -> 0
B27: Convocatoria de Mesas Locales | C27: 4 | D27: =SUM(E27:O27) -> 5 | F27: 1 | G27: 3 | H27: 1
B28: Exposición Informe Territorial ESS | C28: 4 | D28: =SUM(E28:O28) -> 4 | G28: 2 | H28: 2
B29: Primera Sesión de Trabajo | C29: 4 | D29: =SUM(E29:O29) -> 4 | I29: 4
B30: Segunda Sesión - Conformación Secretaria Técnica | C30: 4 | D30: =SUM(E30:O30) -> 1 | J30: 1
B31: Tercera Sesión | C31: 4 | D31: =SUM(E31:O31) -> 0
B32: Elaboracióin del Texto de la Política Local | C32: 1 | D32: =SUM(E32:O32) -> 0
B33: Revisión Técnica DPPP | C33: 1 | D33: =SUM(E33:O33) -> 0
B34: Revisión Area Legal Gobierno Local | C34: 1 | D34: =SUM(E34:O34) -> 0
B35: Incorporación de Observaciones | C35: 1 | D35: =SUM(E35:O35) -> 0
B36: Aval del Director Regional | C36: 1 | D36: =SUM(E36:O36) -> 0
B37: Presentación al Consejo Municipal | C37: 1 | D37: =SUM(E37:O37) -> 0
B38: Presentación ante la Comunidad por parte del Director Regional y Alcalde | C38: 1 | D38: =SUM(E38:O38) -> 0
C39: =SUM(C3:C38) -> 303 | D39: =SUM(D3:D38) -> 136
D40: =D39/C39 -> 0.44884488

Sheet D93 Guácimo
A1: PROGRAMA | B1: D93 GUACIMO | C1: META | D1: AVANCE | E1: ENERO | F1: FEBRERO | G1: MARZO | H1: ABRIL | I1: MAYO | J1: JUNIO | K1: JULIO | L1: AGOSTO | M1: SEPTIEMBRE | N1: OCTUBRE | O1: NOVIEMBRE | P1: DICIEMBRE
C2: 2026 | D2: Porcentual
A3: PSCC | B3: Cuatro actividades de recuperación de espacios públicos, con las comunidades integradas al Programa de Seguridad Comunitaria, que se localicen, en los distritos que contemplan las área georreferenciadas del informe territorial de la Estrategia Sembremos Seguridad 2024, dos por año, una por semestre. | C3: 2 | D3: =SUM(E3:P3) -> 1 | F3: 1
A4: GREAT/MPAS/DARE | B4: Realizar 4 procesos formativos (Cursos de la oferta de los programas DARE - GREAT - MPAS) en Centros Educativos, dos por año, dentro de los distritos que contemplan las áreas georreferenciadas del informe territorial de la Estrategia Sembremos Seguridad 2024. En caso de no contar con instructor acreditado DARE, se puede cumplir la meta con las charlas de Habilidades para la vida DARE, con el aval del Coordinador Nacional. | C4: 2 | D4: =SUM(E4:P4) -> 2 | E4: 0 | F4: 0 | G4: 0 | H4: 1 | I4: 1
A5: PSCC | B5: Dos estrategias de divulgación (Por medio de brochures, post o imágenes en redes sociales) en el tema del procedimiento para realizar una "Denuncia de ventas de drogas” diseñadas por la Estrategia de divulgación de la Dirección de Programas Policiales Preventivos dirigidas a las comunidades integradas al Programa de Seguridad Comunitaria que se localicen, en los distritos que contemplan las áreas georreferenciadas del informe territorial de la Estrategia Sembremos Seguridad 2024, una por año. | C5: 2 | D5: =SUM(E5:P5) -> 1 | G5: 1
A6: PSCC | B6: Dos capacitaciones, en el tema de "Denuncia a búnkers", dirigidas a las comunidades integradas al Programa de Seguridad Comunitaria que se localicen, en los distritos que contemplan las área georreferenciadas del informe territorial de la Estrategia Sembremos Seguridad 2024, una por año. | C6: 1 | D6: =SUM(E6:P6) -> 0
A7: PSCC | B7: Dos estrategias de divulgación (Por medio de brochures, post o imágenes en redes sociales) en el tema del procedimiento para realizar una "Denuncia de búnkers" dirigidas a las comunidades integradas al Programa de Seguridad Comunitaria que se localicen, en los distritos que contemplan las área georreferenciadas del informe territorial de la Estrategia Sembremos Seguridad 2024, una por año. | C7: 1 | D7: =SUM(E7:P7) -> 1 | G7: 1
A8: PSCC | B8: Dos capacitaciones, en el tema de Cultura Preventiva enfocada a delitos contra la propiedad.(Prevención en caso de Hurtos, Robo y Asaltos).", dirigidas a las comunidades integradas al Programa de Seguridad Comunitaria que se localicen, en los distritos que contemplan las área georreferenciadas del informe territorial de la Estrategia Sembremos Seguridad 2024, una por año. | C8: 1 | D8: =SUM(E8:P8) -> 2 | G8: 1 | H8: 1
A9: PSCC | B9: Dos estrategias de divulgación (Por medio de brochures, post o imágenes en redes sociales) en el tema del procedimiento para realizar una "Cultura Preventiva enfocada a delitos contra la propiedad. (Prevención en caso de Hurtos, Robo y Asallos)." dirigidas a las comunidades integradas al Programa de Seguridad Comunitaria, que se localicen, dentro del área georreferenciada del informe territorial de la Estrategia Sembremos Seguridad 2024, una por año. | C9: 1 | D9: =SUM(E9:P9) -> 0
A10: PLAN DE POLITICA LOCAL E IMPLEMENTACIÓN DE LA POLITICA LOCAL DE SEGURIDAD | B10: Conformación Comité | C10: 3 | D10: =SUM(E10:O10) -> 0
B11: Conformación de Comercio | C11: 3 | D11: =SUM(E11:O11) -> 0
B12: Reuniones-Jefaturas | C12: 96 | D12: =SUM(E12:O12) -> 67 | F12: 24 | G12: 24 | H12: 19
B13: Campañas de divulgación | C13: 102 | D13: =SUM(E13:O13) -> 0
B14: Capacitaciones | C14: 0 | D14: =SUM(E14:O14) -> 0
B15: Charlas | C15: 3 | D15: =SUM(E15:O15) -> 0
B16: Talleres | C16: 0 | D16: =SUM(E16:O16) -> 0
B17: Sensibilización | C17: 5 | D17: =SUM(E17:O17) -> 0
B18: Actividades deportivas | C18: 0 | D18: =SUM(E18:O18) -> 0
B19: Cine en mi Barrio | C19: 0 | D19: =SUM(E19:O19) -> 0
B20: Cívico-policial | C20: 2 | D20: =SUM(E20:O20) -> 0
B21: Actividades culturales | C21: 0 | D21: =SUM(E21:O21) -> 0
B22: Ferias | C22: 0 | D22: =SUM(E22:O22) -> 0
B23: Stand informativo | C23: 0 | D23: =SUM(E23:O23) -> 0
B24: Visitas | C24: 35 | D24: =SUM(E24:O24) -> 17 | F24: 17
B25: Recuperación del espacio público | C25: 15 | D25: =SUM(E25:O25) -> 0
B26: Convocatoria de Mesas Locales | C26: 5 | D26: =SUM(E26:O26) -> 4 | G26: 4
B27: Exposición Informe Territorial ESS | C27: 5 | D27: =SUM(E27:O27) -> 4 | H27: 2 | I27: 2
B28: Primera Sesión de Trabajo | C28: 5 | D28: =SUM(E28:O28) -> 4 | I28: 4
B29: Segunda Sesión - Conformación Secretaria Técnica | C29: 5 | D29: =SUM(E29:O29) -> 0
B30: Tercera Sesión | C30: 5 | D30: =SUM(E30:O30) -> 0
B31: Elaboracióin del Texto de la Política Local | C31: 1 | D31: =SUM(E31:O31) -> 0
B32: Revisión Técnica DPPP | C32: 1 | D32: =SUM(E32:O32) -> 0
B33: Revisión Area Legal Gobierno Local | C33: 1 | D33: =SUM(E33:O33) -> 0
B34: Incorporación de Observaciones | C34: 1 | D34: =SUM(E34:O34) -> 0
B35: Aval del Director Regional | C35: 1 | D35: =SUM(E35:O35) -> 0
B36: Presentación al Consejo Municipal | C36: 1 | D36: =SUM(E36:O36) -> 0
B37: Presentación ante la Comunidad por parte del Director Regional y Alcalde | C37: 1 | D37: =SUM(E37:O37) -> 0
C38: =SUM(C3:C37) -> 306 | D38: =SUM(D3:D37) -> 103
D39: =D38/C38 -> 0.33660131

Sheet D98 Pococí Norte
A1: PROGRAMA | B1: D98 POCOCÍ NORTE | C1: META | D1: AVANCE | E1: ENERO | F1: FEBRERO | G1: MARZO | H1: ABRIL | I1: MAYO | J1: JUNIO | K1: JULIO | L1: AGOSTO | M1: SEPTIEMBRE | N1: OCTUBRE | O1: NOVIEMBRE | P1: DICIEMBRE
C2: 2026 | D2: Porcentual
A3: PSCC | B3: Cuatro actividades de recuperación de espacios públicos, con las comunidades integradas al Programa de Seguridad Comunitaria, que se localicen, en los distritos que contemplan las área georreferenciadas del informe territorial de la Estrategia Sembremos Seguridad 2024, dos por año, una por semestre. | C3: 2 | D3: =SUM(E3:P3) -> 1 | G3: 1
A4: GREAT/MPAS/DARE | B4: Realizar 4 procesos formativos (Cursos de la oferta de los programas DARE - GREAT - MPAS) en Centros Educativos, dos por año, dentro de los distritos que contemplan las áreas georreferenciadas del informe territorial de la Estrategia Sembremos Seguridad 2024. En caso de no contar con instructor acreditado DARE, se puede cumplir la meta con las charlas de Habilidades para la vida DARE, con el aval del Coordinador Nacional. | C4: 2 | D4: =SUM(E4:P4) -> 2 | E4: 0 | F4: 0 | G4: 0 | H4: 0 | I4: 2
A5: DARE | B5: Cubrir 2 procesos formativos en Centros Educativos (uno por año) ubicados dentro de los distritos que contemplan las áreas georreferenciadas del informe territorial de la Estrategia Sembremos Seguridad 2024, con los cursos del Programa DARE: Curso primaria. Curso Secundaria; un nivel completo por centro educativo, por semestre. En caso de no contar con instructor acreditado, se puede cumplir la meta con las charlas de Habilidades para la vida DARE, con el aval del Coordinador Nacional. | C5: 2 | D5: =SUM(E5:P5) -> 1 | E5: 0 | F5: 0 | G5: 0 | H5: 1
A6: PSCC | B6: Cuatro comercios capacitados e integrados al Programa de Seguridad Comercial que se localicen, en los distritos que contemplan las área georreferenciadas del informe territorial de la Estrategia Sembremos Seguridad 2024, dos por año, una por semestre. | C6: 2 | D6: =SUM(E6:P6) -> 0
A7: PSCC | B7: Cuatro estrategias de divulgación (Por medio de brochures, post o imágenes en redes sociales) diseñadas por la Estrategia de divulgación de la Dirección de Programas Policiales Preventivos, en el tema de "Prevención del Consumo de alcohol en vía pública" dirigidas a las comunidades integradas al Programa de Seguridad Comunitaria y a los comercios integrados al Programa de Seguridad Comercial que se localicen, en los distritos que contemplan las área georreferenciadas del informe territorial de la Estrategia Sembremos Seguridad 2024, dos por año. | C7: 2 | D7: =SUM(E7:P7) -> 0
A8: PSCC | B8: Dos estrategias de divulgación (Por medio de brochures, post o imágenes en redes sociales) en el tema del procedimiento para realizar una "Denuncia de ventas de drogas" diseñadas por la Estrategia de divulgación de la Dirección de Programas Policiales Preventivos dirigidas a las comunidades integradas al Programa de Seguridad Comunitaria que se localicen, en los distritos que contemplan las área georreferenciadas del informe territorial de la Estrategia Sembremos Seguridad 2024, una por año. | C8: 1 | D8: =SUM(E8:P8) -> 0
A9: PSCC | B9: Cuatro capacitaciones, en el tema de "Denuncia a búnkers", dirigidas a las comunidades integradas al Programa de Seguridad Comunitaria que se localicen, en los distritos que contemplan las área georreferenciadas del informe territorial de la Estrategia Sembremos Seguridad 2024, dos por año, una por semestre. | C9: 2 | D9: =SUM(E9:P9) -> 0
A10: PSCC | B10: Dos estrategias de divulgación (Por medio de brochures, post o imágenes en redes sociales) en el tema del procedimiento para realizar una "Denuncia de búnkers" dirigidas a las comunidades integradas al Programa de Seguridad Comunitaria que se localicen, en los distritos que contemplan las área georreferenciadas del informe territorial de la Estrategia Sembremos Seguridad 2024, una por año. | C10: 1 | D10: =SUM(E10:P10) -> 0
A11: PSCC | B11: Cuatro capacitaciones, en el tema de "Cultura preventiva y auto cuidado", dirigidas a las comunidades integradas al Programa de Seguridad Comunitaria que se localicen, en los distritos que contemplan las área georreferenciadas del informe territorial de la Estrategia Sembremos Seguridad 2024, dos por año, una por semestre. | C11: 2 | D11: =SUM(E11:P11) -> 1 | I11: 1
A12: PSCC | B12: Dos estrategias de divulgación (Por medio de brochures, post o imágenes en redes sociales) en el tema "Cultura preventiva y auto cuidado" dirigidas a las comunidades integradas al Programa de Seguridad Comunitaria que se localicen, en los distritos que contemplan las área georreferenciadas del informe territorial de la Estrategia Sembremos Seguridad 2024, una por año. | C12: 1 | D12: =SUM(E12:P12) -> 1 | I12: 1
A13: PLAN DE POLITICA LOCAL E IMPLEMENTACIÓN DE LA POLITICA LOCAL DE SEGURIDAD | B13: Conformación Comité | C13: 3 | D13: =SUM(E13:O13) -> 0
B14: Conformación de Comercio | C14: 3 | D14: =SUM(E14:O14) -> 0
B15: Reuniones-Jefaturas | C15: 112 | D15: =SUM(E15:O15) -> 54 | F15: 13 | G15: 13 | H15: 28
B16: Campañas de divulgación | C16: 33 | D16: =SUM(E16:O16) -> 14 | F16: 11 | G16: 3
B17: Capacitaciones | C17: 20 | D17: =SUM(E17:O17) -> 4 | H17: 4
B18: Charlas | C18: 18 | D18: =SUM(E18:O18) -> 1 | I18: 1
B19: Talleres | C19: 0 | D19: =SUM(E19:O19) -> 0
B20: Sensibilización | C20: 0 | D20: =SUM(E20:O20) -> 0
B21: Actividades deportivas | C21: 4 | D21: =SUM(E21:O21) -> 1 | H21: 1
B22: Cine en mi Barrio | C22: 1 | D22: =SUM(E22:O22) -> 0
B23: Cívico-policial | C23: 0 | D23: =SUM(E23:O23) -> 0
B24: Actividades culturales | C24: 2 | D24: =SUM(E24:O24) -> 0
B25: Ferias | C25: 0 | D25: =SUM(E25:O25) -> 0
B26: Stand informativo | C26: 12 | D26: =SUM(E26:O26) -> 0
B27: Visitas | C27: 20 | D27: =SUM(E27:O27) -> 13 | G27: 13
B28: Recuperación del espacio público | C28: 2 | D28: =SUM(E28:O28) -> 0
B29: Convocatoria de Mesas Locales | C29: 3 | D29: =SUM(E29:O29) -> 2 | G29: 1 | H29: 1
B30: Exposición Informe Territorial ESS | C30: 3 | D30: =SUM(E30:O30) -> 1 | I30: 1
B31: Primera Sesión de Trabajo | C31: 3 | D31: =SUM(E31:O31) -> 1 | I31: 1
B32: Segunda Sesión - Conformación Secretaria Técnica | C32: 3 | D32: =SUM(E32:O32) -> 0
B33: Tercera Sesión | C33: 3 | D33: =SUM(E33:O33) -> 0
B34: Elaboracióin del Texto de la Política Local | C34: 1 | D34: =SUM(E34:O34) -> 0
B35: Revisión Técnica DPPP | C35: 1 | D35: =SUM(E35:O35) -> 0
B36: Revisión Area Legal Gobierno Local | C36: 1 | D36: =SUM(E36:O36) -> 0
B37: Incorporación de Observaciones | C37: 1 | D37: =SUM(E37:O37) -> 0
B38: Aval del Director Regional | C38: 1 | D38: =SUM(E38:O38) -> 0
B39: Presentación al Consejo Municipal | C39: 1 | D39: =SUM(E39:O39) -> 0
B40: Presentación ante la Comunidad por parte del Director Regional y Alcalde | C40: 1 | D40: =SUM(E40:O40) -> 0
...

Sheet Total Región
A1: Delegación | C1: META | D1: AVANCE | E1: % AVANCE
A2: D58 | B2: SARAPIQUÍ | C2: ='D58 Sarapiquí'!C37 -> 412 | D2: ='D58 Sarapiquí'!D37 -> 164 | E2: =D2/C2 -> 0.39805825
A3: D59 | B3: COLORADO | C3: ='D89 Pococí Sur'!C39 -> 303 | D3: ='D89 Pococí Sur'!D39 -> 136 | E3: =D3/C3 -> 0.44884488
A4: D90 | B4: POCOCÍ | C4: ='D93 Guácimo'!C38 -> 306 | D4: ='D93 Guácimo'!D38 -> 103 | E4: =D4/C4 -> 0.33660131
A5: D93 | B5: GUÁCIMO | C5: ='D98 Pococí Norte'!C41 -> 269 | D5: ='D98 Pococí Norte'!D41 -> 97 | E5: =D5/C5 -> 0.3605948
B6: TOTALES | C6: =SUM(C2:C5) -> 1290 | D6: =SUM(D2:D5) -> 500 | E6: =D6/C6 -> 0.3875969
