Workbook
Name ABANG: [1]DAT2!#REF!
Name ABANG: [2]DAT2!#REF!
Name ABANG: [3]DAT2!#REF!
Name ABANG: [4]DAT2!#REF!
Name ABANG: [5]DAT2!#REF!
Name ABANG: [6]DAT2!#REF!
Name ABANG: [7]DAT2!#REF!
Name ABANG: [8]DAT2!#REF!
Name ABANG: [9]DAT2!#REF!
Name ABANG: [10]DAT2!#REF!
Name ABANG: [11]DAT2!#REF!
Name ABANG: [12]DAT2!#REF!
Name ACOS: [1]DAT2!#REF!
Name ACOS: [2]DAT2!#REF!
Name ACOS: [3]DAT2!#REF!
Name ACOS: [4]DAT2!#REF!
Name ACOS: [5]DAT2!#REF!
Name ACOS: [6]DAT2!#REF!
Name ACOS: [7]DAT2!#REF!
Name ACOS: [8]DAT2!#REF!
Name ACOS: [9]DAT2!#REF!
Name ACOS: [10]DAT2!#REF!
Name ACOS: [11]DAT2!#REF!
Name ACOS: [12]DAT2!#REF!
Name ALAJU: [1]DAT2!#REF!
Name ALAJU: [2]DAT2!#REF!
Name ALAJU: [3]DAT2!#REF!
Name ALAJU: [4]DAT2!#REF!
Name ALAJU: [5]DAT2!#REF!
Name ALAJU: [6]DAT2!#REF!
Name ALAJU: [7]DAT2!#REF!
Name ALAJU: [8]DAT2!#REF!
Name ALAJU: [9]DAT2!#REF!
Name ALAJU: [10]DAT2!#REF!
Name ALAJU: [11]DAT2!#REF!
Name ALAJU: [12]DAT2!#REF!
Name ALAJUE: [1]DAT2!#REF!
Name ALAJUE: [2]DAT2!#REF!
Name ALAJUE: [3]DAT2!#REF!
Name ALAJUE: [4]DAT2!#REF!
Name ALAJUE: [5]DAT2!#REF!
Name ALAJUE: [6]DAT2!#REF!
Name ALAJUE: [7]DAT2!#REF!
Name ALAJUE: [8]DAT2!#REF!
Name ALAJUE: [9]DAT2!#REF!
Name ALAJUE: [10]DAT2!#REF!
Name ALAJUE: [11]DAT2!#REF!
Name ALAJUE: [12]DAT2!#REF!
Name ALVA: [1]DAT2!#REF!
Name ALVA: [2]DAT2!#REF!
Name ALVA: [3]DAT2!#REF!
Name ALVA: [4]DAT2!#REF!
Name ALVA: [5]DAT2!#REF!
Name ALVA: [6]DAT2!#REF!
Name ALVA: [7]DAT2!#REF!
Name ALVA: [8]DAT2!#REF!
Name ALVA: [9]DAT2!#REF!
Name ALVA: [10]DAT2!#REF!
Name ALVA: [11]DAT2!#REF!
Name ALVA: [12]DAT2!#REF!

Sheet D26 Alajuela Sur
A1: PROGRAMA | B1: D26 ALAJUELA SUR | C1: META | D1: AVANCE | E1: ENERO | F1: FEBRERO | G1: MARZO | H1: ABRIL | I1: MAYO | J1: JUNIO | K1: JULIO | L1: AGOSTO | M1: SEPTIEMBRE | N1: OCTUBRE | O1: NOVIEMBRE | P1: DICIEMBRE
C2: 2026 | D2: Porcentual
A3: PSCC | B3: Cuatro actividades de recuperación de espacios públicos, con las comunidades integradas al Programa de Seguridad Comunitaria, que se localicen, en los distritos que contemplan las área georreferenciadas del informe territorial de la Estrategia Sembremos Seguridad 2024, dos por año, una por semestre. | C3: 2 | D3: =SUM(E3:P3) -> 0
A4: GREAT/MPAS/DARE | B4: Realizar 4 procesos formativos (Cursos de la oferta de los programas DARE - GREAT - MPAS) en Centros Educativos, 2 por año, dentro de los distritos que contemplan las áreas georreferenciadas del informe territorial de la Estrategia Sembremos Seguridad 2024. Un curso diferente por semestre, un nivel completo. En caso de no contar con instructor acreditado DARE, se puede cumplir la meta con las charlas de Habilidades para la vida DARE, con el aval del Coordinador Nacional. | C4: 2 | D4: =SUM(E4:P4) -> 1 | E4: 0 | F4: 0 | G4: 0 | H4: 0 | I4: 1
A5: PSCC | B5: Dos estrategias de divulgación (Por medio de brochures, post o imágenes en redes sociales) en el tema del procedimiento para realizar una "Denuncia de ventas de drogas" dirigidas a las comunidades integradas al Programa de Seguridad Comunitaria que se localicen, en los distritos que contemplan las área georreferenciadas del informe territorial de la Estrategia Sembremos Seguridad 2024, una por año. | C5: 1 | D5: =SUM(E5:P5) -> 1 | G5: 1
A6: DARE | B6: Cubrir 4 procesos formativos en Centros Educativos (dos por año) ubicados dentro de los distritos que contemplan las áreas georreferenciadas del informe territorial de la Estrategia Sembremos Seguridad 2024, con los cursos del Programa DARE: , Curso primaria. Curso Secundaria; un nivel completo por centro educativo, por semestre. En caso de no contar con instructor acreditado, se puede cumplir la meta con las charlas de Habilidades para la vida DARE, con el aval del Coordinador Nacional. | C6: 2 | D6: =SUM(E6:P6) -> 1 | E6: 0 | F6: 0 | G6: 0 | H6: 1
A7: PSCC | B7: Cuatro capacitaciones, en el tema de "Denuncia a búnkers", dirigidas a las comunidades integradas al Programa de Seguridad Comunitaria que se localicen, en los distritos que contemplan las área georreferenciadas del informe territorial de la Estrategia Sembremos Seguridad 2024, dos por año, una por semestre. | C7: 2 | D7: =SUM(E7:P7) -> 1 | G7: 1
A8: PSCC | B8: Dos estrategias de divulgación (Por medio de brochures, post o imágenes en redes sociales) en el tema del procedimiento para realizar una "Denuncia de búnkers" dirigidas a las comunidades integradas al Programa de Seguridad Comunitaria que se localicen, en los distritos que contemplan las área georreferenciadas del informe territorial de la Estrategia Sembremos Seguridad 2024, una por año. | C8: 1 | D8: =SUM(E8:P8) -> 0
A9: PSCC | B9: Cuatro Charlas de Cultura Preventiva (Una por año) con énfasis en temas de estafa dirigidas a las comunidades integradas al Programa de Seguridad Comunitaria, que se localicen, en los distritos que contemplan las área georreferenciadas del informe territorial de la Estrategia Sembremos Seguridad 2024, dos por año, una por semestre. | C9: 2 | D9: =SUM(E9:P9) -> 1 | G9: 1
A10: PSCC | B10: Dos estrategias de divulgación (Por medio de brochures, post o imágenes en redes sociales) en el tema del procedimiento para realizar una "Denuncia ante Estafas" dirigidas a las comunidades integradas al Programa de Seguridad Comunitaria, que se localicen, en los distritos que contemplan las área georreferenciadas del informe territorial de la Estrategia Sembremos Seguridad 2024, una por año. | C10: 1 | D10: =SUM(E10:P10) -> 0
A11: PLAN DE POLITICA LOCAL E IMPLEMENTACIÓN DE LA POLITICA LOCAL DE SEGURIDAD | B11: Conformación Comité | C11: 3 | D11: =SUM(E11:O11) -> 3 | H11: 3
B12: Conformación de Comercio | C12: 3 | D12: =SUM(E12:O12) -> 2 | G12: 2
B13: Reuniones-Jefaturas | C13: 112 | D13: =SUM(E13:O13) -> 33 | E13: 1 | F13: 12 | G13: 4 | H13: 9 | I13: 7
B14: Campañas de divulgación | C14: 98 | D14: =SUM(E14:O14) -> 8 | G14: 8
B15: Capacitaciones | C15: 0 | D15: =SUM(E15:O15) -> 0
B16: Charlas | C16: 19 | D16: =SUM(E16:O16) -> 0
B17: Talleres | C17: 0 | D17: =SUM(E17:O17) -> 0
B18: Sensibilización | C18: 1 | D18: =SUM(E18:O18) -> 0
B19: Actividades deportivas | C19: 1 | D19: =SUM(E19:O19) -> 0
B20: Cine en mi Barrio | C20: 1 | D20: =SUM(E20:O20) -> 1 | E20: 1
B21: Cívico-policial | C21: 0 | D21: =SUM(E21:O21) -> 0
B22: Actividades culturales | C22: 0 | D22: =SUM(E22:O22) -> 0
B23: Ferias | C23: 0 | D23: =SUM(E23:O23) -> 0
B24: Stand informativo | C24: 0 | D24: =SUM(E24:O24) -> 0
B25: Visitas | C25: 27 | D25: =SUM(E25:O25) -> 15 | E25: 7 | F25: 1 | H25: 7
B26: Recuperación del espacio público | C26: 3 | D26: =SUM(E26:O26) -> 1 | I26: 1
B27: Convocatoria de Mesas Locales | C27: 0 | D27: =SUM(E27:O27) -> 0
B28: Exposición Informe Territorial ESS | C28: 0 | D28: =SUM(E28:O28) -> 0
B29: Primera Sesión de Trabajo | C29: 0 | D29: =SUM(E29:O29) -> 0
B30: Segunda Sesión - Conformación Secretaria Técnica | C30: 0 | D30: =SUM(E30:O30) -> 0
B31: Tercera Sesión | C31: 0 | D31: =SUM(E31:O31) -> 0
B32: Elaboracióin del Texto de la Política Local | C32: 0 | D32: =SUM(E32:O32) -> 0
B33: Revisión Técnica DPPP | C33: 0 | D33: =SUM(E33:O33) -> 0
B34: Revisión Area Legal Gobierno Local | C34: 0 | D34: =SUM(E34:O34) -> 0
B35: Incorporación de Observaciones | C35: 0 | D35: =SUM(E35:O35) -> 0
B36: Aval del Director Regional | C36: 0 | D36: =SUM(E36:O36) -> 0
B37: Presentación al Consejo Municipal | C37: 0 | D37: =SUM(E37:O37) -> 0
B38: Presentación ante la Comunidad por parte del Director Regional y Alcalde | C38: 0 | D38: =SUM(E38:O38) -> 0
C39: =SUM(C3:C38) -> 281 | D39: =SUM(D3:D38) -> 68
D40: =D39/C39 -> 0.24199288

Sheet D27 Alajuela Norte
A1: PROGRAMA | B1: D27 ALAJUELA NORTE | C1: META | D1: AVANCE | E1: ENERO | F1: FEBRERO | G1: MARZO | H1: ABRIL | I1: MAYO | J1: JUNIO | K1: JULIO | L1: AGOSTO | M1: SEPTIEMBRE | N1: OCTUBRE | O1: NOVIEMBRE | P1: DICIEMBRE
C2: 2026 | D2: Porcentual
A3: PSCC | B3: Cuatro actividades de recuperación de espacios públicos, con las comunidades integradas al Programa de Seguridad Comunitaria, que se localicen, en los distritos que contemplan las área georreferenciadas del informe territorial de la Estrategia Sembremos Seguridad 2024, dos por año, una por semestre. | C3: 2 | D3: =SUM(E3:P3) -> 0
A4: GREAT/MPAS/DARE | B4: Realizar 4 procesos formativos (Cursos de la oferta de los programas DARE - GREAT - MPAS) en Centros Educativos, 2 por año, dentro de los distritos que contemplan las áreas georreferenciadas del informe territorial de la Estrategia Sembremos Seguridad 2024. Un curso diferente por semestre, un nivel completo. En caso de no contar con instructor acreditado DARE, se puede cumplir la meta con las charlas de Habilidades para la vida DARE, con el aval del Coordinador Nacional. | C4: 2 | D4: =SUM(E4:P4) -> 1 | E4: 0 | F4: 0 | G4: 0 | H4: 1
A5: PSCC | B5: Dos estrategias de divulgación (Por medio de brochures, post o imágenes en redes sociales) en el tema del procedimiento para realizar una "Denuncia de ventas de drogas" dirigidas a las comunidades integradas al Programa de Seguridad Comunitaria que se localicen, en los distritos que contemplan las área georreferenciadas del informe territorial de la Estrategia Sembremos Seguridad 2024, una por año. | C5: 1 | D5: =SUM(E5:P5) -> 1 | I5: 1
A6: DARE | B6: Cubrir 4 procesos formativos en Centros Educativos (dos por año) ubicados dentro de los distritos que contemplan las áreas georreferenciadas del informe territorial de la Estrategia Sembremos Seguridad 2024, con los cursos del Programa DARE: , Curso primaria. Curso Secundaria; un nivel completo por centro educativo, por semestre. En caso de no contar con instructor acreditado, se puede cumplir la meta con las charlas de Habilidades para la vida DARE, con el aval del Coordinador Nacional. | C6: 2 | D6: =SUM(E6:P6) -> 1 | E6: 0 | F6: 0 | G6: 0 | H6: 1
A7: PLAN DE POLITICA LOCAL E IMPLEMENTACIÓN DE LA POLITICA LOCAL DE SEGURIDAD | B7: Conformación Comité | C7: 3 | D7: =SUM(E7:O7) -> 1 | G7: 1
B8: Conformación de Comercio | C8: 1 | D8: =SUM(E8:O8) -> 0
B9: Reuniones-Jefaturas | C9: 184 | D9: =SUM(E9:O9) -> 65 | E9: 14 | F9: 15 | G9: 14 | H9: 16 | I9: 6
B10: Campañas de divulgación | C10: 240 | D10: =SUM(E10:O10) -> 80 | G10: 24 | H10: 56
B11: Capacitaciones | C11: 0 | D11: =SUM(E11:O11) -> 0
B12: Charlas | C12: 0 | D12: =SUM(E12:O12) -> 0
B13: Talleres | C13: 0 | D13: =SUM(E13:O13) -> 0
B14: Sensibilización | C14: 0 | D14: =SUM(E14:O14) -> 0
B15: Actividades deportivas | C15: 0 | D15: =SUM(E15:O15) -> 0
B16: Cine en mi Barrio | C16: 0 | D16: =SUM(E16:O16) -> 0
B17: Cívico-policial | C17: 1 | D17: =SUM(E17:O17) -> 1 | E17: 1
B18: Actividades culturales | C18: 0 | D18: =SUM(E18:O18) -> 0
B19: Ferias | C19: 0 | D19: =SUM(E19:O19) -> 0
B20: Stand informativo | C20: 0 | D20: =SUM(E20:O20) -> 0
B21: Visitas | C21: 143 | D21: =SUM(E21:O21) -> 67 | F21: 33 | I21: 34
B22: Recuperación del espacio público | C22: 2 | D22: =SUM(E22:O22) -> 0
B23: Convocatoria de Mesas Locales | C23: 0 | D23: =SUM(E23:O23) -> 0
B24: Exposición Informe Territorial ESS | C24: 0 | D24: =SUM(E24:O24) -> 0
B25: Primera Sesión de Trabajo | C25: 0 | D25: =SUM(E25:O25) -> 0
B26: Segunda Sesión - Conformación Secretaria Técnica | C26: 0 | D26: =SUM(E26:O26) -> 0
B27: Tercera Sesión | C27: 0 | D27: =SUM(E27:O27) -> 0
B28: Elaboracióin del Texto de la Política Local | C28: 0 | D28: =SUM(E28:O28) -> 0
B29: Revisión Técnica DPPP | C29: 0 | D29: =SUM(E29:O29) -> 0
B30: Revisión Area Legal Gobierno Local | C30: 0 | D30: =SUM(E30:O30) -> 0
B31: Incorporación de Observaciones | C31: 0 | D31: =SUM(E31:O31) -> 0
B32: Aval del Director Regional | C32: 0 | D32: =SUM(E32:O32) -> 0
B33: Presentación al Consejo Municipal | C33: 0 | D33: =SUM(E33:O33) -> 0
B34: Presentación ante la Comunidad por parte del Director Regional y Alcalde | C34: 0 | D34: =SUM(E34:O34) -> 0
C35: =SUM(C3:C34) -> 581 | D35: =SUM(D3:D34) -> 217
D36: =D35/C35 -> 0.37349398

Sheet D28 San Ramón
A1: PROGRAMA | B1: D28 SAN RAMÓN | C1: META | D1: AVANCE | E1: ENERO | F1: FEBRERO | G1: MARZO | H1: ABRIL | I1: MAYO | J1: JUNIO | K1: JULIO | L1: AGOSTO | M1: SEPTIEMBRE | N1: OCTUBRE | O1: NOVIEMBRE | P1: DICIEMBRE
C2: 2026 | D2: Porcentual
A3: PSCC | B3: Cuatro actividades de recuperación de espacios públicos, con las comunidades integradas al Programa de Seguridad Comunitaria, que se localicen, en los distritos que contemplan las área georreferenciadas del informe territorial de la Estrategia Sembremos Seguridad 2024, dos por año, una por semestre. | C3: 2 | D3: =SUM(E3:P3) -> 1 | I3: 1
A4: GREAT/MPAS/DARE | B4: Realizar 4 procesos formativos (Cursos de la oferta de los programas DARE - GREAT - MPAS) en Centros Educativos, 2 por año, dentro de los distritos que contemplan las áreas georreferenciadas del informe territorial de la Estrategia Sembremos Seguridad 2024. Un curso diferente por semestre, un nivel completo. En caso de no contar con instructor acreditado DARE, se puede cumplir la meta con las charlas de Habilidades para la vida DARE, con el aval del Coordinador Nacional. | C4: 2 | D4: =SUM(E4:P4) -> 1 | E4: 0 | F4: 0 | G4: 0 | H4: 0 | I4: 1
A5: PSCC | B5: Dos estrategias de divulgación (Por medio de brochures, post o imágenes en redes sociales) en el tema del procedimiento para realizar una "Denuncia de ventas de drogas" dirigidas a las comunidades integradas al Programa de Seguridad Comunitaria que se localicen, en los distritos que contemplan las área georreferenciadas del informe territorial de la Estrategia Sembremos Seguridad 2024, una por año. | C5: 1 | D5: =SUM(E5:P5) -> 1 | E5: 1
A6: DARE | B6: Cubrir 4 procesos formativos en Centros Educativos (dos por año) ubicados dentro de los distritos que contemplan las áreas georreferenciadas del informe territorial de la Estrategia Sembremos Seguridad 2024, con los cursos del Programa DARE: , Curso primaria. Curso Secundaria; un nivel completo por centro educativo, por semestre. En caso de no contar con instructor acreditado, se puede cumplir la meta con las charlas de Habilidades para la vida DARE, con el aval del Coordinador Nacional. | C6: 2 | D6: =SUM(E6:P6) -> 0 | E6: 0 | F6: 0 | G6: 0 | H6: 0
A7: PSCC | B7: Cuatro capacitaciones, en el tema de "Denuncia a búnkers", dirigidas a las comunidades integradas al Programa de Seguridad Comunitaria que se localicen, en los distritos que contemplan las área georreferenciadas del informe territorial de la Estrategia Sembremos Seguridad 2024, dos por año, una por semestre. | C7: 2 | D7: =SUM(E7:P7) -> 1 | E7: 1
A8: PSCC | B8: Dos estrategias de divulgación (Por medio de brochures, post o imágenes en redes sociales) en el tema del procedimiento para realizar una "Denuncia de búnkers" dirigidas a las comunidades integradas al Programa de Seguridad Comunitaria que se localicen, en los distritos que contemplan las área georreferenciadas del informe territorial de la Estrategia Sembremos Seguridad 2024, una por año. | C8: 1 | D8: =SUM(E8:P8) -> 1 | H8: 1
A9: PLAN DE POLITICA LOCAL E IMPLEMENTACIÓN DE LA POLITICA LOCAL DE SEGURIDAD | B9: Conformación Comité | C9: 3 | D9: =SUM(E9:O9) -> 2 | E9: 1 | I9: 1
B10: Conformación de Comercio | C10: 3 | D10: =SUM(E10:O10) -> 3 | G10: 3
B11: Reuniones-Jefaturas | C11: 48 | D11: =SUM(E11:O11) -> 20 | E11: 4 | F11: 4 | G11: 4 | H11: 4 | I11: 4
B12: Campañas de divulgación | C12: 125 | D12: =SUM(E12:O12) -> 85 | E12: 13 | F12: 29 | H12: 43
B13: Capacitaciones | C13: 0 | D13: =SUM(E13:O13) -> 0
B14: Charlas | C14: 5 | D14: =SUM(E14:O14) -> 0
B15: Talleres | C15: 0 | D15: =SUM(E15:O15) -> 0
B16: Sensibilización | C16: 0 | D16: =SUM(E16:O16) -> 0
B17: Actividades deportivas | C17: 1 | D17: =SUM(E17:O17) -> 0
B18: Cine en mi Barrio | C18: 1 | D18: =SUM(E18:O18) -> 1 | I18: 1
B19: Cívico-policial | C19: 0 | D19: =SUM(E19:O19) -> 0
B20: Actividades culturales | C20: 0 | D20: =SUM(E20:O20) -> 0
B21: Ferias | C21: 0 | D21: =SUM(E21:O21) -> 0
B22: Stand informativo | C22: 0 | D22: =SUM(E22:O22) -> 0
B23: Visitas | C23: 38 | D23: =SUM(E23:O23) -> 0
B24: Recuperación del espacio público | C24: 2 | D24: =SUM(E24:O24) -> 0
B25: Convocatoria de Mesas Locales | C25: 12 | D25: =SUM(E25:O25) -> 12 | E25: 8 | G25: 2 | H25: 2
B26: Exposición Informe Territorial ESS | C26: 12 | D26: =SUM(E26:O26) -> 12 | G26: 7 | H26: 5
B27: Primera Sesión de Trabajo | C27: 12 | D27: =SUM(E27:O27) -> 12 | I27: 12
B28: Segunda Sesión - Conformación Secretaria Técnica | C28: 12 | D28: =SUM(E28:O28) -> 0
B29: Tercera Sesión | C29: 12 | D29: =SUM(E29:O29) -> 0
B30: Elaboracióin del Texto de la Política Local | C30: 1 | D30: =SUM(E30:O30) -> 0
B31: Revisión Técnica DPPP | C31: 1 | D31: =SUM(E31:O31) -> 0
B32: Revisión Area Legal Gobierno Local | C32: 1 | D32: =SUM(E32:O32) -> 0
B33: Incorporación de Observaciones | C33: 1 | D33: =SUM(E33:O33) -> 0
B34: Aval del Director Regional | C34: 1 | D34: =SUM(E34:O34) -> 0
B35: Presentación al Consejo Municipal | C35: 1 | D35: =SUM(E35:O35) -> 0
B36: Presentación ante la Comunidad por parte del Director Regional y Alcalde | C36: 1 | D36: =SUM(E36:O36) -> 0
C37: =SUM(C3:C36) -> 303 | D37: =SUM(D3:D36) -> 152
D38: =D37/C37 -> 0.50165017

Sheet D29 Grecia
A1: PROGRAMA | B1: D29 GRECIA | C1: META | D1: AVANCE | E1: ENERO | F1: FEBRERO | G1: MARZO | H1: ABRIL | I1: MAYO | J1: JUNIO | K1: JULIO | L1: AGOSTO | M1: SEPTIEMBRE | N1: OCTUBRE | O1: NOVIEMBRE | P1: DICIEMBRE
C2: 2026 | D2: Porcentual
A3: PSCC | B3: Cuatro actividades de recuperación de espacios públicos, dos por año, una por semestre. | C3: 2 | D3: =SUM(E3:P3) -> 0
A4: GREAT/MPAS/DARE | B4: Realizar 4 procesos formativos (Cursos de la oferta de los programas DARE - GREAT - MPAS) en Centros Educativos, 2 por año, dentro de los distritos que contemplan las áreas georreferenciadas del informe territorial de la Estrategia Sembremos Seguridad 2024. Un curso diferente por semestre, un nivel completo. En caso de no contar con instructor acreditado DARE, se puede cumplir la meta con las charlas de Habilidades para la vida DARE, con el aval del Coordinador Nacional. | C4: 2 | D4: =SUM(E4:P4) -> 2 | E4: 0 | F4: 0 | G4: 0 | H4: 0 | I4: 1 | J4: 1
A5: PSCC | B5: Dos estrategias de divulgación (Por medio de brochures, post o imágenes en redes sociales) en el tema del procedimiento para realizar una "Denuncia de Ventas de drogas" dirigida a los comités y comercios que integran los Programas de Seguridad Comunitaria y Comercial en el distrito ; dos veces por año. | C5: 1 | D5: =SUM(E5:P5) -> 0
A6: DARE | B6: Cubrir 4 procesos formativos en Centros Educativos (dos por año) ubicados dentro de los distritos que contemplan las áreas georreferenciadas del informe territorial de la Estrategia Sembremos Seguridad 2024, con los cursos del Programa DARE: , Curso primaria. Curso Secundaria; un nivel completo por centro educativo, por semestre. En caso de no contar con instructor acreditado, se puede cumplir la meta con las charlas de Habilidades para la vida DARE, con el aval del Coordinador Nacional. | C6: 2 | D6: =SUM(E6:P6) -> 0 | E6: 0 | F6: 0 | G6: 0 | H6: 0
A7: PSCC | B7: Dos Charlas de Cultura Preventiva (Una por año) con énfasis en temas de estafa, dirigidas a los comités y comercios del cantón. | C7: 1 | D7: =SUM(E7:P7) -> 0
A8: PSCC | B8: Dos estrategias de divulgación (Por medio de brochures, post o imágenes en redes sociales) en el tema del procedimiento para realizar una "Denuncia de búnkers" dirigida al comercio del distrito ; dos veces por año. | C8: 1 | D8: =SUM(E8:P8) -> 0
A9: PLAN DE POLITICA LOCAL E IMPLEMENTACIÓN DE LA POLITICA LOCAL DE SEGURIDAD | B9: Conformación Comité | C9: 3 | D9: =SUM(E9:O9) -> 1 | G9: 1
B10: Conformación de Comercio | C10: 3 | D10: =SUM(E10:O10) -> 3 | H10: 3
B11: Reuniones-Jefaturas | C11: 48 | D11: =SUM(E11:O11) -> 23 | F11: 5 | G11: 6 | I11: 12
B12: Campañas de divulgación | C12: 132 | D12: =SUM(E12:O12) -> 32 | G12: 32
B13: Capacitaciones | C13: 0 | D13: =SUM(E13:O13) -> 0
B14: Charlas | C14: 0 | D14: =SUM(E14:O14) -> 0
B15: Talleres | C15: 0 | D15: =SUM(E15:O15) -> 0
B16: Sensibilización | C16: 0 | D16: =SUM(E16:O16) -> 0
B17: Actividades deportivas | C17: 0 | D17: =SUM(E17:O17) -> 0
B18: Cine en mi Barrio | C18: 0 | D18: =SUM(E18:O18) -> 0
B19: Cívico-policial | C19: 0 | D19: =SUM(E19:O19) -> 0
B20: Actividades culturales | C20: 0 | D20: =SUM(E20:O20) -> 0
B21: Ferias | C21: 0 | D21: =SUM(E21:O21) -> 0
B22: Stand informativo | C22: 0 | D22: =SUM(E22:O22) -> 0
B23: Visitas | C23: 130 | D23: =SUM(E23:O23) -> 61 | F23: 27 | G23: 3 | I23: 31
B24: Recuperación del espacio público | C24: 2 | D24: =SUM(E24:O24) -> 1 | G24: 1
B25: Convocatoria de Mesas Locales | C25: 7 | D25: =SUM(E25:O25) -> 7 | F25: 1 | G25: 6
B26: Exposición Informe Territorial ESS | C26: 7 | D26: =SUM(E26:O26) -> 6 | H26: 6
B27: Primera Sesión de Trabajo | C27: 7 | D27: =SUM(E27:O27) -> 0
B28: Segunda Sesión - Conformación Secretaria Técnica | C28: 7 | D28: =SUM(E28:O28) -> 0
B29: Tercera Sesión | C29: 7 | D29: =SUM(E29:O29) -> 0
B30: Elaboracióin del Texto de la Política Local | C30: 1 | D30: =SUM(E30:O30) -> 0
B31: Revisión Técnica DPPP | C31: 1 | D31: =SUM(E31:O31) -> 0
B32: Revisión Area Legal Gobierno Local | C32: 1 | D32: =SUM(E32:O32) -> 0
B33: Incorporación de Observaciones | C33: 1 | D33: =SUM(E33:O33) -> 0
B34: Aval del Director Regional | C34: 1 | D34: =SUM(E34:O34) -> 0
B35: Presentación al Consejo Municipal | C35: 1 | D35: =SUM(E35:O35) -> 0
B36: Presentación ante la Comunidad por parte del Director Regional y Alcalde | C36: 1 | D36: =SUM(E36:O36) -> 0
C37: =SUM(C3:C36) -> 369 | D37: =SUM(D3:D36) -> 136
D38: =D37/C37 -> 0.36856369

Sheet D30 San Mateo
A1: PROGRAMA | B1: D30 SAN MATEO | C1: META | D1: AVANCE | E1: ENERO | F1: FEBRERO | G1: MARZO | H1: ABRIL | I1: MAYO | J1: JUNIO | K1: JULIO | L1: AGOSTO | M1: SEPTIEMBRE | N1: OCTUBRE | O1: NOVIEMBRE | P1: DICIEMBRE
C2: 2026 | D2: Porcentual
A3: PSCC | B3: Cuatro actividades de recuperación de espacios públicos, con las comunidades integradas al Programa de Seguridad Comunitaria, que se localicen, en los distritos que contemplan las área georreferenciadas del informe territorial de la Estrategia Sembremos Seguridad 2024, dos por año, una por semestre. | C3: 2 | D3: =SUM(E3:P3) -> 0
A4: GREAT/MPAS/DARE | B4: Realizar 4 procesos formativos (Cursos de la oferta de los programas DARE - GREAT - MPAS) en Centros Educativos, 2 por año, dentro de los distritos que contemplan las áreas georreferenciadas del informe territorial de la Estrategia Sembremos Seguridad 2024. Un curso diferente por semestre, un nivel completo. En caso de no contar con instructor acreditado DARE, se puede cumplir la meta con las charlas de Habilidades para la vida DARE, con el aval del Coordinador Nacional. | C4: 2 | D4: =SUM(E4:P4) -> 0 | E4: 0 | F4: 0 | G4: 0 | H4: 0
A5: DARE | B5: Cubrir 4 procesos formativos en Centros Educativos (dos por año) ubicados dentro de los distritos que contemplan las áreas georreferenciadas del informe territorial de la Estrategia Sembremos Seguridad 2024, con los cursos del Programa DARE: , Curso primaria. Curso Secundaria; un nivel completo por centro educativo, por semestre. En caso de no contar con instructor acreditado, se puede cumplir la meta con las charlas de Habilidades para la vida DARE, con el aval del Coordinador Nacional. | C5: 2 | D5: =SUM(E5:P5) -> 0 | E5: 0 | F5: 0 | G5: 0 | H5: 0
A6: PSCC | B6: Cuatro comercios capacitados e integrados al Programa de Seguridad Comercial que se localicen, en los distritos que contemplan las área georreferenciadas del informe territorial de la Estrategia Sembremos Seguridad 2024, dos por año, una por semestre. | C6: 2 | D6: =SUM(E6:P6) -> 0
A7: PSCC | B7: Cuatro estrategias de divulgación (Por medio de brochures, post o imágenes en redes sociales) diseñadas por la Estrategia de divulgación de la Dirección de Programas Policiales Preventivos, en el tema de "Prevención del Consumo de alcohol en vía pública" dirigidas a las comunidades integradas al Programa de Seguridad Comunitaria y a los comercios integrados al Programa de Seguridad Comercial que se localicen, en los distritos que contemplan las área georreferenciadas del informe territorial de la Estrategia Sembremos Seguridad 2024, dos por año. | C7: 2 | D7: =SUM(E7:P7) -> 0
A8: PSCC | B8: Dos estrategias de divulgación (Por medio de brochures, post o imágenes en redes sociales) en el tema del procedimiento para realizar una "Denuncia de ventas de drogas" diseñadas por la Estrategia de divulgación de la Dirección de Programas Policiales Preventivos dirigidas a las comunidades integradas al Programa de Seguridad Comunitaria que se localicen, en los distritos que contemplan las área georreferenciadas del informe territorial de la Estrategia Sembremos Seguridad 2024, una por año. | C8: 1 | D8: =SUM(E8:P8) -> 0
A9: PLAN DE POLITICA LOCAL E IMPLEMENTACIÓN DE LA POLITICA LOCAL DE SEGURIDAD | B9: Conformación Comité | C9: 3 | D9: =SUM(E9:O9) -> 0
B10: Conformación de Comercio | C10: 3 | D10: =SUM(E10:O10) -> 0
B11: Reuniones-Jefaturas | C11: 52 | D11: =SUM(E11:O11) -> 9 | F11: 7 | G11: 1 | H11: 1
B12: Campañas de divulgación | C12: 24 | D12: =SUM(E12:O12) -> 0
B13: Capacitaciones | C13: 0 | D13: =SUM(E13:O13) -> 0
B14: Charlas | C14: 68 | D14: =SUM(E14:O14) -> 2 | F14: 2
B15: Talleres | C15: 0 | D15: =SUM(E15:O15) -> 0
B16: Sensibilización | C16: 0 | D16: =SUM(E16:O16) -> 0
B17: Actividades deportivas | C17: 0 | D17: =SUM(E17:O17) -> 0
B18: Cine en mi Barrio | C18: 0 | D18: =SUM(E18:O18) -> 0
B19: Cívico-policial | C19: 0 | D19: =SUM(E19:O19) -> 0
B20: Actividades culturales | C20: 0 | D20: =SUM(E20:O20) -> 0
B21: Ferias | C21: 0 | D21: =SUM(E21:O21) -> 0
B22: Stand informativo | C22: 0 | D22: =SUM(E22:O22) -> 0
B23: Visitas | C23: 55 | D23: =SUM(E23:O23) -> 19 | E23: 10 | G23: 9
B24: Recuperación del espacio público | C24: 2 | D24: =SUM(E24:O24) -> 0
B25: Convocatoria de Mesas Locales | C25: 4 | D25: =SUM(E25:O25) -> 4 | G25: 4
B26: Exposición Informe Territorial ESS | C26: 4 | D26: =SUM(E26:O26) -> 4 | H26: 4
B27: Primera Sesión de Trabajo | C27: 4 | D27: =SUM(E27:O27) -> 4 | I27: 4
B28: Segunda Sesión - Conformación Secretaria Técnica | C28: 4 | D28: =SUM(E28:O28) -> 0
B29: Tercera Sesión | C29: 4 | D29: =SUM(E29:O29) -> 0
B30: Elaboracióin del Texto de la Política Local | C30: 1 | D30: =SUM(E30:O30) -> 0
B31: Revisión Técnica DPPP | C31: 1 | D31: =SUM(E31:O31) -> 0
B32: Revisión Area Legal Gobierno Local | C32: 1 | D32: =SUM(E32:O32) -> 0
B33: Incorporación de Observaciones | C33: 1 | D33: =SUM(E33:O33) -> 0
B34: Aval del Director Regional | C34: 1 | D34: =SUM(E34:O34) -> 0
B35: Presentación al Consejo Municipal | C35: 1 | D35: =SUM(E35:O35) -> 0
B36: Presentación ante la Comunidad por parte del Director Regional y Alcalde | C36: 1 | D36: =SUM(E36:O36) -> 0
C37: =SUM(C3:C36) -> 245 | D37: =SUM(D3:D36) -> 42
D38: =D37/C37 -> 0.17142857

Sheet D31 Atenas
A1: PROGRAMA | B1: D31 ATENAS | C1: META | D1: AVANCE | E1: ENERO | F1: FEBRERO | G1: MARZO | H1: ABRIL | I1: MAYO | J1: JUNIO | K1: JULIO | L1: AGOSTO | M1: SEPTIEMBRE | N1: OCTUBRE | O1: NOVIEMBRE | P1: DICIEMBRE
C2: 2026 | D2: Porcentual
A3: PSCC | B3: Cuatro actividades de recuperación de espacios públicos, con las comunidades integradas al Programa de Seguridad Comunitaria, que se localicen, en los distritos que contemplan las área georreferenciadas del informe territorial de la Estrategia Sembremos Seguridad 2024, dos por año, una por semestre. | C3: 2 | D3: =SUM(E3:P3) -> 0
A4: GREAT/MPAS/DARE | B4: Realizar 4 procesos formativos (Cursos de la oferta de los programas DARE - GREAT - MPAS) en Centros Educativos, 2 por año, dentro de los distritos que contemplan las áreas georreferenciadas del informe territorial de la Estrategia Sembremos Seguridad 2024. Un curso diferente por semestre, un nivel completo. En caso de no contar con instructor acreditado DARE, se puede cumplir la meta con las charlas de Habilidades para la vida DARE, con el aval del Coordinador Nacional. | C4: 2 | D4: =SUM(E4:P4) -> 1 | E4: 0 | F4: 0 | G4: 0 | H4: 0 | I4: 1
A5: DARE | B5: Cubrir 2 procesos formativos en Centros Educativos (uno por año) ubicados dentro de los distritos que contemplan las áreas georreferenciadas del informe territorial de la Estrategia Sembremos Seguridad 2024, con los cursos del Programa DARE: Curso primaria. Curso Secundaria; un nivel completo por centro educativo, por semestre. En caso de no contar con instructor acreditado, se puede cumplir la meta con las charlas de Habilidades para la vida DARE, con el aval del Coordinador Nacional. | C5: 1 | D5: =SUM(E5:P5) -> 0 | E5: 0 | F5: 0 | G5: 0 | H5: 0
A6: PSCC | B6: Cuatro comercios capacitados e integrados al Programa de Seguridad Comercial que se localicen, en los distritos que contemplan las área georreferenciadas del informe territorial de la Estrategia Sembremos Seguridad 2024, dos por año, una por semestre. | C6: 2 | D6: =SUM(E6:P6) -> 0
A7: PSCC | B7: Cuatro estrategias de divulgación (Por medio de brochures, post o imágenes en redes sociales) diseñadas por la Estrategia de divulgación de la Dirección de Programas Policiales Preventivos, en el tema de "Prevención del Consumo de alcohol en vía pública" dirigidas a las comunidades integradas al Programa de Seguridad Comunitaria y a los comercios integrados al Programa de Seguridad Comercial que se localicen, en los distritos que contemplan las área georreferenciadas del informe territorial de la Estrategia Sembremos Seguridad 2024, dos por año. | C7: 2 | D7: =SUM(E7:P7) -> 0
A8: PSCC | B8: Dos estrategias de divulgación (Por medio de brochures, post o imágenes en redes sociales) en el tema del procedimiento para realizar una "Denuncia de ventas de drogas" diseñadas por la Estrategia de divulgación de la Dirección de Programas Policiales Preventivos dirigidas a las comunidades integradas al Programa de Seguridad Comunitaria que se localicen, en los distritos que contemplan las área georreferenciadas del informe territorial de la Estrategia Sembremos Seguridad 2024, una por año. | C8: 1 | D8: =SUM(E8:P8) -> 0
A9: PLAN DE POLITICA LOCAL E IMPLEMENTACIÓN DE LA POLITICA LOCAL DE SEGURIDAD | B9: Conformación Comité | C9: 3 | D9: =SUM(E9:O9) -> 4 | G9: 1 | I9: 3
B10: Conformación de Comercio | C10: 3 | D10: =SUM(E10:O10) -> 2 | G10: 2
B11: Reuniones-Jefaturas | C11: 24 | D11: =SUM(E11:O11) -> 8 | F11: 3 | G11: 2 | H11: 3
B12: Campañas de divulgación | C12: 72 | D12: =SUM(E12:O12) -> 26 | F12: 26
B13: Capacitaciones | C13: 0 | D13: =SUM(E13:O13) -> 0
B14: Charlas | C14: 6 | D14: =SUM(E14:O14) -> 0
B15: Talleres | C15: 0 | D15: =SUM(E15:O15) -> 0
B16: Sensibilización | C16: 26 | D16: =SUM(E16:O16) -> 6 | I16: 6
B17: Actividades deportivas | C17: 0 | D17: =SUM(E17:O17) -> 0
B18: Cine en mi Barrio | C18: 0 | D18: =SUM(E18:O18) -> 0
B19: Cívico-policial | C19: 0 | D19: =SUM(E19:O19) -> 0
B20: Actividades culturales | C20: 0 | D20: =SUM(E20:O20) -> 0
B21: Ferias | C21: 0 | D21: =SUM(E21:O21) -> 0
B22: Stand informativo | C22: 0 | D22: =SUM(E22:O22) -> 0
B23: Visitas | C23: 80 | D23: =SUM(E23:O23) -> 40 | F23: 20 | H23: 20
B24: Recuperación del espacio público | C24: 2 | D24: =SUM(E24:O24) -> 0
B25: Convocatoria de Mesas Locales | C25: 8 | D25: =SUM(E25:O25) -> 8 | G25: 8
B26: Exposición Informe Territorial ESS | C26: 8 | D26: =SUM(E26:O26) -> 8 | H26: 8
B27: Primera Sesión de Trabajo | C27: 8 | D27: =SUM(E27:O27) -> 8 | I27: 8
B28: Segunda Sesión - Conformación Secretaria Técnica | C28: 8 | D28: =SUM(E28:O28) -> 0
B29: Tercera Sesión | C29: 8 | D29: =SUM(E29:O29) -> 0
B30: Elaboracióin del Texto de la Política Local | C30: 1 | D30: =SUM(E30:O30) -> 0
B31: Revisión Técnica DPPP | C31: 1 | D31: =SUM(E31:O31) -> 0
B32: Revisión Area Legal Gobierno Local | C32: 1 | D32: =SUM(E32:O32) -> 0
B33: Incorporación de Observaciones | C33: 1 | D33: =SUM(E33:O33) -> 0
B34: Aval del Director Regional | C34: 1 | D34: =SUM(E34:O34) -> 0
B35: Presentación al Consejo Municipal | C35: 1 | D35: =SUM(E35:O35) -> 0
B36: Presentación ante la Comunidad por parte del Director Regional y Alcalde | C36: 1 | D36: =SUM(E36:O36) -> 0
C37: =SUM(C3:C36) -> 273 | D37: =SUM(D3:D36) -> 111
D38: =D37/C37 -> 0.40659341

Sheet D32 Naranjo
A1: PROGRAMA | B1: D32 NARANJO | C1: META | D1: AVANCE | E1: ENERO | F1: FEBRERO | G1: MARZO | H1: ABRIL | I1: MAYO | J1: JUNIO | K1: JULIO | L1: AGOSTO | M1: SEPTIEMBRE | N1: OCTUBRE | O1: NOVIEMBRE | P1: DICIEMBRE
C2: 2026 | D2: Porcentual
A3: PSCC | B3: Cuatro actividades de recuperación de espacios públicos, con las comunidades integradas al Programa de Seguridad Comunitaria, que se localicen, en los distritos que contemplan las área georreferenciadas del informe territorial de la Estrategia Sembremos Seguridad 2024, dos por año, una por semestre. | C3: 2 | D3: =SUM(E3:P3) -> 1 | E3: 1
A4: GREAT/MPAS/DARE | B4: Realizar 4 procesos formativos (Cursos de la oferta de los programas DARE - GREAT - MPAS) en Centros Educativos, 2 por año, dentro de los distritos que contemplan las áreas georreferenciadas del informe territorial de la Estrategia Sembremos Seguridad 2024. Un curso diferente por semestre, un nivel completo. En caso de no contar con instructor acreditado DARE, se puede cumplir la meta con las charlas de Habilidades para la vida DARE, con el aval del Coordinador Nacional. | C4: 2 | D4: =SUM(E4:P4) -> 1 | E4: 0 | F4: 0 | G4: 0 | H4: 1
A5: DARE | B5: Cubrir 2 procesos formativos en Centros Educativos (uno por año) ubicados dentro de los distritos que contemplan las áreas georreferenciadas del informe territorial de la Estrategia Sembremos Seguridad 2024, con los cursos del Programa DARE: , Curso primaria. Curso Secundaria; un nivel completo por centro educativo, por semestre. En caso de no contar con instructor acreditado, se puede cumplir la meta con las charlas de Habilidades para la vida DARE, con el aval del Coordinador Nacional. | C5: 1 | D5: =SUM(E5:P5) -> 1 | E5: 0 | F5: 0 | G5: 0 | H5: 1
A6: PSCC | B6: Cuatro comercios capacitados e integrados al Programa de Seguridad Comercial que se localicen, en los distritos que contemplan las áreas georreferenciadas del informe territorial de la Estrategia Sembremos Seguridad 2024, dos por año, una por semestre. | C6: 2 | D6: =SUM(E6:P6) -> 0
A7: PSCC | B7: Cuatro estrategias de divulgación (Por medio de brochures, post o imágenes en redes sociales) diseñadas por la Estrategia de divulgación de la Dirección de Programas Policiales Preventivos, en el tema de "Prevención del Consumo de alcohol en vía pública" dirigidas a las comunidades integradas al Programa de Seguridad Comunitaria y a los comercios integrados al Programa de Seguridad Comercial que se localicen, en los distritos que contemplan las área georreferenciadas del informe territorial de la Estrategia Sembremos Seguridad 2024, dos por año. | C7: 2 | D7: =SUM(E7:P7) -> 1 | H7: 1
A8: PSCC | B8: Dos estrategias de divulgación (Por medio de brochures, post o imágenes en redes sociales) en el tema del procedimiento para realizar una "Denuncia de ventas de drogas" diseñadas por la Estrategia de divulgación de la Dirección de Programas Policiales Preventivos dirigidas a las comunidades integradas al Programa de Seguridad Comunitaria que se localicen, en los distritos que contemplan las área georreferenciadas del informe territorial de la Estrategia Sembremos Seguridad 2024, una por año. | C8: 1 | D8: =SUM(E8:P8) -> 1 | H8: 1
A9: PLAN DE POLITICA LOCAL E IMPLEMENTACIÓN DE LA POLITICA LOCAL DE SEGURIDAD | B9: Conformación Comité | C9: 0 | D9: =SUM(E9:O9) -> 0
B10: Conformación de Comercio | C10: 0 | D10: =SUM(E10:O10) -> 0
B11: Reuniones-Jefaturas | C11: 48 | D11: =SUM(E11:O11) -> 17 | E11: 3 | F11: 8 | H11: 6
B12: Campañas de divulgación | C12: 127 | D12: =SUM(E12:O12) -> 47 | F12: 38 | H12: 5 | I12: 4
B13: Capacitaciones | C13: 0 | D13: =SUM(E13:O13) -> 0
B14: Charlas | C14: 1 | D14: =SUM(E14:O14) -> 0
B15: Talleres | C15: 0 | D15: =SUM(E15:O15) -> 0
B16: Sensibilización | C16: 0 | D16: =SUM(E16:O16) -> 0
B17: Actividades deportivas | C17: 0 | D17: =SUM(E17:O17) -> 0
B18: Cine en mi Barrio | C18: 0 | D18: =SUM(E18:O18) -> 0
B19: Cívico-policial | C19: 1 | D19: =SUM(E19:O19) -> 0
B20: Actividades culturales | C20: 0 | D20: =SUM(E20:O20) -> 0
B21: Ferias | C21: 0 | D21: =SUM(E21:O21) -> 0
B22: Stand informativo | C22: 0 | D22: =SUM(E22:O22) -> 0
B23: Visitas | C23: 60 | D23: =SUM(E23:O23) -> 53 | F23: 10 | G23: 7 | H23: 36
B24: Recuperación del espacio público | C24: 2 | D24: =SUM(E24:O24) -> 1 | E24: 1
B25: Convocatoria de Mesas Locales | C25: 8 | D25: =SUM(E25:O25) -> 5 | G25: 5
B26: Exposición Informe Territorial ESS | C26: 8 | D26: =SUM(E26:O26) -> 7 | G26: 1 | H26: 6
B27: Primera Sesión de Trabajo | C27: 8 | D27: =SUM(E27:O27) -> 8 | I27: 8
B28: Segunda Sesión - Conformación Secretaria Técnica | C28: 8 | D28: =SUM(E28:O28) -> 0
B29: Tercera Sesión | C29: 8 | D29: =SUM(E29:O29) -> 0
B30: Elaboracióin del Texto de la Política Local | C30: 1 | D30: =SUM(E30:O30) -> 0
B31: Revisión Técnica DPPP | C31: 1 | D31: =SUM(E31:O31) -> 0
B32: Revisión Area Legal Gobierno Local | C32: 1 | D32: =SUM(E32:O32) -> 0
B33: Incorporación de Observaciones | C33: 1 | D33: =SUM(E33:O33) -> 0
B34: Aval del Director Regional | C34: 1 | D34: =SUM(E34:O34) -> 0
B35: Presentación al Consejo Municipal | C35: 1 | D35: =SUM(E35:O35) -> 0
B36: Presentación ante la Comunidad por parte del Director Regional y Alcalde | C36: 1 | D36: =SUM(E36:O36) -> 0
C37: =SUM(C3:C36) -> 296 | D37: =SUM(D3:D36) -> 143
D38: =D37/C37 -> 0.48310811

Sheet D33 Palmares
A1: PROGRAMA | B1: D33 PALMARES | C1: META | D1: AVANCE | E1: ENERO | F1: FEBRERO | G1: MARZO | H1: ABRIL | I1: MAYO | J1: JUNIO | K1: JULIO | L1: AGOSTO | M1: SEPTIEMBRE | N1: OCTUBRE | O1: NOVIEMBRE | P1: DICIEMBRE
C2: 2026 | D2: Porcentual
A3: PSCC | B3: Cuatro actividades de recuperación de espacios públicos, con las comunidades integradas al Programa de Seguridad Comunitaria, que se localicen, en los distritos que contemplan las área georreferenciadas del informe territorial de la Estrategia Sembremos Seguridad 2024, dos por año, una por semestre. | C3: 2 | D3: =SUM(E3:P3) -> 0
A4: GREAT/MPAS/DARE | B4: Realizar 4 procesos formativos (Cursos de la oferta de los programas DARE - GREAT - MPAS) en Centros Educativos, 2 por año, dentro de los distritos que contemplan las áreas georreferenciadas del informe territorial de la Estrategia Sembremos Seguridad 2024. Un curso diferente por semestre, un nivel completo. En caso de no contar con instructor acreditado DARE, se puede cumplir la meta con las charlas de Habilidades para la vida DARE, con el aval del Coordinador Nacional. | C4: 2 | D4: =SUM(E4:P4) -> 0 | E4: 0 | F4: 0 | G4: 0 | H4: 0
A5: DARE | B5: Cubrir 2 procesos formativos en Centros Educativos (uno por año) ubicados dentro de los distritos que contemplan las áreas georreferenciadas del informe territorial de la Estrategia Sembremos Seguridad 2024, con los cursos del Programa DARE: , Curso primaria. Curso Secundaria; un nivel completo por centro educativo, por semestre. En caso de no contar con instructor acreditado, se puede cumplir la meta con las charlas de Habilidades para la vida DARE, con el aval del Coordinador Nacional. | C5: 1 | D5: =SUM(E5:P5) -> 1 | E5: 0 | F5: 0 | G5: 0 | H5: 0 | J5: 1
A6: PSCC | B6: Cuatro comercios capacitados e integrados al Programa de Seguridad Comercial que se localicen, en los distritos que contemplan las área georreferenciadas del informe territorial de la Estrategia Sembremos Seguridad 2024, dos por año, una por semestre. | C6: 2 | D6: =SUM(E6:P6) -> 0
A7: PSCC | B7: Cuatro estrategias de divulgación (Por medio de brochures, post o imágenes en redes sociales) diseñadas por la Estrategia de divulgación de la Dirección de Programas Policiales Preventivos, en el tema de "Prevención del Consumo de alcohol en vía pública" dirigidas a las comunidades integradas al Programa de Seguridad Comunitaria y a los comercios integrados al Programa de Seguridad Comercial que se localicen, en los distritos que contemplan las área georreferenciadas del informe territorial de la Estrategia Sembremos Seguridad 2024, dos por año. | C7: 2 | D7: =SUM(E7:P7) -> 0
A8: PSCC | B8: Dos estrategias de divulgación (Por medio de brochures, post o imágenes en redes sociales) en el tema del procedimiento para realizar una "Denuncia de ventas de drogas" diseñadas por la Estrategia de divulgación de la Dirección de Programas Policiales Preventivos dirigidas a las comunidades integradas al Programa de Seguridad Comunitaria que se localicen, en los distritos que contemplan las área georreferenciadas del informe territorial de la Estrategia Sembremos Seguridad 2024, una por año. | C8: 1 | D8: =SUM(E8:P8) -> 0
A9: PLAN DE POLITICA LOCAL E IMPLEMENTACIÓN DE LA POLITICA LOCAL DE SEGURIDAD | B9: Conformación Comité | C9: 3 | D9: =SUM(E9:O9) -> 0
B10: Conformación de Comercio | C10: 3 | D10: =SUM(E10:O10) -> 0
B11: Reuniones-Jefaturas | C11: 92 | D11: =SUM(E11:O11) -> 26 | E11: 3 | F11: 4 | G11: 5 | H11: 6 | I11: 8
B12: Campañas de divulgación | C12: 83 | D12: =SUM(E12:O12) -> 43 | G12: 22 | H12: 21
B13: Capacitaciones | C13: 0 | D13: =SUM(E13:O13) -> 0
B14: Charlas | C14: 6 | D14: =SUM(E14:O14) -> 1 | G14: 1
B15: Talleres | C15: 0 | D15: =SUM(E15:O15) -> 0
B16: Sensibilización | C16: 0 | D16: =SUM(E16:O16) -> 0
B17: Actividades deportivas | C17: 0 | D17: =SUM(E17:O17) -> 0
B18: Cine en mi Barrio | C18: 0 | D18: =SUM(E18:O18) -> 0
B19: Cívico-policial | C19: 0 | D19: =SUM(E19:O19) -> 0
B20: Actividades culturales | C20: 0 | D20: =SUM(E20:O20) -> 0
B21: Ferias | C21: 0 | D21: =SUM(E21:O21) -> 0
B22: Stand informativo | C22: 0 | D22: =SUM(E22:O22) -> 0
B23: Visitas | C23: 85 | D23: =SUM(E23:O23) -> 51 | E23: 21 | F23: 7 | I23: 23
B24: Recuperación del espacio público | C24: 2 | D24: =SUM(E24:O24) -> 0
B25: Convocatoria de Mesas Locales | C25: 7 | D25: =SUM(E25:O25) -> 7 | E25: 4 | G25: 3
B26: Exposición Informe Territorial ESS | C26: 7 | D26: =SUM(E26:O26) -> 7 | H26: 7
B27: Primera Sesión de Trabajo | C27: 7 | D27: =SUM(E27:O27) -> 7 | I27: 7
B28: Segunda Sesión - Conformación Secretaria Técnica | C28: 7 | D28: =SUM(E28:O28) -> 0
B29: Tercera Sesión | C29: 7 | D29: =SUM(E29:O29) -> 0
B30: Elaboracióin del Texto de la Política Local | C30: 1 | D30: =SUM(E30:O30) -> 0
B31: Revisión Técnica DPPP | C31: 1 | D31: =SUM(E31:O31) -> 0
B32: Revisión Area Legal Gobierno Local | C32: 1 | D32: =SUM(E32:O32) -> 0
B33: Incorporación de Observaciones | C33: 1 | D33: =SUM(E33:O33) -> 0
B34: Aval del Director Regional | C34: 1 | D34: =SUM(E34:O34) -> 0
B35: Presentación al Consejo Municipal | C35: 1 | D35: =SUM(E35:O35) -> 0
B36: Presentación ante la Comunidad por parte del Director Regional y Alcalde | C36: 1 | D36: =SUM(E36:O36) -> 0
C37: =SUM(C3:C36) -> 326 | D37: =SUM(D3:D36) -> 143
D38: =D37/C37 -> 0.43865031

Sheet D34 Poás
A1: PROGRAMA | B1: D10 Curridabat | C1: META | D1: AVANCE | E1: ENERO | F1: FEBRERO | G1: MARZO | H1: ABRIL | I1: MAYO | J1: JUNIO | K1: JULIO | L1: AGOSTO | M1: SEPTIEMBRE | N1: OCTUBRE | O1: NOVIEMBRE | P1: DICIEMBRE
C2: 2026 | D2: Porcentual
A3: PSCC | B3: Cuatro actividades de recuperación de espacios públicos, con las comunidades integradas al Programa de Seguridad Comunitaria, que se localicen, en los distritos que contemplan las área georreferenciadas del informe territorial de la Estrategia Sembremos Seguridad 2024, dos por año, una por semestre. | C3: 2 | D3: =SUM(E3:P3) -> 1 | G3: 1
A4: GREAT/MPAS/DARE | B4: Realizar 4 procesos formativos (Cursos de la oferta de los programas DARE - GREAT - MPAS) en Centros Educativos, 2 por año, dentro de los distritos que contemplan las áreas georreferenciadas del informe territorial de la Estrategia Sembremos Seguridad 2024. Un curso diferente por semestre, un nivel completo. En caso de no contar con instructor acreditado DARE, se puede cumplir la meta con las charlas de Habilidades para la vida DARE, con el aval del Coordinador Nacional. | C4: 2 | D4: =SUM(E4:P4) -> 0 | E4: 0 | F4: 0 | G4: 0 | H4: 0
A5: DARE | B5: Cubrir 2 procesos formativos en Centros Educativos (uno por año) ubicados dentro de los distritos que contemplan las áreas georreferenciadas del informe territorial de la Estrategia Sembremos Seguridad 2024, con los cursos del Programa DARE: , Curso primaria. Curso Secundaria; un nivel completo por centro educativo, por semestre. En caso de no contar con instructor acreditado, se puede cumplir la meta con las charlas de Habilidades para la vida DARE, con el aval del Coordinador Nacional. | C5: 1 | D5: =SUM(E5:P5) -> 0 | E5: 0 | F5: 0 | G5: 0 | H5: 0
A6: PSCC | B6: Cuatro comercios capacitados e integrados al Programa de Seguridad Comercial que se localicen, en los distritos que contemplan las área georreferenciadas del informe territorial de la Estrategia Sembremos Seguridad 2024, dos por año, una por semestre. | C6: 2 | D6: =SUM(E6:P6) -> 1 | G6: 1
A7: PSCC | B7: Cuatro estrategias de divulgación (Por medio de brochures, post o imágenes en redes sociales) diseñadas por la Estrategia de divulgación de la Dirección de Programas Policiales Preventivos, en el tema de "Prevención del Consumo de alcohol en vía pública" dirigidas a las comunidades integradas al Programa de Seguridad Comunitaria y a los comercios integrados al Programa de Seguridad Comercial que se localicen, en los distritos que contemplan las área georreferenciadas del informe territorial de la Estrategia Sembremos Seguridad 2024, dos por año. | C7: 2 | D7: =SUM(E7:P7) -> 1 | E7: 1
A8: PSCC | B8: Dos estrategias de divulgación (Por medio de brochures, post o imágenes en redes sociales) en el tema del procedimiento para realizar una "Denuncia de ventas de drogas" diseñadas por la Estrategia de divulgación de la Dirección de Programas Policiales Preventivos dirigidas a las comunidades integradas al Programa de Seguridad Comunitaria que se localicen, en los distritos que contemplan las área georreferenciadas del informe territorial de la Estrategia Sembremos Seguridad 2024, una por año. | C8: 1 | D8: =SUM(E8:P8) -> 1 | G8: 1
A9: PSCC | B9: Cuatro capacitaciones, en el tema de "Cultura Preventiva en zonas de riesgo", dirigidas a las comunidades integradas al Programa de Seguridad Comunitaria que se localicen, en los distritos que contemplan las área georreferenciadas del informe territorial de la Estrategia Sembremos Seguridad 2024, dos por año, una por semestre. | C9: 2 | D9: =SUM(E9:P9) -> 0
A10: PSCC | B10: Dos estrategias de divulgación (Por medio de brochures, post o imágenes en redes sociales) en el tema del procedimiento para realizar una "Denuncia de búnkers / venta de drogas" dirigidas a las comunidades integradas al Programa de Seguridad Comunitaria que se localicen, en los distritos que contemplan las área georreferenciadas del informe territorial de la Estrategia Sembremos Seguridad 2024, una por año. | C10: 1 | D10: =SUM(E10:P10) -> 1 | G10: 1
A11: PLAN DE POLITICA LOCAL E IMPLEMENTACIÓN DE LA POLITICA LOCAL DE SEGURIDAD | B11: Conformación Comité | C11: 3 | D11: =SUM(E11:O11) -> 1 | G11: 1
B12: Conformación de Comercio | C12: 3 | D12: =SUM(E12:O12) -> 2 | G12: 1 | H12: 1
B13: Reuniones-Jefaturas | C13: 65 | D13: =SUM(E13:O13) -> 28 | F13: 6 | G13: 15 | I13: 7
B14: Campañas de divulgación | C14: 79 | D14: =SUM(E14:O14) -> 22 | G14: 9 | H14: 13
B15: Capacitaciones | C15: 2 | D15: =SUM(E15:O15) -> 0
B16: Charlas | C16: 12 | D16: =SUM(E16:O16) -> 0
B17: Talleres | C17: 0 | D17: =SUM(E17:O17) -> 0
B18: Sensibilización | C18: 2 | D18: =SUM(E18:O18) -> 1 | G18: 1
B19: Actividades deportivas | C19: 0 | D19: =SUM(E19:O19) -> 0
B20: Cine en mi Barrio | C20: 0 | D20: =SUM(E20:O20) -> 0
B21: Cívico-policial | C21: 0 | D21: =SUM(E21:O21) -> 0
B22: Actividades culturales | C22: 0 | D22: =SUM(E22:O22) -> 0
B23: Ferias | C23: 0 | D23: =SUM(E23:O23) -> 0
B24: Stand informativo | C24: 0 | D24: =SUM(E24:O24) -> 0
B25: Visitas | C25: 36 | D25: =SUM(E25:O25) -> 19 | E25: 9 | H25: 10
B26: Recuperación del espacio público | C26: 2 | D26: =SUM(E26:O26) -> 1 | H26: 1
B27: Convocatoria de Mesas Locales | C27: 5 | D27: =SUM(E27:O27) -> 5 | E27: 2 | F27: 2 | G27: 1
B28: Exposición Informe Territorial ESS | C28: 5 | D28: =SUM(E28:O28) -> 5 | G28: 2 | H28: 3
B29: Primera Sesión de Trabajo | C29: 5 | D29: =SUM(E29:O29) -> 5 | I29: 5
B30: Segunda Sesión - Conformación Secretaria Técnica | C30: 5 | D30: =SUM(E30:O30) -> 0
B31: Tercera Sesión | C31: 5 | D31: =SUM(E31:O31) -> 0
B32: Elaboracióin del Texto de la Política Local | C32: 1 | D32: =SUM(E32:O32) -> 0
B33: Revisión Técnica DPPP | C33: 1 | D33: =SUM(E33:O33) -> 0
B34: Revisión Area Legal Gobierno Local | C34: 1 | D34: =SUM(E34:O34) -> 0
B35: Incorporación de Observaciones | C35: 1 | D35: =SUM(E35:O35) -> 0
B36: Aval del Director Regional | C36: 1 | D36: =SUM(E36:O36) -> 0
B37: Presentación al Consejo Municipal | C37: 1 | D37: =SUM(E37:O37) -> 0
B38: Presentación ante la Comunidad por parte del Director Regional y Alcalde | C38: 1 | D38: =SUM(E38:O38) -> 0
C39: =SUM(C3:C38) -> 249 | D39: =SUM(D3:D38) -> 94
D40: =D39/C39 -> 0.37751004

Sheet D35 Orotina
A1: PROGRAMA | B1: D35 OROTINA | C1: META | D1: AVANCE | E1: AVANCE | F1: ENERO | G1: FEBRERO | H1: MARZO | I1: ABRIL | J1: MAYO | K1: JUNIO | L1: JULIO | M1: AGOSTO | N1: SEPTIEMBRE | O1: OCTUBRE | P1: NOVIEMBRE | Q1: DICIEMBRE
C2: 2026 | D2: Porcentual | E2: Porcentual
A3: PSCC | B3: Cuatro actividades de recuperación de espacios públicos, con las comunidades integradas al Programa de Seguridad Comunitaria, que se localicen, en los distritos que contemplan las área georreferenciadas del informe territorial de la Estrategia Sembremos Seguridad 2024, dos por año, una por semestre. | C3: 2 | D3: =SUM(E3:Q3) -> 0
A4: GREAT/MPAS/DARE | B4: Realizar 4 procesos formativos (Cursos de la oferta de los programas DARE - GREAT - MPAS) en Centros Educativos, 2 por año, dentro de los distritos que contemplan las áreas georreferenciadas del informe territorial de la Estrategia Sembremos Seguridad 2024. Un curso diferente por semestre, un nivel completo. En caso de no contar con instructor acreditado DARE, se puede cumplir la meta con las charlas de Habilidades para la vida DARE, con el aval del Coordinador Nacional. | C4: 2 | D4: =SUM(E4:Q4) -> 0 | F4: 0 | G4: 0 | H4: 0 | I4: 0
A5: PSCC | B5: Dos estrategias de divulgación (Por medio de brochures, post o imágenes en redes sociales) en el tema del procedimiento para realizar una "Denuncia de ventas de drogas" dirigidas a las comunidades integradas al Programa de Seguridad Comunitaria que se localicen, en los distritos que contemplan las área georreferenciadas del informe territorial de la Estrategia Sembremos Seguridad 2024, una por año. | C5: 1 | D5: =SUM(E5:Q5) -> 0
A6: DARE | B6: Cubrir 2 procesos formativos en Centros Educativos (dos por año) ubicados dentro de los distritos que contemplan las áreas georreferenciadas del informe territorial de la Estrategia Sembremos Seguridad 2024, con los cursos del Programa DARE: , Curso primaria. Curso Secundaria; un nivel completo por centro educativo, por año. En caso de no contar con instructor acreditado, se puede cumplir la meta con las charlas de Habilidades para la vida DARE, con el aval del Coordinador Nacional. | C6: 1 | D6: =SUM(E6:Q6) -> 1 | F6: 0 | G6: 0 | H6: 0 | I6: 0 | K6: 1
A7: PSCC | B7: Cuatro capacitaciones, en el tema de "Denuncia a búnkers", dirigidas a las comunidades integradas al Programa de Seguridad Comunitaria que se localicen, en los distritos que contemplan las área georreferenciadas del informe territorial de la Estrategia Sembremos Seguridad 2024, dos por año, una por semestre. | C7: 2 | D7: =SUM(E7:Q7) -> 1 | J7: 1
A8: PSCC | B8: Dos estrategias de divulgación (Por medio de brochures, post o imágenes en redes sociales) en el tema del procedimiento para realizar una "Denuncia de búnkers" dirigidas a las comunidades integradas al Programa de Seguridad Comunitaria que se localicen, en los distritos que contemplan las área georreferenciadas del informe territorial de la Estrategia Sembremos Seguridad 2024, una por año. | C8: 1 | D8: =SUM(E8:Q8) -> 0
A9: PSCC | B9: Cuatro Charlas de Cultura Preventiva (Una por año) con énfasis en temas de estafa dirigidas a las comunidades integradas al Programa de Seguridad Comunitaria, que se localicen, en los distritos que contemplan las área georreferenciadas del informe territorial de la Estrategia Sembremos Seguridad 2024, dos por año, una por semestre. | C9: 2 | D9: =SUM(E9:Q9) -> 1 | H9: 1
A10: PSCC | B10: Dos estrategias de divulgación (Por medio de brochures, post o imágenes en redes sociales) en el tema del procedimiento para realizar una "Denuncia ante Estafas" dirigidas a las comunidades integradas al Programa de Seguridad Comunitaria, que se localicen, en los distritos que contemplan las área georreferenciadas del informe territorial de la Estrategia Sembremos Seguridad 2024, una por año. | C10: 1 | D10: =SUM(E10:Q10) -> 0
A11: PLAN DE POLITICA LOCAL E IMPLEMENTACIÓN DE LA POLITICA LOCAL DE SEGURIDAD | B11: Conformación Comité | C11: 3 | D11: =SUM(E11:P11) -> 1 | J11: 1
B12: Conformación de Comercio | C12: 3 | D12: =SUM(E12:P12) -> 0
B13: Reuniones-Jefaturas | C13: 28 | D13: =SUM(E13:P13) -> 11 | F13: 4 | G13: 4 | H13: 2 | J13: 1
B14: Campañas de divulgación | C14: 41 | D14: =SUM(E14:P14) -> 14 | G14: 7 | H14: 7
B15: Capacitaciones | C15: 2 | D15: =SUM(E15:P15) -> 0
B16: Charlas | C16: 2 | D16: =SUM(E16:P16) -> 0
B17: Talleres | C17: 0 | D17: =SUM(E17:P17) -> 0
B18: Sensibilización | C18: 0 | D18: =SUM(E18:P18) -> 0
B19: Actividades deportivas | C19: 0 | D19: =SUM(E19:P19) -> 0
B20: Cine en mi Barrio | C20: 0 | D20: =SUM(E20:P20) -> 0
B21: Cívico-policial | C21: 0 | D21: =SUM(E21:P21) -> 0
B22: Actividades culturales | C22: 0 | D22: =SUM(E22:P22) -> 0
B23: Ferias | C23: 0 | D23: =SUM(E23:P23) -> 0
B24: Stand informativo | C24: 0 | D24: =SUM(E24:P24) -> 0
B25: Visitas | C25: 52 | D25: =SUM(E25:P25) -> 26 | F25: 13 | H25: 13
B26: Recuperación del espacio público | C26: 2 | D26: =SUM(E26:P26) -> 0
B27: Convocatoria de Mesas Locales | C27: 5 | D27: =SUM(E27:P27) -> 3 | G27: 3
B28: Exposición Informe Territorial ESS | C28: 5 | D28: =SUM(E28:P28) -> 5 | H28: 5
B29: Primera Sesión de Trabajo | C29: 5 | D29: =SUM(E29:P29) -> 5 | J29: 5
B30: Segunda Sesión - Conformación Secretaria Técnica | C30: 5 | D30: =SUM(E30:P30) -> 0
B31: Tercera Sesión | C31: 5 | D31: =SUM(E31:P31) -> 0
B32: Elaboracióin del Texto de la Política Local | C32: 1 | D32: =SUM(E32:P32) -> 0
B33: Revisión Técnica DPPP | C33: 1 | D33: =SUM(E33:P33) -> 0
B34: Revisión Area Legal Gobierno Local | C34: 1 | D34: =SUM(E34:P34) -> 0
B35: Incorporación de Observaciones | C35: 1 | D35: =SUM(E35:P35) -> 0
B36: Aval del Director Regional | C36: 1 | D36: =SUM(E36:P36) -> 0
B37: Presentación al Consejo Municipal | C37: 1 | D37: =SUM(E37:P37) -> 0
B38: Presentación ante la Comunidad por parte del Director Regional y Alcalde | C38: 1 | D38: =SUM(E38:P38) -> 0
C39: =SUM(C3:C38) -> 177 | D39: =SUM(D3:D38) -> 68
D40: =D39/C39 -> 0.38418079

Sheet D36 Sarchí
A1: PROGRAMA | B1: D36 SARCHÍ | C1: META | D1: AVANCE | E1: ENERO | F1: FEBRERO | G1: MARZO | H1: ABRIL | I1: MAYO | J1: JUNIO | K1: JULIO | L1: AGOSTO | M1: SEPTIEMBRE | N1: OCTUBRE | O1: NOVIEMBRE | P1: DICIEMBRE
C2: 2026 | D2: Porcentual
A3: PSCC | B3: Cuatro actividades de recuperación de espacios públicos, con las comunidades integradas al Programa de Seguridad Comunitaria, que se localicen, en los distritos que contemplan las área georreferenciadas del informe territorial de la Estrategia Sembremos Seguridad 2024, dos por año, una por semestre. | C3: 2 | D3: =SUM(E3:P3) -> 0
A4: GREAT/MPAS/DARE | B4: Realizar 4 procesos formativos (Cursos de la oferta de los programas DARE - GREAT - MPAS) en Centros Educativos, 2 por año, dentro de los distritos que contemplan las áreas georreferenciadas del informe territorial de la Estrategia Sembremos Seguridad 2024. Un curso diferente por semestre, un nivel completo. En caso de no contar con instructor acreditado DARE, se puede cumplir la meta con las charlas de Habilidades para la vida DARE, con el aval del Coordinador Nacional. | C4: 2 | D4: =SUM(E4:P4) -> 0 | E4: 0 | F4: 0 | G4: 0 | H4: 0
A5: DARE | B5: Cubrir 2 procesos formativos en Centros Educativos (uno por año) ubicados dentro de los distritos que contemplan las áreas georreferenciadas del informe territorial de la Estrategia Sembremos Seguridad 2024, con los cursos del Programa DARE: , Curso primaria. Curso Secundaria; un nivel completo por centro educativo, por semestre. En caso de no contar con instructor acreditado, se puede cumplir la meta con las charlas de Habilidades para la vida DARE, con el aval del Coordinador Nacional. | C5: 1 | D5: =SUM(E5:P5) -> 0 | E5: 0 | F5: 0 | G5: 0 | H5: 0
A6: PSCC | B6: Cuatro comercios capacitados e integrados al Programa de Seguridad Comercial que se localicen, en los distritos que contemplan las áreas georreferenciadas del informe territorial de la Estrategia Sembremos Seguridad 2024, dos por año, una por semestre. | C6: 2 | D6: =SUM(E6:P6) -> 0
A7: PSCC | B7: Cuatro estrategias de divulgación (Por medio de brochures, post o imágenes en redes sociales) diseñadas por la Estrategia de divulgación de la Dirección de Programas Policiales Preventivos, en el tema de "Prevención del Consumo de alcohol en vía pública" dirigidas a las comunidades integradas al Programa de Seguridad Comunitaria y a los comercios integrados al Programa de Seguridad Comercial que se localicen, en los distritos que contemplan las área georreferenciadas del informe territorial de la Estrategia Sembremos Seguridad 2024, dos por año. | C7: 2 | D7: =SUM(E7:P7) -> 0
A8: PSCC | B8: Dos estrategias de divulgación (Por medio de brochures, post o imágenes en redes sociales) en el tema del procedimiento para realizar una "Denuncia de ventas de drogas" diseñadas por la Estrategia de divulgación de la Dirección de Programas Policiales Preventivos dirigidas a las comunidades integradas al Programa de Seguridad Comunitaria que se localicen, en los distritos que contemplan las área georreferenciadas del informe territorial de la Estrategia Sembremos Seguridad 2024, una por año. | C8: 1 | D8: =SUM(E8:P8) -> 0
A9: PLAN DE POLITICA LOCAL E IMPLEMENTACIÓN DE LA POLITICA LOCAL DE SEGURIDAD | B9: Conformación Comité | C9: 3 | D9: =SUM(E9:O9) -> 1 | I9: 1
B10: Conformación de Comercio | C10: 3 | D10: =SUM(E10:O10) -> 0
B11: Reuniones-Jefaturas | C11: 36 | D11: =SUM(E11:O11) -> 12 | F11: 3 | I11: 9
B12: Campañas de divulgación | C12: 16 | D12: =SUM(E12:O12) -> 9 | G12: 2 | H12: 7
B13: Capacitaciones | C13: 1 | D13: =SUM(E13:O13) -> 0
B14: Charlas | C14: 3 | D14: =SUM(E14:O14) -> 0
B15: Talleres | C15: 0 | D15: =SUM(E15:O15) -> 0
B16: Sensibilización | C16: 0 | D16: =SUM(E16:O16) -> 0
B17: Actividades deportivas | C17: 4 | D17: =SUM(E17:O17) -> 4 | F17: 4
B18: Cine en mi Barrio | C18: 0 | D18: =SUM(E18:O18) -> 0
B19: Cívico-policial | C19: 0 | D19: =SUM(E19:O19) -> 0
B20: Actividades culturales | C20: 0 | D20: =SUM(E20:O20) -> 0
B21: Ferias | C21: 0 | D21: =SUM(E21:O21) -> 0
B22: Stand informativo | C22: 0 | D22: =SUM(E22:O22) -> 0
B23: Visitas | C23: 48 | D23: =SUM(E23:O23) -> 32 | E23: 6 | G23: 11 | I23: 15
B24: Recuperación del espacio público | C24: 2 | D24: =SUM(E24:O24) -> 0
B25: Convocatoria de Mesas Locales | C25: 5 | D25: =SUM(E25:O25) -> 5 | G25: 5
B26: Exposición Informe Territorial ESS | C26: 5 | D26: =SUM(E26:O26) -> 5 | H26: 5
B27: Primera Sesión de Trabajo | C27: 5 | D27: =SUM(E27:O27) -> 5 | I27: 5
B28: Segunda Sesión - Conformación Secretaria Técnica | C28: 5 | D28: =SUM(E28:O28) -> 0
B29: Tercera Sesión | C29: 5 | D29: =SUM(E29:O29) -> 0
B30: Elaboracióin del Texto de la Política Local | C30: 1 | D30: =SUM(E30:O30) -> 0
B31: Revisión Técnica DPPP | C31: 1 | D31: =SUM(E31:O31) -> 0
B32: Revisión Area Legal Gobierno Local | C32: 1 | D32: =SUM(E32:O32) -> 0
B33: Incorporación de Observaciones | C33: 1 | D33: =SUM(E33:O33) -> 0
B34: Aval del Director Regional | C34: 1 | D34: =SUM(E34:O34) -> 0
B35: Presentación al Consejo Municipal | C35: 1 | D35: =SUM(E35:O35) -> 0
