Workbook
Name ABANG: [1]DAT2!#REF!
Name ABANG: [2]DAT2!#REF!
Name ABANG: [3]DAT2!#REF!
Name ABANG: [4]DAT2!#REF!
Name ABANG: [5]DAT2!#REF!
Name ABANG: [6]DAT2!#REF!
Name ABANG: [7]DAT2!#REF!
Name ABANG: [8]DAT2!#REF!
Name ABANG: [9]DAT2!#REF!
Name ABANG: [10]DAT2!#REF!
Name ABANG: [11]DAT2!#REF!
Name ABANG: [12]DAT2!#REF!
Name ABANG: [13]DAT2!#REF!
Name ACOS: [1]DAT2!#REF!
Name ACOS: [2]DAT2!#REF!
Name ACOS: [3]DAT2!#REF!
Name ACOS: [4]DAT2!#REF!
Name ACOS: [5]DAT2!#REF!
Name ACOS: [6]DAT2!#REF!
Name ACOS: [7]DAT2!#REF!
Name ACOS: [8]DAT2!#REF!
Name ACOS: [9]DAT2!#REF!
Name ACOS: [10]DAT2!#REF!
Name ACOS: [11]DAT2!#REF!
Name ACOS: [12]DAT2!#REF!
Name ACOS: [13]DAT2!#REF!
Name ALAJU: [1]DAT2!#REF!
Name ALAJU: [2]DAT2!#REF!
Name ALAJU: [3]DAT2!#REF!
Name ALAJU: [4]DAT2!#REF!
Name ALAJU: [5]DAT2!#REF!
Name ALAJU: [6]DAT2!#REF!
Name ALAJU: [7]DAT2!#REF!
Name ALAJU: [8]DAT2!#REF!
Name ALAJU: [9]DAT2!#REF!
Name ALAJU: [10]DAT2!#REF!
Name ALAJU: [11]DAT2!#REF!
Name ALAJU: [12]DAT2!#REF!
Name ALAJU: [13]DAT2!#REF!
Name ALAJUE: [1]DAT2!#REF!
Name ALAJUE: [2]DAT2!#REF!
Name ALAJUE: [3]DAT2!#REF!
Name ALAJUE: [4]DAT2!#REF!
Name ALAJUE: [5]DAT2!#REF!
Name ALAJUE: [6]DAT2!#REF!
Name ALAJUE: [7]DAT2!#REF!
Name ALAJUE: [8]DAT2!#REF!
Name ALAJUE: [9]DAT2!#REF!
Name ALAJUE: [10]DAT2!#REF!
Name ALAJUE: [11]DAT2!#REF!
Name ALAJUE: [12]DAT2!#REF!
Name ALAJUE: [13]DAT2!#REF!
Name ALVA: [1]DAT2!#REF!
Name ALVA: [2]DAT2!#REF!
Name ALVA: [3]DAT2!#REF!
Name ALVA: [4]DAT2!#REF!
Name ALVA: [5]DAT2!#REF!
Name ALVA: [6]DAT2!#REF!
Name ALVA: [7]DAT2!#REF!
Name ALVA: [8]DAT2!#REF!

Sheet D37 Cartago
A1: PROGRAMA | B1: D37 CARTAGO | C1: META | D1: AVANCE | E1: ENERO | F1: FEBRERO | G1: MARZO | H1: ABRIL | I1: MAYO | J1: JUNIO | K1: JULIO | L1: AGOSTO | M1: SEPTIEMBRE | N1: OCTUBRE | O1: NOVIEMBRE | P1: DICIEMBRE
C2: 2026 | D2: Porcentual
A3: PSCC | B3: Cuatro actividades de recuperación de espacios públicos, con las comunidades integradas al Programa de Seguridad Comunitaria, que se localicen, en los distritos que contemplan las área georreferenciadas del informe territorial de la Estrategia Sembremos Seguridad 2024, dos por año, una por semestre. | C3: 2 | D3: =SUM(E3:P3) -> 1 | F3: 1
A4: GREAT/MPAS/DARE | B4: Realizar 4 procesos formativos (Cursos de la oferta de los programas DARE - GREAT - MPAS) en Centros Educativos, 2 por año, dentro de los distritos que contemplan las áreas georreferenciadas del informe territorial de la Estrategia Sembremos Seguridad 2024. Un curso diferente por semestre, un nivel completo. En caso de no contar con instructor acreditado DARE, se puede cumplir la meta con las charlas de Habilidades para la vida DARE, con el aval del Coordinador Nacional. | C4: 2 | D4: =SUM(E4:P4) -> 0 | E4: 0 | F4: 0 | G4: 0 | H4: 0
A5: DARE | B5: Cubrir 4 procesos formativos en Centros Educativos (dos por año) ubicados dentro de los distritos que contemplan las áreas georreferenciadas del informe territorial de la Estrategia Sembremos Seguridad 2024, con los cursos del Programa DARE: , Curso primaria. Curso Secundaria; un nivel completo por centro educativo, por semestre. En caso de no contar con instructor acreditado, se puede cumplir la meta con las charlas de Habilidades para la vida DARE, con el aval del Coordinador Nacional. | C5: 2 | D5: =SUM(E5:P5) -> 1 | E5: 0 | F5: 0 | G5: 0 | H5: 1
A6: PSCC | B6: Cuatro capacitaciones, en el tema de "Denuncia a búnkers", dirigidas a las comunidades integradas al Programa de Seguridad Comunitaria que se localicen, en los distritos que contemplan las área georreferenciadas del informe territorial de la Estrategia Sembremos Seguridad 2024, dos por año, una por semestre. | C6: 2 | D6: =SUM(E6:P6) -> 1 | G6: 1
A7: PSCC | B7: Dos estrategias de divulgación (Por medio de brochures, post o imágenes en redes sociales) en el tema del procedimiento para realizar una "Denuncia de búnkers" dirigidas a las comunidades integradas al Programa de Seguridad Comunitaria que se localicen, en los distritos que contemplan las área georreferenciadas del informe territorial de la Estrategia Sembremos Seguridad 2024, una por año. | C7: 1 | D7: =SUM(E7:P7) -> 1 | I7: 1
A8: PLAN DE POLITICA LOCAL E IMPLEMENTACIÓN DE LA POLITICA LOCAL DE SEGURIDAD | B8: Conformación Comité | C8: 3 | D8: =SUM(E8:O8) -> 5 | G8: 2 | H8: 3
B9: Conformación de Comercio | C9: 3 | D9: =SUM(E9:O9) -> 0
B10: Reuniones-Jefaturas | C10: 172 | D10: =SUM(E10:O10) -> 72 | E10: 12 | F10: 16 | G10: 13 | H10: 11 | I10: 18 | J10: 2
B11: Campañas de divulgación | C11: 197 | D11: =SUM(E11:O11) -> 114 | G11: 30 | H11: 78 | I11: 6
B12: Capacitaciones | C12: 0 | D12: =SUM(E12:O12) -> 0
B13: Charlas | C13: 15 | D13: =SUM(E13:O13) -> 1 | G13: 1
B14: Talleres | C14: 0 | D14: =SUM(E14:O14) -> 0
B15: Sensibilización | C15: 0 | D15: =SUM(E15:O15) -> 0
B16: Actividades deportivas | C16: 0 | D16: =SUM(E16:O16) -> 0
B17: Cine en mi Barrio | C17: 0 | D17: =SUM(E17:O17) -> 0
B18: Cívico-policial | C18: 4 | D18: =SUM(E18:O18) -> 0
B19: Actividades culturales | C19: 0 | D19: =SUM(E19:O19) -> 0
B20: Ferias | C20: 0 | D20: =SUM(E20:O20) -> 0
B21: Stand informativo | C21: 0 | D21: =SUM(E21:O21) -> 0
B22: Visitas | C22: 378 | D22: =SUM(E22:O22) -> 147 | E22: 32 | F22: 65 | G22: 15 | H22: 24 | I22: 11
B23: Recuperación del espacio público | C23: 2 | D23: =SUM(E23:O23) -> 0
B24: Convocatoria de Mesas Locales | C24: 8 | D24: =SUM(E24:O24) -> 4 | F24: 2 | G24: 2
B25: Exposición Informe Territorial ESS | C25: 8 | D25: =SUM(E25:O25) -> 7 | G25: 1 | H25: 6
B26: Primera Sesión de Trabajo | C26: 8 | D26: =SUM(E26:O26) -> 0
B27: Segunda Sesión - Conformación Secretaria Técnica | C27: 8 | D27: =SUM(E27:O27) -> 1 | J27: 1
B28: Tercera Sesión | C28: 8 | D28: =SUM(E28:O28) -> 0
B29: Elaboracióin del Texto de la Política Local | C29: 1 | D29: =SUM(E29:O29) -> 0
B30: Revisión Técnica DPPP | C30: 1 | D30: =SUM(E30:O30) -> 0
B31: Revisión Area Legal Gobierno Local | C31: 1 | D31: =SUM(E31:O31) -> 0
B32: Incorporación de Observaciones | C32: 1 | D32: =SUM(E32:O32) -> 0
B33: Aval del Director Regional | C33: 1 | D33: =SUM(E33:O33) -> 0
B34: Presentación al Consejo Municipal | C34: 1 | D34: =SUM(E34:O34) -> 0
B35: Presentación ante la Comunidad por parte del Director Regional y Alcalde | C35: 1 | D35: =SUM(E35:O35) -> 0
C36: =SUM(C3:C35) -> 830 | D36: =SUM(D3:D35) -> 355
D37: =D36/C36 -> 0.42771084

Sheet D38 Paraiso
A1: PROGRAMA | B1: D38 PARAISO | C1: META | D1: AVANCE | E1: ENERO | F1: FEBRERO | G1: MARZO | H1: ABRIL | I1: MAYO | J1: JUNIO | K1: JULIO | L1: AGOSTO | M1: SEPTIEMBRE | N1: OCTUBRE | O1: NOVIEMBRE | P1: DICIEMBRE
C2: 2026 | D2: Porcentual
A3: PSCC | B3: Cuatro actividades de recuperación de espacios públicos, con las comunidades integradas al Programa de Seguridad Comunitaria, que se localicen, en los distritos que contemplan las área georreferenciadas del informe territorial de la Estrategia Sembremos Seguridad 2024, dos por año, una por semestre. | C3: 2 | D3: =SUM(E3:P3) -> 1 | G3: 1
A4: GREAT/MPAS/DARE | B4: Realizar 4 procesos formativos (Cursos de la oferta de los programas DARE - GREAT - MPAS) en Centros Educativos, 2 por año, dentro de los distritos que contemplan las áreas georreferenciadas del informe territorial de la Estrategia Sembremos Seguridad 2024. Un curso diferente por semestre, un nivel completo. En caso de no contar con instructor acreditado DARE, se puede cumplir la meta con las charlas de Habilidades para la vida DARE, con el aval del Coordinador Nacional. | C4: 2 | D4: =SUM(E4:P4) -> 2 | E4: 0 | F4: 0 | G4: 0 | H4: 0 | I4: 2
A5: DARE | B5: Cubrir 4 procesos formativos en Centros Educativos (dos por año) ubicados dentro de los distritos que contemplan las áreas georreferenciadas del informe territorial de la Estrategia Sembremos Seguridad 2024, con los cursos del Programa DARE: , Curso primaria. Curso Secundaria; un nivel completo por centro educativo, por semestre. En caso de no contar con instructor acreditado, se puede cumplir la meta con las charlas de Habilidades para la vida DARE, con el aval del Coordinador Nacional. | C5: 2 | D5: =SUM(E5:P5) -> 1 | E5: 0 | F5: 0 | G5: 0 | H5: 0 | I5: 1
A6: PSCC | B6: Cuatro capacitaciones, en el tema de "Denuncia a búnkers", dirigidas a las comunidades integradas al Programa de Seguridad Comunitaria que se localicen, en los distritos que contemplan las área georreferenciadas del informe territorial de la Estrategia Sembremos Seguridad 2024, dos por año, una por semestre. | C6: 2 | D6: =SUM(E6:P6) -> 2 | E6: 1 | H6: 1
A7: PSCC | B7: Dos estrategias de divulgación (Por medio de brochures, post o imágenes en redes sociales) en el tema del procedimiento para realizar una "Denuncia de búnkers" dirigidas a las comunidades integradas al Programa de Seguridad Comunitaria que se localicen, en los distritos que contemplan las área georreferenciadas del informe territorial de la Estrategia Sembremos Seguridad 2024, una por año. | C7: 1 | D7: =SUM(E7:P7) -> 1 | G7: 1
A8: PLAN DE POLITICA LOCAL E IMPLEMENTACIÓN DE LA POLITICA LOCAL DE SEGURIDAD | B8: Conformación Comité | C8: 3 | D8: =SUM(E8:O8) -> 2 | E8: 1 | F8: 1
B9: Conformación de Comercio | C9: 3 | D9: =SUM(E9:O9) -> 0
B10: Reuniones-Jefaturas | C10: 92 | D10: =SUM(E10:O10) -> 41 | E10: 2 | F10: 11 | G10: 8 | H10: 10 | I10: 9 | J10: 1
B11: Campañas de divulgación | C11: 70 | D11: =SUM(E11:O11) -> 32 | E11: 1 | G11: 9 | H11: 12 | J11: 10
B12: Capacitaciones | C12: 0 | D12: =SUM(E12:O12) -> 0
B13: Charlas | C13: 20 | D13: =SUM(E13:O13) -> 0
B14: Talleres | C14: 0 | D14: =SUM(E14:O14) -> 0
B15: Sensibilización | C15: 0 | D15: =SUM(E15:O15) -> 0
B16: Actividades deportivas | C16: 0 | D16: =SUM(E16:O16) -> 0
B17: Cine en mi Barrio | C17: 0 | D17: =SUM(E17:O17) -> 0
B18: Cívico-policial | C18: 0 | D18: =SUM(E18:O18) -> 0
B19: Actividades culturales | C19: 0 | D19: =SUM(E19:O19) -> 0
B20: Ferias | C20: 0 | D20: =SUM(E20:O20) -> 0
B21: Stand informativo | C21: 0 | D21: =SUM(E21:O21) -> 0
B22: Visitas | C22: 52 | D22: =SUM(E22:O22) -> 24 | E22: 12 | G22: 2 | H22: 10
B23: Recuperación del espacio público | C23: 2 | D23: =SUM(E23:O23) -> 1 | G23: 1
B24: Convocatoria de Mesas Locales | C24: 6 | D24: =SUM(E24:O24) -> 4 | F24: 1 | G24: 3
B25: Exposición Informe Territorial ESS | C25: 6 | D25: =SUM(E25:O25) -> 6 | G25: 1 | H25: 5
B26: Primera Sesión de Trabajo | C26: 6 | D26: =SUM(E26:O26) -> 6 | I26: 6
B27: Segunda Sesión - Conformación Secretaria Técnica | C27: 6 | D27: =SUM(E27:O27) -> 2 | J27: 2
B28: Tercera Sesión | C28: 6 | D28: =SUM(E28:O28) -> 0
B29: Elaboracióin del Texto de la Política Local | C29: 1 | D29: =SUM(E29:O29) -> 0
B30: Revisión Técnica DPPP | C30: 1 | D30: =SUM(E30:O30) -> 0
B31: Revisión Area Legal Gobierno Local | C31: 1 | D31: =SUM(E31:O31) -> 0
B32: Incorporación de Observaciones | C32: 1 | D32: =SUM(E32:O32) -> 0
B33: Aval del Director Regional | C33: 1 | D33: =SUM(E33:O33) -> 0
B34: Presentación al Consejo Municipal | C34: 1 | D34: =SUM(E34:O34) -> 0
B35: Presentación ante la Comunidad por parte del Director Regional y Alcalde | C35: 1 | D35: =SUM(E35:O35) -> 0
C36: =SUM(C3:C35) -> 288 | D36: =SUM(D3:D35) -> 125
D37: =D36/C36 -> 0.43402778

Sheet D39 La Unión
A1: PROGRAMA | B1: D39 LA UNIÓN | C1: META | D1: AVANCE | E1: ENERO | F1: FEBRERO | G1: MARZO | H1: ABRIL | I1: MAYO | J1: JUNIO | K1: JULIO | L1: AGOSTO | M1: SEPTIEMBRE | N1: OCTUBRE | O1: NOVIEMBRE | P1: DICIEMBRE
C2: 2026 | D2: Porcentual
A3: PSCC | B3: Cuatro actividades de recuperación de espacios públicos, con las comunidades integradas al Programa de Seguridad Comunitaria, que se localicen, en los distritos que contemplan las área georreferenciadas del informe territorial de la Estrategia Sembremos Seguridad 2024, dos por año, una por semestre. | C3: 2 | D3: =SUM(E3:P3) -> 0
A4: GREAT/MPAS/DARE | B4: Realizar 4 procesos formativos (Cursos de la oferta de los programas DARE - GREAT - MPAS) en Centros Educativos, 2 por año, dentro de los distritos que contemplan las áreas georreferenciadas del informe territorial de la Estrategia Sembremos Seguridad 2024. Un curso diferente por semestre, un nivel completo. En caso de no contar con instructor acreditado DARE, se puede cumplir la meta con las charlas de Habilidades para la vida DARE, con el aval del Coordinador Nacional. | C4: 2 | D4: =SUM(E4:P4) -> 0 | E4: 0 | F4: 0 | G4: 0 | H4: 0
A5: DARE | B5: Cubrir 4 procesos formativos en Centros Educativos (dos por año) ubicados dentro de los distritos que contemplan las áreas georreferenciadas del informe territorial de la Estrategia Sembremos Seguridad 2024, con los cursos del Programa DARE: , Curso primaria. Curso Secundaria; un nivel completo por centro educativo, por semestre. En caso de no contar con instructor acreditado, se puede cumplir la meta con las charlas de Habilidades para la vida DARE, con el aval del Coordinador Nacional. | C5: 2 | D5: =SUM(E5:P5) -> 0 | E5: 0 | F5: 0 | G5: 0 | H5: 0
A6: PSCC | B6: Dos estrategias de divulgación (Por medio de brochures, post o imágenes en redes sociales) en el tema del procedimiento para realizar una "Denuncia de ventas de drogas" dirigidas a las comunidades integradas al Programa de Seguridad Comunitaria que se localicen, en los distritos que contemplan las área georreferenciadas del informe territorial de la Estrategia Sembremos Seguridad 2024, una por año. | C6: 1 | D6: =SUM(E6:P6) -> 0
A7: PSCC | B7: Cuatro capacitaciones, en el tema de "Denuncia a búnkers", dirigidas a las comunidades integradas al Programa de Seguridad Comunitaria que se localicen, en los distritos que contemplan las área georreferenciadas del informe territorial de la Estrategia Sembremos Seguridad 2024, dos por año, una por semestre. | C7: 2 | D7: =SUM(E7:P7) -> 0
A8: PSCC | B8: Dos estrategias de divulgación (Por medio de brochures, post o imágenes en redes sociales) en el tema del procedimiento para realizar una "Denuncia de búnkers" dirigidas a las comunidades integradas al Programa de Seguridad Comunitaria que se localicen, en los distritos que contemplan las área georreferenciadas del informe territorial de la Estrategia Sembremos Seguridad 2024, una por año. | C8: 1 | D8: =SUM(E8:P8) -> 0
A9: PLAN DE POLITICA LOCAL E IMPLEMENTACIÓN DE LA POLITICA LOCAL DE SEGURIDAD | B9: Conformación Comité | C9: 3 | D9: =SUM(E9:O9) -> 0
B10: Conformación de Comercio | C10: 2 | D10: =SUM(E10:O10) -> 0
B11: Reuniones-Jefaturas | C11: 124 | D11: =SUM(E11:O11) -> 68 | E11: 10 | F11: 12 | G11: 14 | H11: 20 | I11: 11 | J11: 1
B12: Campañas de divulgación | C12: 127 | D12: =SUM(E12:O12) -> 39 | G12: 22 | H12: 17
B13: Capacitaciones | C13: 0 | D13: =SUM(E13:O13) -> 0
B14: Charlas | C14: 13 | D14: =SUM(E14:O14) -> 0
B15: Talleres | C15: 0 | D15: =SUM(E15:O15) -> 0
B16: Sensibilización | C16: 3 | D16: =SUM(E16:O16) -> 0
B17: Actividades deportivas | C17: 0 | D17: =SUM(E17:O17) -> 0
B18: Cine en mi Barrio | C18: 0 | D18: =SUM(E18:O18) -> 0
B19: Cívico-policial | C19: 2 | D19: =SUM(E19:O19) -> 0
B20: Actividades culturales | C20: 0 | D20: =SUM(E20:O20) -> 0
B21: Ferias | C21: 0 | D21: =SUM(E21:O21) -> 0
B22: Stand informativo | C22: 0 | D22: =SUM(E22:O22) -> 0
B23: Visitas | C23: 80 | D23: =SUM(E23:O23) -> 49 | E23: 20 | G23: 9 | H23: 20
B24: Recuperación del espacio público | C24: 0 | D24: =SUM(E24:O24) -> 0
B25: Convocatoria de Mesas Locales | C25: 8 | D25: =SUM(E25:O25) -> 8 | G25: 8
B26: Exposición Informe Territorial ESS | C26: 8 | D26: =SUM(E26:O26) -> 8 | H26: 8
B27: Primera Sesión de Trabajo | C27: 8 | D27: =SUM(E27:O27) -> 8 | I27: 8
B28: Segunda Sesión - Conformación Secretaria Técnica | C28: 8 | D28: =SUM(E28:O28) -> 0
B29: Tercera Sesión | C29: 8 | D29: =SUM(E29:O29) -> 0
B30: Elaboracióin del Texto de la Política Local | C30: 1 | D30: =SUM(E30:O30) -> 0
B31: Revisión Técnica DPPP | C31: 1 | D31: =SUM(E31:O31) -> 0
B32: Revisión Area Legal Gobierno Local | C32: 1 | D32: =SUM(E32:O32) -> 0
B33: Incorporación de Observaciones | C33: 1 | D33: =SUM(E33:O33) -> 0
B34: Aval del Director Regional | C34: 1 | D34: =SUM(E34:O34) -> 0
B35: Presentación al Consejo Municipal | C35: 1 | D35: =SUM(E35:O35) -> 0
B36: Presentación ante la Comunidad por parte del Director Regional y Alcalde | C36: 1 | D36: =SUM(E36:O36) -> 0
C37: =SUM(C3:C36) -> 411 | D37: =SUM(D3:D36) -> 180
D38: =D37/C37 -> 0.4379562

Sheet D40 Jiménez
A1: PROGRAMA | B1: D40 JIMÉNEZ | C1: META | D1: AVANCE | E1: ENERO | F1: FEBRERO | G1: MARZO | H1: ABRIL | I1: MAYO | J1: JUNIO | K1: JULIO | L1: AGOSTO | M1: SEPTIEMBRE | N1: OCTUBRE | O1: NOVIEMBRE | P1: DICIEMBRE
C2: 2026 | D2: Porcentual
A3: PSCC | B3: Cuatro actividades de recuperación de espacios públicos, con las comunidades integradas al Programa de Seguridad Comunitaria, que se localicen, en los distritos que contemplan las área georreferenciadas del informe territorial de la Estrategia Sembremos Seguridad 2024, dos por año, una por semestre. | C3: 2 | D3: =SUM(E3:P3) -> 1 | E3: 1
A4: GREAT/MPAS/DARE | B4: Realizar 4 procesos formativos (Cursos de la oferta de los programas DARE - GREAT - MPAS) en Centros Educativos, 2 por año, dentro de los distritos que contemplan las áreas georreferenciadas del informe territorial de la Estrategia Sembremos Seguridad 2024. Un curso diferente por semestre, un nivel completo. En caso de no contar con instructor acreditado DARE, se puede cumplir la meta con las charlas de Habilidades para la vida DARE, con el aval del Coordinador Nacional. | C4: 2 | D4: =SUM(E4:P4) -> 1 | E4: 0 | F4: 0 | G4: 0 | H4: 0 | I4: 1
A5: DARE | B5: Cubrir 2 procesos formativos en Centros Educativos (uno por año) ubicados dentro de los distritos que contemplan las áreas georreferenciadas del informe territorial de la Estrategia Sembremos Seguridad 2024, con los cursos del Programa DARE: , Curso primaria. Curso Secundaria; un nivel completo por centro educativo, por semestre. En caso de no contar con instructor acreditado, se puede cumplir la meta con las charlas de Habilidades para la vida DARE, con el aval del Coordinador Nacional. | C5: 1 | D5: =SUM(E5:P5) -> 1 | E5: 0 | F5: 0 | G5: 0 | H5: 1
A6: PSCC | B6: Cuatro comercios capacitados e integrados al Programa de Seguridad Comercial que se localicen, en los distritos que contemplan las áreas georreferenciadas del informe territorial de la Estrategia Sembremos Seguridad 2024, dos por año, una por semestre. | C6: 2 | D6: =SUM(E6:P6) -> 0
A7: PSCC | B7: Cuatro estrategias de divulgación (Por medio de brochures, post o imágenes en redes sociales) diseñadas por la Estrategia de divulgación de la Dirección de Programas Policiales Preventivos, en el tema de "Prevención del Consumo de alcohol en vía pública" dirigidas a las comunidades integradas al Programa de Seguridad Comunitaria y a los comercios integrados al Programa de Seguridad Comercial que se localicen, en los distritos que contemplan las área georreferenciadas del informe territorial de la Estrategia Sembremos Seguridad 2024, dos por año. | C7: 2 | D7: =SUM(E7:P7) -> 2 | E7: 2
A8: PLAN DE POLITICA LOCAL E IMPLEMENTACIÓN DE LA POLITICA LOCAL DE SEGURIDAD | B8: Conformación Comité | C8: 3 | D8: =SUM(E8:O8) -> 0
B9: Conformación de Comercio | C9: 3 | D9: =SUM(E9:O9) -> 0
B10: Reuniones-Jefaturas | C10: 36 | D10: =SUM(E10:O10) -> 15 | E10: 1 | F10: 4 | G10: 1 | I10: 9
B11: Campañas de divulgación | C11: 148 | D11: =SUM(E11:O11) -> 37 | G11: 28 | H11: 9
B12: Capacitaciones | C12: 0 | D12: =SUM(E12:O12) -> 0
B13: Charlas | C13: 0 | D13: =SUM(E13:O13) -> 0
B14: Talleres | C14: 0 | D14: =SUM(E14:O14) -> 0
B15: Sensibilización | C15: 0 | D15: =SUM(E15:O15) -> 0
B16: Actividades deportivas | C16: 0 | D16: =SUM(E16:O16) -> 0
B17: Cine en mi Barrio | C17: 0 | D17: =SUM(E17:O17) -> 0
B18: Cívico-policial | C18: 0 | D18: =SUM(E18:O18) -> 0
B19: Actividades culturales | C19: 0 | D19: =SUM(E19:O19) -> 0
B20: Ferias | C20: 0 | D20: =SUM(E20:O20) -> 0
B21: Stand informativo | C21: 0 | D21: =SUM(E21:O21) -> 0
B22: Visitas | C22: 0 | D22: =SUM(E22:O22) -> 0
B23: Recuperación del espacio público | C23: 3 | D23: =SUM(E23:O23) -> 1 | E23: 1
B24: Convocatoria de Mesas Locales | C24: 4 | D24: =SUM(E24:O24) -> 3 | G24: 3
B25: Exposición Informe Territorial ESS | C25: 4 | D25: =SUM(E25:O25) -> 4 | H25: 4
B26: Primera Sesión de Trabajo | C26: 4 | D26: =SUM(E26:O26) -> 4 | I26: 4
B27: Segunda Sesión - Conformación Secretaria Técnica | C27: 4 | D27: =SUM(E27:O27) -> 0
B28: Tercera Sesión | C28: 4 | D28: =SUM(E28:O28) -> 0
B29: Elaboracióin del Texto de la Política Local | C29: 1 | D29: =SUM(E29:O29) -> 0
B30: Revisión Técnica DPPP | C30: 1 | D30: =SUM(E30:O30) -> 0
B31: Revisión Area Legal Gobierno Local | C31: 1 | D31: =SUM(E31:O31) -> 0
B32: Incorporación de Observaciones | C32: 1 | D32: =SUM(E32:O32) -> 0
B33: Aval del Director Regional | C33: 1 | D33: =SUM(E33:O33) -> 0
B34: Presentación al Consejo Municipal | C34: 1 | D34: =SUM(E34:O34) -> 0
B35: Presentación ante la Comunidad por parte del Director Regional y Alcalde | C35: 1 | D35: =SUM(E35:O35) -> 0
C36: =SUM(C3:C35) -> 229 | D36: =SUM(D3:D35) -> 69
D37: =D36/C36 -> 0.30131004

Sheet D41 Turrialba
A1: PROGRAMA | B1: D41 TURIALBA | C1: META | D1: AVANCE | E1: ENERO | F1: FEBRERO | G1: MARZO | H1: ABRIL | I1: MAYO | J1: JUNIO | K1: JULIO | L1: AGOSTO | M1: SEPTIEMBRE | N1: OCTUBRE | O1: NOVIEMBRE | P1: DICIEMBRE
C2: 2026 | D2: Porcentual
A3: PSCC | B3: Dos estrategias de divulgación (Por medio de brochures, post o imágenes en redes sociales) en el tema del procedimiento para realizar una "Denuncia de ventas de drogas" dirigidas a las comunidades integradas al Programa de Seguridad Comunitaria que se localicen, en los distritos que contemplan las área georreferenciadas del informe territorial de la Estrategia Sembremos Seguridad 2024, una por año. | C3: 2 | D3: =SUM(E3:P3) -> 0
A4: PSCC | B4: Cuatro capacitaciones, en el tema de "Denuncia a búnkers", dirigidas a las comunidades integradas al Programa de Seguridad Comunitaria que se localicen, en los distritos que contemplan las área georreferenciadas del informe territorial de la Estrategia Sembremos Seguridad 2024, dos por año, una por semestre. | C4: 2 | D4: =SUM(E4:P4) -> 0
A5: PSCC | B5: Dos estrategias de divulgación (Por medio de brochures, post o imágenes en redes sociales) en el tema del procedimiento para realizar una "Denuncia de búnkers" dirigidas a las comunidades integradas al Programa de Seguridad Comunitaria que se localicen, en los distritos que contemplan las área georreferenciadas del informe territorial de la Estrategia Sembremos Seguridad 2024, una por año. | C5: 1 | D5: =SUM(E5:P5) -> 0
A6: PSCC | B6: Cuatro actividades de recuperación de espacios públicos, con las comunidades integradas al Programa de Seguridad Comunitaria, que se localicen, en los distritos que contemplan las área georreferenciadas del informe territorial de la Estrategia Sembremos Seguridad 2024, dos por año, una por semestre. | C6: 2 | D6: =SUM(E6:P6) -> 0
A7: GREAT/MPAS/DARE | B7: Realizar 4 procesos formativos (Cursos de la oferta de los programas DARE - GREAT - MPAS) en Centros Educativos, 2 por año, dentro de los distritos que contemplan las áreas georreferenciadas del informe territorial de la Estrategia Sembremos Seguridad 2024. Un curso diferente por semestre, un nivel completo. En caso de no contar con instructor acreditado DARE, se puede cumplir la meta con las charlas de Habilidades para la vida DARE, con el aval del Coordinador Nacional. | C7: 2 | D7: =SUM(E7:P7) -> 0 | E7: 0 | F7: 0 | G7: 0 | H7: 0
A8: PSCC | B8: Cuatro Charlas de Cultura Preventiva (Una por año) con énfasis en temas de estafa dirigidas a las comunidades integradas al Programa de Seguridad Comunitaria, que se localicen, en los distritos que contemplan las área georreferenciadas del informe territorial de la Estrategia Sembremos Seguridad 2024, dos por año, una por semestre. | C8: 1 | D8: =SUM(E8:P8) -> 0
A9: PSCC | B9: Dos estrategias de divulgación (Por medio de brochures, post o imágenes en redes sociales) en el tema del procedimiento para realizar una "Denuncia ante Estafas" dirigidas a las comunidades integradas al Programa de Seguridad Comunitaria, que se localicen, en los distritos que contemplan las área georreferenciadas del informe territorial de la Estrategia Sembremos Seguridad 2024, una por año. | C9: 2 | D9: =SUM(E9:P9) -> 0
A10: PLAN DE POLITICA LOCAL E IMPLEMENTACIÓN DE LA POLITICA LOCAL DE SEGURIDAD | B10: Conformación Comité | C10: 3 | D10: =SUM(E10:O10) -> 0
B11: Conformación de Comercio | C11: 3 | D11: =SUM(E11:O11) -> 0
B12: Reuniones-Jefaturas | C12: 56 | D12: =SUM(E12:O12) -> 17 | E12: 4 | F12: 3 | G12: 4 | I12: 6
B13: Campañas de divulgación | C13: 96 | D13: =SUM(E13:O13) -> 14 | G13: 14
B14: Capacitaciones | C14: 0 | D14: =SUM(E14:O14) -> 0
B15: Charlas | C15: 4 | D15: =SUM(E15:O15) -> 1 | I15: 1
B16: Talleres | C16: 0 | D16: =SUM(E16:O16) -> 0
B17: Sensibilización | C17: 8 | D17: =SUM(E17:O17) -> 0
B18: Actividades deportivas | C18: 3 | D18: =SUM(E18:O18) -> 0
B19: Cine en mi Barrio | C19: 0 | D19: =SUM(E19:O19) -> 0
B20: Cívico-policial | C20: 0 | D20: =SUM(E20:O20) -> 0
B21: Actividades culturales | C21: 0 | D21: =SUM(E21:O21) -> 0
B22: Ferias | C22: 0 | D22: =SUM(E22:O22) -> 0
B23: Stand informativo | C23: 0 | D23: =SUM(E23:O23) -> 0
B24: Visitas | C24: 94 | D24: =SUM(E24:O24) -> 56 | E24: 6 | F24: 11 | G24: 12 | I24: 26 | J24: 1
B25: Recuperación del espacio público | C25: 0 | D25: =SUM(E25:O25) -> 0
B26: Convocatoria de Mesas Locales | C26: 12 | D26: =SUM(E26:O26) -> 12 | G26: 11 | H26: 1
B27: Exposición Informe Territorial ESS | C27: 12 | D27: =SUM(E27:O27) -> 12 | H27: 12
B28: Primera Sesión de Trabajo | C28: 12 | D28: =SUM(E28:O28) -> 0
B29: Segunda Sesión - Conformación Secretaria Técnica | C29: 12 | D29: =SUM(E29:O29) -> 0
B30: Tercera Sesión | C30: 12 | D30: =SUM(E30:O30) -> 0
B31: Elaboracióin del Texto de la Política Local | C31: 1 | D31: =SUM(E31:O31) -> 0
B32: Revisión Técnica DPPP | C32: 1 | D32: =SUM(E32:O32) -> 0
B33: Revisión Area Legal Gobierno Local | C33: 1 | D33: =SUM(E33:O33) -> 0
B34: Incorporación de Observaciones | C34: 1 | D34: =SUM(E34:O34) -> 0
B35: Aval del Director Regional | C35: 1 | D35: =SUM(E35:O35) -> 0
B36: Presentación al Consejo Municipal | C36: 1 | D36: =SUM(E36:O36) -> 0
B37: Presentación ante la Comunidad por parte del Director Regional y Alcalde | C37: 1 | D37: =SUM(E37:O37) -> 0
C38: =SUM(C3:C37) -> 346 | D38: =SUM(D3:D37) -> 112
D39: =D38/C38 -> 0.32369942

Sheet D42 Alvarado
A1: PROGRAMA | B1: D42 ALVARADO | C1: META | D1: AVANCE | E1: ENERO | F1: FEBRERO | G1: MARZO | H1: ABRIL | I1: MAYO | J1: JUNIO | K1: JULIO | L1: AGOSTO | M1: SEPTIEMBRE | N1: OCTUBRE | O1: NOVIEMBRE | P1: DICIEMBRE
C2: 2026 | D2: Porcentual
A3: PSCC | B3: Cuatro actividades de recuperación de espacios públicos, con las comunidades integradas al Programa de Seguridad Comunitaria, que se localicen, en los distritos que contemplan las área georreferenciadas del informe territorial de la Estrategia Sembremos Seguridad 2024, dos por año, una por semestre. | C3: 2 | D3: =SUM(E3:P3) -> 0
A4: GREAT/MPAS/DARE | B4: Realizar 4 procesos formativos (Cursos de la oferta de los programas DARE - GREAT - MPAS) en Centros Educativos, 2 por año, dentro de los distritos que contemplan las áreas georreferenciadas del informe territorial de la Estrategia Sembremos Seguridad 2024. Un curso diferente por semestre, un nivel completo. En caso de no contar con instructor acreditado DARE, se puede cumplir la meta con las charlas de Habilidades para la vida DARE, con el aval del Coordinador Nacional. | C4: 2 | D4: =SUM(E4:P4) -> 1 | E4: 0 | F4: 0 | G4: 0 | H4: 0 | I4: 1
A5: DARE | B5: Cubrir 2 procesos formativos en Centros Educativos (uno por año) ubicados dentro de los distritos que contemplan las áreas georreferenciadas del informe territorial de la Estrategia Sembremos Seguridad 2024, con los cursos del Programa DARE: , Curso primaria. Curso Secundaria; un nivel completo por centro educativo, por semestre. En caso de no contar con instructor acreditado, se puede cumplir la meta con las charlas de Habilidades para la vida DARE, con el aval del Coordinador Nacional. | C5: 1 | D5: =SUM(E5:P5) -> 1 | E5: 0 | F5: 0 | G5: 0 | H5: 1
A6: PSCC | B6: Cuatro comercios capacitados e integrados al Programa de Seguridad Comercial que se localicen, en los distritos que contemplan las área georreferenciadas del informe territorial de la Estrategia Sembremos Seguridad 2024, dos por año, una por semestre. | C6: 2 | D6: =SUM(E6:P6) -> 0
A7: PSCC | B7: Cuatro estrategias de divulgación (Por medio de brochures, post o imágenes en redes sociales) diseñadas por la Estrategia de divulgación de la Dirección de Programas Policiales Preventivos, en el tema de "Prevención del Consumo de alcohol en vía pública" dirigidas a las comunidades integradas al Programa de Seguridad Comunitaria y a los comercios integrados al Programa de Seguridad Comercial que se localicen, en los distritos que contemplan las área georreferenciadas del informe territorial de la Estrategia Sembremos Seguridad 2024, dos por año. | C7: 2 | D7: =SUM(E7:P7) -> 0
A8: PSCC | B8: Dos estrategias de divulgación (Por medio de brochures, post o imágenes en redes sociales) en el tema del procedimiento para realizar una "Denuncia de ventas de drogas" diseñadas por la Estrategia de divulgación de la Dirección de Programas Policiales Preventivos dirigidas a las comunidades integradas al Programa de Seguridad Comunitaria que se localicen, en los distritos que contemplan las área georreferenciadas del informe territorial de la Estrategia Sembremos Seguridad 2024, una por año. | C8: 1 | D8: =SUM(E8:P8) -> 0
A9: PSCC | B9: Cuatro capacitaciones, en el tema de "Cultura Preventiva en zonas de riesgo", dirigidas a las comunidades integradas al Programa de Seguridad Comunitaria que se localicen, en los distritos que contemplan las área georreferenciadas del informe territorial de la Estrategia Sembremos Seguridad 2024, dos por año, una por semestre. | C9: 2 | D9: =SUM(E9:P9) -> 0
A10: PSCC | B10: Dos estrategias de divulgación (Por medio de brochures, post o imágenes en redes sociales) en el tema del procedimiento para realizar una "Denuncia de búnkers / venta de drogas" dirigidas a las comunidades integradas al Programa de Seguridad Comunitaria que se localicen, en los distritos que contemplan las área georreferenciadas del informe territorial de la Estrategia Sembremos Seguridad 2024, una por año. | C10: 1 | D10: =SUM(E10:P10) -> 0
A11: PLAN DE POLITICA LOCAL E IMPLEMENTACIÓN DE LA POLITICA LOCAL DE SEGURIDAD | B11: Conformación Comité | C11: 3 | D11: =SUM(E11:O11) -> 1 | H11: 1
B12: Conformación de Comercio | C12: 3 | D12: =SUM(E12:O12) -> 0
B13: Reuniones-Jefaturas | C13: 44 | D13: =SUM(E13:O13) -> 15 | F13: 5 | G13: 4 | H13: 3 | I13: 3
B14: Campañas de divulgación | C14: 0 | D14: =SUM(E14:O14) -> 0
B15: Capacitaciones | C15: 0 | D15: =SUM(E15:O15) -> 0
B16: Charlas | C16: 7 | D16: =SUM(E16:O16) -> 1 | H16: 1
B17: Talleres | C17: 0 | D17: =SUM(E17:O17) -> 0
B18: Sensibilización | C18: 0 | D18: =SUM(E18:O18) -> 0
B19: Actividades deportivas | C19: 0 | D19: =SUM(E19:O19) -> 0
B20: Cine en mi Barrio | C20: 0 | D20: =SUM(E20:O20) -> 0
B21: Cívico-policial | C21: 0 | D21: =SUM(E21:O21) -> 0
B22: Actividades culturales | C22: 0 | D22: =SUM(E22:O22) -> 0
B23: Ferias | C23: 0 | D23: =SUM(E23:O23) -> 0
B24: Stand informativo | C24: 0 | D24: =SUM(E24:O24) -> 0
B25: Visitas | C25: 156 | D25: =SUM(E25:O25) -> 104 | E25: 26 | F25: 8 | G25: 2 | H25: 34 | J25: 34
B26: Recuperación del espacio público | C26: 1 | D26: =SUM(E26:O26) -> 0
B27: Convocatoria de Mesas Locales | C27: 3 | D27: =SUM(E27:O27) -> 3 | G27: 3
B28: Exposición Informe Territorial ESS | C28: 3 | D28: =SUM(E28:O28) -> 3 | H28: 3
B29: Primera Sesión de Trabajo | C29: 3 | D29: =SUM(E29:O29) -> 3 | I29: 3
B30: Segunda Sesión - Conformación Secretaria Técnica | C30: 3 | D30: =SUM(E30:O30) -> 0
B31: Tercera Sesión | C31: 3 | D31: =SUM(E31:O31) -> 0
B32: Elaboracióin del Texto de la Política Local | C32: 1 | D32: =SUM(E32:O32) -> 0
B33: Revisión Técnica DPPP | C33: 1 | D33: =SUM(E33:O33) -> 0
B34: Revisión Area Legal Gobierno Local | C34: 1 | D34: =SUM(E34:O34) -> 0
B35: Incorporación de Observaciones | C35: 1 | D35: =SUM(E35:O35) -> 0
B36: Aval del Director Regional | C36: 1 | D36: =SUM(E36:O36) -> 0
B37: Presentación al Consejo Municipal | C37: 1 | D37: =SUM(E37:O37) -> 0
B38: Presentación ante la Comunidad por parte del Director Regional y Alcalde | C38: 1 | D38: =SUM(E38:O38) -> 0
C39: =SUM(C3:C38) -> 249 | D39: =SUM(D3:D38) -> 132
D40: =D39/C39 -> 0.53012048

Sheet D43 Oreamuno
A1: PROGRAMA | B1: D43 OREAMUNO | C1: META | D1: AVANCE | E1: ENERO | F1: FEBRERO | G1: MARZO | H1: ABRIL | I1: MAYO | J1: JUNIO | K1: JULIO | L1: AGOSTO | M1: SEPTIEMBRE | N1: OCTUBRE | O1: NOVIEMBRE | P1: DICIEMBRE
C2: 2026 | D2: Porcentual
A3: PSCC | B3: Cuatro actividades de recuperación de espacios públicos, con las comunidades integradas al Programa de Seguridad Comunitaria, que se localicen, en los distritos que contemplan las área georreferenciadas del informe territorial de la Estrategia Sembremos Seguridad 2024, dos por año, una por semestre. | C3: 2 | D3: =SUM(E3:P3) -> 1 | F3: 1
A4: GREAT/MPAS/DARE | B4: Realizar 4 procesos formativos (Cursos de la oferta de los programas DARE - GREAT - MPAS) en Centros Educativos, 2 por año, dentro de los distritos que contemplan las áreas georreferenciadas del informe territorial de la Estrategia Sembremos Seguridad 2024. Un curso diferente por semestre, un nivel completo. En caso de no contar con instructor acreditado DARE, se puede cumplir la meta con las charlas de Habilidades para la vida DARE, con el aval del Coordinador Nacional. | C4: 2 | D4: =SUM(E4:P4) -> 1 | E4: 0 | F4: 0 | G4: 0 | H4: 0 | I4: 1
A5: DARE | B5: Cubrir 2 procesos formativos en Centros Educativos (uno por año) ubicados dentro de los distritos que contemplan las áreas georreferenciadas del informe territorial de la Estrategia Sembremos Seguridad 2024, con los cursos del Programa DARE: , Curso primaria. Curso Secundaria; un nivel completo por centro educativo, por semestre. En caso de no contar con instructor acreditado, se puede cumplir la meta con las charlas de Habilidades para la vida DARE, con el aval del Coordinador Nacional. | C5: 1 | D5: =SUM(E5:P5) -> 1 | E5: 0 | F5: 0 | G5: 0 | H5: 1
A6: PSCC | B6: Cuatro comercios capacitados e integrados al Programa de Seguridad Comercial que se localicen, en los distritos que contemplan las área georreferenciadas del informe territorial de la Estrategia Sembremos Seguridad 2024, dos por año, una por semestre. | C6: 2 | D6: =SUM(E6:P6) -> 0
A7: PSCC | B7: Cuatro estrategias de divulgación (Por medio de brochures, post o imágenes en redes sociales) diseñadas por la Estrategia de divulgación de la Dirección de Programas Policiales Preventivos, en el tema de "Prevención del Consumo de alcohol en vía pública" dirigidas a las comunidades integradas al Programa de Seguridad Comunitaria y a los comercios integrados al Programa de Seguridad Comercial que se localicen, en los distritos que contemplan las área georreferenciadas del informe territorial de la Estrategia Sembremos Seguridad 2024, dos por año. | C7: 2 | D7: =SUM(E7:P7) -> 0
A8: PSCC | B8: Cuatro capacitaciones, en el tema de "Cultura Preventiva en zonas de riesgo", dirigidas a las comunidades integradas al Programa de Seguridad Comunitaria que se localicen, en los distritos que contemplan las área georreferenciadas del informe territorial de la Estrategia Sembremos Seguridad 2024, dos por año, una por semestre. | C8: 2 | D8: =SUM(E8:P8) -> 0
A9: PSCC | B9: Dos estrategias de divulgación (Por medio de brochures, post o imágenes en redes sociales) en el tema del procedimiento para realizar una "Denuncia de búnkers / venta de drogas" dirigidas a las comunidades integradas al Programa de Seguridad Comunitaria que se localicen, en los distritos que contemplan las área georreferenciadas del informe territorial de la Estrategia Sembremos Seguridad 2024, una por año. | C9: 1 | D9: =SUM(E9:P9) -> 1 | G9: 1
A10: PLAN DE POLITICA LOCAL E IMPLEMENTACIÓN DE LA POLITICA LOCAL DE SEGURIDAD | B10: Conformación Comité | C10: 3 | D10: =SUM(E10:O10) -> 0
B11: Conformación de Comercio | C11: 3 | D11: =SUM(E11:O11) -> 0
B12: Reuniones-Jefaturas | C12: 156 | D12: =SUM(E12:O12) -> 56 | E12: 9 | F12: 10 | G12: 15 | H12: 15 | I12: 7
B13: Campañas de divulgación | C13: 300 | D13: =SUM(E13:O13) -> 24 | G13: 24
B14: Capacitaciones | C14: 0 | D14: =SUM(E14:O14) -> 0
B15: Charlas | C15: 0 | D15: =SUM(E15:O15) -> 0
B16: Talleres | C16: 0 | D16: =SUM(E16:O16) -> 0
B17: Sensibilización | C17: 0 | D17: =SUM(E17:O17) -> 0
B18: Actividades deportivas | C18: 0 | D18: =SUM(E18:O18) -> 0
B19: Cine en mi Barrio | C19: 0 | D19: =SUM(E19:O19) -> 0
B20: Cívico-policial | C20: 0 | D20: =SUM(E20:O20) -> 0
B21: Actividades culturales | C21: 0 | D21: =SUM(E21:O21) -> 0
B22: Ferias | C22: 0 | D22: =SUM(E22:O22) -> 0
B23: Stand informativo | C23: 0 | D23: =SUM(E23:O23) -> 0
B24: Visitas | C24: 222 | D24: =SUM(E24:O24) -> 49 | F24: 33 | H24: 16
B25: Recuperación del espacio público | C25: 0 | D25: =SUM(E25:O25) -> 0
B26: Convocatoria de Mesas Locales | C26: 5 | D26: =SUM(E26:O26) -> 0
B27: Exposición Informe Territorial ESS | C27: 5 | D27: =SUM(E27:O27) -> 5 | G27: 2 | H27: 3
B28: Primera Sesión de Trabajo | C28: 5 | D28: =SUM(E28:O28) -> 5 | I28: 5
B29: Segunda Sesión - Conformación Secretaria Técnica | C29: 5 | D29: =SUM(E29:O29) -> 2 | J29: 2
B30: Tercera Sesión | C30: 5 | D30: =SUM(E30:O30) -> 0
B31: Elaboracióin del Texto de la Política Local | C31: 1 | D31: =SUM(E31:O31) -> 0
B32: Revisión Técnica DPPP | C32: 1 | D32: =SUM(E32:O32) -> 0
B33: Revisión Area Legal Gobierno Local | C33: 1 | D33: =SUM(E33:O33) -> 0
B34: Incorporación de Observaciones | C34: 1 | D34: =SUM(E34:O34) -> 0
B35: Aval del Director Regional | C35: 1 | D35: =SUM(E35:O35) -> 0
B36: Presentación al Consejo Municipal | C36: 1 | D36: =SUM(E36:O36) -> 0
B37: Presentación ante la Comunidad por parte del Director Regional y Alcalde | C37: 1 | D37: =SUM(E37:O37) -> 0
C38: =SUM(C3:C37) -> 728 | D38: =SUM(D3:D37) -> 145
D39: =D38/C38 -> 0.19917582

Sheet D44 El Guarco
A1: PROGRAMA | B1: D44 EL GUARCO | C1: META | D1: AVANCE | E1: ENERO | F1: FEBRERO | G1: MARZO | H1: ABRIL | I1: MAYO | J1: JUNIO | K1: JULIO | L1: AGOSTO | M1: SEPTIEMBRE | N1: OCTUBRE | O1: NOVIEMBRE | P1: DICIEMBRE
C2: 2026 | D2: Porcentual
A3: PSCC | B3: Cuatro capacitaciones, en el tema de "Denuncia a búnkers", dirigidas a las comunidades integradas al Programa de Seguridad Comunitaria que se localicen, en los distritos que contemplan las área georreferenciadas del informe territorial de la Estrategia Sembremos Seguridad 2024, dos por año, una por semestre. | C3: 2 | D3: =SUM(E3:P3) -> 0
A4: PSCC | B4: Dos estrategias de divulgación (Por medio de brochures, post o imágenes en redes sociales) en el tema del procedimiento para realizar una "Denuncia de búnkers” dirigidas a las comunidades integradas al Programa de Seguridad Comunitaria que se localicen, en los distritos que contemplan las áreas georreferenciadas del informe territorial de la Estrategia Sembremos Seguridad 2024, una por año. | C4: 1 | D4: =SUM(E4:P4) -> 1 | H4: 1
A5: PSCC | B5: Cuatro actividades de recuperación de espacios públicos, con las comunidades integradas al Programa de Seguridad Comunitaria, que se localicen, en los distritos que contemplan las área georreferenciadas del informe territorial de la Estrategia Sembremos Seguridad 2024, dos por año, una por semestre. | C5: 2 | D5: =SUM(E5:P5) -> 1 | G5: 1
A6: GREAT/MPAS/DARE | B6: Realizar 4 procesos formativos (Cursos de la oferta de los programas DARE - GREAT - MPAS) en Centros Educativos, 2 por año, dentro de los distritos que contemplan las áreas georreferenciadas del informe territorial de la Estrategia Sembremos Seguridad 2024. Un curso diferente por semestre, un nivel completo. En caso de no contar con instructor acreditado DARE, se puede cumplir la meta con las charlas de Habilidades para la vida DARE, con el aval del Coordinador Nacional. | C6: 2 | D6: =SUM(E6:P6) -> 1 | E6: 0 | F6: 0 | G6: 0 | H6: 0 | I6: 1
A7: DARE | B7: Cubrir 4 procesos formativos en Centros Educativos (dos por año) ubicados dentro de los distritos que contemplan las áreas georreferenciadas del informe territorial de la Estrategia Sembremos Seguridad 2024, con los cursos del Programa DARE: , Curso primaria. Curso Secundaria; un nivel completo por centro educativo, por semestre. En caso de no contar con instructor acreditado, se puede cumplir la meta con las charlas de Habilidades para la vida DARE, con el aval del Coordinador Nacional. | C7: 2 | D7: =SUM(E7:P7) -> 0 | E7: 0 | F7: 0 | G7: 0 | H7: 0
A8: PSCC | B8: Cuatro capacitaciones, en el tema de "Denuncia en casos de receptación ", dirigidas a las comunidades integradas al Programa de Seguridad Comunitaria, que se localicen, en los distritos que contemplan las área georreferenciadas del informe territorial de la Estrategia Sembremos Seguridad 2024, dos por año, una por semestre. | C8: 2 | D8: =SUM(E8:P8) -> 0
A9: PSCC | B9: Dos estrategias de divulgación (Por medio de brochures, post o imágenes en redes sociales) en el tema del procedimiento para realizar una "Denuncia en casos de receptación" dirigidas a las comunidades integradas al Programa de Seguridad Comunitaria, que se localicen, en los distritos que contemplan las área georreferenciadas del informe territorial de la Estrategia Sembremos Seguridad 2024, una por año. | C9: 1 | D9: =SUM(E9:P9) -> 0
A10: PLAN DE POLITICA LOCAL E IMPLEMENTACIÓN DE LA POLITICA LOCAL DE SEGURIDAD | B10: Conformación Comité | C10: 3 | D10: =SUM(E10:O10) -> 0
B11: Conformación de Comercio | C11: 2 | D11: =SUM(E11:O11) -> 14 | G11: 4 | H11: 10
B12: Reuniones-Jefaturas | C12: 60 | D12: =SUM(E12:O12) -> 25 | E12: 2 | F12: 10 | G12: 1 | H12: 2 | I12: 10
B13: Campañas de divulgación | C13: 53 | D13: =SUM(E13:O13) -> 23 | G13: 15 | H13: 8
B14: Capacitaciones | C14: 0 | D14: =SUM(E14:O14) -> 0
B15: Charlas | C15: 0 | D15: =SUM(E15:O15) -> 0
B16: Talleres | C16: 0 | D16: =SUM(E16:O16) -> 0
B17: Sensibilización | C17: 0 | D17: =SUM(E17:O17) -> 0
B18: Actividades deportivas | C18: 0 | D18: =SUM(E18:O18) -> 0
B19: Cine en mi Barrio | C19: 0 | D19: =SUM(E19:O19) -> 0
B20: Cívico-policial | C20: 0 | D20: =SUM(E20:O20) -> 0
B21: Actividades culturales | C21: 0 | D21: =SUM(E21:O21) -> 0
B22: Ferias | C22: 0 | D22: =SUM(E22:O22) -> 0
B23: Stand informativo | C23: 0 | D23: =SUM(E23:O23) -> 0
B24: Visitas | C24: 143 | D24: =SUM(E24:O24) -> 71 | E24: 30 | H24: 41
B25: Recuperación del espacio público | C25: 0 | D25: =SUM(E25:O25) -> 0
B26: Convocatoria de Mesas Locales | C26: 3 | D26: =SUM(E26:O26) -> 2 | G26: 2
B27: Exposición Informe Territorial ESS | C27: 3 | D27: =SUM(E27:O27) -> 3 | H27: 3
B28: Primera Sesión de Trabajo | C28: 3 | D28: =SUM(E28:O28) -> 3 | I28: 3
B29: Segunda Sesión - Conformación Secretaria Técnica | C29: 3 | D29: =SUM(E29:O29) -> 0
B30: Tercera Sesión | C30: 3 | D30: =SUM(E30:O30) -> 0
B31: Elaboracióin del Texto de la Política Local | C31: 1 | D31: =SUM(E31:O31) -> 0
B32: Revisión Técnica DPPP | C32: 1 | D32: =SUM(E32:O32) -> 0
B33: Revisión Area Legal Gobierno Local | C33: 1 | D33: =SUM(E33:O33) -> 0
B34: Incorporación de Observaciones | C34: 1 | D34: =SUM(E34:O34) -> 0
B35: Aval del Director Regional | C35: 1 | D35: =SUM(E35:O35) -> 0
B36: Presentación al Consejo Municipal | C36: 1 | D36: =SUM(E36:O36) -> 0
B37: Presentación ante la Comunidad por parte del Director Regional y Alcalde | C37: 1 | D37: =SUM(E37:O37) -> 0
C38: =SUM(C3:C37) -> 295 | D38: =SUM(D3:D37) -> 144
D39: =D38/C38 -> 0.48813559

Sheet D45 Tarrazú
A1: PROGRAMA | B1: D45 TARRAZÚ | C1: META | D1: AVANCE | E1: ENERO | F1: FEBRERO | G1: MARZO | H1: ABRIL | I1: MAYO | J1: JUNIO | K1: JULIO | L1: AGOSTO | M1: SEPTIEMBRE | N1: OCTUBRE | O1: NOVIEMBRE | P1: DICIEMBRE
C2: 2026 | D2: Porcentual
A3: PSCC | B3: Cuatro actividades de recuperación de espacios públicos, con las comunidades integradas al Programa de Seguridad Comunitaria, que se localicen, en los distritos que contemplan las área georreferenciadas del informe territorial de la Estrategia Sembremos Seguridad 2024, dos por año, una por semestre. | C3: 2 | D3: =SUM(E3:P3) -> 1 | F3: 1
A4: GREAT/MPAS/DARE | B4: Realizar 4 procesos formativos (Cursos de la oferta de los programas DARE - GREAT - MPAS) en Centros Educativos, 2 por año, dentro de los distritos que contemplan las áreas georreferenciadas del informe territorial de la Estrategia Sembremos Seguridad 2024. Un curso diferente por semestre, un nivel completo. En caso de no contar con instructor acreditado DARE, se puede cumplir la meta con las charlas de Habilidades para la vida DARE, con el aval del Coordinador Nacional. | C4: 2 | D4: =SUM(E4:P4) -> 1 | E4: 0 | F4: 0 | G4: 0 | H4: 0 | I4: 1
A5: DARE | B5: Cubrir 2 procesos formativos en Centros Educativos (uno por año) ubicados dentro de los distritos que contemplan las áreas georreferenciadas del informe territorial de la Estrategia Sembremos Seguridad 2024, con los cursos del Programa DARE: , Curso primaria. Curso Secundaria; un nivel completo por centro educativo, por semestre. En caso de no contar con instructor acreditado, se puede cumplir la meta con las charlas de Habilidades para la vida DARE, con el aval del Coordinador Nacional. | C5: 1 | D5: =SUM(E5:P5) -> 0 | E5: 0 | F5: 0 | G5: 0 | H5: 0
A6: PSCC | B6: Cuatro comercios capacitados e integrados al Programa de Seguridad Comercial que se localicen, en los distritos que contemplan las área georreferenciadas del informe territorial de la Estrategia Sembremos Seguridad 2024, dos por año, una por semestre. | C6: 2 | D6: =SUM(E6:P6) -> 2 | F6: 1 | G6: 1
A7: PSCC | B7: Cuatro estrategias de divulgación (Por medio de brochures, post o imágenes en redes sociales) diseñadas por la Estrategia de divulgación de la Dirección de Programas Policiales Preventivos, en el tema de "Prevención del Consumo de alcohol en vía pública" dirigidas a las comunidades integradas al Programa de Seguridad Comunitaria y a los comercios integrados al Programa de Seguridad Comercial que se localicen, en los distritos que contemplan las área georreferenciadas del informe territorial de la Estrategia Sembremos Seguridad 2024, dos por año. | C7: 2 | D7: =SUM(E7:P7) -> 2 | E7: 2
A8: PSCC | B8: Cuatro capacitaciones, en el tema de "Cultura Preventiva en zonas de riesgo", dirigidas a las comunidades integradas al Programa de Seguridad Comunitaria que se localicen, en los distritos que contemplan las área georreferenciadas del informe territorial de la Estrategia Sembremos Seguridad 2024, dos por año, una por semestre. | C8: 2 | D8: =SUM(E8:P8) -> 1 | H8: 1
A9: PSCC | B9: Dos estrategias de divulgación (Por medio de brochures, post o imágenes en redes sociales) en el tema del procedimiento para realizar una "Denuncia de búnkers / venta de drogas" dirigidas a las comunidades integradas al Programa de Seguridad Comunitaria que se localicen, en los distritos que contemplan las área georreferenciadas del informe territorial de la Estrategia Sembremos Seguridad 2024, una por año. | C9: 1 | D9: =SUM(E9:P9) -> 1 | F9: 1
A10: PLAN DE POLITICA LOCAL E IMPLEMENTACIÓN DE LA POLITICA LOCAL DE SEGURIDAD | B10: Conformación Comité | C10: 3 | D10: =SUM(E10:O10) -> 4 | G10: 1 | H10: 3
B11: Conformación de Comercio | C11: 3 | D11: =SUM(E11:O11) -> 3 | F11: 1 | G11: 2
B12: Reuniones-Jefaturas | C12: 104 | D12: =SUM(E12:O12) -> 43 | E12: 7 | F12: 9 | G12: 6 | H12: 9 | I12: 10 | J12: 2
B13: Campañas de divulgación | C13: 110 | D13: =SUM(E13:O13) -> 58 | E13: 26 | H13: 32
B14: Capacitaciones | C14: 0 | D14: =SUM(E14:O14) -> 0
B15: Charlas | C15: 0 | D15: =SUM(E15:O15) -> 0
B16: Talleres | C16: 0 | D16: =SUM(E16:O16) -> 0
B17: Sensibilización | C17: 0 | D17: =SUM(E17:O17) -> 0
B18: Actividades deportivas | C18: 0 | D18: =SUM(E18:O18) -> 0
B19: Cine en mi Barrio | C19: 0 | D19: =SUM(E19:O19) -> 0
B20: Cívico-policial | C20: 0 | D20: =SUM(E20:O20) -> 0
B21: Actividades culturales | C21: 0 | D21: =SUM(E21:O21) -> 0
B22: Ferias | C22: 0 | D22: =SUM(E22:O22) -> 0
B23: Stand informativo | C23: 0 | D23: =SUM(E23:O23) -> 0
B24: Visitas | C24: 134 | D24: =SUM(E24:O24) -> 64 | E24: 35 | H24: 29
B25: Recuperación del espacio público | C25: 0 | D25: =SUM(E25:O25) -> 0
B26: Convocatoria de Mesas Locales | C26: 3 | D26: =SUM(E26:O26) -> 3 | F26: 3
B27: Exposición Informe Territorial ESS | C27: 3 | D27: =SUM(E27:O27) -> 0
B28: Primera Sesión de Trabajo | C28: 3 | D28: =SUM(E28:O28) -> 3 | I28: 3
B29: Segunda Sesión - Conformación Secretaria Técnica | C29: 3 | D29: =SUM(E29:O29) -> 0
B30: Tercera Sesión | C30: 3 | D30: =SUM(E30:O30) -> 0
B31: Elaboracióin del Texto de la Política Local | C31: 1 | D31: =SUM(E31:O31) -> 0
B32: Revisión Técnica DPPP | C32: 1 | D32: =SUM(E32:O32) -> 0
B33: Revisión Area Legal Gobierno Local | C33: 1 | D33: =SUM(E33:O33) -> 0
B34: Incorporación de Observaciones | C34: 1 | D34: =SUM(E34:O34) -> 0
B35: Aval del Director Regional | C35: 1 | D35: =SUM(E35:O35) -> 0
B36: Presentación al Consejo Municipal | C36: 1 | D36: =SUM(E36:O36) -> 0
B37: Presentación ante la Comunidad por parte del Director Regional y Alcalde | C37: 1 | D37: =SUM(E37:O37) -> 0
C38: =SUM(C3:C37) -> 388 | D38: =SUM(D3:D37) -> 186
D39: =D38/C38 -> 0.47938144

Sheet D46 Dota
A1: PROGRAMA | B1: D46 DOTA | C1: META | D1: AVANCE | E1: ENERO | F1: FEBRERO | G1: MARZO | H1: ABRIL | I1: MAYO | J1: JUNIO | K1: JULIO | L1: AGOSTO | M1: SEPTIEMBRE | N1: OCTUBRE | O1: NOVIEMBRE | P1: DICIEMBRE
C2: 2026 | D2: Porcentual
A3: PSCC | B3: Cuatro actividades de recuperación de espacios públicos, con las comunidades integradas al Programa de Seguridad Comunitaria, que se localicen, en los distritos que contemplan las área georreferenciadas del informe territorial de la Estrategia Sembremos Seguridad 2024, dos por año, una por semestre. | C3: 2 | D3: =SUM(E3:P3) -> 0
A4: GREAT/MPAS/DARE | B4: Realizar 4 procesos formativos (Cursos de la oferta de los programas DARE - GREAT - MPAS) en Centros Educativos, 2 por año, dentro de los distritos que contemplan las áreas georreferenciadas del informe territorial de la Estrategia Sembremos Seguridad 2024. Un curso diferente por semestre, un nivel completo. En caso de no contar con instructor acreditado DARE, se puede cumplir la meta con las charlas de Habilidades para la vida DARE, con el aval del Coordinador Nacional. | C4: 2 | D4: =SUM(E4:P4) -> 0 | E4: 0 | F4: 0 | G4: 0 | H4: 0
A5: PSCC | B5: Dos estrategias de divulgación (Por medio de brochures, post o imágenes en redes sociales) en el tema del procedimiento para realizar una "Denuncia de ventas de drogas" dirigidas a las comunidades integradas al Programa de Seguridad Comunitaria que se localicen, en los distritos que contemplan las área georreferenciadas del informe territorial de la Estrategia Sembremos Seguridad 2024, una por año. | C5: 1 | D5: =SUM(E5:P5) -> 0 | E5: 0 | F5: 0 | G5: 0 | H5: 0
A6: PLAN DE POLITICA LOCAL E IMPLEMENTACIÓN DE LA POLITICA LOCAL DE SEGURIDAD | B6: Conformación Comité | C6: 3 | D6: =SUM(E6:O6) -> 0
B7: Conformación de Comercio | C7: 3 | D7: =SUM(E7:O7) -> 0
B8: Reuniones-Jefaturas | C8: 64 | D8: =SUM(E8:O8) -> 20 | F8: 4 | G8: 6 | H8: 6 | I8: 2 | J8: 2
B9: Campañas de divulgación | C9: 53 | D9: =SUM(E9:O9) -> 21 | G9: 13 | H9: 8
B10: Capacitaciones | C10: 0 | D10: =SUM(E10:O10) -> 0
B11: Charlas | C11: 11 | D11: =SUM(E11:O11) -> 0
B12: Talleres | C12: 0 | D12: =SUM(E12:O12) -> 0
B13: Sensibilización | C13: 0 | D13: =SUM(E13:O13) -> 0
B14: Actividades deportivas | C14: 0 | D14: =SUM(E14:O14) -> 0
B15: Cine en mi Barrio | C15: 0 | D15: =SUM(E15:O15) -> 0
B16: Cívico-policial | C16: 0 | D16: =SUM(E16:O16) -> 0
B17: Actividades culturales | C17: 0 | D17: =SUM(E17:O17) -> 0
B18: Ferias | C18: 0 | D18: =SUM(E18:O18) -> 0
B19: Stand informativo | C19: 0 | D19: =SUM(E19:O19) -> 0
B20: Visitas | C20: 108 | D20: =SUM(E20:O20) -> 29 | E20: 5 | G20: 5 | H20: 10 | I20: 9
B21: Recuperación del espacio público | C21: 0 | D21: =SUM(E21:O21) -> 0
B22: Convocatoria de Mesas Locales | C22: 3 | D22: =SUM(E22:O22) -> 0
B23: Exposición Informe Territorial ESS | C23: 3 | D23: =SUM(E23:O23) -> 3 | H23: 3
B24: Primera Sesión de Trabajo | C24: 3 | D24: =SUM(E24:O24) -> 3 | I24: 3
B25: Segunda Sesión - Conformación Secretaria Técnica | C25: 3 | D25: =SUM(E25:O25) -> 0
B26: Tercera Sesión | C26: 3 | D26: =SUM(E26:O26) -> 0
B27: Elaboracióin del Texto de la Política Local | C27: 1 | D27: =SUM(E27:O27) -> 0
B28: Revisión Técnica DPPP | C28: 1 | D28: =SUM(E28:O28) -> 0
B29: Revisión Area Legal Gobierno Local | C29: 1 | D29: =SUM(E29:O29) -> 0
B30: Incorporación de Observaciones | C30: 1 | D30: =SUM(E30:O30) -> 0
B31: Aval del Director Regional | C31: 1 | D31: =SUM(E31:O31) -> 0
B32: Presentación al Consejo Municipal | C32: 1 | D32: =SUM(E32:O32) -> 0
B33: Presentación ante la Comunidad por parte del Director Regional y Alcalde | C33: 1 | D33: =SUM(E33:O33) -> 0
C34: =SUM(C3:C33) -> 269 | D34: =SUM(D3:D33) -> 76
D35: =D34/C34 -> 0.28252788

Sheet D47 León Cortés
A1: PROGRAMA | B1: D47 LEÓN CORTÉS | C1: META | D1: AVANCE | E1: ENERO | F1: FEBRERO | G1: MARZO | H1: ABRIL | I1: MAYO | J1: JUNIO | K1: JULIO | L1: AGOSTO | M1: SEPTIEMBRE | N1: OCTUBRE | O1: NOVIEMBRE | P1: DICIEMBRE
C2: 2026 | D2: Porcentual
A3: PSCC | B3: Cuatro actividades de recuperación de espacios públicos, con las comunidades integradas al Programa de Seguridad Comunitaria, que se localicen, en los distritos que contemplan las área georreferenciadas del informe territorial de la Estrategia Sembremos Seguridad 2024, dos por año, una por semestre. | C3: 2 | D3: =SUM(E3:P3) -> 1 | J3: 1
A4: GREAT/MPAS/DARE | B4: Realizar 4 procesos formativos (Cursos de la oferta de los programas DARE - GREAT - MPAS) en Centros Educativos, 2 por año, dentro de los distritos que contemplan las áreas georreferenciadas del informe territorial de la Estrategia Sembremos Seguridad 2024. Un curso diferente por semestre, un nivel completo. En caso de no contar con instructor acreditado DARE, se puede cumplir la meta con las charlas de Habilidades para la vida DARE, con el aval del Coordinador Nacional. | C4: 2 | D4: =SUM(E4:P4) -> 0 | E4: 0 | F4: 0 | G4: 0 | H4: 0
A5: PSCC | B5: Dos estrategias de divulgación (Por medio de brochures, post o imágenes en redes sociales) en el tema del procedimiento para realizar una "Denuncia de ventas de drogas" diseñadas por la Estrategia de divulgación de la Dirección de Programas Policiales Preventivos dirigidas a las comunidades integradas al Programa de Seguridad Comunitaria que se localicen, en los distritos que contemplan las área georreferenciadas del informe territorial de la Estrategia Sembremos Seguridad 2024, una por año. | C5: 1 | D5: =SUM(E5:P5) -> 0
A6: PSCC | B6: Cuatro capacitaciones, en el tema de "Cultura Preventiva en zonas de riesgo", dirigidas a las comunidades integradas al Programa de Seguridad Comunitaria que se localicen, en los distritos que contemplan las área georreferenciadas del informe territorial de la Estrategia Sembremos Seguridad 2024, dos por año, una por semestre. | C6: 2 | D6: =SUM(E6:P6) -> 0
A7: PSCC | B7: Dos estrategias de divulgación (Por medio de brochures, post o imágenes en redes sociales) en el tema del procedimiento para realizar una "Denuncia de búnkers / venta de drogas" dirigidas a las comunidades integradas al Programa de Seguridad Comunitaria que se localicen, en los distritos que contemplan las área georreferenciadas del informe territorial de la Estrategia Sembremos Seguridad 2024, una por año. | C7: 2 | D7: =SUM(E7:P7) -> 1 | E7: 1
A8: PLAN DE POLITICA LOCAL E IMPLEMENTACIÓN DE LA POLITICA LOCAL DE SEGURIDAD | B8: Conformación Comité | C8: 3 | D8: =SUM(E8:O8) -> 0
B9: Conformación de Comercio | C9: 1 | D9: =SUM(E9:O9) -> 0
B10: Reuniones-Jefaturas | C10: 48 | D10: =SUM(E10:O10) -> 21 | E10: 3 | F10: 5 | G10: 4 | H10: 4 | I10: 4 | J10: 1
B11: Campañas de divulgación | C11: 36 | D11: =SUM(E11:O11) -> 43 | E11: 10 | G11: 10 | H11: 23
B12: Capacitaciones | C12: 0 | D12: =SUM(E12:O12) -> 0
B13: Charlas | C13: 0 | D13: =SUM(E13:O13) -> 0
B14: Talleres | C14: 0 | D14: =SUM(E14:O14) -> 0
B15: Sensibilización | C15: 0 | D15: =SUM(E15:O15) -> 0
B16: Actividades deportivas | C16: 0 | D16: =SUM(E16:O16) -> 0
B17: Cine en mi Barrio | C17: 0 | D17: =SUM(E17:O17) -> 0
B18: Cívico-policial | C18: 0 | D18: =SUM(E18:O18) -> 0
B19: Actividades culturales | C19: 0 | D19: =SUM(E19:O19) -> 0
B20: Ferias | C20: 0 | D20: =SUM(E20:O20) -> 0
B21: Stand informativo | C21: 0 | D21: =SUM(E21:O21) -> 0
B22: Visitas | C22: 160 | D22: =SUM(E22:O22) -> 61 | E22: 10 | F22: 15 | G22: 7 | H22: 11 | I22: 12 | J22: 6
B23: Recuperación del espacio público | C23: 0 | D23: =SUM(E23:O23) -> 0
B24: Convocatoria de Mesas Locales | C24: 6 | D24: =SUM(E24:O24) -> 6 | F24: 2 | G24: 4
B25: Exposición Informe Territorial ESS | C25: 6 | D25: =SUM(E25:O25) -> 6 | H25: 6
B26: Primera Sesión de Trabajo | C26: 6 | D26: =SUM(E26:O26) -> 6 | I26: 6
B27: Segunda Sesión - Conformación Secretaria Técnica | C27: 6 | D27: =SUM(E27:O27) -> 1 | J27: 1
B28: Tercera Sesión | C28: 6 | D28: =SUM(E28:O28) -> 0
B29: Elaboracióin del Texto de la Política Local | C29: 1 | D29: =SUM(E29:O29) -> 0
B30: Revisión Técnica DPPP | C30: 1 | D30: =SUM(E30:O30) -> 0
B31: Revisión Area Legal Gobierno Local | C31: 1 | D31: =SUM(E31:O31) -> 0
B32: Incorporación de Observaciones | C32: 1 | D32: =SUM(E32:O32) -> 0
B33: Aval del Director Regional | C33: 1 | D33: =SUM(E33:O33) -> 0
B34: Presentación al Consejo Municipal | C34: 1 | D34: =SUM(E34:O34) -> 0
B35: Presentación ante la Comunidad por parte del Director Regional y Alcalde | C35: 1 | D35: =SUM(E35:O35) -> 0
C36: =SUM(C3:C35) -> 294 | D36: =SUM(D3:D35) -> 146
D37: =D36/C36 -> 0.49659864

Sheet D48 Guadalupe
A1: PROGRAMA | B1: D48 GUADALUPE | C1: META | D1: AVANCE | E1: ENERO | F1: FEBRERO | G1: MARZO | H1: ABRIL | I1: MAYO | J1: JUNIO | K1: JULIO | L1: AGOSTO | M1: SEPTIEMBRE | N1: OCTUBRE | O1: NOVIEMBRE | P1: DICIEMBRE
C2: 2026 | D2: Porcentual
A3: PSCC | B3: Cuatro actividades de recuperación de espacios públicos, con las comunidades integradas al Programa de Seguridad Comunitaria, que se localicen, en los distritos que contemplan las área georreferenciadas del informe territorial de la Estrategia Sembremos Seguridad 2024, dos por año, una por semestre. | C3: 2 | D3: =SUM(E3:P3) -> 1 | E3: 1
A4: GREAT/MPAS/DARE | B4: Realizar 4 procesos formativos (Cursos de la oferta de los programas DARE - GREAT - MPAS) en Centros Educativos, 2 por año, dentro de los distritos que contemplan las áreas georreferenciadas del informe territorial de la Estrategia Sembremos Seguridad 2024. Un curso diferente por semestre, un nivel completo. En caso de no contar con instructor acreditado DARE, se puede cumplir la meta con las charlas de Habilidades para la vida DARE, con el aval del Coordinador Nacional. | C4: 2 | D4: =SUM(E4:P4) -> 0 | E4: 0 | F4: 0 | G4: 0 | H4: 0
A5: DARE | B5: Cubrir 4 procesos formativos en Centros Educativos (dos por año) ubicados dentro de los distritos que contemplan las áreas georreferenciadas del informe territorial de la Estrategia Sembremos Seguridad 2024, con los cursos del Programa DARE: , Curso primaria. Curso Secundaria; un nivel completo por centro educativo, por semestre. En caso de no contar con instructor acreditado, se puede cumplir la meta con las charlas de Habilidades para la vida DARE, con el aval del Coordinador Nacional. | C5: 2 | D5: =SUM(E5:P5) -> 0 | E5: 0 | F5: 0 | G5: 0 | H5: 0
A6: PSCC | B6: Cuatro capacitaciones, en el tema de "Denuncia a búnkers", dirigidas a las comunidades integradas al Programa de Seguridad Comunitaria que se localicen, en los distritos que contemplan las área georreferenciadas del informe territorial de la Estrategia Sembremos Seguridad 2024, dos por año, una por semestre. | C6: 2 | D6: =SUM(E6:P6) -> 0
