Workbook
Name ABANG: [1]DAT2!#REF!
Name ABANG: [2]DAT2!#REF!
Name ABANG: [3]DAT2!#REF!
Name ABANG: [4]DAT2!#REF!
Name ABANG: [5]DAT2!#REF!
Name ABANG: [6]DAT2!#REF!
Name ABANG: [7]DAT2!#REF!
Name ABANG: [8]DAT2!#REF!
Name ABANG: [9]DAT2!#REF!
Name ABANG: [10]DAT2!#REF!
Name ABANG: [11]DAT2!#REF!
Name ABANG: [12]DAT2!#REF!
Name ACOS: [1]DAT2!#REF!
Name ACOS: [2]DAT2!#REF!
Name ACOS: [3]DAT2!#REF!
Name ACOS: [4]DAT2!#REF!
Name ACOS: [5]DAT2!#REF!
Name ACOS: [6]DAT2!#REF!
Name ACOS: [7]DAT2!#REF!
Name ACOS: [8]DAT2!#REF!
Name ACOS: [9]DAT2!#REF!
Name ACOS: [10]DAT2!#REF!
Name ACOS: [11]DAT2!#REF!
Name ACOS: [12]DAT2!#REF!
Name ALAJU: [1]DAT2!#REF!
Name ALAJU: [2]DAT2!#REF!
Name ALAJU: [3]DAT2!#REF!
Name ALAJU: [4]DAT2!#REF!
Name ALAJU: [5]DAT2!#REF!
Name ALAJU: [6]DAT2!#REF!
Name ALAJU: [7]DAT2!#REF!
Name ALAJU: [8]DAT2!#REF!
Name ALAJU: [9]DAT2!#REF!
Name ALAJU: [10]DAT2!#REF!
Name ALAJU: [11]DAT2!#REF!
Name ALAJU: [12]DAT2!#REF!
Name ALAJUE: [1]DAT2!#REF!
Name ALAJUE: [2]DAT2!#REF!
Name ALAJUE: [3]DAT2!#REF!
Name ALAJUE: [4]DAT2!#REF!
Name ALAJUE: [5]DAT2!#REF!
Name ALAJUE: [6]DAT2!#REF!
Name ALAJUE: [7]DAT2!#REF!
Name ALAJUE: [8]DAT2!#REF!
Name ALAJUE: [9]DAT2!#REF!
Name ALAJUE: [10]DAT2!#REF!
Name ALAJUE: [11]DAT2!#REF!
Name ALAJUE: [12]DAT2!#REF!
Name ALVA: [1]DAT2!#REF!
Name ALVA: [2]DAT2!#REF!
Name ALVA: [3]DAT2!#REF!
Name ALVA: [4]DAT2!#REF!
Name ALVA: [5]DAT2!#REF!
Name ALVA: [6]DAT2!#REF!
Name ALVA: [7]DAT2!#REF!
Name ALVA: [8]DAT2!#REF!
Name ALVA: [9]DAT2!#REF!
Name ALVA: [10]DAT2!#REF!
Name ALVA: [11]DAT2!#REF!
Name ALVA: [12]DAT2!#REF!

Sheet D60 Liberia
A1: PROGRAMA | B1: D60 LIBERIA | C1: META | D1: AVANCE | E1: ENERO | F1: FEBRERO | G1: MARZO | H1: ABRIL | I1: MAYO | J1: JUNIO | K1: JULIO | L1: AGOSTO | M1: SEPTIEMBRE | N1: OCTUBRE | O1: NOVIEMBRE | P1: DICIEMBRE
C2: 2026 | D2: Porcentual
A3: PSCC | B3: Cuatro actividades de recuperación de espacios públicos, con las comunidades integradas al Programa de Seguridad Comunitaria, que se localicen, en los distritos que contemplan las área georreferenciadas del informe territorial de la Estrategia Sembremos Seguridad 2024, dos por año, una por semestre. | C3: 2 | D3: =SUM(E3:P3) -> 1 | J3: 1
A4: GREAT/MPAS/DARE | B4: Realizar 4 procesos formativos (Cursos de la oferta de los programas DARE - GREAT - MPAS) en Centros Educativos, 2 por año, dentro de los distritos que contemplan las áreas georreferenciadas del informe territorial de la Estrategia Sembremos Seguridad 2024. Un curso diferente por semestre, un nivel completo. En caso de no contar con instructor acreditado DARE, se puede cumplir la meta con las charlas de Habilidades para la vida DARE, con el aval del Coordinador Nacional. | C4: 2 | D4: =SUM(E4:P4) -> 1 | E4: 0 | F4: 0 | G4: 0 | H4: 0 | I4: 1
A5: DARE | B5: Cubrir 4 procesos formativos en Centros Educativos (dos por año) ubicados dentro de los distritos que contemplan las áreas georreferenciadas del informe territorial de la Estrategia Sembremos Seguridad 2024, con los cursos del Programa DARE: , Curso primaria. Curso Secundaria; un nivel completo por centro educativo, por semestre. En caso de no contar con instructor acreditado, se puede cumplir la meta con las charlas de Habilidades para la vida DARE, con el aval del Coordinador Nacional. | C5: 2 | D5: =SUM(E5:P5) -> 0 | E5: 0 | F5: 0 | G5: 0 | H5: 0
A6: PSCC | B6: Cuatro capacitaciones, en el tema de "Denuncia a búnkers", dirigidas a las comunidades integradas al Programa de Seguridad Comunitaria que se localicen, en los distritos que contemplan las área georreferenciadas del informe territorial de la Estrategia Sembremos Seguridad 2024, dos por año, una por semestre. | C6: 2 | D6: =SUM(E6:P6) -> 0
A7: PSCC | B7: Dos estrategias de divulgación (Por medio de brochures, post o imágenes en redes sociales) en el tema del procedimiento para realizar una "Denuncia de búnkers" dirigidas a las comunidades integradas al Programa de Seguridad Comunitaria que se localicen, en los distritos que contemplan las área georreferenciadas del informe territorial de la Estrategia Sembremos Seguridad 2024, una por año. | C7: 1 | D7: =SUM(E7:P7) -> 0
A8: PSCC | B8: Dos estrategias de divulgación (Por medio de brochures, post o imágenes en redes sociales) en el tema del procedimiento para realizar una "Denuncia de ventas de drogas" dirigidas a las comunidades integradas al Programa de Seguridad Comunitaria que se localicen, en los distritos que contemplan las área georreferenciadas del informe territorial de la Estrategia Sembremos Seguridad 2024, una por año. | C8: 1 | D8: =SUM(E8:P8) -> 0
A9: PLAN DE POLITICA LOCAL E IMPLEMENTACIÓN DE LA POLITICA LOCAL DE SEGURIDAD | B9: Conformación Comité | C9: 4 | D9: =SUM(E9:O9) -> 0
B10: Conformación de Comercio | C10: 5 | D10: =SUM(E10:O10) -> 0
B11: Reuniones-Jefaturas | C11: 209 | D11: =SUM(E11:O11) -> 88 | E11: 14 | F11: 10 | G11: 26 | H11: 13 | I11: 23 | J11: 2
B12: Campañas de divulgación | C12: 85 | D12: =SUM(E12:O12) -> 36 | G12: 32 | H12: 4
B13: Capacitaciones | C13: 0 | D13: =SUM(E13:O13) -> 0
B14: Charlas | C14: 11 | D14: =SUM(E14:O14) -> 0
B15: Talleres | C15: 20 | D15: =SUM(E15:O15) -> 0
B16: Sensibilización | C16: 41 | D16: =SUM(E16:O16) -> 10 | H16: 8 | I16: 2
B17: Actividades deportivas | C17: 2 | D17: =SUM(E17:O17) -> 0
B18: Cine en mi Barrio | C18: 3 | D18: =SUM(E18:O18) -> 0
B19: Cívico-policial | C19: 21 | D19: =SUM(E19:O19) -> 2 | H19: 2
B20: Actividades culturales | C20: 0 | D20: =SUM(E20:O20) -> 0
B21: Ferias | C21: 0 | D21: =SUM(E21:O21) -> 0
B22: Stand informativo | C22: 0 | D22: =SUM(E22:O22) -> 0
B23: Visitas | C23: 190 | D23: =SUM(E23:O23) -> 61 | E23: 36 | G23: 1 | H23: 18 | I23: 6
B24: Recuperación del espacio público | C24: 6 | D24: =SUM(E24:O24) -> 0
B25: Convocatoria de Mesas Locales | C25: 4 | D25: =SUM(E25:O25) -> 3 | F25: 1 | G25: 2
B26: Exposición Informe Territorial ESS | C26: 4 | D26: =SUM(E26:O26) -> 2 | H26: 2
B27: Primera Sesión de Trabajo | C27: 4 | D27: =SUM(E27:O27) -> 4 | I27: 3 | J27: 1
B28: Segunda Sesión - Conformación Secretaria Técnica | C28: 4 | D28: =SUM(E28:O28) -> 2 | J28: 2
B29: Tercera Sesión | C29: 4 | D29: =SUM(E29:O29) -> 0
B30: Elaboracióin del Texto de la Política Local | C30: 1 | D30: =SUM(E30:O30) -> 0
B31: Revisión Técnica DPPP | C31: 1 | D31: =SUM(E31:O31) -> 0
B32: Revisión Area Legal Gobierno Local | C32: 1 | D32: =SUM(E32:O32) -> 0
B33: Incorporación de Observaciones | C33: 1 | D33: =SUM(E33:O33) -> 0
B34: Aval del Director Regional | C34: 1 | D34: =SUM(E34:O34) -> 0
B35: Presentación al Consejo Municipal | C35: 1 | D35: =SUM(E35:O35) -> 0
B36: Presentación ante la Comunidad por parte del Director Regional y Alcalde | C36: 1 | D36: =SUM(E36:O36) -> 0
C37: =SUM(C3:C36) -> 634 | D37: =SUM(D3:D36) -> 210
D38: =D37/C37 -> 0.33123028

Sheet D61 Nicoya
A1: PROGRAMA | B1: D61 NICOYA | C1: META | D1: AVANCE | E1: ENERO | F1: FEBRERO | G1: MARZO | H1: ABRIL | I1: MAYO | J1: JUNIO | K1: JULIO | L1: AGOSTO | M1: SEPTIEMBRE | N1: OCTUBRE | O1: NOVIEMBRE | P1: DICIEMBRE
C2: 2026 | D2: Porcentual
A3: PSCC | B3: Cuatro actividades de recuperación de espacios públicos, con las comunidades integradas al Programa de Seguridad Comunitaria, que se localicen, en los distritos que contemplan las área georreferenciadas del informe territorial de la Estrategia Sembremos Seguridad 2024, dos por año, una por semestre. | C3: 2 | D3: =SUM(E3:P3) -> 0
A4: GREAT/MPAS/DARE | B4: Realizar 4 procesos formativos (Cursos de la oferta de los programas DARE - GREAT - MPAS) en Centros Educativos, 2 por año, dentro de los distritos que contemplan las áreas georreferenciadas del informe territorial de la Estrategia Sembremos Seguridad 2024. Un curso diferente por semestre, un nivel completo. En caso de no contar con instructor acreditado DARE, se puede cumplir la meta con las charlas de Habilidades para la vida DARE, con el aval del Coordinador Nacional. | C4: 2 | D4: =SUM(E4:P4) -> 0 | E4: 0 | F4: 0 | G4: 0 | H4: 0
A5: PSCC | B5: Cubrir 4 procesos formativos en Centros Educativos (dos por año) ubicados dentro de los distritos que contemplan las áreas georreferenciadas del informe territorial de la Estrategia Sembremos Seguridad 2024, con los cursos del Programa DARE: , Curso primaria. Curso Secundaria; un nivel completo por centro educativo, por semestre. En caso de no contar con instructor acreditado, se puede cumplir la meta con las charlas de Habilidades para la vida DARE, con el aval del Coordinador Nacional. | C5: 2 | D5: =SUM(E5:P5) -> 0 | E5: 0 | F5: 0 | G5: 0 | H5: 0
A6: DARE | B6: Cuatro capacitaciones, en el tema de "Denuncia a búnkers", dirigidas a las comunidades integradas al Programa de Seguridad Comunitaria que se localicen, en los distritos que contemplan las área georreferenciadas del informe territorial de la Estrategia Sembremos Seguridad 2024, dos por año, una por semestre. | C6: 2 | D6: =SUM(E6:P6) -> 1 | F6: 1
A7: PSCC | B7: Dos estrategias de divulgación (Por medio de brochures, post o imágenes en redes sociales) en el tema del procedimiento para realizar una "Denuncia de búnkers" dirigidas a las comunidades integradas al Programa de Seguridad Comunitaria que se localicen, en los distritos que contemplan las área georreferenciadas del informe territorial de la Estrategia Sembremos Seguridad 2024, una por año. | C7: 1 | D7: =SUM(E7:P7) -> 1 | F7: 1
A8: PLAN DE POLITICA LOCAL E IMPLEMENTACIÓN DE LA POLITICA LOCAL DE SEGURIDAD | B8: Conformación Comité | C8: 3 | D8: =SUM(E8:O8) -> 0
B9: Conformación de Comercio | C9: 3 | D9: =SUM(E9:O9) -> 0
B10: Reuniones-Jefaturas | C10: 192 | D10: =SUM(E10:O10) -> 81 | F10: 19 | G10: 16 | H10: 30 | I10: 16
B11: Campañas de divulgación | C11: 158 | D11: =SUM(E11:O11) -> 58 | F11: 20 | G11: 21 | H11: 1 | J11: 16
B12: Capacitaciones | C12: 8 | D12: =SUM(E12:O12) -> 3 | G12: 3
B13: Charlas | C13: 2 | D13: =SUM(E13:O13) -> 0
B14: Talleres | C14: 0 | D14: =SUM(E14:O14) -> 0
B15: Sensibilización | C15: 2 | D15: =SUM(E15:O15) -> 0
B16: Actividades deportivas | C16: 3 | D16: =SUM(E16:O16) -> 1 | E16: 1
B17: Cine en mi Barrio | C17: 1 | D17: =SUM(E17:O17) -> 0
B18: Cívico-policial | C18: 7 | D18: =SUM(E18:O18) -> 0
B19: Actividades culturales | C19: 0 | D19: =SUM(E19:O19) -> 0
B20: Ferias | C20: 0 | D20: =SUM(E20:O20) -> 0
B21: Stand informativo | C21: 0 | D21: =SUM(E21:O21) -> 0
B22: Visitas | C22: 160 | D22: =SUM(E22:O22) -> 66 | E22: 21 | F22: 6 | G22: 4 | H22: 21 | I22: 9 | J22: 5
B23: Recuperación del espacio público | C23: 1 | D23: =SUM(E23:O23) -> 0
B24: Convocatoria de Mesas Locales | C24: 7 | D24: =SUM(E24:O24) -> 4 | G24: 4
B25: Exposición Informe Territorial ESS | C25: 7 | D25: =SUM(E25:O25) -> 6 | H25: 5 | I25: 1
B26: Primera Sesión de Trabajo | C26: 7 | D26: =SUM(E26:O26) -> 6 | I26: 6
B27: Segunda Sesión - Conformación Secretaria Técnica | C27: 7 | D27: =SUM(E27:O27) -> 0
B28: Tercera Sesión | C28: 7 | D28: =SUM(E28:O28) -> 0
B29: Elaboracióin del Texto de la Política Local | C29: 1 | D29: =SUM(E29:O29) -> 0
B30: Revisión Técnica DPPP | C30: 1 | D30: =SUM(E30:O30) -> 0
B31: Revisión Area Legal Gobierno Local | C31: 1 | D31: =SUM(E31:O31) -> 0
B32: Incorporación de Observaciones | C32: 1 | D32: =SUM(E32:O32) -> 0
B33: Aval del Director Regional | C33: 1 | D33: =SUM(E33:O33) -> 0
B34: Presentación al Consejo Municipal | C34: 1 | D34: =SUM(E34:O34) -> 0
B35: Presentación ante la Comunidad por parte del Director Regional y Alcalde | C35: 1 | D35: =SUM(E35:O35) -> 0
C36: =SUM(C3:C35) -> 591 | D36: =SUM(D3:D35) -> 227
D37: =D36/C36 -> 0.38409475

Sheet D62 Santa Cruz
A1: PROGRAMA | B1: D62 SANTA CRUZ | C1: META | D1: AVANCE | E1: ENERO | F1: FEBRERO | G1: MARZO | H1: ABRIL | I1: MAYO | J1: JUNIO | K1: JULIO | L1: AGOSTO | M1: SEPTIEMBRE | N1: OCTUBRE | O1: NOVIEMBRE | P1: DICIEMBRE
C2: 2026 | D2: Porcentual
A3: PSCC | B3: Cuatro actividades de recuperación de espacios públicos, con las comunidades integradas al Programa de Seguridad Comunitaria, que se localicen, en los distritos que contemplan las área georreferenciadas del informe territorial de la Estrategia Sembremos Seguridad 2024, dos por año, una por semestre. | C3: 2 | D3: =SUM(E3:P3) -> 1 | G3: 1
A4: GREAT/MPAS/DARE | B4: Realizar 4 procesos formativos (Cursos de la oferta de los programas DARE - GREAT - MPAS) en Centros Educativos, 2 por año, dentro de los distritos que contemplan las áreas georreferenciadas del informe territorial de la Estrategia Sembremos Seguridad 2024. Un curso diferente por semestre, un nivel completo. En caso de no contar con instructor acreditado DARE, se puede cumplir la meta con las charlas de Habilidades para la vida DARE, con el aval del Coordinador Nacional. | C4: 2 | D4: =SUM(E4:P4) -> 0 | E4: 0 | F4: 0 | G4: 0 | H4: 0
A5: DARE | B5: Cubrir 4 procesos formativos en Centros Educativos (dos por año) ubicados dentro de los distritos que contemplan las áreas georreferenciadas del informe territorial de la Estrategia Sembremos Seguridad 2024, con los cursos del Programa DARE: , Curso primaria. Curso Secundaria; un nivel completo por centro educativo, por semestre. En caso de no contar con instructor acreditado, se puede cumplir la meta con las charlas de Habilidades para la vida DARE, con el aval del Coordinador Nacional. | C5: 2 | D5: =SUM(E5:P5) -> 1 | E5: 0 | F5: 0 | G5: 0 | H5: 1
A6: PSCC | B6: Cuatro capacitaciones, en el tema de "Denuncia a búnkers", dirigidas a las comunidades integradas al Programa de Seguridad Comunitaria que se localicen, en los distritos que contemplan las área georreferenciadas del informe territorial de la Estrategia Sembremos Seguridad 2024, dos por año, una por semestre. | C6: 2 | D6: =SUM(E6:P6) -> 1 | G6: 1
A7: PSCC | B7: Dos estrategias de divulgación (Por medio de brochures, post o imágenes en redes sociales) en el tema del procedimiento para realizar una "Denuncia de búnkers" dirigidas a las comunidades integradas al Programa de Seguridad Comunitaria que se localicen, en los distritos que contemplan las área georreferenciadas del informe territorial de la Estrategia Sembremos Seguridad 2024, una por año. | C7: 1 | D7: =SUM(E7:P7) -> 0
A8: PSCC | B8: Dos estrategias de divulgación (Por medio de brochures, post o imágenes en redes sociales) en el tema del procedimiento para realizar una "Denuncia en caso de Receptación" dirigidas a las comunidades integradas al Programa de Seguridad Comunitaria que se localicen, en los distritos que contemplan las área georreferenciadas del informe territorial de la Estrategia Sembremos Seguridad 2024, una por año. | C8: 1 | D8: =SUM(E8:P8) -> 1 | H8: 1
A9: PLAN DE POLITICA LOCAL E IMPLEMENTACIÓN DE LA POLITICA LOCAL DE SEGURIDAD | B9: Conformación Comité | C9: 3 | D9: =SUM(E9:O9) -> 3 | G9: 1 | H9: 1 | I9: 1
B10: Conformación de Comercio | C10: 3 | D10: =SUM(E10:O10) -> 0
B11: Reuniones-Jefaturas | C11: 88 | D11: =SUM(E11:O11) -> 41 | F11: 9 | G11: 9 | H11: 11 | I11: 12
B12: Campañas de divulgación | C12: 64 | D12: =SUM(E12:O12) -> 43 | G12: 21 | H12: 11 | J12: 11
B13: Capacitaciones | C13: 2 | D13: =SUM(E13:O13) -> 1 | G13: 1
B14: Charlas | C14: 20 | D14: =SUM(E14:O14) -> 0
B15: Talleres | C15: 0 | D15: =SUM(E15:O15) -> 0
B16: Sensibilización | C16: 0 | D16: =SUM(E16:O16) -> 0
B17: Actividades deportivas | C17: 0 | D17: =SUM(E17:O17) -> 0
B18: Cine en mi Barrio | C18: 0 | D18: =SUM(E18:O18) -> 0
B19: Cívico-policial | C19: 0 | D19: =SUM(E19:O19) -> 0
B20: Actividades culturales | C20: 2 | D20: =SUM(E20:O20) -> 0
B21: Ferias | C21: 0 | D21: =SUM(E21:O21) -> 0
B22: Stand informativo | C22: 0 | D22: =SUM(E22:O22) -> 0
B23: Visitas | C23: 128 | D23: =SUM(E23:O23) -> 57 | F23: 10 | G23: 16 | H23: 11 | I23: 11 | J23: 9
B24: Recuperación del espacio público | C24: 2 | D24: =SUM(E24:O24) -> 0
B25: Convocatoria de Mesas Locales | C25: 9 | D25: =SUM(E25:O25) -> 9 | F25: 4 | G25: 5
B26: Exposición Informe Territorial ESS | C26: 9 | D26: =SUM(E26:O26) -> 9 | H26: 9
B27: Primera Sesión de Trabajo | C27: 9 | D27: =SUM(E27:O27) -> 9 | I27: 9
B28: Segunda Sesión - Conformación Secretaria Técnica | C28: 9 | D28: =SUM(E28:O28) -> 0
B29: Tercera Sesión | C29: 9 | D29: =SUM(E29:O29) -> 0
B30: Elaboracióin del Texto de la Política Local | C30: 1 | D30: =SUM(E30:O30) -> 0
B31: Revisión Técnica DPPP | C31: 1 | D31: =SUM(E31:O31) -> 0
B32: Revisión Area Legal Gobierno Local | C32: 1 | D32: =SUM(E32:O32) -> 0
B33: Incorporación de Observaciones | C33: 1 | D33: =SUM(E33:O33) -> 0
B34: Aval del Director Regional | C34: 1 | D34: =SUM(E34:O34) -> 0
B35: Presentación al Consejo Municipal | C35: 1 | D35: =SUM(E35:O35) -> 0
B36: Presentación ante la Comunidad por parte del Director Regional y Alcalde | C36: 1 | D36: =SUM(E36:O36) -> 0
C37: =SUM(C3:C36) -> 374 | D37: =SUM(D3:D36) -> 176
D38: =D37/C37 -> 0.47058824

Sheet D63 Bagaces
A1: PROGRAMA | B1: D63 BAGACES | C1: META | D1: AVANCE | E1: ENERO | F1: FEBRERO | G1: MARZO | H1: ABRIL | I1: MAYO | J1: JUNIO | K1: JULIO | L1: AGOSTO | M1: SEPTIEMBRE | N1: OCTUBRE | O1: NOVIEMBRE | P1: DICIEMBRE
C2: 2026 | D2: Porcentual
A3: PSCC | B3: Cuatro actividades de recuperación de espacios públicos, con las comunidades integradas al Programa de Seguridad Comunitaria, que se localicen, en los distritos que contemplan las área georreferenciadas del informe territorial de la Estrategia Sembremos Seguridad 2024, dos por año, una por semestre. | C3: 2 | D3: =SUM(E3:P3) -> 0
A4: GREAT/MPAS/DARE | B4: Realizar 4 procesos formativos (Cursos de la oferta de los programas DARE - GREAT - MPAS) en Centros Educativos, 2 por año, dentro de los distritos que contemplan las áreas georreferenciadas del informe territorial de la Estrategia Sembremos Seguridad 2024. Un curso diferente por semestre, un nivel completo. En caso de no contar con instructor acreditado DARE, se puede cumplir la meta con las charlas de Habilidades para la vida DARE, con el aval del Coordinador Nacional. | C4: 2 | D4: =SUM(E4:P4) -> 0 | E4: 0 | F4: 0 | G4: 0 | H4: 0
A5: DARE | B5: Cubrir 4 procesos formativos en Centros Educativos (dos por año) ubicados dentro de los distritos que contemplan las áreas georreferenciadas del informe territorial de la Estrategia Sembremos Seguridad 2024, con los cursos del Programa DARE: , Curso primaria. Curso Secundaria; un nivel completo por centro educativo, por semestre. En caso de no contar con instructor acreditado, se puede cumplir la meta con las charlas de Habilidades para la vida DARE, con el aval del Coordinador Nacional. | C5: 2 | D5: =SUM(E5:P5) -> 1 | E5: 0 | F5: 0 | G5: 0 | H5: 1
A6: PLAN DE POLITICA LOCAL E IMPLEMENTACIÓN DE LA POLITICA LOCAL DE SEGURIDAD | B6: Conformación Comité | C6: 3 | D6: =SUM(E6:O6) -> 0
B7: Conformación de Comercio | C7: 3 | D7: =SUM(E7:O7) -> 0
B8: Reuniones-Jefaturas | C8: 84 | D8: =SUM(E8:O8) -> 31 | E8: 3 | F8: 8 | G8: 9 | H8: 6 | I8: 3 | J8: 2
B9: Campañas de divulgación | C9: 56 | D9: =SUM(E9:O9) -> 27 | G9: 7 | H9: 18 | J9: 2
B10: Capacitaciones | C10: 0 | D10: =SUM(E10:O10) -> 0
B11: Charlas | C11: 9 | D11: =SUM(E11:O11) -> 1 | I11: 1
B12: Talleres | C12: 0 | D12: =SUM(E12:O12) -> 0
B13: Sensibilización | C13: 0 | D13: =SUM(E13:O13) -> 0
B14: Actividades deportivas | C14: 0 | D14: =SUM(E14:O14) -> 0
B15: Cine en mi Barrio | C15: 0 | D15: =SUM(E15:O15) -> 0
B16: Cívico-policial | C16: 0 | D16: =SUM(E16:O16) -> 0
B17: Actividades culturales | C17: 0 | D17: =SUM(E17:O17) -> 0
B18: Ferias | C18: 0 | D18: =SUM(E18:O18) -> 0
B19: Stand informativo | C19: 0 | D19: =SUM(E19:O19) -> 0
B20: Visitas | C20: 56 | D20: =SUM(E20:O20) -> 21 | E20: 8 | G20: 7 | H20: 6
B21: Recuperación del espacio público | C21: 0 | D21: =SUM(E21:O21) -> 0
B22: Convocatoria de Mesas Locales | C22: 5 | D22: =SUM(E22:O22) -> 5 | F22: 4 | G22: 1
B23: Exposición Informe Territorial ESS | C23: 5 | D23: =SUM(E23:O23) -> 4 | H23: 4
B24: Primera Sesión de Trabajo | C24: 5 | D24: =SUM(E24:O24) -> 4 | I24: 4
B25: Segunda Sesión - Conformación Secretaria Técnica | C25: 5 | D25: =SUM(E25:O25) -> 0
B26: Tercera Sesión | C26: 5 | D26: =SUM(E26:O26) -> 0
B27: Elaboracióin del Texto de la Política Local | C27: 1 | D27: =SUM(E27:O27) -> 0
B28: Revisión Técnica DPPP | C28: 1 | D28: =SUM(E28:O28) -> 0
B29: Revisión Area Legal Gobierno Local | C29: 1 | D29: =SUM(E29:O29) -> 0
B30: Incorporación de Observaciones | C30: 1 | D30: =SUM(E30:O30) -> 0
B31: Aval del Director Regional | C31: 1 | D31: =SUM(E31:O31) -> 0
B32: Presentación al Consejo Municipal | C32: 1 | D32: =SUM(E32:O32) -> 0
B33: Presentación ante la Comunidad por parte del Director Regional y Alcalde | C33: 1 | D33: =SUM(E33:O33) -> 0
C34: =SUM(C3:C33) -> 249 | D34: =SUM(D3:D33) -> 94
D35: =D34/C34 -> 0.37751004

Sheet D64 Carrillo
A1: PROGRAMA | B1: D64 CARRILLO | C1: META | D1: AVANCE | E1: ENERO | F1: FEBRERO | G1: MARZO | H1: ABRIL | I1: MAYO | J1: JUNIO | K1: JULIO | L1: AGOSTO | M1: SEPTIEMBRE | N1: OCTUBRE | O1: NOVIEMBRE | P1: DICIEMBRE
C2: 2026 | D2: Porcentual
A3: PSCC | B3: Cuatro actividades de recuperación de espacios públicos, con las comunidades integradas al Programa de Seguridad Comunitaria, que se localicen, en los distritos que contemplan las área georreferenciadas del informe territorial de la Estrategia Sembremos Seguridad 2024, dos por año, una por semestre. | C3: 2 | D3: =SUM(E3:P3) -> 0
A4: GREAT/MPAS/DARE | B4: Realizar 4 procesos formativos (Cursos de la oferta de los programas DARE - GREAT - MPAS) en Centros Educativos, 2 por año, dentro de los distritos que contemplan las áreas georreferenciadas del informe territorial de la Estrategia Sembremos Seguridad 2024. Un curso diferente por semestre, un nivel completo. En caso de no contar con instructor acreditado DARE, se puede cumplir la meta con las charlas de Habilidades para la vida DARE, con el aval del Coordinador Nacional. | C4: 2 | D4: =SUM(E4:P4) -> 0 | E4: 0 | F4: 0 | G4: 0 | H4: 0
A5: DARE | B5: Cubrir 4 procesos formativos en Centros Educativos (dos por año) ubicados dentro de los distritos que contemplan las áreas georreferenciadas del informe territorial de la Estrategia Sembremos Seguridad 2024, con los cursos del Programa DARE: , Curso primaria. Curso Secundaria; un nivel completo por centro educativo, por semestre. En caso de no contar con instructor acreditado, se puede cumplir la meta con las charlas de Habilidades para la vida DARE, con el aval del Coordinador Nacional. | C5: 2 | D5: =SUM(E5:P5) -> 1 | E5: 0 | F5: 0 | G5: 0 | H5: 1
A6: PSCC | B6: Cuatro capacitaciones, en el tema de "Denuncia a búnkers", dirigidas a las comunidades integradas al Programa de Seguridad Comunitaria que se localicen, en los distritos que contemplan las área georreferenciadas del informe territorial de la Estrategia Sembremos Seguridad 2024, dos por año, una por semestre. | C6: 2 | D6: =SUM(E6:P6) -> 0
A7: PSCC | B7: Dos estrategias de divulgación (Por medio de brochures, post o imágenes en redes sociales) en el tema del procedimiento para realizar una "Denuncia de búnkers" dirigidas a las comunidades integradas al Programa de Seguridad Comunitaria que se localicen, en los distritos que contemplan las área georreferenciadas del informe territorial de la Estrategia Sembremos Seguridad 2024, una por año. | C7: 1 | D7: =SUM(E7:P7) -> 0
A8: PLAN DE POLITICA LOCAL E IMPLEMENTACIÓN DE LA POLITICA LOCAL DE SEGURIDAD | B8: Conformación Comité | C8: 1 | D8: =SUM(E8:O8) -> 0
B9: Conformación de Comercio | C9: 1 | D9: =SUM(E9:O9) -> 0
B10: Reuniones-Jefaturas | C10: 76 | D10: =SUM(E10:O10) -> 27 | E10: 5 | F10: 6 | H10: 6 | I10: 6 | J10: 4
B11: Campañas de divulgación | C11: 37 | D11: =SUM(E11:O11) -> 13 | E11: 7 | F11: 6
B12: Capacitaciones | C12: 0 | D12: =SUM(E12:O12) -> 0
B13: Charlas | C13: 2 | D13: =SUM(E13:O13) -> 1 | J13: 1
B14: Talleres | C14: 0 | D14: =SUM(E14:O14) -> 0
B15: Sensibilización | C15: 19 | D15: =SUM(E15:O15) -> 19 | H15: 6 | I15: 6 | J15: 7
B16: Actividades deportivas | C16: 0 | D16: =SUM(E16:O16) -> 0
B17: Cine en mi Barrio | C17: 1 | D17: =SUM(E17:O17) -> 0
B18: Cívico-policial | C18: 1 | D18: =SUM(E18:O18) -> 0
B19: Actividades culturales | C19: 0 | D19: =SUM(E19:O19) -> 0
B20: Ferias | C20: 0 | D20: =SUM(E20:O20) -> 0
B21: Stand informativo | C21: 1 | D21: =SUM(E21:O21) -> 1 | H21: 1
B22: Visitas | C22: 110 | D22: =SUM(E22:O22) -> 24 | E22: 6 | F22: 6 | H22: 6 | I22: 6
B23: Recuperación del espacio público | C23: 1 | D23: =SUM(E23:O23) -> 1 | H23: 1
B24: Convocatoria de Mesas Locales | C24: 4 | D24: =SUM(E24:O24) -> 4 | G24: 4
B25: Exposición Informe Territorial ESS | C25: 4 | D25: =SUM(E25:O25) -> 4 | H25: 4
B26: Primera Sesión de Trabajo | C26: 4 | D26: =SUM(E26:O26) -> 3 | I26: 1 | J26: 2
B27: Segunda Sesión - Conformación Secretaria Técnica | C27: 4 | D27: =SUM(E27:O27) -> 0
B28: Tercera Sesión | C28: 4 | D28: =SUM(E28:O28) -> 0
B29: Elaboracióin del Texto de la Política Local | C29: 1 | D29: =SUM(E29:O29) -> 0
B30: Revisión Técnica DPPP | C30: 1 | D30: =SUM(E30:O30) -> 0
B31: Revisión Area Legal Gobierno Local | C31: 1 | D31: =SUM(E31:O31) -> 0
B32: Incorporación de Observaciones | C32: 1 | D32: =SUM(E32:O32) -> 0
B33: Aval del Director Regional | C33: 1 | D33: =SUM(E33:O33) -> 0
B34: Presentación al Consejo Municipal | C34: 1 | D34: =SUM(E34:O34) -> 0
B35: Presentación ante la Comunidad por parte del Director Regional y Alcalde | C35: 1 | D35: =SUM(E35:O35) -> 0
C36: =SUM(C3:C35) -> 286 | D36: =SUM(D3:D35) -> 98
D37: =D36/C36 -> 0.34265734

Sheet D65 Cañas
A1: PROGRAMA | B1: D65 CAÑAS | C1: META | D1: AVANCE | E1: ENERO | F1: FEBRERO | G1: MARZO | H1: ABRIL | I1: MAYO | J1: JUNIO | K1: JULIO | L1: AGOSTO | M1: SEPTIEMBRE | N1: OCTUBRE | O1: NOVIEMBRE | P1: DICIEMBRE
C2: 2026 | D2: Porcentual
A3: PSCC | B3: Cuatro actividades de recuperación de espacios públicos, con las comunidades integradas al Programa de Seguridad Comunitaria, que se localicen, en los distritos que contemplan las área georreferenciadas del informe territorial de la Estrategia Sembremos Seguridad 2024, dos por año, una por semestre. | C3: 2 | D3: =SUM(E3:P3) -> 0
A4: GREAT/MPAS/DARE | B4: Realizar 4 procesos formativos (Cursos de la oferta de los programas DARE - GREAT - MPAS) en Centros Educativos, 2 por año, dentro de los distritos que contemplan las áreas georreferenciadas del informe territorial de la Estrategia Sembremos Seguridad 2024. Un curso diferente por semestre, un nivel completo. En caso de no contar con instructor acreditado DARE, se puede cumplir la meta con las charlas de Habilidades para la vida DARE, con el aval del Coordinador Nacional. | C4: 2 | D4: =SUM(E4:P4) -> 0 | E4: 0 | F4: 0 | G4: 0 | H4: 0
A5: DARE | B5: Cubrir 2 procesos formativos en Centros Educativos (dos por año) ubicados dentro de los distritos que contemplan las áreas georreferenciadas del informe territorial de la Estrategia Sembremos Seguridad 2024, con los cursos del Programa DARE: , Curso primaria. Curso Secundaria; un nivel completo por centro educativo, por semestre. En caso de no contar con instructor acreditado, se puede cumplir la meta con las charlas de Habilidades para la vida DARE, con el aval del Coordinador Nacional. | C5: 1 | D5: =SUM(E5:P5) -> 1 | E5: 0 | F5: 0 | G5: 0 | H5: 1
A6: PLAN DE POLITICA LOCAL E IMPLEMENTACIÓN DE LA POLITICA LOCAL DE SEGURIDAD | B6: Conformación Comité | C6: 3 | D6: =SUM(E6:O6) -> 3 | I6: 3
B7: Conformación de Comercio | C7: 3 | D7: =SUM(E7:O7) -> 0
B8: Reuniones-Jefaturas | C8: 80 | D8: =SUM(E8:O8) -> 27 | E8: 9 | F8: 7 | G8: 1 | H8: 7 | I8: 3
B9: Campañas de divulgación | C9: 80 | D9: =SUM(E9:O9) -> 28 | G9: 16 | H9: 12
B10: Capacitaciones | C10: 2 | D10: =SUM(E10:O10) -> 0
B11: Charlas | C11: 12 | D11: =SUM(E11:O11) -> 0
B12: Talleres | C12: 0 | D12: =SUM(E12:O12) -> 0
B13: Sensibilización | C13: 56 | D13: =SUM(E13:O13) -> 29 | G13: 7 | H13: 14 | I13: 8
B14: Actividades deportivas | C14: 0 | D14: =SUM(E14:O14) -> 0
B15: Cine en mi Barrio | C15: 0 | D15: =SUM(E15:O15) -> 0
B16: Cívico-policial | C16: 0 | D16: =SUM(E16:O16) -> 0
B17: Actividades culturales | C17: 0 | D17: =SUM(E17:O17) -> 0
B18: Ferias | C18: 0 | D18: =SUM(E18:O18) -> 0
B19: Stand informativo | C19: 3 | D19: =SUM(E19:O19) -> 1 | I19: 1
B20: Visitas | C20: 212 | D20: =SUM(E20:O20) -> 62 | E20: 1 | F20: 7 | G20: 15 | H20: 17 | I20: 7 | J20: 15
B21: Recuperación del espacio público | C21: 3 | D21: =SUM(E21:O21) -> 2 | G21: 1 | H21: 1
B22: Convocatoria de Mesas Locales | C22: 5 | D22: =SUM(E22:O22) -> 3 | G22: 3
B23: Exposición Informe Territorial ESS | C23: 5 | D23: =SUM(E23:O23) -> 5 | H23: 5
B24: Primera Sesión de Trabajo | C24: 5 | D24: =SUM(E24:O24) -> 5 | I24: 5
B25: Segunda Sesión - Conformación Secretaria Técnica | C25: 5 | D25: =SUM(E25:O25) -> 0
B26: Tercera Sesión | C26: 5 | D26: =SUM(E26:O26) -> 0
B27: Elaboracióin del Texto de la Política Local | C27: 1 | D27: =SUM(E27:O27) -> 0
B28: Revisión Técnica DPPP | C28: 1 | D28: =SUM(E28:O28) -> 0
B29: Revisión Area Legal Gobierno Local | C29: 1 | D29: =SUM(E29:O29) -> 0
B30: Incorporación de Observaciones | C30: 1 | D30: =SUM(E30:O30) -> 0
B31: Aval del Director Regional | C31: 1 | D31: =SUM(E31:O31) -> 0
B32: Presentación al Consejo Municipal | C32: 1 | D32: =SUM(E32:O32) -> 0
B33: Presentación ante la Comunidad por parte del Director Regional y Alcalde | C33: 1 | D33: =SUM(E33:O33) -> 0
C34: =SUM(C3:C33) -> 491 | D34: =SUM(D3:D33) -> 166
D35: =D34/C34 -> 0.33808554

Sheet D66 Abangares
A1: PROGRAMA | B1: D66 ABANGARES | C1: META | D1: AVANCE | E1: ENERO | F1: FEBRERO | G1: MARZO | H1: ABRIL | I1: MAYO | J1: JUNIO | K1: JULIO | L1: AGOSTO | M1: SEPTIEMBRE | N1: OCTUBRE | O1: NOVIEMBRE | P1: DICIEMBRE
C2: 2026 | D2: Porcentual
A3: PSCC | B3: Dos actividades de recuperación de espacios públicos, con las comunidades integradas al Programa de Seguridad Comunitaria, que se localicen, en los distritos que contemplan las área georreferenciadas del informe territorial de la Estrategia Sembremos Seguridad 2024, una por año. | C3: 1 | D3: =SUM(E3:P3) -> 1 | J3: 1
A4: GREAT/MPAS/DARE | B4: Realizar 4 procesos formativos (Cursos de la oferta de los programas DARE - GREAT - MPAS) en Centros Educativos, 2 por año, dentro de los distritos que contemplan las áreas georreferenciadas del informe territorial de la Estrategia Sembremos Seguridad 2024. Un curso diferente por semestre, un nivel completo. En caso de no contar con instructor acreditado DARE, se puede cumplir la meta con las charlas de Habilidades para la vida DARE, con el aval del Coordinador Nacional. | C4: 2 | D4: =SUM(E4:P4) -> 0 | E4: 0 | F4: 0 | G4: 0 | H4: 0
A5: DARE | B5: Cubrir 2 procesos formativos en Centros Educativos (uno por año) ubicados dentro de los distritos que contemplan las áreas georreferenciadas del informe territorial de la Estrategia Sembremos Seguridad 2024, con los cursos del Programa DARE: Curso primaria. Curso Secundaria; un nivel completo por centro educativo, por semestre. En caso de no contar con instructor acreditado, se puede cumplir la meta con las charlas de Habilidades para la vida DARE, con el aval del Coordinador Nacional. | C5: 2 | D5: =SUM(E5:P5) -> 2 | E5: 0 | F5: 0 | G5: 0 | H5: 1 | J5: 1
A6: PSCC | B6: Cuatro capacitaciones, en el tema de Cultura Preventiva, dirigidas a las comunidades integradas al Programa de Seguridad Comunitaria que se localicen, en los distritos que contemplan las área georreferenciadas del informe territorial de la Estrategia Sembremos Seguridad 2024, una por año. | C6: 2 | D6: =SUM(E6:P6) -> 2 | E6: 1 | H6: 1
A7: PSCC | B7: Cuatro estrategias de divulgación (Por medio de brochures, post o imágenes en redes sociales) en el tema del procedimiento para realizar una "Denuncia en caso de Robo de Vehículos" dirigidas a las comunidades integradas al Programa de Seguridad Comunitaria que se localicen, en los distritos que contemplan las área georreferenciadas del informe territorial de la Estrategia Sembremos Seguridad 2024, una por año. | C7: 2 | D7: =SUM(E7:P7) -> 2 | E7: 1 | H7: 1
A8: PSCC | B8: Dos estrategias de divulgación (Por medio de brochures, post o imágenes en redes sociales) en el tema del procedimiento para realizar una "Denuncia de ventas de drogas" diseñadas por la Estrategia de divulgación de la Dirección de Programas Policiales Preventivos dirigidas a las comunidades integradas al Programa de Seguridad Comunitaria que se localicen, en los distritos que contemplan las área georreferenciadas del informe territorial de la Estrategia Sembremos Seguridad 2024, una por año. | C8: 1 | D8: =SUM(E8:P8) -> 1 | E8: 1
A9: PSCC | B9: Cuatro capacitaciones, en el tema de "Denuncia a búnkers", dirigidas a las comunidades integradas al Programa de Seguridad Comunitaria que se localicen, en los distritos que contemplan las área georreferenciadas del informe territorial de la Estrategia Sembremos Seguridad 2024, dos por año, una por semestre. | C9: 2 | D9: =SUM(E9:P9) -> 2 | E9: 1 | H9: 1
A10: PSCC | B10: Dos estrategias de divulgación (Por medio de brochures, post o imágenes en redes sociales) diseñadas por la Estrategia de divulgación de la Dirección de Programas Policiales Preventivos, en el tema del procedimiento para realizar una "Denuncia de búnkers" dirigidas a las comunidades integradas al Programa de Seguridad Comunitaria que se localicen, en los distritos que contemplan las área georreferenciadas del informe territorial de la Estrategia Sembremos Seguridad 2024, una por año. | C10: 1 | D10: =SUM(E10:P10) -> 2 | E10: 1 | H10: 1
A11: PSCC | B11: Dos estrategias de divulgación (Por medio de brochures, post o imágenes en redes sociales) diseñadas por la Estrategia de divulgación de la Dirección de Programas Policiales Preventivos, en el tema del procedimiento para realizar una "Denuncia de receptación" dirigidas a las comunidades integradas al Programa de Seguridad Comunitaria que se localicen, en los distritos que contemplan las áreas georreferenciadas del informe territorial de la Estrategia Sembremos Seguridad 2024, una por año. | C11: 1 | D11: =SUM(E11:P11) -> 1 | E11: 1
A12: PLAN DE POLITICA LOCAL E IMPLEMENTACIÓN DE LA POLITICA LOCAL DE SEGURIDAD | B12: Conformación Comité | C12: 1 | D12: =SUM(E12:O12) -> 0
B13: Conformación de Comercio | C13: 1 | D13: =SUM(E13:O13) -> 0
B14: Reuniones-Jefaturas | C14: 20 | D14: =SUM(E14:O14) -> 6 | E14: 1 | F14: 2 | H14: 1 | I14: 2
B15: Campañas de divulgación | C15: 156 | D15: =SUM(E15:O15) -> 38 | G15: 38
B16: Capacitaciones | C16: 0 | D16: =SUM(E16:O16) -> 0
B17: Charlas | C17: 30 | D17: =SUM(E17:O17) -> 0
B18: Talleres | C18: 0 | D18: =SUM(E18:O18) -> 0
B19: Sensibilización | C19: 0 | D19: =SUM(E19:O19) -> 0
B20: Actividades deportivas | C20: 0 | D20: =SUM(E20:O20) -> 0
B21: Cine en mi Barrio | C21: 0 | D21: =SUM(E21:O21) -> 0
B22: Cívico-policial | C22: 0 | D22: =SUM(E22:O22) -> 0
B23: Actividades culturales | C23: 0 | D23: =SUM(E23:O23) -> 0
B24: Ferias | C24: 0 | D24: =SUM(E24:O24) -> 0
B25: Stand informativo | C25: 0 | D25: =SUM(E25:O25) -> 0
B26: Visitas | C26: 136 | D26: =SUM(E26:O26) -> 66 | E26: 33 | H26: 33
B27: Recuperación del espacio público | C27: 0 | D27: =SUM(E27:O27) -> 0
B28: Convocatoria de Mesas Locales | C28: 4 | D28: =SUM(E28:O28) -> 4 | F28: 2 | H28: 2
B29: Exposición Informe Territorial ESS | C29: 4 | D29: =SUM(E29:O29) -> 2 | H29: 2
B30: Primera Sesión de Trabajo | C30: 4 | D30: =SUM(E30:O30) -> 2 | H30: 2
B31: Segunda Sesión - Conformación Secretaria Técnica | C31: 4 | D31: =SUM(E31:O31) -> 1 | I31: 1
B32: Tercera Sesión | C32: 4 | D32: =SUM(E32:O32) -> 0
B33: Elaboracióin del Texto de la Política Local | C33: 1 | D33: =SUM(E33:O33) -> 0
B34: Revisión Técnica DPPP | C34: 1 | D34: =SUM(E34:O34) -> 0
B35: Revisión Area Legal Gobierno Local | C35: 1 | D35: =SUM(E35:O35) -> 0
B36: Incorporación de Observaciones | C36: 1 | D36: =SUM(E36:O36) -> 0
B37: Aval del Director Regional | C37: 1 | D37: =SUM(E37:O37) -> 0
B38: Presentación al Consejo Municipal | C38: 1 | D38: =SUM(E38:O38) -> 0
B39: Presentación ante la Comunidad por parte del Director Regional y Alcalde | C39: 1 | D39: =SUM(E39:O39) -> 0
C40: =SUM(C3:C39) -> 385 | D40: =SUM(D3:D39) -> 132
...

Sheet D67 Tilarán
A1: PROGRAMA | B1: D67 TILARÁN | C1: META | D1: AVANCE | E1: ENERO | F1: FEBRERO | G1: MARZO | H1: ABRIL | I1: MAYO | J1: JUNIO | K1: JULIO | L1: AGOSTO | M1: SEPTIEMBRE | N1: OCTUBRE | O1: NOVIEMBRE | P1: DICIEMBRE
C2: 2026 | D2: Porcentual
A3: GREAT/MPAS/DARE | B3: Realizar 4 procesos formativos (Cursos de la oferta de los programas DARE - GREAT - MPAS) en Centros Educativos, 2 por año, dentro de los distritos que contemplan las áreas georreferenciadas del informe territorial de la Estrategia Sembremos Seguridad 2024. Un curso diferente por semestre, un nivel completo. En caso de no contar con instructor acreditado DARE, se puede cumplir la meta con las charlas de Habilidades para la vida DARE, con el aval del Coordinador Nacional. | C3: 2 | D3: =SUM(E3:P3) -> 1 | E3: 0 | F3: 0 | G3: 0 | H3: 1
A4: PLAN DE POLITICA LOCAL E IMPLEMENTACIÓN DE LA POLITICA LOCAL DE SEGURIDAD | B4: Conformación Comité | C4: 2 | D4: =SUM(E4:O4) -> 0
B5: Conformación de Comercio | C5: 3 | D5: =SUM(E5:O5) -> 3 | G5: 1 | H5: 2
B6: Reuniones-Jefaturas | C6: 24 | D6: =SUM(E6:O6) -> 9 | F6: 3 | G6: 1 | H6: 3 | I6: 2
B7: Campañas de divulgación | C7: 57 | D7: =SUM(E7:O7) -> 6 | G7: 6
B8: Capacitaciones | C8: 0 | D8: =SUM(E8:O8) -> 0
B9: Charlas | C9: 4 | D9: =SUM(E9:O9) -> 0
B10: Talleres | C10: 0 | D10: =SUM(E10:O10) -> 0
B11: Sensibilización | C11: 6 | D11: =SUM(E11:O11) -> 3 | H11: 3
B12: Actividades deportivas | C12: 0 | D12: =SUM(E12:O12) -> 0
B13: Cine en mi Barrio | C13: 2 | D13: =SUM(E13:O13) -> 0
B14: Cívico-policial | C14: 2 | D14: =SUM(E14:O14) -> 0
B15: Actividades culturales | C15: 0 | D15: =SUM(E15:O15) -> 0
B16: Ferias | C16: 0 | D16: =SUM(E16:O16) -> 0
B17: Stand informativo | C17: 0 | D17: =SUM(E17:O17) -> 0
B18: Visitas | C18: 71 | D18: =SUM(E18:O18) -> 22 | F18: 9 | G18: 1 | H18: 6 | I18: 6
B19: Recuperación del espacio público | C19: 2 | D19: =SUM(E19:O19) -> 0
B20: Convocatoria de Mesas Locales | C20: 8 | D20: =SUM(E20:O20) -> 6 | F20: 4 | G20: 2
B21: Exposición Informe Territorial ESS | C21: 8 | D21: =SUM(E21:O21) -> 2 | H21: 2
B22: Primera Sesión de Trabajo | C22: 8 | D22: =SUM(E22:O22) -> 2 | I22: 2
B23: Segunda Sesión - Conformación Secretaria Técnica | C23: 8 | D23: =SUM(E23:O23) -> 1 | J23: 1
B24: Tercera Sesión | C24: 8 | D24: =SUM(E24:O24) -> 0
B25: Elaboracióin del Texto de la Política Local | C25: 1 | D25: =SUM(E25:O25) -> 0
B26: Revisión Técnica DPPP | C26: 1 | D26: =SUM(E26:O26) -> 0
B27: Revisión Area Legal Gobierno Local | C27: 1 | D27: =SUM(E27:O27) -> 0
B28: Incorporación de Observaciones | C28: 1 | D28: =SUM(E28:O28) -> 0
B29: Aval del Director Regional | C29: 1 | D29: =SUM(E29:O29) -> 0
B30: Presentación al Consejo Municipal | C30: 1 | D30: =SUM(E30:O30) -> 0
B31: Presentación ante la Comunidad por parte del Director Regional y Alcalde | C31: 1 | D31: =SUM(E31:O31) -> 0
C32: =SUM(C3:C31) -> 222 | D32: =SUM(D3:D31) -> 55
D33: =D32/C32 -> 0.24774775

Sheet D68 Nandayure
A1: PROGRAMA | B1: D68 NANDAYURE | C1: META | D1: AVANCE | E1: ENERO | F1: FEBRERO | G1: MARZO | H1: ABRIL | I1: MAYO | J1: JUNIO | K1: JULIO | L1: AGOSTO | M1: SEPTIEMBRE | N1: OCTUBRE | O1: NOVIEMBRE | P1: DICIEMBRE
C2: 2026 | D2: Porcentual
A3: PSCC | B3: Cuatro actividades de recuperación de espacios públicos, con las comunidades integradas al Programa de Seguridad Comunitaria, que se localicen, en los distritos que contemplan las área georreferenciadas del informe territorial de la Estrategia Sembremos Seguridad 2024, dos por año, una por semestre. | C3: 2 | D3: =SUM(E3:P3) -> 0
A4: GREAT/MPAS/DARE | B4: Realizar 4 procesos formativos (Cursos de la oferta de los programas DARE - GREAT - MPAS) en Centros Educativos, 2 por año, dentro de los distritos que contemplan las áreas georreferenciadas del informe territorial de la Estrategia Sembremos Seguridad 2024. Un curso diferente por semestre, un nivel completo. En caso de no contar con instructor acreditado DARE, se puede cumplir la meta con las charlas de Habilidades para la vida DARE, con el aval del Coordinador Nacional. | C4: 2 | D4: =SUM(E4:P4) -> 0 | E4: 0 | F4: 0 | G4: 0 | H4: 0
A5: DARE | B5: Cubrir 2 procesos formativos en Centros Educativos (uno por año) ubicados dentro de los distritos que contemplan las áreas georreferenciadas del informe territorial de la Estrategia Sembremos Seguridad 2024, con los cursos del Programa DARE: Curso primaria. Curso Secundaria; un nivel completo por centro educativo, por semestre. En caso de no contar con instructor acreditado, se puede cumplir la meta con las charlas de Habilidades para la vida DARE, con el aval del Coordinador Nacional. | C5: 2 | D5: =SUM(E5:P5) -> 1 | E5: 0 | F5: 0 | G5: 0 | H5: 1
A6: PLAN DE POLITICA LOCAL E IMPLEMENTACIÓN DE LA POLITICA LOCAL DE SEGURIDAD | B6: Conformación Comité | C6: 3 | D6: =SUM(E6:O6) -> 0
B7: Conformación de Comercio | C7: 3 | D7: =SUM(E7:O7) -> 1 | I7: 1
B8: Reuniones-Jefaturas | C8: 27 | D8: =SUM(E8:O8) -> 9 | F8: 1 | G8: 1 | H8: 3 | I8: 4
B9: Campañas de divulgación | C9: 40 | D9: =SUM(E9:O9) -> 19 | G9: 9 | H9: 10
B10: Capacitaciones | C10: 0 | D10: =SUM(E10:O10) -> 0
B11: Charlas | C11: 10 | D11: =SUM(E11:O11) -> 0
B12: Talleres | C12: 1 | D12: =SUM(E12:O12) -> 0
B13: Sensibilización | C13: 1 | D13: =SUM(E13:O13) -> 0
B14: Actividades deportivas | C14: 2 | D14: =SUM(E14:O14) -> 1 | H14: 1
B15: Cine en mi Barrio | C15: 1 | D15: =SUM(E15:O15) -> 0
B16: Cívico-policial | C16: 1 | D16: =SUM(E16:O16) -> 0
B17: Actividades culturales | C17: 1 | D17: =SUM(E17:O17) -> 0
B18: Ferias | C18: 0 | D18: =SUM(E18:O18) -> 0
B19: Stand informativo | C19: 1 | D19: =SUM(E19:O19) -> 0
B20: Visitas | C20: 24 | D20: =SUM(E20:O20) -> 15 | E20: 3 | F20: 5 | G20: 2 | H20: 1 | I20: 4
B21: Recuperación del espacio público | C21: 3 | D21: =SUM(E21:O21) -> 0
B22: Convocatoria de Mesas Locales | C22: 6 | D22: =SUM(E22:O22) -> 6 | F22: 6
B23: Exposición Informe Territorial ESS | C23: 6 | D23: =SUM(E23:O23) -> 6 | H23: 6
B24: Primera Sesión de Trabajo | C24: 6 | D24: =SUM(E24:O24) -> 4 | I24: 4
B25: Segunda Sesión - Conformación Secretaria Técnica | C25: 6 | D25: =SUM(E25:O25) -> 2 | J25: 2
B26: Tercera Sesión | C26: 6 | D26: =SUM(E26:O26) -> 0
B27: Elaboracióin del Texto de la Política Local | C27: 1 | D27: =SUM(E27:O27) -> 0
B28: Revisión Técnica DPPP | C28: 1 | D28: =SUM(E28:O28) -> 0
B29: Revisión Area Legal Gobierno Local | C29: 1 | D29: =SUM(E29:O29) -> 0
B30: Incorporación de Observaciones | C30: 1 | D30: =SUM(E30:O30) -> 0
B31: Aval del Director Regional | C31: 1 | D31: =SUM(E31:O31) -> 0
B32: Presentación al Consejo Municipal | C32: 1 | D32: =SUM(E32:O32) -> 0
B33: Presentación ante la Comunidad por parte del Director Regional y Alcalde | C33: 1 | D33: =SUM(E33:O33) -> 0
C34: =SUM(C3:C33) -> 161 | D34: =SUM(D3:D33) -> 64
D35: =D34/C34 -> 0.39751553

Sheet D69 Hojancha
A1: PROGRAMA | B1: D69 HOJANCHA | C1: META | D1: AVANCE | E1: ENERO | F1: FEBRERO | G1: MARZO | H1: ABRIL | I1: MAYO | J1: JUNIO | K1: JULIO | L1: AGOSTO | M1: SEPTIEMBRE | N1: OCTUBRE | O1: NOVIEMBRE | P1: DICIEMBRE
C2: 2026 | D2: Porcentual
A3: GREAT/MPAS/DARE | B3: Realizar 4 procesos formativos (Cursos de la oferta de los programas DARE - GREAT - MPAS) en Centros Educativos, 2 por año, dentro de los distritos que contemplan las áreas georreferenciadas del informe territorial de la Estrategia Sembremos Seguridad 2024. Un curso diferente por semestre, un nivel completo. En caso de no contar con instructor acreditado DARE, se puede cumplir la meta con las charlas de Habilidades para la vida DARE, con el aval del Coordinador Nacional. | C3: 2 | D3: =SUM(E3:P3) -> 0 | E3: 0 | F3: 0 | G3: 0 | H3: 0
A4: DARE | B4: Cubrir 4 procesos formativos en Centros Educativos (dos por año) ubicados dentro de los distritos que contemplan las áreas georreferenciadas del informe territorial de la Estrategia Sembremos Seguridad 2024, con los cursos del Programa DARE: , Curso primaria. Curso Secundaria; un nivel completo por centro educativo, por semestre. En caso de no contar con instructor acreditado, se puede cumplir la meta con las charlas de Habilidades para la vida DARE, con el aval del Coordinador Nacional. | C4: 2 | D4: =SUM(E4:P4) -> 1 | E4: 0 | F4: 0 | G4: 0 | H4: 0 | J4: 1
A5: PSCC | B5: Cuatro capacitaciones, en el tema de "Denuncia a búnkers", dirigidas a las comunidades integradas al Programa de Seguridad Comunitaria que se localicen, en los distritos que contemplan las área georreferenciadas del informe territorial de la Estrategia Sembremos Seguridad 2024, dos por año, una por semestre. | C5: 2 | D5: =SUM(E5:P5) -> 1 | G5: 1
A6: PSCC | B6: Dos estrategias de divulgación (Por medio de brochures, post o imágenes en redes sociales) en el tema del procedimiento para realizar una "Denuncia de búnkers" dirigidas a las comunidades integradas al Programa de Seguridad Comunitaria que se localicen, en los distritos que contemplan las área georreferenciadas del informe territorial de la Estrategia Sembremos Seguridad 2024, una por año. | C6: 2 | D6: =SUM(E6:P6) -> 0
A7: PSCC | B7: Dos estrategias de divulgación (Por medio de brochures, post o imágenes en redes sociales) en el tema del procedimiento para realizar una "Denuncia de ventas de drogas" diseñadas por la Estrategia de divulgación de la Dirección de Programas Policiales Preventivos dirigidas a las comunidades integradas al Programa de Seguridad Comunitaria que se localicen, en los distritos que contemplan las área georreferenciadas del informe territorial de la Estrategia Sembremos Seguridad 2024, una por año. | C7: 1 | D7: =SUM(E7:P7) -> 1 | F7: 1
A8: PLAN DE POLITICA LOCAL E IMPLEMENTACIÓN DE LA POLITICA LOCAL DE SEGURIDAD | B8: Conformación Comité | C8: 2 | D8: =SUM(E8:O8) -> 1 | H8: 1
B9: Conformación de Comercio | C9: 3 | D9: =SUM(E9:O9) -> 0
B10: Reuniones-Jefaturas | C10: 80 | D10: =SUM(E10:O10) -> 37 | E10: 2 | F10: 12 | G10: 4 | H10: 8 | I10: 11
B11: Campañas de divulgación | C11: 39 | D11: =SUM(E11:O11) -> 17 | G11: 2 | H11: 15
B12: Capacitaciones | C12: 2 | D12: =SUM(E12:O12) -> 0
B13: Charlas | C13: 7 | D13: =SUM(E13:O13) -> 0
B14: Talleres | C14: 0 | D14: =SUM(E14:O14) -> 0
B15: Sensibilización | C15: 0 | D15: =SUM(E15:O15) -> 0
B16: Actividades deportivas | C16: 0 | D16: =SUM(E16:O16) -> 0
B17: Cine en mi Barrio | C17: 0 | D17: =SUM(E17:O17) -> 0
B18: Cívico-policial | C18: 0 | D18: =SUM(E18:O18) -> 0
B19: Actividades culturales | C19: 1 | D19: =SUM(E19:O19) -> 0
B20: Ferias | C20: 0 | D20: =SUM(E20:O20) -> 0
B21: Stand informativo | C21: 0 | D21: =SUM(E21:O21) -> 0
B22: Visitas | C22: 67 | D22: =SUM(E22:O22) -> 35 | E22: 5 | F22: 11 | G22: 8 | H22: 4 | I22: 4 | J22: 3
B23: Recuperación del espacio público | C23: 0 | D23: =SUM(E23:O23) -> 0
B24: Convocatoria de Mesas Locales | C24: 5 | D24: =SUM(E24:O24) -> 3 | G24: 3
B25: Exposición Informe Territorial ESS | C25: 5 | D25: =SUM(E25:O25) -> 5 | H25: 5
B26: Primera Sesión de Trabajo | C26: 5 | D26: =SUM(E26:O26) -> 5 | I26: 5
B27: Segunda Sesión - Conformación Secretaria Técnica | C27: 5 | D27: =SUM(E27:O27) -> 0
B28: Tercera Sesión | C28: 5 | D28: =SUM(E28:O28) -> 0
B29: Elaboracióin del Texto de la Política Local | C29: 1 | D29: =SUM(E29:O29) -> 0
B30: Revisión Técnica DPPP | C30: 1 | D30: =SUM(E30:O30) -> 0
B31: Revisión Area Legal Gobierno Local | C31: 1 | D31: =SUM(E31:O31) -> 0
B32: Incorporación de Observaciones | C32: 1 | D32: =SUM(E32:O32) -> 0
B33: Aval del Director Regional | C33: 1 | D33: =SUM(E33:O33) -> 0
B34: Presentación al Consejo Municipal | C34: 1 | D34: =SUM(E34:O34) -> 0
B35: Presentación ante la Comunidad por parte del Director Regional y Alcalde | C35: 1 | D35: =SUM(E35:O35) -> 0
C36: =SUM(C3:C35) -> 242 | D36: =SUM(D3:D35) -> 106
D37: =D36/C36 -> 0.43801653

Sheet D70 La Cruz
A1: PROGRAMA | B1: D70 LA CRUZ | C1: META | D1: AVANCE | E1: ENERO | F1: FEBRERO | G1: MARZO | H1: ABRIL | I1: MAYO | J1: JUNIO | K1: JULIO | L1: AGOSTO | M1: SEPTIEMBRE | N1: OCTUBRE | O1: NOVIEMBRE | P1: DICIEMBRE
C2: 2026 | D2: Porcentual
A3: PSCC | B3: Cuatro actividades de recuperación de espacios públicos, con las comunidades integradas al Programa de Seguridad Comunitaria, que se localicen, en los distritos que contemplan las área georreferenciadas del informe territorial de la Estrategia Sembremos Seguridad 2024, dos por año, una por semestre. | C3: 2 | D3: =SUM(E3:P3) -> 1 | G3: 1
A4: GREAT/MPAS/DARE | B4: Realizar 4 procesos formativos (Cursos de la oferta de los programas DARE - GREAT - MPAS) en Centros Educativos, 2 por año, dentro de los distritos que contemplan las áreas georreferenciadas del informe territorial de la Estrategia Sembremos Seguridad 2024. Un curso diferente por semestre, un nivel completo. En caso de no contar con instructor acreditado DARE, se puede cumplir la meta con las charlas de Habilidades para la vida DARE, con el aval del Coordinador Nacional. | C4: 2 | D4: =SUM(E4:P4) -> 2 | E4: 0 | F4: 0 | G4: 0 | H4: 1 | I4: 1
A5: DARE | B5: Cubrir 4 procesos formativos en Centros Educativos (dos por año) ubicados dentro de los distritos que contemplan las áreas georreferenciadas del informe territorial de la Estrategia Sembremos Seguridad 2024, con los cursos del Programa DARE: , Curso primaria. Curso Secundaria; un nivel completo por centro educativo, por semestre. En caso de no contar con instructor acreditado, se puede cumplir la meta con las charlas de Habilidades para la vida DARE, con el aval del Coordinador Nacional. | C5: 2 | D5: =SUM(E5:P5) -> 2 | E5: 0 | F5: 0 | G5: 0 | H5: 2
A6: PLAN DE POLITICA LOCAL E IMPLEMENTACIÓN DE LA POLITICA LOCAL DE SEGURIDAD | B6: Conformación Comité | C6: 1 | D6: =SUM(E6:O6) -> 0
B7: Conformación de Comercio | C7: 3 | D7: =SUM(E7:O7) -> 0
B8: Reuniones-Jefaturas | C8: 92 | D8: =SUM(E8:O8) -> 46 | E8: 8 | F8: 11 | G8: 4 | H8: 11 | I8: 8 | J8: 4
B9: Campañas de divulgación | C9: 95 | D9: =SUM(E9:O9) -> 54 | G9: 23 | H9: 31
B10: Capacitaciones | C10: 0 | D10: =SUM(E10:O10) -> 0
B11: Charlas | C11: 15 | D11: =SUM(E11:O11) -> 3 | G11: 2 | H11: 1
B12: Talleres | C12: 0 | D12: =SUM(E12:O12) -> 0
B13: Sensibilización | C13: 0 | D13: =SUM(E13:O13) -> 0
B14: Actividades deportivas | C14: 0 | D14: =SUM(E14:O14) -> 0
B15: Cine en mi Barrio | C15: 0 | D15: =SUM(E15:O15) -> 0
B16: Cívico-policial | C16: 0 | D16: =SUM(E16:O16) -> 0
B17: Actividades culturales | C17: 0 | D17: =SUM(E17:O17) -> 0
B18: Ferias | C18: 0 | D18: =SUM(E18:O18) -> 0
B19: Stand informativo | C19: 0 | D19: =SUM(E19:O19) -> 0
B20: Visitas | C20: 126 | D20: =SUM(E20:O20) -> 54 | E20: 36 | I20: 18
B21: Recuperación del espacio público | C21: 0 | D21: =SUM(E21:O21) -> 0
B22: Convocatoria de Mesas Locales | C22: 4 | D22: =SUM(E22:O22) -> 0
B23: Exposición Informe Territorial ESS | C23: 4 | D23: =SUM(E23:O23) -> 0
B24: Primera Sesión de Trabajo | C24: 4 | D24: =SUM(E24:O24) -> 0
B25: Segunda Sesión - Conformación Secretaria Técnica | C25: 4 | D25: =SUM(E25:O25) -> 0
B26: Tercera Sesión | C26: 4 | D26: =SUM(E26:O26) -> 0
B27: Elaboracióin del Texto de la Política Local | C27: 1 | D27: =SUM(E27:O27) -> 0
B28: Revisión Técnica DPPP | C28: 1 | D28: =SUM(E28:O28) -> 0
B29: Revisión Area Legal Gobierno Local | C29: 1 | D29: =SUM(E29:O29) -> 0
B30: Incorporación de Observaciones | C30: 1 | D30: =SUM(E30:O30) -> 0
B31: Aval del Director Regional | C31: 1 | D31: =SUM(E31:O31) -> 0
B32: Presentación al Consejo Municipal | C32: 1 | D32: =SUM(E32:O32) -> 0
B33: Presentación ante la Comunidad por parte del Director Regional y Alcalde | C33: 1 | D33: =SUM(E33:O33) -> 0
C34: =SUM(C3:C33) -> 365 | D34: =SUM(D3:D33) -> 162
D35: =D34/C34 -> 0.44383562

Sheet Total Región
A1: Delegación | C1: META | D1: AVANCE | E1: % AVANCE
A2: D60 | B2: LIBERIA | C2: ='D60 Liberia'!C37 -> 634 | D2: ='D60 Liberia'!D37 -> 210 | E2: =D2/C2 -> 0.33123028
A3: D61 | B3: NICOYA | C3: ='D61 Nicoya'!C36 -> 591 | D3: ='D61 Nicoya'!D36 -> 227 | E3: =D3/C3 -> 0.38409475
A4: D62 | B4: SANTA CRUZ | C4: ='D62 Santa Cruz'!C37 -> 374 | D4: ='D62 Santa Cruz'!D37 -> 176 | E4: =D4/C4 -> 0.47058824
A5: D63 | B5: BAGACES | C5: ='D63 Bagaces'!C34 -> 249 | D5: ='D63 Bagaces'!D34 -> 94 | E5: =D5/C5 -> 0.37751004
A6: D64 | B6: CARRILLO | C6: ='D64 Carrillo'!C36 -> 286 | D6: ='D64 Carrillo'!D36 -> 98 | E6: =D6/C6 -> 0.34265734
A7: D65 | B7: CAÑAS | C7: ='D65 Cañas'!C34 -> 491 | D7: ='D65 Cañas'!D34 -> 166 | E7: =D7/C7 -> 0.33808554
A8: D66 | B8: ABANGARES | C8: ='D66 Abangares'!C40 -> 385 | D8: ='D66 Abangares'!D40 -> 132 | E8: =D8/C8 -> 0.34285714
A9: D67 | B9: TILARÁN | C9: ='D67 Tilarán'!C32 -> 222 | D9: ='D67 Tilarán'!D32 -> 55 | E9: =D9/C9 -> 0.24774775
A10: D68 | B10: NANDAYURE | C10: ='D68 Nandayure'!C34 -> 161 | D10: ='D68 Nandayure'!D34 -> 64 | E10: =D10/C10 -> 0.39751553
A11: D69 | B11: HOJANCHA | C11: ='D69 Hojancha'!C36 -> 242 | D11: ='D69 Hojancha'!D36 -> 106 | E11: =D11/C11 -> 0.43801653
A12: D70 | B12: LA CRUZ | C12: ='D70 La Cruz'!C34 -> 365 | D12: ='D70 La Cruz'!D34 -> 162 | E12: =D12/C12 -> 0.44383562
B13: TOTALES | C13: =SUM(C2:C12) -> 4000 | D13: =SUM(D2:D12) -> 1490 | E13: =D13/C13 -> 0.3725
