Workbook
Name ABANG: [1]DAT2!#REF!
Name ABANG: [2]DAT2!#REF!
Name ABANG: [3]DAT2!#REF!
Name ABANG: [4]DAT2!#REF!
Name ABANG: [5]DAT2!#REF!
Name ABANG: [6]DAT2!#REF!
Name ABANG: [7]DAT2!#REF!
Name ABANG: [8]DAT2!#REF!
Name ABANG: [9]DAT2!#REF!
Name ACOS: [1]DAT2!#REF!
Name ACOS: [2]DAT2!#REF!
Name ACOS: [3]DAT2!#REF!
Name ACOS: [4]DAT2!#REF!
Name ACOS: [5]DAT2!#REF!
Name ACOS: [6]DAT2!#REF!
Name ACOS: [7]DAT2!#REF!
Name ACOS: [8]DAT2!#REF!
Name ACOS: [9]DAT2!#REF!
Name ALAJU: [1]DAT2!#REF!
Name ALAJU: [2]DAT2!#REF!
Name ALAJU: [3]DAT2!#REF!
Name ALAJU: [4]DAT2!#REF!
Name ALAJU: [5]DAT2!#REF!
Name ALAJU: [6]DAT2!#REF!
Name ALAJU: [7]DAT2!#REF!
Name ALAJU: [8]DAT2!#REF!
Name ALAJU: [9]DAT2!#REF!
Name ALAJUE: [1]DAT2!#REF!
Name ALAJUE: [2]DAT2!#REF!
Name ALAJUE: [3]DAT2!#REF!
Name ALAJUE: [4]DAT2!#REF!
Name ALAJUE: [5]DAT2!#REF!
Name ALAJUE: [6]DAT2!#REF!
Name ALAJUE: [7]DAT2!#REF!
Name ALAJUE: [8]DAT2!#REF!
Name ALAJUE: [9]DAT2!#REF!
Name ALVA: [1]DAT2!#REF!
Name ALVA: [2]DAT2!#REF!
Name ALVA: [3]DAT2!#REF!
Name ALVA: [4]DAT2!#REF!
Name ALVA: [5]DAT2!#REF!
Name ALVA: [6]DAT2!#REF!
Name ALVA: [7]DAT2!#REF!
Name ALVA: [8]DAT2!#REF!
Name ALVA: [9]DAT2!#REF!
Name ASERR: [1]DAT2!#REF!
Name ASERR: [2]DAT2!#REF!
Name ASERR: [3]DAT2!#REF!
Name ASERR: [4]DAT2!#REF!
Name ASERR: [5]DAT2!#REF!
Name ASERR: [6]DAT2!#REF!
Name ASERR: [7]DAT2!#REF!
Name ASERR: [8]DAT2!#REF!
Name ASERR: [9]DAT2!#REF!
Name ATE: [1]DAT2!#REF!
Name ATE: [2]DAT2!#REF!
Name ATE: [3]DAT2!#REF!
Name ATE: [4]DAT2!#REF!
Name ATE: [5]DAT2!#REF!
Name ATE: [6]DAT2!#REF!

Sheet D71 Puntarenas
A1: PROGRAMA | B1: D71 PUNTARENAS | C1: META | D1: AVANCE | E1: ENERO | F1: FEBRERO | G1: MARZO | H1: ABRIL | I1: MAYO | J1: JUNIO | K1: JULIO | L1: AGOSTO | M1: SEPTIEMBRE | N1: OCTUBRE | O1: NOVIEMBRE | P1: DICIEMBRE
C2: 2026 | D2: Porcentual
A3: PSCC | B3: Cuatro actividades de recuperación de espacios públicos, con las comunidades integradas al Programa de Seguridad Comunitaria, que se localicen, en los distritos que contemplan las área georreferenciadas del informe territorial de la Estrategia Sembremos Seguridad 2024, dos por año, una por semestre. | C3: 2 | D3: =SUM(E3:P3) -> 0
A4: GREAT/MPAS/DARE | B4: Realizar 4 procesos formativos (Cursos de la oferta de los programas DARE - GREAT - MPAS) en Centros Educativos, 2 por año, dentro de los distritos que contemplan las áreas georreferenciadas del informe territorial de la Estrategia Sembremos Seguridad 2024. Un curso diferente por semestre, un nivel completo. En caso de no contar con instructor acreditado DARE, se puede cumplir la meta con las charlas de Habilidades para la vida DARE, con el aval del Coordinador Nacional. | C4: 2 | D4: =SUM(E4:P4) -> 1 | E4: 0 | F4: 0 | G4: 0 | H4: 0 | I4: 1
A5: DARE | B5: Cubrir 4 procesos formativos en Centros Educativos (dos por año) ubicados dentro de los distritos que contemplan las áreas georreferenciadas del informe territorial de la Estrategia Sembremos Seguridad 2024, con los cursos del Programa DARE: , Curso primaria. Curso Secundaria; un nivel completo por centro educativo, por semestre. En caso de no contar con instructor acreditado, se puede cumplir la meta con las charlas de Habilidades para la vida DARE, con el aval del Coordinador Nacional. | C5: 2 | D5: =SUM(E5:P5) -> 0 | E5: 0 | F5: 0 | G5: 0 | H5: 0
A6: PLAN DE POLITICA LOCAL E IMPLEMENTACIÓN DE LA POLITICA LOCAL DE SEGURIDAD | B6: Conformación Comité | C6: 3 | D6: =SUM(E6:O6) -> 2 | E6: 1 | H6: 1
B7: Conformación de Comercio | C7: 3 | D7: =SUM(E7:O7) -> 3 | H7: 3
B8: Reuniones-Jefaturas | C8: 160 | D8: =SUM(E8:O8) -> 70 | E8: 7 | F8: 11 | G8: 19 | H8: 15 | I8: 16 | J8: 2
B9: Campañas de divulgación | C9: 123 | D9: =SUM(E9:O9) -> 39 | G9: 39
B10: Capacitaciones | C10: 0 | D10: =SUM(E10:O10) -> 0
B11: Charlas | C11: 0 | D11: =SUM(E11:O11) -> 0
B12: Talleres | C12: 0 | D12: =SUM(E12:O12) -> 0
B13: Sensibilización | C13: 0 | D13: =SUM(E13:O13) -> 0
B14: Actividades deportivas | C14: 0 | D14: =SUM(E14:O14) -> 0
B15: Cine en mi Barrio | C15: 0 | D15: =SUM(E15:O15) -> 0
B16: Cívico-policial | C16: 36 | D16: =SUM(E16:O16) -> 0
B17: Actividades culturales | C17: 0 | D17: =SUM(E17:O17) -> 0
B18: Ferias | C18: 0 | D18: =SUM(E18:O18) -> 0
B19: Stand informativo | C19: 0 | D19: =SUM(E19:O19) -> 0
B20: Visitas | C20: 169 | D20: =SUM(E20:O20) -> 84 | F20: 42 | I20: 42
B21: Recuperación del espacio público | C21: 0 | D21: =SUM(E21:O21) -> 0
B22: Convocatoria de Mesas Locales | C22: 1 | D22: =SUM(E22:O22) -> 1 | G22: 1
B23: Exposición Informe Territorial ESS | C23: 1 | D23: =SUM(E23:O23) -> 1 | I23: 1
B24: Primera Sesión de Trabajo | C24: 1 | D24: =SUM(E24:O24) -> 1 | I24: 1
B25: Segunda Sesión - Conformación Secretaria Técnica | C25: 1 | D25: =SUM(E25:O25) -> 0
B26: Tercera Sesión | C26: 1 | D26: =SUM(E26:O26) -> 0
B27: Elaboracióin del Texto de la Política Local | C27: 1 | D27: =SUM(E27:O27) -> 0
B28: Revisión Técnica DPPP | C28: 1 | D28: =SUM(E28:O28) -> 0
B29: Revisión Area Legal Gobierno Local | C29: 1 | D29: =SUM(E29:O29) -> 0
B30: Incorporación de Observaciones | C30: 1 | D30: =SUM(E30:O30) -> 0
B31: Aval del Director Regional | C31: 1 | D31: =SUM(E31:O31) -> 0
B32: Presentación al Consejo Municipal | C32: 1 | D32: =SUM(E32:O32) -> 0
B33: Presentación ante la Comunidad por parte del Director Regional y Alcalde | C33: 1 | D33: =SUM(E33:O33) -> 0
C34: =SUM(C3:C33) -> 512 | D34: =SUM(D3:D33) -> 202
D35: =D34/C34 -> 0.39453125

Sheet D72 Esparza
A1: PROGRAMA | B1: D72 ESPARZA | C1: META | D1: AVANCE | E1: ENERO | F1: FEBRERO | G1: MARZO | H1: ABRIL | I1: MAYO | J1: JUNIO | K1: JULIO | L1: AGOSTO | M1: SEPTIEMBRE | N1: OCTUBRE | O1: NOVIEMBRE | P1: DICIEMBRE
C2: 2026 | D2: Porcentual
A3: PSCC | B3: Cuatro actividades de recuperación de espacios públicos, con las comunidades integradas al Programa de Seguridad Comunitaria, que se localicen, en los distritos que contemplan las área georreferenciadas del informe territorial de la Estrategia Sembremos Seguridad 2024, dos por año, una por semestre. | C3: 2 | D3: =SUM(E3:P3) -> 1 | H3: 1
A4: GREAT/MPAS/DARE | B4: Realizar 4 procesos formativos (Cursos de la oferta de los programas DARE - GREAT - MPAS) en Centros Educativos, 2 por año, dentro de los distritos que contemplan las áreas georreferenciadas del informe territorial de la Estrategia Sembremos Seguridad 2024. Un curso diferente por semestre, un nivel completo. En caso de no contar con instructor acreditado DARE, se puede cumplir la meta con las charlas de Habilidades para la vida DARE, con el aval del Coordinador Nacional. | C4: 2 | D4: =SUM(E4:P4) -> 1 | E4: 0 | F4: 0 | G4: 0 | H4: 1
A5: PSCC | B5: Dos estrategias de divulgación (Por medio de brochures, post o imágenes en redes sociales) en el tema del procedimiento para realizar una "Denuncia de ventas de drogas" diseñadas por la Estrategia de divulgación de la Dirección de Programas Policiales Preventivos dirigidas a las comunidades integradas al Programa de Seguridad Comunitaria que se localicen, en los distritos que contemplan las área georreferenciadas del informe territorial de la Estrategia Sembremos Seguridad 2024, una por año. | C5: 1 | D5: =SUM(E5:P5) -> 1 | E5: 1
A6: PSCC | B6: Cuatro Charlas de Cultura Preventiva (Dos por año) con énfasis en temas de estafa dirigidas a las comunidades integradas al Programa de Seguridad Comunitaria, que se localicen, en los distritos que contemplan las área georreferenciadas del informe territorial de la Estrategia Sembremos Seguridad 2024, dos por año, una por semestre. | C6: 2 | D6: =SUM(E6:P6) -> 1 | I6: 1
A7: PSCC | B7: Dos estrategias de divulgación (Por medio de brochures, post o imágenes en redes sociales) en el tema del procedimiento para realizar una "Denuncia ante Estafas" dirigidas a las comunidades integradas al Programa de Seguridad Comunitaria, que se localicen, en los distritos que contemplan las área georreferenciadas del informe territorial de la Estrategia Sembremos Seguridad 2024, una por año. | C7: 1 | D7: =SUM(E7:P7) -> 0
A8: PSCC | B8: Dos capacitaciones, en el tema "Cultura Preventiva y sitios peligrosos", dirigidas a las comunidades integradas al Programa de Seguridad Comunitaria que se localicen, en los distritos que contemplan las área georreferenciadas del informe territorial de la Estrategia Sembremos Seguridad 2024, una por año | C8: 1 | D8: =SUM(E8:P8) -> 0
A9: PSCC | B9: Dos estrategias de divulgación (Por medio de brochures, post o imágenes en redes sociales) en el tema del procedimiento para realizar una "Denuncia de búnkers" dirigidas a las comunidades integradas al Programa de Seguridad Comunitaria que se localicen, en los distritos que contemplan las área georreferenciadas del informe territorial de la Estrategia Sembremos Seguridad 2024, una por año. | C9: 1 | D9: =SUM(E9:P9) -> 1 | G9: 1
A10: DARE | B10: Cubrir 2 procesos formativos en Centros Educativos (uno por año) ubicados dentro de los distritos que contemplan las áreas georreferenciadas del informe territorial de la Estrategia Sembremos Seguridad 2024, con los cursos del Programa DARE: , Curso primaria. Curso Secundaria; un nivel completo por centro educativo, por semestre. En caso de no contar con instructor acreditado, se puede cumplir la meta con las charlas de Habilidades para la vida DARE, con el aval del Coordinador Nacional. | C10: 1 | D10: =SUM(E10:P10) -> 0
A11: PSCC | B11: Cuatro comercios capacitados e integrados al Programa de Seguridad Comercial que se localicen, en los distritos que contemplan las área georreferenciadas del informe territorial de la Estrategia Sembremos Seguridad 2024, dos por año, una por semestre. | C11: 2 | D11: =SUM(E11:P11) -> 0
A12: PSCC | B12: Cuatro estrategias de divulgación (Por medio de brochures, post o imágenes en redes sociales) diseñadas por la Estrategia de divulgación de la Dirección de Programas Policiales Preventivos, en el tema de "Prevención del Consumo de alcohol en vía pública" dirigidas a las comunidades integradas al Programa de Seguridad Comunitaria y a los comercios integrados al Programa de Seguridad Comercial que se localicen, en los distritos que contemplan las área georreferenciadas del informe territorial de la Estrategia Sembremos Seguridad 2024, dos por año. | C12: 2 | D12: =SUM(E12:P12) -> 1 | E12: 1
A13: PLAN DE POLITICA LOCAL E IMPLEMENTACIÓN DE LA POLITICA LOCAL DE SEGURIDAD | B13: Conformación Comité | C13: 2 | D13: =SUM(E13:O13) -> 0
B14: Conformación de Comercio | C14: 3 | D14: =SUM(E14:O14) -> 0
B15: Reuniones-Jefaturas | C15: 56 | D15: =SUM(E15:O15) -> 22 | E15: 3 | F15: 5 | G15: 5 | H15: 5 | I15: 4
B16: Campañas de divulgación | C16: 50 | D16: =SUM(E16:O16) -> 18 | E16: 5 | F16: 5 | G16: 4 | H16: 4
B17: Capacitaciones | C17: 0 | D17: =SUM(E17:O17) -> 0
B18: Charlas | C18: 2 | D18: =SUM(E18:O18) -> 1 | I18: 1
B19: Talleres | C19: 0 | D19: =SUM(E19:O19) -> 0
B20: Sensibilización | C20: 0 | D20: =SUM(E20:O20) -> 0
B21: Actividades deportivas | C21: 0 | D21: =SUM(E21:O21) -> 0
B22: Cine en mi Barrio | C22: 0 | D22: =SUM(E22:O22) -> 0
B23: Cívico-policial | C23: 0 | D23: =SUM(E23:O23) -> 0
B24: Actividades culturales | C24: 0 | D24: =SUM(E24:O24) -> 0
B25: Ferias | C25: 0 | D25: =SUM(E25:O25) -> 0
B26: Stand informativo | C26: 0 | D26: =SUM(E26:O26) -> 0
B27: Visitas | C27: 134 | D27: =SUM(E27:O27) -> 51 | E27: 20 | F27: 7 | G27: 4 | H27: 19 | J27: 1
B28: Recuperación del espacio público | C28: 2 | D28: =SUM(E28:O28) -> 1 | H28: 1
B29: Convocatoria de Mesas Locales | C29: 6 | D29: =SUM(E29:O29) -> 5 | G29: 5
B30: Exposición Informe Territorial ESS | C30: 6 | D30: =SUM(E30:O30) -> 6 | H30: 5 | I30: 1
B31: Primera Sesión de Trabajo | C31: 6 | D31: =SUM(E31:O31) -> 5 | I31: 5
B32: Segunda Sesión - Conformación Secretaria Técnica | C32: 6 | D32: =SUM(E32:O32) -> 0
B33: Tercera Sesión | C33: 6 | D33: =SUM(E33:O33) -> 0
B34: Elaboracióin del Texto de la Política Local | C34: 1 | D34: =SUM(E34:O34) -> 0
B35: Revisión Técnica DPPP | C35: 1 | D35: =SUM(E35:O35) -> 0
B36: Revisión Area Legal Gobierno Local | C36: 1 | D36: =SUM(E36:O36) -> 0
B37: Incorporación de Observaciones | C37: 1 | D37: =SUM(E37:O37) -> 0
B38: Aval del Director Regional | C38: 1 | D38: =SUM(E38:O38) -> 0
B39: Presentación al Consejo Municipal | C39: 1 | D39: =SUM(E39:O39) -> 0
B40: Presentación ante la Comunidad por parte del Director Regional y Alcalde | C40: 1 | D40: =SUM(E40:O40) -> 0
...

Sheet D73 Montes de Oro
A1: PROGRAMA | B1: D3 MONTES DE ORO | C1: META | D1: AVANCE | E1: ENERO | F1: FEBRERO | G1: MARZO | H1: ABRIL | I1: MAYO | J1: JUNIO | K1: JULIO | L1: AGOSTO | M1: SEPTIEMBRE | N1: OCTUBRE | O1: NOVIEMBRE | P1: DICIEMBRE
C2: 2026 | D2: Porcentual
A3: PSCC | B3: Cuatro actividades de recuperación de espacios públicos, con las comunidades integradas al Programa de Seguridad Comunitaria, que se localicen, en los distritos que contemplan las área georreferenciadas del informe territorial de la Estrategia Sembremos Seguridad 2024, dos por año, una por semestre. | C3: 1 | D3: =SUM(E3:P3) -> 0
A4: GREAT/MPAS/DARE | B4: Realizar 4 procesos formativos (Cursos de la oferta de los programas DARE - GREAT - MPAS) en Centros Educativos, 2 por año, dentro de los distritos que contemplan las áreas georreferenciadas del informe territorial de la Estrategia Sembremos Seguridad 2024. Un curso diferente por semestre, un nivel completo. En caso de no contar con instructor acreditado DARE, se puede cumplir la meta con las charlas de Habilidades para la vida DARE, con el aval del Coordinador Nacional. | C4: 2 | D4: =SUM(E4:P4) -> 1 | E4: 0 | F4: 0 | G4: 0 | H4: 0 | J4: 1
A5: PSCC | B5: Dos estrategias de divulgación (Por medio de brochures, post o imágenes en redes sociales) en el tema del procedimiento para realizar una "Denuncia de ventas de drogas" diseñadas por la Estrategia de divulgación de la Dirección de Programas Policiales Preventivos dirigidas a las comunidades integradas al Programa de Seguridad Comunitaria que se localicen, en los distritos que contemplan las área georreferenciadas del informe territorial de la Estrategia Sembremos Seguridad 2024, una por año. | C5: 2 | D5: =SUM(E5:P5) -> 0
A6: PSCC | B6: Dos estrategias de divulgación (Por medio de brochures, post o imágenes en redes sociales) en el tema del procedimiento para realizar una "Denuncia de receptación" dirigidas a las comunidades integradas al Programa de Seguridad Comunitaria que se localicen, en los distritos que contemplan las área georreferenciadas del informe territorial de la Estrategia Sembremos Seguridad 2024, una por año. | C6: 2 | D6: =SUM(E6:P6) -> 1 | F6: 1
A7: PLAN DE POLITICA LOCAL E IMPLEMENTACIÓN DE LA POLITICA LOCAL DE SEGURIDAD | B7: Conformación Comité | C7: 3 | D7: =SUM(E7:O7) -> 1 | E7: 1
B8: Conformación de Comercio | C8: 3 | D8: =SUM(E8:O8) -> 1 | F8: 1
B9: Reuniones-Jefaturas | C9: 28 | D9: =SUM(E9:O9) -> 12 | E9: 3 | F9: 2 | G9: 2 | H9: 2 | I9: 3
B10: Campañas de divulgación | C10: 68 | D10: =SUM(E10:O10) -> 38 | G10: 9 | H10: 29
B11: Capacitaciones | C11: 0 | D11: =SUM(E11:O11) -> 0
B12: Charlas | C12: 4 | D12: =SUM(E12:O12) -> 0
B13: Talleres | C13: 0 | D13: =SUM(E13:O13) -> 0
B14: Sensibilización | C14: 0 | D14: =SUM(E14:O14) -> 0
B15: Actividades deportivas | C15: 0 | D15: =SUM(E15:O15) -> 0
B16: Cine en mi Barrio | C16: 0 | D16: =SUM(E16:O16) -> 0
B17: Cívico-policial | C17: 0 | D17: =SUM(E17:O17) -> 0
B18: Actividades culturales | C18: 0 | D18: =SUM(E18:O18) -> 0
B19: Ferias | C19: 0 | D19: =SUM(E19:O19) -> 0
B20: Stand informativo | C20: 0 | D20: =SUM(E20:O20) -> 0
B21: Visitas | C21: 46 | D21: =SUM(E21:O21) -> 23 | E21: 23
B22: Recuperación del espacio público | C22: 2 | D22: =SUM(E22:O22) -> 0
B23: Convocatoria de Mesas Locales | C23: 4 | D23: =SUM(E23:O23) -> 4 | G23: 3 | H23: 1
B24: Exposición Informe Territorial ESS | C24: 4 | D24: =SUM(E24:O24) -> 4 | H24: 3 | I24: 1
B25: Primera Sesión de Trabajo | C25: 4 | D25: =SUM(E25:O25) -> 4 | I25: 4
B26: Segunda Sesión - Conformación Secretaria Técnica | C26: 4 | D26: =SUM(E26:O26) -> 0
B27: Tercera Sesión | C27: 4 | D27: =SUM(E27:O27) -> 0
B28: Elaboracióin del Texto de la Política Local | C28: 1 | D28: =SUM(E28:O28) -> 0
B29: Revisión Técnica DPPP | C29: 1 | D29: =SUM(E29:O29) -> 0
B30: Revisión Area Legal Gobierno Local | C30: 1 | D30: =SUM(E30:O30) -> 0
B31: Incorporación de Observaciones | C31: 1 | D31: =SUM(E31:O31) -> 0
B32: Aval del Director Regional | C32: 1 | D32: =SUM(E32:O32) -> 0
B33: Presentación al Consejo Municipal | C33: 1 | D33: =SUM(E33:O33) -> 0
B34: Presentación ante la Comunidad por parte del Director Regional y Alcalde | C34: 1 | D34: =SUM(E34:O34) -> 0
C35: =SUM(C3:C34) -> 188 | D35: =SUM(D3:D34) -> 89
D36: =D35/C35 -> 0.47340426

Sheet D74 Quepos
A1: PROGRAMA | B1: D74 QUEPOS | C1: META | D1: AVANCE | E1: ENERO | F1: FEBRERO | G1: MARZO | H1: ABRIL | I1: MAYO | J1: JUNIO | K1: JULIO | L1: AGOSTO | M1: SEPTIEMBRE | N1: OCTUBRE | O1: NOVIEMBRE | P1: DICIEMBRE
C2: 2026 | D2: Porcentual
A3: PSCC | B3: Dos actividades de recuperación de espacios públicos, con las comunidades integradas al Programa de Seguridad Comunitaria, que se localicen, en los distritos que contemplan las área georreferenciadas del informe territorial de la Estrategia Sembremos Seguridad 2024, una por año. | C3: 1 | D3: =SUM(E3:P3) -> 1 | G3: 1
A4: PSCC | B4: Dos estrategias de divulgación (Por medio de brochures, post o imágenes en redes sociales) en el tema del procedimiento para realizar una "Denuncia de ventas de drogas" dirigidas a las comunidades integradas al Programa de Seguridad Comunitaria que se localicen, en los distritos que contemplan las área georreferenciadas del informe territorial de la Estrategia Sembremos Seguridad 2024, una por año. | C4: 1 | D4: =SUM(E4:P4) -> 1 | H4: 1
A5: DARE | B5: Cubrir 2 procesos formativos en Centros Educativos (uno por año) ubicados dentro de los distritos que contemplan las áreas georreferenciadas del informe territorial de la Estrategia Sembremos Seguridad 2024, con los cursos del Programa DARE: Curso primaria. Curso Secundaria; un nivel completo por centro educativo, por semestre. En caso de no contar con instructor acreditado, se puede cumplir la meta con las charlas de Habilidades para la vida DARE, con el aval del Coordinador Nacional. | C5: 1 | D5: =SUM(E5:P5) -> 1 | J5: 1
A6: PSCC | B6: Dos capacitaciones, en el tema "Cultura Preventiva y sitios peligrosos", dirigidas a las comunidades integradas al Programa de Seguridad Comunitaria que se localicen, en los distritos que contemplan las área georreferenciadas del informe territorial de la Estrategia Sembremos Seguridad 2024, una por año | C6: 1 | D6: =SUM(E6:P6) -> 0
A7: PSCC | B7: Dos estrategias de divulgación (Por medio de brochures, post o imágenes en redes sociales) en el tema del procedimiento para realizar una "Denuncia de búnkers" dirigidas a las comunidades integradas al Programa de Seguridad Comunitaria que se localicen, en los distritos que contemplan las área georreferenciadas del informe territorial de la Estrategia Sembremos Seguridad 2024, una por año. | C7: 1 | D7: =SUM(E7:P7) -> 1 | I7: 1
A8: PSCC | B8: Cuatro capacitaciones, en el tema de Justicia Restaurativa y Resolución Alternativa de Conflictos, dirigidas a las comunidades integradas al Programa de Seguridad Comunitaria que se localicen, en los distritos que contemplan las área georreferenciadas del informe territorial de la Estrategia Sembremos Seguridad 2024, dos por año, una por semestre | C8: 2 | D8: =SUM(E8:P8) -> 0
A9: GREAT/MPAS/DARE | B9: Realizar 2 procesos formativos (Cursos de la oferta de los programas GREAT - MPAS) en Centros Educativos, Uno por año, dentro de los distritos que contemplan las áreas georreferenciadas del informe territorial de la Estrategia Sembremos Seguridad 2024. Un curso diferente por semestre, un nivel completo. | C9: 1 | D9: =SUM(E9:P9) -> 1 | E9: 0 | F9: 0 | G9: 0 | H9: 1
A10: GREAT/MPAS/DARE | B10: Cuatro cursos del componente, Familias GREAT, dirigido a las comunidades integradas al Programa de Seguridad Comunitaria dentro de los distritos que contemplan las áreas georreferenciadas del informe territorial de la Estrategia Sembremos Seguridad 2024, según los lineamientos del programa. | C10: 2 | D10: =SUM(E10:P10) -> 0
A11: PSCC | B11: Dos actividades de recuperación de espacios públicos, con las comunidades integradas al Programa de Seguridad Comunitaria, que se localicen, en los distritos que contemplan las área georreferenciadas del informe territorial de la Estrategia Sembremos Seguridad 2024, una por año. | C11: 1 | D11: =SUM(E11:P11) -> 0
A12: PLAN DE POLITICA LOCAL E IMPLEMENTACIÓN DE LA POLITICA LOCAL DE SEGURIDAD | B12: Conformación Comité | C12: 3 | D12: =SUM(E12:O12) -> 1 | F12: 1
B13: Conformación de Comercio | C13: 3 | D13: =SUM(E13:O13) -> 0
B14: Reuniones-Jefaturas | C14: 32 | D14: =SUM(E14:O14) -> 10 | E14: 2 | F14: 1 | G14: 5 | H14: 2
B15: Campañas de divulgación | C15: 8 | D15: =SUM(E15:O15) -> 8 | H15: 8
B16: Capacitaciones | C16: 0 | D16: =SUM(E16:O16) -> 0
B17: Charlas | C17: 8 | D17: =SUM(E17:O17) -> 0
B18: Talleres | C18: 0 | D18: =SUM(E18:O18) -> 0
B19: Sensibilización | C19: 2 | D19: =SUM(E19:O19) -> 0
B20: Actividades deportivas | C20: 0 | D20: =SUM(E20:O20) -> 0
B21: Cine en mi Barrio | C21: 1 | D21: =SUM(E21:O21) -> 0
B22: Cívico-policial | C22: 0 | D22: =SUM(E22:O22) -> 0
B23: Actividades culturales | C23: 0 | D23: =SUM(E23:O23) -> 0
B24: Ferias | C24: 4 | D24: =SUM(E24:O24) -> 0
B25: Stand informativo | C25: 1 | D25: =SUM(E25:O25) -> 0
B26: Visitas | C26: 111 | D26: =SUM(E26:O26) -> 34 | E26: 3 | F26: 3 | G26: 28
B27: Recuperación del espacio público | C27: 1 | D27: =SUM(E27:O27) -> 0
B28: Convocatoria de Mesas Locales | C28: 3 | D28: =SUM(E28:O28) -> 3 | G28: 3
B29: Exposición Informe Territorial ESS | C29: 3 | D29: =SUM(E29:O29) -> 3 | H29: 3
B30: Primera Sesión de Trabajo | C30: 3 | D30: =SUM(E30:O30) -> 3 | I30: 3
B31: Segunda Sesión - Conformación Secretaria Técnica | C31: 3 | D31: =SUM(E31:O31) -> 0
B32: Tercera Sesión | C32: 3 | D32: =SUM(E32:O32) -> 0
B33: Elaboracióin del Texto de la Política Local | C33: 1 | D33: =SUM(E33:O33) -> 0
B34: Revisión Técnica DPPP | C34: 1 | D34: =SUM(E34:O34) -> 0
B35: Revisión Area Legal Gobierno Local | C35: 1 | D35: =SUM(E35:O35) -> 0
B36: Incorporación de Observaciones | C36: 1 | D36: =SUM(E36:O36) -> 0
B37: Aval del Director Regional | C37: 1 | D37: =SUM(E37:O37) -> 0
B38: Presentación al Consejo Municipal | C38: 1 | D38: =SUM(E38:O38) -> 0
B39: Presentación ante la Comunidad por parte del Director Regional y Alcalde | C39: 1 | D39: =SUM(E39:O39) -> 0
C40: =SUM(C3:C39) -> 207 | D40: =SUM(D3:D39) -> 67
...

Sheet D75 Parrita
A1: PROGRAMA | B1: D75 PARRITA | C1: META | D1: AVANCE | E1: ENERO | F1: FEBRERO | G1: MARZO | H1: ABRIL | I1: MAYO | J1: JUNIO | K1: JULIO | L1: AGOSTO | M1: SEPTIEMBRE | N1: OCTUBRE | O1: NOVIEMBRE | P1: DICIEMBRE
C2: 2026 | D2: Porcentual
A3: PSCC | B3: Cuatro actividades de recuperación de espacios públicos, con las comunidades integradas al Programa de Seguridad Comunitaria, que se localicen, en los distritos que contemplan las área georreferenciadas del informe territorial de la Estrategia Sembremos Seguridad 2024, dos por año, una por semestre. | C3: 2 | D3: =SUM(E3:P3) -> 1 | H3: 1
A4: GREAT/MPAS/DARE | B4: Realizar 4 procesos formativos (Cursos de la oferta de los programas DARE - GREAT - MPAS) en Centros Educativos, 2 por año, dentro de los distritos que contemplan las áreas georreferenciadas del informe territorial de la Estrategia Sembremos Seguridad 2024. Un curso diferente por semestre, un nivel completo. En caso de no contar con instructor acreditado DARE, se puede cumplir la meta con las charlas de Habilidades para la vida DARE, con el aval del Coordinador Nacional. | C4: 2 | D4: =SUM(E4:P4) -> 2 | E4: 0 | F4: 0 | G4: 0 | H4: 0 | I4: 2
A5: DARE | B5: Cubrir 2 procesos formativos en Centros Educativos (uno por año) ubicados dentro de los distritos que contemplan las áreas georreferenciadas del informe territorial de la Estrategia Sembremos Seguridad 2024, con los cursos del Programa DARE: , Curso primaria. Curso Secundaria; un nivel completo por centro educativo, por semestre. En caso de no contar con instructor acreditado, se puede cumplir la meta con las charlas de Habilidades para la vida DARE, con el aval del Coordinador Nacional. | C5: 1 | D5: =SUM(E5:P5) -> 0 | E5: 0 | F5: 0 | G5: 0 | H5: 0
A6: PSCC | B6: Cuatro comercios capacitados e integrados al Programa de Seguridad Comercial que se localicen, en los distritos que contemplan las área georreferenciadas del informe territorial de la Estrategia Sembremos Seguridad 2024, dos por año, una por semestre. | C6: 2 | D6: =SUM(E6:P6) -> 1 | H6: 1
A7: PSCC | B7: Cuatro estrategias de divulgación (Por medio de brochures, post o imágenes en redes sociales) diseñadas por la Estrategia de divulgación de la Dirección de Programas Policiales Preventivos, en el tema de "Prevención del Consumo de alcohol en vía pública" dirigidas a las comunidades integradas al Programa de Seguridad Comunitaria y a los comercios integrados al Programa de Seguridad Comercial que se localicen, en los distritos que contemplan las área georreferenciadas del informe territorial de la Estrategia Sembremos Seguridad 2024, dos por año. | C7: 2 | D7: =SUM(E7:P7) -> 1 | E7: 1
A8: PSCC | B8: Dos estrategias de divulgación (Por medio de brochures, post o imágenes en redes sociales) en el tema del procedimiento para realizar una "Denuncia de ventas de drogas" diseñadas por la Estrategia de divulgación de la Dirección de Programas Policiales Preventivos dirigidas a las comunidades integradas al Programa de Seguridad Comunitaria que se localicen, en los distritos que contemplan las área georreferenciadas del informe territorial de la Estrategia Sembremos Seguridad 2024, una por año. | C8: 1 | D8: =SUM(E8:P8) -> 1 | E8: 1
A9: PLAN DE POLITICA LOCAL E IMPLEMENTACIÓN DE LA POLITICA LOCAL DE SEGURIDAD | B9: Conformación Comité | C9: 2 | D9: =SUM(E9:O9) -> 0
B10: Conformación de Comercio | C10: 2 | D10: =SUM(E10:O10) -> 1 | H10: 1
B11: Reuniones-Jefaturas | C11: 104 | D11: =SUM(E11:O11) -> 44 | E11: 17 | F11: 10 | H11: 17
B12: Campañas de divulgación | C12: 141 | D12: =SUM(E12:O12) -> 71 | G12: 25 | H12: 36 | I12: 10
B13: Capacitaciones | C13: 0 | D13: =SUM(E13:O13) -> 0
B14: Charlas | C14: 13 | D14: =SUM(E14:O14) -> 1 | H14: 1
B15: Talleres | C15: 0 | D15: =SUM(E15:O15) -> 0
B16: Sensibilización | C16: 1 | D16: =SUM(E16:O16) -> 0
B17: Actividades deportivas | C17: 0 | D17: =SUM(E17:O17) -> 0
B18: Cine en mi Barrio | C18: 0 | D18: =SUM(E18:O18) -> 0
B19: Cívico-policial | C19: 15 | D19: =SUM(E19:O19) -> 0
B20: Actividades culturales | C20: 0 | D20: =SUM(E20:O20) -> 0
B21: Ferias | C21: 3 | D21: =SUM(E21:O21) -> 2 | H21: 2
B22: Stand informativo | C22: 1 | D22: =SUM(E22:O22) -> 0
B23: Visitas | C23: 72 | D23: =SUM(E23:O23) -> 36 | E23: 36
B24: Recuperación del espacio público | C24: 2 | D24: =SUM(E24:O24) -> 1 | H24: 1
B25: Convocatoria de Mesas Locales | C25: 0 | D25: =SUM(E25:O25) -> 0
B26: Exposición Informe Territorial ESS | C26: 0 | D26: =SUM(E26:O26) -> 0
B27: Primera Sesión de Trabajo | C27: 0 | D27: =SUM(E27:O27) -> 0
B28: Segunda Sesión - Conformación Secretaria Técnica | C28: 0 | D28: =SUM(E28:O28) -> 0
B29: Tercera Sesión | C29: 0 | D29: =SUM(E29:O29) -> 0
B30: Elaboracióin del Texto de la Política Local | C30: 0 | D30: =SUM(E30:O30) -> 0
B31: Revisión Técnica DPPP | C31: 1 | D31: =SUM(E31:O31) -> 0
B32: Revisión Area Legal Gobierno Local | C32: 1 | D32: =SUM(E32:O32) -> 0
B33: Incorporación de Observaciones | C33: 1 | D33: =SUM(E33:O33) -> 0
B34: Aval del Director Regional | C34: 1 | D34: =SUM(E34:O34) -> 0
B35: Presentación al Consejo Municipal | C35: 1 | D35: =SUM(E35:O35) -> 0
B36: Presentación ante la Comunidad por parte del Director Regional y Alcalde | C36: 1 | D36: =SUM(E36:O36) -> 0
C37: =SUM(C3:C36) -> 372 | D37: =SUM(D3:D36) -> 162
D38: =D37/C37 -> 0.43548387

Sheet D76 Garabito
A1: PROGRAMA | B1: D76 GARABITO | C1: META | D1: AVANCE | E1: ENERO | F1: FEBRERO | G1: MARZO | H1: ABRIL | I1: MAYO | J1: JUNIO | K1: JULIO | L1: AGOSTO | M1: SEPTIEMBRE | N1: OCTUBRE | O1: NOVIEMBRE | P1: DICIEMBRE
C2: 2026 | D2: Porcentual
A3: PSCC | B3: Cuatro actividades de recuperación de espacios públicos, con las comunidades integradas al Programa de Seguridad Comunitaria, que se localicen, en los distritos que contemplan las área georreferenciadas del informe territorial de la Estrategia Sembremos Seguridad 2024, dos por año, una por semestre. | C3: 2 | D3: =SUM(E3:P3) -> 1 | H3: 1
A4: GREAT/MPAS/DARE | B4: Realizar 4 procesos formativos (Cursos de la oferta de los programas DARE - GREAT - MPAS) en Centros Educativos, 2 por año, dentro de los distritos que contemplan las áreas georreferenciadas del informe territorial de la Estrategia Sembremos Seguridad 2024. Un curso diferente por semestre, un nivel completo. En caso de no contar con instructor acreditado DARE, se puede cumplir la meta con las charlas de Habilidades para la vida DARE, con el aval del Coordinador Nacional. | C4: 2 | D4: =SUM(E4:P4) -> 0 | E4: 0 | F4: 0 | G4: 0 | H4: 0
A5: DARE | B5: Cubrir 2 procesos formativos en Centros Educativos (uno por año) ubicados dentro de los distritos que contemplan las áreas georreferenciadas del informe territorial de la Estrategia Sembremos Seguridad 2024, con los cursos del Programa DARE: Curso primaria. Curso Secundaria; un nivel completo por centro educativo, por semestre. En caso de no contar con instructor acreditado, se puede cumplir la meta con las charlas de Habilidades para la vida DARE, con el aval del Coordinador Nacional. | C5: 2 | D5: =SUM(E5:P5) -> 1 | E5: 0 | F5: 0 | G5: 0 | H5: 1
A6: PSCC | B6: Cuatro comercios capacitados e integrados al Programa de Seguridad Comercial que se localicen, en los distritos que contemplan las área georreferenciadas del informe territorial de la Estrategia Sembremos Seguridad 2024, dos por año, una por semestre. | C6: 2 | D6: =SUM(E6:P6) -> 0
A7: PSCC | B7: Cuatro estrategias de divulgación (Por medio de brochures, post o imágenes en redes sociales) diseñadas por la Estrategia de divulgación de la Dirección de Programas Policiales Preventivos, en el tema de "Prevención del Consumo de alcohol en vía pública" dirigidas a las comunidades integradas al Programa de Seguridad Comunitaria y a los comercios integrados al Programa de Seguridad Comercial que se localicen, en los distritos que contemplan las área georreferenciadas del informe territorial de la Estrategia Sembremos Seguridad 2024, dos por año. | C7: 2 | D7: =SUM(E7:P7) -> 1 | F7: 1
A8: PSCC | B8: Dos estrategias de divulgación (Por medio de brochures, post o imágenes en redes sociales) en el tema del procedimiento para realizar una "Denuncia de ventas de drogas" diseñadas por la Estrategia de divulgación de la Dirección de Programas Policiales Preventivos dirigidas a las comunidades integradas al Programa de Seguridad Comunitaria que se localicen, en los distritos que contemplan las área georreferenciadas del informe territorial de la Estrategia Sembremos Seguridad 2024, una por año. | C8: 1 | D8: =SUM(E8:P8) -> 1 | F8: 1
A9: PSCC | B9: Dos capacitaciones, en el tema "Cultura Preventiva y sitios peligrosos", dirigidas a las comunidades integradas al Programa de Seguridad Comunitaria que se localicen, en los distritos que contemplan las área georreferenciadas del informe territorial de la Estrategia Sembremos Seguridad 2024, una por año | C9: 1 | D9: =SUM(E9:P9) -> 1 | J9: 1
A10: PSCC | B10: Dos estrategias de divulgación (Por medio de brochures, post o imágenes en redes sociales) en el tema del procedimiento para realizar una "Denuncia de búnkers" dirigidas a las comunidades integradas al Programa de Seguridad Comunitaria que se localicen, en los distritos que contemplan las área georreferenciadas del informe territorial de la Estrategia Sembremos Seguridad 2024, una por año. | C10: 1 | D10: =SUM(E10:P10) -> 0
A11: PLAN DE POLITICA LOCAL E IMPLEMENTACIÓN DE LA POLITICA LOCAL DE SEGURIDAD | B11: Conformación Comité | C11: 3 | D11: =SUM(E11:O11) -> 1 | H11: 1
B12: Conformación de Comercio | C12: 3 | D12: =SUM(E12:O12) -> 0
B13: Reuniones-Jefaturas | C13: 28 | D13: =SUM(E13:O13) -> 8 | F13: 3 | G13: 2 | I13: 2 | J13: 1
B14: Campañas de divulgación | C14: 14 | D14: =SUM(E14:O14) -> 7 | G14: 7
B15: Capacitaciones | C15: 0 | D15: =SUM(E15:O15) -> 0
B16: Charlas | C16: 7 | D16: =SUM(E16:O16) -> 4 | H16: 3 | J16: 1
B17: Talleres | C17: 0 | D17: =SUM(E17:O17) -> 0
B18: Sensibilización | C18: 0 | D18: =SUM(E18:O18) -> 0
B19: Actividades deportivas | C19: 2 | D19: =SUM(E19:O19) -> 1 | H19: 1
B20: Cine en mi Barrio | C20: 0 | D20: =SUM(E20:O20) -> 0
B21: Cívico-policial | C21: 3 | D21: =SUM(E21:O21) -> 0
B22: Actividades culturales | C22: 0 | D22: =SUM(E22:O22) -> 0
B23: Ferias | C23: 0 | D23: =SUM(E23:O23) -> 0
B24: Stand informativo | C24: 0 | D24: =SUM(E24:O24) -> 0
B25: Visitas | C25: 224 | D25: =SUM(E25:O25) -> 113 | E25: 56 | H25: 56 | J25: 1
B26: Recuperación del espacio público | C26: 2 | D26: =SUM(E26:O26) -> 2 | H26: 1 | J26: 1
B27: Convocatoria de Mesas Locales | C27: 3 | D27: =SUM(E27:O27) -> 3 | G27: 3
B28: Exposición Informe Territorial ESS | C28: 3 | D28: =SUM(E28:O28) -> 3 | H28: 1 | J28: 2
B29: Primera Sesión de Trabajo | C29: 3 | D29: =SUM(E29:O29) -> 3 | H29: 1 | J29: 2
B30: Segunda Sesión - Conformación Secretaria Técnica | C30: 3 | D30: =SUM(E30:O30) -> 0
B31: Tercera Sesión | C31: 3 | D31: =SUM(E31:O31) -> 0
B32: Elaboracióin del Texto de la Política Local | C32: 1 | D32: =SUM(E32:O32) -> 0
B33: Revisión Técnica DPPP | C33: 1 | D33: =SUM(E33:O33) -> 0
B34: Revisión Area Legal Gobierno Local | C34: 1 | D34: =SUM(E34:O34) -> 0
B35: Incorporación de Observaciones | C35: 1 | D35: =SUM(E35:O35) -> 0
B36: Aval del Director Regional | C36: 1 | D36: =SUM(E36:O36) -> 0
B37: Presentación al Consejo Municipal | C37: 1 | D37: =SUM(E37:O37) -> 0
B38: Presentación ante la Comunidad por parte del Director Regional y Alcalde | C38: 1 | D38: =SUM(E38:O38) -> 0
C39: =SUM(C3:C38) -> 321 | D39: =SUM(D3:D38) -> 150
D40: =D39/C39 -> 0.46728972

Sheet D77 Paquera
A1: PROGRAMA | B1: D77 PAQUERA | C1: META | D1: AVANCE | E1: ENERO | F1: FEBRERO | G1: MARZO | H1: ABRIL | I1: MAYO | J1: JUNIO | K1: JULIO | L1: AGOSTO | M1: SEPTIEMBRE | N1: OCTUBRE | O1: NOVIEMBRE | P1: DICIEMBRE
C2: 2026 | D2: Porcentual
A3: GREAT/MPAS/DARE | B3: Realizar 4 procesos formativos (Cursos de la oferta de los programas DARE - GREAT - MPAS) en Centros Educativos, 2 por año, dentro de los distritos que contemplan las áreas georreferenciadas del informe territorial de la Estrategia Sembremos Seguridad 2024. Un curso diferente por semestre, un nivel completo. En caso de no contar con instructor acreditado DARE, se puede cumplir la meta con las charlas de Habilidades para la vida DARE, con el aval del Coordinador Nacional. | C3: 2 | D3: =SUM(E3:P3) -> 0 | E3: 0 | F3: 0 | G3: 0 | H3: 0
A4: PSCC | B4: Dos estrategias de divulgación (Por medio de brochures, post o imágenes en redes sociales) en el tema del procedimiento para realizar una "Denuncia de ventas de drogas" dirigidas a las comunidades integradas al Programa de Seguridad Comunitaria que se localicen, en los distritos que contemplan las área georreferenciadas del informe territorial de la Estrategia Sembremos Seguridad 2024, una por año. | C4: 1 | D4: =SUM(E4:P4) -> 1 | E4: 1
A5: DARE | B5: Cubrir 4 procesos formativos en Centros Educativos (dos por año) ubicados dentro de los distritos que contemplan las áreas georreferenciadas del informe territorial de la Estrategia Sembremos Seguridad 2024, con los cursos del Programa DARE: , Curso primaria. Curso Secundaria; un nivel completo por centro educativo, por semestre. En caso de no contar con instructor acreditado, se puede cumplir la meta con las charlas de Habilidades para la vida DARE, con el aval del Coordinador Nacional. | C5: 2 | D5: =SUM(E5:P5) -> 1 | E5: 0 | F5: 0 | G5: 0 | H5: 1
A6: PSCC | B6: Dos capacitaciones, en el tema "Cultura Preventiva y sitios peligrosos", dirigidas a las comunidades integradas al Programa de Seguridad Comunitaria que se localicen, en los distritos que contemplan las área georreferenciadas del informe territorial de la Estrategia Sembremos Seguridad 2024, una por año | C6: 1 | D6: =SUM(E6:P6) -> 0
A7: PSCC | B7: Dos estrategias de divulgación (Por medio de brochures, post o imágenes en redes sociales) en el tema del procedimiento para realizar una "Denuncia de búnkers" dirigidas a las comunidades integradas al Programa de Seguridad Comunitaria que se localicen, en los distritos que contemplan las área georreferenciadas del informe territorial de la Estrategia Sembremos Seguridad 2024, una por año. | C7: 1 | D7: =SUM(E7:P7) -> 1 | E7: 1
A8: PSCC | B8: Dos capacitaciones, en el tema “Cultura Preventiva y como realizar una Denuncia de robo de vehículo", dirigidas a las comunidades integradas al Programa de Seguridad Comunitaria que se localicen, en los distritos que contemplan las área georreferenciadas del informe territorial de la Estrategia Sembremos Seguridad 2024, una por año. | C8: 1 | D8: =SUM(E8:P8) -> 1 | G8: 1
A9: PSCC | B9: Cuatro estrategias de divulgación (Por medio de brochures, post o imágenes en redes sociales) en el tema del procedimiento para " Cultura Preventiva y como realizar una Denuncia de robo de vehículo " dirigidas a las comunidades integradas al Programa de Seguridad Comunitaria que se localicen, en los distritos que contemplan las área georreferenciadas del informe territorial de la Estrategia Sembremos Seguridad 2024, dos por año, una por semestre. | C9: 2 | D9: =SUM(E9:P9) -> 0
A10: PSCC | B10: Cuatro actividades de recuperación de espacios públicos, con las comunidades integradas al Programa de Seguridad Comunitaria, que se localicen, dentro del área georreferenciada del informe territorial de la Estrategia Sembremos Seguridad 2024, dos por año, una por semestre. | C10: 2 | D10: =SUM(E10:P10) -> 1 | H10: 1
A11: PLAN DE POLITICA LOCAL E IMPLEMENTACIÓN DE LA POLITICA LOCAL DE SEGURIDAD | B11: Conformación Comité | C11: 1 | D11: =SUM(E11:O11) -> 0
B12: Conformación de Comercio | C12: 3 | D12: =SUM(E12:O12) -> 0
B13: Reuniones-Jefaturas | C13: 60 | D13: =SUM(E13:O13) -> 23 | E13: 3 | F13: 8 | G13: 4 | H13: 8
B14: Campañas de divulgación | C14: 60 | D14: =SUM(E14:O14) -> 15 | G14: 15
B15: Capacitaciones | C15: 0 | D15: =SUM(E15:O15) -> 0
B16: Charlas | C16: 0 | D16: =SUM(E16:O16) -> 0
B17: Talleres | C17: 0 | D17: =SUM(E17:O17) -> 0
B18: Sensibilización | C18: 0 | D18: =SUM(E18:O18) -> 0
B19: Actividades deportivas | C19: 0 | D19: =SUM(E19:O19) -> 0
B20: Cine en mi Barrio | C20: 0 | D20: =SUM(E20:O20) -> 0
B21: Cívico-policial | C21: 0 | D21: =SUM(E21:O21) -> 0
B22: Actividades culturales | C22: 0 | D22: =SUM(E22:O22) -> 0
B23: Ferias | C23: 0 | D23: =SUM(E23:O23) -> 0
B24: Stand informativo | C24: 0 | D24: =SUM(E24:O24) -> 0
B25: Visitas | C25: 96 | D25: =SUM(E25:O25) -> 43 | E25: 7 | F25: 12 | G25: 5 | H25: 7 | I25: 12
B26: Recuperación del espacio público | C26: 0 | D26: =SUM(E26:O26) -> 0
B27: Convocatoria de Mesas Locales | C27: 3 | D27: =SUM(E27:O27) -> 3 | G27: 3
B28: Exposición Informe Territorial ESS | C28: 3 | D28: =SUM(E28:O28) -> 3 | H28: 3
B29: Primera Sesión de Trabajo | C29: 3 | D29: =SUM(E29:O29) -> 2 | I29: 2
B30: Segunda Sesión - Conformación Secretaria Técnica | C30: 3 | D30: =SUM(E30:O30) -> 0
B31: Tercera Sesión | C31: 3 | D31: =SUM(E31:O31) -> 0
B32: Elaboracióin del Texto de la Política Local | C32: 0 | D32: =SUM(E32:O32) -> 0
B33: Revisión Técnica DPPP | C33: 0 | D33: =SUM(E33:O33) -> 0
B34: Revisión Area Legal Gobierno Local | C34: 0 | D34: =SUM(E34:O34) -> 0
B35: Incorporación de Observaciones | C35: 0 | D35: =SUM(E35:O35) -> 0
B36: Aval del Director Regional | C36: 0 | D36: =SUM(E36:O36) -> 0
B37: Presentación al Consejo Municipal | C37: 0 | D37: =SUM(E37:O37) -> 0
B38: Presentación ante la Comunidad por parte del Director Regional y Alcalde | C38: 0 | D38: =SUM(E38:O38) -> 0
C39: =SUM(C3:C38) -> 247 | D39: =SUM(D3:D38) -> 94
D40: =D39/C39 -> 0.3805668

Sheet D78 Judas de Chomes
A3: PROGRAMA | B3: D78 JUDAS DE CHOMES | C3: META | D3: AVANCE | E3: ENERO | F3: FEBRERO | G3: MARZO | H3: ABRIL | I3: MAYO | J3: JUNIO | K3: JULIO | L3: AGOSTO | M3: SEPTIEMBRE | N3: OCTUBRE | O3: NOVIEMBRE | P3: DICIEMBRE
B4: (MONTEVERDE) | C4: 2026 | D4: Porcentual
A5: PSCC | B5: Dos actividades de recuperación de espacios públicos, con las comunidades integradas al Programa de Seguridad Comunitaria, que se localicen, en los distritos que contemplan las área georreferenciadas del informe territorial de la Estrategia Sembremos Seguridad 2024, una por año. | C5: 1 | D5: =SUM(E5:P5) -> 1 | I5: 1
A6: GREAT/MPAS/DARE | B6: Realizar 2 procesos formativos (Cursos de la oferta de los programas DARE - GREAT - MPAS) en Centros Educativos, Uno por año, dentro de los distritos que contemplan las áreas georreferenciadas del informe territorial de la Estrategia Sembremos Seguridad 2024. En caso de no contar con instructor acreditado DARE, se puede cumplir la meta con las charlas de Habilidades para la vida DARE, con el aval del Coordinador Nacional. | C6: 1 | D6: =SUM(E6:P6) -> 0 | E6: 0 | F6: 0 | G6: 0 | H6: 0
A7: PSCC | B7: Dos estrategias de divulgación (Por medio de brochures, post o imágenes en redes sociales) en el tema del procedimiento para realizar una "Denuncia de Ventas de drogas" dirigidas a las comunidades integradas al Programa de Seguridad Comunitaria que se localicen, en los distritos que contemplan las área georreferenciadas del informe territorial de la Estrategia Sembremos Seguridad 2024, una por año. | C7: 1 | D7: =SUM(E7:P7) -> 1 | E7: 0 | F7: 0 | G7: 0 | H7: 0 | I7: 1
A8: DARE | B8: Cubrir 2 procesos formativos en Centros Educativos (uno por año) ubicados dentro de los distritos que contemplan las áreas georreferenciadas del informe territorial de la Estrategia Sembremos Seguridad 2024, con los cursos del Programa DARE: Curso primaria. Curso Secundaria; un nivel completo por centro educativo, por semestre. En caso de no contar con instructor acreditado, se puede cumplir la meta con las charlas de Habilidades para la vida DARE, con el aval del Coordinador Nacional. | C8: 1 | D8: =SUM(E8:P8) -> 0
A9: PSCC | B9: Dos capacitaciones, en el tema "Cultura Preventiva y sitios peligrosos", dirigidas a las comunidades integradas al Programa de Seguridad Comunitaria que se localicen, en los distritos que contemplan las área georreferenciadas del informe territorial de la Estrategia Sembremos Seguridad 2024, una por año | C9: 1 | D9: =SUM(E9:P9) -> 0
A10: PSCC | B10: Dos estrategias de divulgación (Por medio de brochures, post o imágenes en redes sociales) en el tema del procedimiento para realizar una "Denuncia de búnkers" dirigidas a las comunidades integradas al Programa de Seguridad Comunitaria que se localicen, en los distritos que contemplan las área georreferenciadas del informe territorial de la Estrategia Sembremos Seguridad 2024, una por año. | C10: 1 | D10: =SUM(E10:P10) -> 0
A11: PSCC | B11: Dos capacitaciones, en el tema "Cultura Preventiva y auto cuidado para evitar Hurtos", dirigidas a las comunidades integradas al Programa de Seguridad Comunitaria que se localicen, en los distritos que contemplan las área georreferenciadas del informe territorial de la Estrategia Sembremos Seguridad 2024, una por año. | C11: 1 | D11: =SUM(E11:P11) -> 0
A12: PSCC | B12: Dos estrategias de divulgación (Por medio de brochures, post o imágenes en redes sociales) en el tema del procedimiento para realizar una "Denuncia en caso de Hurtos" dirigidas a las comunidades integradas al Programa de Seguridad Comunitaria que se localicen, en los distritos que contemplan las área georreferenciadas del informe territorial de la Estrategia Sembremos Seguridad 2024, una por año. | C12: 1 | D12: =SUM(E12:P12) -> 0
A13: MONTEVERDE
A14: PSCC | B14: Dos actividades de recuperación de espacios públicos, con las comunidades integradas al Programa de Seguridad Comunitaria, que se localicen, en los distritos que contemplan las área georreferenciadas del informe territorial de la Estrategia Sembremos Seguridad 2024, una por año. | C14: 1 | D14: =SUM(E14:P14) -> 0
A15: GREAT/MPAS/DARE | B15: Realizar 2 procesos formativos (Cursos de la oferta de los programas DARE - GREAT - MPAS) en Centros Educativos, Uno por año, dentro de los distritos que contemplan las áreas georreferenciadas del informe territorial de la Estrategia Sembremos Seguridad 2024. En caso de no contar con instructor acreditado DARE, se puede cumplir la meta con las charlas de Habilidades para la vida DARE, con el aval del Coordinador Nacional. | C15: 1 | D15: =SUM(E15:P15) -> 0
A16: PSCC | B16: Dos estrategias de divulgación (Por medio de brochures, post o imágenes en redes sociales) en el tema del procedimiento para realizar una "Denuncia de Ventas de drogas" dirigidas a las comunidades integradas al Programa de Seguridad Comunitaria que se localicen, en los distritos que contemplan las área georreferenciadas del informe territorial de la Estrategia Sembremos Seguridad 2024, una por año. | C16: 1 | D16: =SUM(E16:P16) -> 0
A17: PLAN DE POLITICA LOCAL E IMPLEMENTACIÓN DE LA POLITICA LOCAL DE SEGURIDAD | B17: Conformación Comité | C17: 3 | D17: =SUM(E17:O17) -> 0
B18: Conformación de Comercio | C18: 3 | D18: =SUM(E18:O18) -> 0
B19: Reuniones-Jefaturas | C19: 44 | D19: =SUM(E19:O19) -> 22 | E19: 11 | H19: 11
B20: Campañas de divulgación | C20: 78 | D20: =SUM(E20:O20) -> 31 | G20: 11 | H20: 20
B21: Capacitaciones | C21: 0 | D21: =SUM(E21:O21) -> 0
B22: Charlas | C22: 11 | D22: =SUM(E22:O22) -> 0
B23: Talleres | C23: 0 | D23: =SUM(E23:O23) -> 0
B24: Sensibilización | C24: 0 | D24: =SUM(E24:O24) -> 0
B25: Actividades deportivas | C25: 0 | D25: =SUM(E25:O25) -> 0
B26: Cine en mi Barrio | C26: 0 | D26: =SUM(E26:O26) -> 0
B27: Cívico-policial | C27: 0 | D27: =SUM(E27:O27) -> 0
B28: Actividades culturales | C28: 0 | D28: =SUM(E28:O28) -> 0
B29: Ferias | C29: 0 | D29: =SUM(E29:O29) -> 0
B30: Stand informativo | C30: 8 | D30: =SUM(E30:O30) -> 0
B31: Visitas | C31: 56 | D31: =SUM(E31:O31) -> 28 | E31: 28
B32: Recuperación del espacio público | C32: 3 | D32: =SUM(E32:O32) -> 2 | I32: 2
B33: Convocatoria de Mesas Locales | C33: 7 | D33: =SUM(E33:O33) -> 7 | G33: 7
B34: Exposición Informe Territorial ESS | C34: 7 | D34: =SUM(E34:O34) -> 7 | H34: 7
B35: Primera Sesión de Trabajo | C35: 7 | D35: =SUM(E35:O35) -> 7 | I35: 7
B36: Segunda Sesión - Conformación Secretaria Técnica | C36: 7 | D36: =SUM(E36:O36) -> 0
B37: Tercera Sesión | C37: 7 | D37: =SUM(E37:O37) -> 0
B38: Elaboracióin del Texto de la Política Local | C38: 2 | D38: =SUM(E38:O38) -> 0
B39: Revisión Técnica DPPP | C39: 2 | D39: =SUM(E39:O39) -> 0
B40: Revisión Area Legal Gobierno Local | C40: 2 | D40: =SUM(E40:O40) -> 0
B41: Incorporación de Observaciones | C41: 2 | D41: =SUM(E41:O41) -> 0
B42: Aval del Director Regional | C42: 2 | D42: =SUM(E42:O42) -> 0
...

Sheet Total Región
A1: Delegación | C1: META | D1: AVANCE | E1: % AVANCE
A2: D71 | B2: PUNTARENAS | C2: ='D71 Puntarenas'!C34 -> 512 | D2: ='D71 Puntarenas'!D34 -> 202 | E2: =D2/C2 -> 0.39453125
A3: D72 | B3: ESPARZA | C3: ='D72 Esparza'!C41 -> 301 | D3: ='D72 Esparza'!D41 -> 115 | E3: =D3/C3 -> 0.3820598
A4: D73 | B4: MONTES DE ORO | C4: ='D73 Montes de Oro'!C35 -> 188 | D4: ='D73 Montes de Oro'!D35 -> 89 | E4: =D4/C4 -> 0.47340426
A5: D74 | B5: QUEPOS | C5: ='D74 Quepos'!C40 -> 207 | D5: ='D74 Quepos'!D40 -> 67 | E5: =D5/C5 -> 0.3236715
A6: D75 | B6: PARRITA | C6: ='D75 Parrita'!C37 -> 372 | D6: ='D75 Parrita'!D37 -> 162 | E6: =D6/C6 -> 0.43548387
A7: D76 | B7: GARABITO | C7: ='D76 Garabito'!C39 -> 321 | D7: ='D76 Garabito'!D39 -> 150 | E7: =D7/C7 -> 0.46728972
A8: D77 | B8: PAQUERA | C8: ='D77 Paquera'!C39 -> 247 | D8: ='D77 Paquera'!D39 -> 94 | E8: =D8/C8 -> 0.3805668
A9: D78 | B9: JUDAS DE CHOMES | C9: ='D78 Judas de Chomes'!C45 -> 266 | D9: ='D78 Judas de Chomes'!D45 -> 106 | E9: =D9/C9 -> 0.39849624
B10: TOTALES | C10: =SUM(C2:C9) -> 2414 | D10: =SUM(D2:D9) -> 985 | E10: =D10/C10 -> 0.40803645
