Workbook
Name ABANG: [1]DAT2!#REF!
Name ABANG: [2]DAT2!#REF!
Name ABANG: [3]DAT2!#REF!
Name ABANG: [4]DAT2!#REF!
Name ABANG: [5]DAT2!#REF!
Name ACOS: [1]DAT2!#REF!
Name ACOS: [2]DAT2!#REF!
Name ACOS: [3]DAT2!#REF!
Name ACOS: [4]DAT2!#REF!
Name ACOS: [5]DAT2!#REF!
Name ALAJU: [1]DAT2!#REF!
Name ALAJU: [2]DAT2!#REF!
Name ALAJU: [3]DAT2!#REF!
Name ALAJU: [4]DAT2!#REF!
Name ALAJU: [5]DAT2!#REF!
Name ALAJUE: [1]DAT2!#REF!
Name ALAJUE: [2]DAT2!#REF!
Name ALAJUE: [3]DAT2!#REF!
Name ALAJUE: [4]DAT2!#REF!
Name ALAJUE: [5]DAT2!#REF!
Name ALVA: [1]DAT2!#REF!
Name ALVA: [2]DAT2!#REF!
Name ALVA: [3]DAT2!#REF!
Name ALVA: [4]DAT2!#REF!
Name ALVA: [5]DAT2!#REF!
Name ASERR: [1]DAT2!#REF!
Name ASERR: [2]DAT2!#REF!
Name ASERR: [3]DAT2!#REF!
Name ASERR: [4]DAT2!#REF!
Name ASERR: [5]DAT2!#REF!
Name ATE: [1]DAT2!#REF!
Name ATE: [2]DAT2!#REF!
Name ATE: [3]DAT2!#REF!
Name ATE: [4]DAT2!#REF!
Name ATE: [5]DAT2!#REF!
Name BAGAC: [1]DAT2!#REF!
Name BAGAC: [2]DAT2!#REF!
Name BAGAC: [3]DAT2!#REF!
Name BAGAC: [4]DAT2!#REF!
Name BAGAC: [5]DAT2!#REF!
Name BARV: [1]DAT2!#REF!
Name BARV: [2]DAT2!#REF!
Name BARV: [3]DAT2!#REF!
Name BARV: [4]DAT2!#REF!
Name BARV: [5]DAT2!#REF!
Name BEL: [1]DAT2!#REF!
Name BEL: [2]DAT2!#REF!
Name BEL: [3]DAT2!#REF!
Name BEL: [4]DAT2!#REF!
Name BEL: [5]DAT2!#REF!
Name BUEN: [1]DAT2!#REF!
Name BUEN: [2]DAT2!#REF!
Name BUEN: [3]DAT2!#REF!
Name BUEN: [4]DAT2!#REF!
Name BUEN: [5]DAT2!#REF!
Name CANTÓNN: [5]!Tabla103[#All]
Name CAÑ: [1]DAT2!#REF!
Name CAÑ: [2]DAT2!#REF!
Name CAÑ: [3]DAT2!#REF!
Name CAÑ: [4]DAT2!#REF!

Sheet D88 Limón
A1: PROGRAMA | B1: D88 LIMÓN | C1: META | D1: AVANCE | E1: ENERO | F1: FEBRERO | G1: MARZO | H1: ABRIL | I1: MAYO | J1: JUNIO | K1: JULIO | L1: AGOSTO | M1: SEPTIEMBRE | N1: OCTUBRE | O1: NOVIEMBRE | P1: DICIEMBRE
C2: 2026 | D2: Porcentual
A3: GREAT/MPAS/DARE | B3: Realizar 2 procesos formativos (Cursos de la oferta de los programas DARE - GREAT - MPAS) en Centros Educativos, Uno por año, dentro de los distritos que contemplan las áreas georreferenciadas del informe territorial de la Estrategia Sembremos Seguridad 2024. En caso de no contar con instructor acreditado DARE, se puede cumplir la meta con las charlas de Habilidades para la vida DARE, con el aval del Coordinador Nacional. | C3: 2 | D3: =SUM(E3:P3) -> 3 | E3: 0 | F3: 0 | G3: 0 | H3: 1 | I3: 1 | J3: 1
A4: PSCC | B4: Dos estrategias de divulgación (Por medio de brochures, post o imágenes en redes sociales) en el tema del procedimiento para realizar una "Denuncia de ventas de drogas" dirigidas a las comunidades integradas al Programa de Seguridad Comunitaria que se localicen, en los distritos que contemplan las área georreferenciadas del informe territorial de la Estrategia Sembremos Seguridad 2024, una por año. | C4: 1 | D4: =SUM(E4:P4) -> 0
A5: PSCC | B5: Cuatro capacitaciones, en el tema de "Denuncia a búnkers", dirigidas a las comunidades integradas al Programa de Seguridad Comunitaria que se localicen, en los distritos que contemplan las área georreferenciadas del informe territorial de la Estrategia Sembremos Seguridad 2024, dos por año, una por semestre. | C5: 2 | D5: =SUM(E5:P5) -> 0
A6: PSCC | B6: Dos estrategias de divulgación (Por medio de brochures, post o imágenes en redes sociales) en el tema del procedimiento para realizar una "Denuncia de búnkers" dirigidas a las comunidades integradas al Programa de Seguridad Comunitaria que se localicen, en los distritos que contemplan las área georreferenciadas del informe territorial de la Estrategia Sembremos Seguridad 2024, una por año. | C6: 1 | D6: =SUM(E6:P6) -> 0
A7: PSCC | B7: Cuatro Charlas de Cultura Preventiva (dos por año) con énfasis en temas de estafa dirigidas a las comunidades integradas al Programa de Seguridad Comunitaria, que se localicen, en los distritos que contemplan las área georreferenciadas del informe territorial de la Estrategia Sembremos Seguridad 2024, dos por año, una por semestre. | C7: 2 | D7: =SUM(E7:P7) -> 0
A8: PSCC | B8: Dos estrategias de divulgación (Por medio de brochures, post o imágenes en redes sociales) en el tema del procedimiento para realizar una "Denuncia ante Estafas" dirigidas a las comunidades integradas al Programa de Seguridad Comunitaria, que se localicen, en los distritos que contemplan las área georreferenciadas del informe territorial de la Estrategia Sembremos Seguridad 2024, una por año. | C8: 1 | D8: =SUM(E8:P8) -> 0
A9: PLAN DE POLITICA LOCAL E IMPLEMENTACIÓN DE LA POLITICA LOCAL DE SEGURIDAD | B9: Conformación Comité | C9: 3 | D9: =SUM(E9:O9) -> 0
B10: Conformación de Comercio | C10: 3 | D10: =SUM(E10:O10) -> 0
B11: Reuniones-Jefaturas | C11: 117 | D11: =SUM(E11:O11) -> 24 | E11: 11 | F11: 7 | H11: 6
B12: Campañas de divulgación | C12: 94 | D12: =SUM(E12:O12) -> 56 | G12: 18 | H12: 38
B13: Capacitaciones | C13: 10 | D13: =SUM(E13:O13) -> 1 | G13: 1
B14: Charlas | C14: 6 | D14: =SUM(E14:O14) -> 1 | G14: 1
B15: Talleres | C15: 0 | D15: =SUM(E15:O15) -> 0
B16: Sensibilización | C16: 0 | D16: =SUM(E16:O16) -> 0
B17: Actividades deportivas | C17: 2 | D17: =SUM(E17:O17) -> 0
B18: Cine en mi Barrio | C18: 2 | D18: =SUM(E18:O18) -> 0
B19: Cívico-policial | C19: 0 | D19: =SUM(E19:O19) -> 0
B20: Actividades culturales | C20: 0 | D20: =SUM(E20:O20) -> 0
B21: Ferias | C21: 0 | D21: =SUM(E21:O21) -> 0
B22: Stand informativo | C22: 0 | D22: =SUM(E22:O22) -> 0
B23: Visitas | C23: 204 | D23: =SUM(E23:O23) -> 103 | E23: 52 | H23: 51
B24: Recuperación del espacio público | C24: 4 | D24: =SUM(E24:O24) -> 3 | F24: 2 | G24: 1
B25: Convocatoria de Mesas Locales | C25: 2 | D25: =SUM(E25:O25) -> 2 | H25: 2
B26: Exposición Informe Territorial ESS | C26: 2 | D26: =SUM(E26:O26) -> 2 | H26: 2
B27: Primera Sesión de Trabajo | C27: 2 | D27: =SUM(E27:O27) -> 2 | I27: 2
B28: Segunda Sesión - Conformación Secretaria Técnica | C28: 2 | D28: =SUM(E28:O28) -> 2 | I28: 2
B29: Tercera Sesión | C29: 2 | D29: =SUM(E29:O29) -> 1 | I29: 1
B30: Elaboracióin del Texto de la Política Local | C30: 1 | D30: =SUM(E30:O30) -> 0
B31: Revisión Técnica DPPP | C31: 1 | D31: =SUM(E31:O31) -> 0
B32: Revisión Area Legal Gobierno Local | C32: 1 | D32: =SUM(E32:O32) -> 0
B33: Incorporación de Observaciones | C33: 1 | D33: =SUM(E33:O33) -> 0
B34: Aval del Director Regional | C34: 1 | D34: =SUM(E34:O34) -> 0
B35: Presentación al Consejo Municipal | C35: 1 | D35: =SUM(E35:O35) -> 0
B36: Presentación ante la Comunidad por parte del Director Regional y Alcalde | C36: 1 | D36: =SUM(E36:O36) -> 0
C37: =SUM(C3:C36) -> 471 | D37: =SUM(D3:D36) -> 200
D38: =D37/C37 -> 0.42462845

Sheet D90 Siquirres
A1: PROGRAMA | B1: D90 SIQUIRRES | C1: META | D1: AVANCE | E1: ENERO | F1: FEBRERO | G1: MARZO | H1: ABRIL | I1: MAYO | J1: JUNIO | K1: JULIO | L1: AGOSTO | M1: SEPTIEMBRE | N1: OCTUBRE | O1: NOVIEMBRE | P1: DICIEMBRE
C2: 2026 | D2: Porcentual
A3: PSCC | B3: Cuatro actividades de recuperación de espacios públicos, con las comunidades integradas al Programa de Seguridad Comunitaria, que se localicen, en los distritos que contemplan las área georreferenciadas del informe territorial de la Estrategia Sembremos Seguridad 2024, dos por año, una por semestre. | C3: 2 | D3: =SUM(E3:P3) -> 0
A4: GREAT/MPAS/DARE | B4: Realizar 2 procesos formativos (Cursos de la oferta de los programas DARE - GREAT - MPAS) en Centros Educativos, Uno por año, dentro de los distritos que contemplan las áreas georreferenciadas del informe territorial de la Estrategia Sembremos Seguridad 2024. En caso de no contar con instructor acreditado DARE, se puede cumplir la meta con las charlas de Habilidades para la vida DARE, con el aval del Coordinador Nacional. | C4: 1 | D4: =SUM(E4:P4) -> 0 | E4: 0 | F4: 0 | G4: 0 | H4: 0
A5: PSCC | B5: Dos estrategias de divulgación (Por medio de brochures, post o imágenes en redes sociales) en el tema del procedimiento para realizar una "Denuncia de ventas de drogas" dirigidas a las comunidades integradas al Programa de Seguridad Comunitaria que se localicen, en los distritos que contemplan las área georreferenciadas del informe territorial de la Estrategia Sembremos Seguridad 2024, una por año. | C5: 1 | D5: =SUM(E5:P5) -> 0
A6: PSCC | B6: Cuatro capacitaciones, en el tema de "Denuncia a búnkers", dirigidas a las comunidades integradas al Programa de Seguridad Comunitaria que se localicen, en los distritos que contemplan las área georreferenciadas del informe territorial de la Estrategia Sembremos Seguridad 2024, dos por año, una por semestre. | C6: 2 | D6: =SUM(E6:P6) -> 1 | I6: 1
A7: PSCC | B7: Dos estrategias de divulgación (Por medio de brochures, post o imágenes en redes sociales) en el tema del procedimiento para realizar una "Denuncia de búnkers" dirigidas a las comunidades integradas al Programa de Seguridad Comunitaria que se localicen, en los distritos que contemplan las área georreferenciadas del informe territorial de la Estrategia Sembremos Seguridad 2024, una por año. | C7: 1 | D7: =SUM(E7:P7) -> 0
A8: PSCC | B8: Dos estrategias de divulgación (Por medio de brochures, post o imágenes en redes sociales) en el tema del procedimiento para realizar una "Denuncia de receptación" dirigidas a las comunidades integradas al Programa de Seguridad Comunitaria, que se localicen, dentro del área georreferenciada del informe territorial de la Estrategia Sembremos Seguridad 2024, una por año. | C8: 1 | D8: =SUM(E8:P8) -> 0
A9: PLAN DE POLITICA LOCAL E IMPLEMENTACIÓN DE LA POLITICA LOCAL DE SEGURIDAD | B9: Conformación Comité | C9: 3 | D9: =SUM(E9:O9) -> 1 | G9: 1
B10: Conformación de Comercio | C10: 3 | D10: =SUM(E10:O10) -> 0
B11: Reuniones-Jefaturas | C11: 96 | D11: =SUM(E11:O11) -> 33 | F11: 13 | G11: 11 | H11: 7 | I11: 1 | J11: 1
B12: Campañas de divulgación | C12: 43 | D12: =SUM(E12:O12) -> 24 | G12: 13 | H12: 11
B13: Capacitaciones | C13: 12 | D13: =SUM(E13:O13) -> 0
B14: Charlas | C14: 8 | D14: =SUM(E14:O14) -> 6 | G14: 1 | H14: 3 | I14: 2
B15: Talleres | C15: 4 | D15: =SUM(E15:O15) -> 0
B16: Sensibilización | C16: 2 | D16: =SUM(E16:O16) -> 0
B17: Actividades deportivas | C17: 1 | D17: =SUM(E17:O17) -> 0
B18: Cine en mi Barrio | C18: 3 | D18: =SUM(E18:O18) -> 0
B19: Cívico-policial | C19: 1 | D19: =SUM(E19:O19) -> 0
B20: Actividades culturales | C20: 0 | D20: =SUM(E20:O20) -> 0
B21: Ferias | C21: 1 | D21: =SUM(E21:O21) -> 0
B22: Stand informativo | C22: 2 | D22: =SUM(E22:O22) -> 0
B23: Visitas | C23: 145 | D23: =SUM(E23:O23) -> 53 | E23: 10 | F23: 18 | G23: 14 | H23: 10 | J23: 1
B24: Recuperación del espacio público | C24: 2 | D24: =SUM(E24:O24) -> 0
B25: Convocatoria de Mesas Locales | C25: 7 | D25: =SUM(E25:O25) -> 7 | G25: 7
B26: Exposición Informe Territorial ESS | C26: 7 | D26: =SUM(E26:O26) -> 7 | H26: 7
B27: Primera Sesión de Trabajo | C27: 7 | D27: =SUM(E27:O27) -> 7 | I27: 7
B28: Segunda Sesión - Conformación Secretaria Técnica | C28: 7 | D28: =SUM(E28:O28) -> 0
B29: Tercera Sesión | C29: 7 | D29: =SUM(E29:O29) -> 0
B30: Elaboracióin del Texto de la Política Local | C30: 1 | D30: =SUM(E30:O30) -> 0
B31: Revisión Técnica DPPP | C31: 1 | D31: =SUM(E31:O31) -> 0
B32: Revisión Area Legal Gobierno Local | C32: 1 | D32: =SUM(E32:O32) -> 0
B33: Incorporación de Observaciones | C33: 1 | D33: =SUM(E33:O33) -> 0
B34: Aval del Director Regional | C34: 1 | D34: =SUM(E34:O34) -> 0
B35: Presentación al Consejo Municipal | C35: 1 | D35: =SUM(E35:O35) -> 0
B36: Presentación ante la Comunidad por parte del Director Regional y Alcalde | C36: 1 | D36: =SUM(E36:O36) -> 0
C37: =SUM(C3:C36) -> 376 | D37: =SUM(D3:D36) -> 139
D38: =D37/C37 -> 0.36968085

Sheet D91 Talamanca
A1: PROGRAMA | B1: D91 TALAMANCA | C1: META | D1: AVANCE | E1: ENERO | F1: FEBRERO | G1: MARZO | H1: ABRIL | I1: MAYO | J1: JUNIO | K1: JULIO | L1: AGOSTO | M1: SEPTIEMBRE | N1: OCTUBRE | O1: NOVIEMBRE | P1: DICIEMBRE
C2: 2026 | D2: Porcentual
A3: PSCC | B3: Cuatro actividades de recuperación de espacios públicos, con las comunidades integradas al Programa de Seguridad Comunitaria, que se localicen, en los distritos que contemplan las área georreferenciadas del informe territorial de la Estrategia Sembremos Seguridad 2024, dos por año, una por semestre. | C3: 2 | D3: =SUM(E3:P3) -> 0
A4: GREAT/MPAS/DARE | B4: Realizar 2 procesos formativos (Cursos de la oferta de los programas DARE - GREAT - MPAS) en Centros Educativos, Uno por año, dentro de los distritos que contemplan las áreas georreferenciadas del informe territorial de la Estrategia Sembremos Seguridad 2024. En caso de no contar con instructor acreditado DARE, se puede cumplir la meta con las charlas de Habilidades para la vida DARE, con el aval del Coordinador Nacional. | C4: 1 | D4: =SUM(E4:P4) -> 0 | E4: 0 | F4: 0 | G4: 0 | H4: 0
A5: DARE | B5: Cubrir 2 procesos formativos en Centros Educativos (uno por año) ubicados dentro de los distritos que contemplan las áreas georreferenciadas del informe territorial de la Estrategia Sembremos Seguridad 2024, con los cursos del Programa DARE: , Curso primaria. Curso Secundaria; un nivel completo por centro educativo, por semestre. En caso de no contar con instructor acreditado, se puede cumplir la meta con las charlas de Habilidades para la vida DARE, con el aval del Coordinador Nacional. | C5: 1 | D5: =SUM(E5:P5) -> 2 | E5: 0 | F5: 0 | G5: 0 | H5: 2
A6: PSCC | B6: Cuatro comercios capacitados e integrados al Programa de Seguridad Comercial que se localicen, en los distritos que contemplan las área georreferenciadas del informe territorial de la Estrategia Sembremos Seguridad 2024, dos por año, una por semestre. | C6: 2 | D6: =SUM(E6:P6) -> 0
A7: PSCC | B7: Cuatro estrategias de divulgación (Por medio de brochures, post o imágenes en redes sociales) diseñadas por la Estrategia de divulgación de la Dirección de Programas Policiales Preventivos, en el tema de "Prevención del Consumo de alcohol en vía pública" dirigidas a las comunidades integradas al Programa de Seguridad Comunitaria y a los comercios integrados al Programa de Seguridad Comercial que se localicen, en los distritos que contemplan las área georreferenciadas del informe territorial de la Estrategia Sembremos Seguridad 2024, dos por año. | C7: 2 | D7: =SUM(E7:P7) -> 1 | G7: 1
A8: PSCC | B8: Dos estrategias de divulgación (Por medio de brochures, post o imágenes en redes sociales) en el tema del procedimiento para realizar una "Denuncia de ventas de drogas" diseñadas por la Estrategia de divulgación de la Dirección de Programas Policiales Preventivos dirigidas a las comunidades integradas al Programa de Seguridad Comunitaria que se localicen, en los distritos que contemplan las área georreferenciadas del informe territorial de la Estrategia Sembremos Seguridad 2024, una por año. | C8: 1 | D8: =SUM(E8:P8) -> 1 | G8: 1
A9: PSCC | B9: Cuatro capacitaciones, en el tema de "Denuncia a búnkers", dirigidas a las comunidades integradas al Programa de Seguridad Comunitaria que se localicen, en los distritos que contemplan las área georreferenciadas del informe territorial de la Estrategia Sembremos Seguridad 2024, dos por año, una por semestre. | C9: 2 | D9: =SUM(E9:P9) -> 2 | G9: 2
A10: PSCC | B10: Dos estrategias de divulgación (Por medio de brochures, post o imágenes en redes sociales) en el tema del procedimiento para realizar una "Denuncia de búnkers" dirigidas a las comunidades integradas al Programa de Seguridad Comunitaria que se localicen, en los distritos que contemplan las área georreferenciadas del informe territorial de la Estrategia Sembremos Seguridad 2024, una por año. | C10: 1 | D10: =SUM(E10:P10) -> 1 | H10: 1
A11: PSCC | B11: Dos estrategias de divulgación (Por medio de brochures, post o imágenes en redes sociales) en el tema del procedimiento para realizar una "Denuncia de receptación" dirigidas a las comunidades integradas al Programa de Seguridad Comunitaria, que se localicen, dentro del área georreferenciada del informe territorial de la Estrategia Sembremos Seguridad 2024, una por año. | C11: 2 | D11: =SUM(E11:P11) -> 1 | G11: 1
A12: PLAN DE POLITICA LOCAL E IMPLEMENTACIÓN DE LA POLITICA LOCAL DE SEGURIDAD | B12: Conformación Comité | C12: 3 | D12: =SUM(E12:O12) -> 0
B13: Conformación de Comercio | C13: 3 | D13: =SUM(E13:O13) -> 0
B14: Reuniones-Jefaturas | C14: 88 | D14: =SUM(E14:O14) -> 39 | F14: 10 | G14: 10 | H14: 13 | I14: 6
B15: Campañas de divulgación | C15: 43 | D15: =SUM(E15:O15) -> 11 | H15: 11
B16: Capacitaciones | C16: 1 | D16: =SUM(E16:O16) -> 0
B17: Charlas | C17: 5 | D17: =SUM(E17:O17) -> 0
B18: Talleres | C18: 0 | D18: =SUM(E18:O18) -> 0
B19: Sensibilización | C19: 0 | D19: =SUM(E19:O19) -> 0
B20: Actividades deportivas | C20: 0 | D20: =SUM(E20:O20) -> 0
B21: Cine en mi Barrio | C21: 1 | D21: =SUM(E21:O21) -> 0
B22: Cívico-policial | C22: 4 | D22: =SUM(E22:O22) -> 0
B23: Actividades culturales | C23: 0 | D23: =SUM(E23:O23) -> 0
B24: Ferias | C24: 0 | D24: =SUM(E24:O24) -> 0
B25: Stand informativo | C25: 2 | D25: =SUM(E25:O25) -> 2 | H25: 2
B26: Visitas | C26: 190 | D26: =SUM(E26:O26) -> 77 | F26: 36 | H26: 3 | I26: 38
B27: Recuperación del espacio público | C27: 2 | D27: =SUM(E27:O27) -> 2 | H27: 2
B28: Convocatoria de Mesas Locales | C28: 4 | D28: =SUM(E28:O28) -> 0
B29: Exposición Informe Territorial ESS | C29: 4 | D29: =SUM(E29:O29) -> 0
B30: Primera Sesión de Trabajo | C30: 4 | D30: =SUM(E30:O30) -> 0
B31: Segunda Sesión - Conformación Secretaria Técnica | C31: 4 | D31: =SUM(E31:O31) -> 0
B32: Tercera Sesión | C32: 4 | D32: =SUM(E32:O32) -> 0
B33: Elaboracióin del Texto de la Política Local | C33: 1 | D33: =SUM(E33:O33) -> 0
B34: Revisión Técnica DPPP | C34: 1 | D34: =SUM(E34:O34) -> 0
B35: Revisión Area Legal Gobierno Local | C35: 1 | D35: =SUM(E35:O35) -> 0
B36: Incorporación de Observaciones | C36: 1 | D36: =SUM(E36:O36) -> 0
B37: Aval del Director Regional | C37: 1 | D37: =SUM(E37:O37) -> 0
B38: Presentación al Consejo Municipal | C38: 1 | D38: =SUM(E38:O38) -> 0
B39: Presentación ante la Comunidad por parte del Director Regional y Alcalde | C39: 1 | D39: =SUM(E39:O39) -> 0
C40: =SUM(C3:C39) -> 383 | D40: =SUM(D3:D39) -> 139
...

Sheet D92 Matina
A1: PROGRAMA | B1: D92 MATINA | C1: META | D1: AVANCE | E1: ENERO | F1: FEBRERO | G1: MARZO | H1: ABRIL | I1: MAYO | J1: JUNIO | K1: JULIO | L1: AGOSTO | M1: SEPTIEMBRE | N1: OCTUBRE | O1: NOVIEMBRE | P1: DICIEMBRE
C2: 2026 | D2: Porcentual
A3: GREAT/MPAS/DARE | B3: Realizar 2 procesos formativos (Cursos de la oferta de los programas DARE - GREAT - MPAS) en Centros Educativos, Uno por año, dentro de los distritos que contemplan las áreas georreferenciadas del informe territorial de la Estrategia Sembremos Seguridad 2024. En caso de no contar con instructor acreditado DARE, se puede cumplir la meta con las charlas de Habilidades para la vida DARE, con el aval del Coordinador Nacional. | C3: 1 | D3: =SUM(E3:P3) -> 0 | E3: 0 | F3: 0 | G3: 0 | H3: 0
A4: PSCC | B4: Dos estrategias de divulgación (Por medio de brochures, post o imágenes en redes sociales) en el tema del procedimiento para realizar una "Denuncia de ventas de drogas" dirigidas a las comunidades integradas al Programa de Seguridad Comunitaria que se localicen, en los distritos que contemplan las área georreferenciadas del informe territorial de la Estrategia Sembremos Seguridad 2024, una por año. | C4: 1 | D4: =SUM(E4:P4) -> 1 | F4: 1
A5: PSCC | B5: Cuatro capacitaciones, en el tema de "Denuncia a búnkers", dirigidas a las comunidades integradas al Programa de Seguridad Comunitaria que se localicen, en los distritos que contemplan las área georreferenciadas del informe territorial de la Estrategia Sembremos Seguridad 2024, dos por año, una por semestre. | C5: 2 | D5: =SUM(E5:P5) -> 1 | F5: 1
A6: PSCC | B6: Dos estrategias de divulgación (Por medio de brochures, post o imágenes en redes sociales) en el tema del procedimiento para realizar una "Denuncia de búnkers" dirigidas a las comunidades integradas al Programa de Seguridad Comunitaria que se localicen, en los distritos que contemplan las área georreferenciadas del informe territorial de la Estrategia Sembremos Seguridad 2024, una por año. | C6: 1 | D6: =SUM(E6:P6) -> 0
A7: PSCC | B7: Cuatro actividades de recuperación de espacios públicos, con las comunidades integradas al Programa de Seguridad Comunitaria, que se localicen, en los distritos que contemplan las área georreferenciadas del informe territorial de la Estrategia Sembremos Seguridad 2024, dos por año, una por semestre. | C7: 2 | D7: =SUM(E7:P7) -> 1 | F7: 1
A8: PLAN DE POLITICA LOCAL E IMPLEMENTACIÓN DE LA POLITICA LOCAL DE SEGURIDAD | B8: Conformación Comité | C8: 3 | D8: =SUM(E8:O8) -> 0
B9: Conformación de Comercio | C9: 3 | D9: =SUM(E9:O9) -> 0
B10: Reuniones-Jefaturas | C10: 100 | D10: =SUM(E10:O10) -> 30 | E10: 4 | F10: 8 | G10: 7 | H10: 4 | I10: 7
B11: Campañas de divulgación | C11: 70 | D11: =SUM(E11:O11) -> 48 | G11: 21 | H11: 27
B12: Capacitaciones | C12: 0 | D12: =SUM(E12:O12) -> 0
B13: Charlas | C13: 17 | D13: =SUM(E13:O13) -> 2 | G13: 2
B14: Talleres | C14: 0 | D14: =SUM(E14:O14) -> 0
B15: Sensibilización | C15: 0 | D15: =SUM(E15:O15) -> 0
B16: Actividades deportivas | C16: 0 | D16: =SUM(E16:O16) -> 0
B17: Cine en mi Barrio | C17: 0 | D17: =SUM(E17:O17) -> 0
B18: Cívico-policial | C18: 0 | D18: =SUM(E18:O18) -> 0
B19: Actividades culturales | C19: 0 | D19: =SUM(E19:O19) -> 0
B20: Ferias | C20: 0 | D20: =SUM(E20:O20) -> 0
B21: Stand informativo | C21: 0 | D21: =SUM(E21:O21) -> 0
B22: Visitas | C22: 107 | D22: =SUM(E22:O22) -> 48 | E22: 24 | H22: 24
B23: Recuperación del espacio público | C23: 2 | D23: =SUM(E23:O23) -> 0
B24: Convocatoria de Mesas Locales | C24: 1 | D24: =SUM(E24:O24) -> 0
B25: Exposición Informe Territorial ESS | C25: 1 | D25: =SUM(E25:O25) -> 1 | G25: 1
B26: Primera Sesión de Trabajo | C26: 1 | D26: =SUM(E26:O26) -> 1 | H26: 1
B27: Segunda Sesión - Conformación Secretaria Técnica | C27: 1 | D27: =SUM(E27:O27) -> 1 | I27: 1
B28: Tercera Sesión | C28: 1 | D28: =SUM(E28:O28) -> 0
B29: Elaboracióin del Texto de la Política Local | C29: 1 | D29: =SUM(E29:O29) -> 0
B30: Revisión Técnica DPPP | C30: 1 | D30: =SUM(E30:O30) -> 0
B31: Revisión Area Legal Gobierno Local | C31: 1 | D31: =SUM(E31:O31) -> 0
B32: Incorporación de Observaciones | C32: 1 | D32: =SUM(E32:O32) -> 0
B33: Aval del Director Regional | C33: 1 | D33: =SUM(E33:O33) -> 0
B34: Presentación al Consejo Municipal | C34: 1 | D34: =SUM(E34:O34) -> 0
B35: Presentación ante la Comunidad por parte del Director Regional y Alcalde | C35: 1 | D35: =SUM(E35:O35) -> 0
C36: =SUM(C3:C35) -> 321 | D36: =SUM(D3:D35) -> 134
D37: =D36/C36 -> 0.41744548

Sheet Total Región
A1: Delegación | C1: META | D1: AVANCE | E1: % AVANCE
A2: D88 | B2: LIMÓN | C2: ='D88 Limón'!C37 -> 471 | D2: ='D88 Limón'!D37 -> 200 | E2: =D2/C2 -> 0.42462845
A3: D90 | B3: SIQUIRRES | C3: ='D90 Siquirres'!C37 -> 376 | D3: ='D90 Siquirres'!D37 -> 139 | E3: =D3/C3 -> 0.36968085
A4: D91 | B4: TALAMANCA | C4: ='D91 Talamanca'!C40 -> 383 | D4: ='D91 Talamanca'!D40 -> 139 | E4: =D4/C4 -> 0.36292428
A5: D92 | B5: MATINA | C5: ='D92 Matina'!C36 -> 321 | D5: ='D92 Matina'!D36 -> 134 | E5: =D5/C5 -> 0.41744548
B6: TOTALES | C6: =SUM(C2:C5) -> 1551 | D6: =SUM(D2:D5) -> 612 | E6: =D6/C6 -> 0.39458414
